&map[app:pachyderm-kube-event-tail container:kube-event-tail filename:/var/log/pods/default_pachyderm-kube-event-tail-7d7764b7c6-dlqgb_5578a06f-b9fd-4705-b06a-00af2a31bcd7/kube-event-tail/0.log job:default/pachyderm-kube-event-tail namespace:default node_name:pach-control-plane pod:pachyderm-kube-event-tail-7d7764b7c6-dlqgb pod_template_hash:7d7764b7c6 stream:stderr suite:pachyderm]
{"level":"info","ts":1714065862.403699,"logger":"maxprocs","caller":"maxprocs/maxprocs.go:47","msg":"maxprocs: Leaving GOMAXPROCS=32: CPU quota undefined"}
{"level":"info","ts":1714065862.4053433,"caller":"server/server.go:160","msg":"app starting","name":"kube-event-tail","version":"0.0.7"}
W0425 17:24:22.405902       1 client_config.go:615] Neither --kubeconfig nor --master was specified.  Using the inClusterConfig.  This might not work.
{"level":"info","ts":1714065862.4063988,"caller":"server/server.go:522","msg":"listening","server":"debug","addr":"[::]:8081"}
{"level":"info","ts":1714065862.4186747,"logger":"event","caller":"kube-event-tail/main.go:98","msg":"0/1 nodes are available: 1 node(s) had untolerated taint {node.kubernetes.io/not-ready: }. preemption: 0/1 nodes are available: 1 Preemption is not helpful for scheduling.","event":{"namespace":"default","name":"console-75f9f5b8d8-qvkwn.17c995ce1786fb19","involvedObject":{"name":"Pod/console-75f9f5b8d8-qvkwn"},"reason":"FailedScheduling","source.component":"default-scheduler","firstTimestamp":1714065845,"lastTimestamp":1714065845,"count":1,"reportingController":"default-scheduler","type":"Warning"}}
{"level":"info","ts":1714065862.418725,"logger":"event","caller":"kube-event-tail/main.go:98","msg":"Successfully assigned default/console-75f9f5b8d8-qvkwn to pach-control-plane","event":{"namespace":"default","name":"console-75f9f5b8d8-qvkwn.17c995ce891cdec4","involvedObject":{"name":"Pod/console-75f9f5b8d8-qvkwn"},"reason":"Scheduled","source.component":"default-scheduler","firstTimestamp":1714065847,"lastTimestamp":1714065847,"count":1,"reportingController":"default-scheduler"}}
{"level":"info","ts":1714065862.4187403,"logger":"event","caller":"kube-event-tail/main.go:98","msg":"Pulling image \"pachyderm/haberdashery:2.8.0-alpha.5\"","event":{"namespace":"default","name":"console-75f9f5b8d8-qvkwn.17c995ceb6ca8b70","involvedObject":{"name":"Pod/console-75f9f5b8d8-qvkwn","fieldPath":"spec.containers{console}"},"reason":"Pulling","source.component":"kubelet","source.host":"pach-control-plane","firstTimestamp":1714065848,"lastTimestamp":1714065848,"count":1,"reportingController":"kubelet","reportingInstance":"pach-control-plane"}}
{"level":"info","ts":1714065862.418746,"logger":"event","caller":"kube-event-tail/main.go:98","msg":"Created pod: console-75f9f5b8d8-qvkwn","event":{"namespace":"default","name":"console-75f9f5b8d8.17c995ce16ad3e28","involvedObject":{"name":"ReplicaSet/console-75f9f5b8d8"},"reason":"SuccessfulCreate","source.component":"replicaset-controller","firstTimestamp":1714065845,"lastTimestamp":1714065845,"count":1,"reportingController":"replicaset-controller"}}
{"level":"info","ts":1714065862.4187508,"logger":"event","caller":"kube-event-tail/main.go:98","msg":"Scaled up replica set console-75f9f5b8d8 to 1","event":{"namespace":"default","name":"console.17c995ce15bf41e0","involvedObject":{"name":"Deployment/console"},"reason":"ScalingReplicaSet","source.component":"deployment-controller","firstTimestamp":1714065845,"lastTimestamp":1714065845,"count":1,"reportingController":"deployment-controller"}}
{"level":"info","ts":1714065862.4187584,"logger":"event","caller":"kube-event-tail/main.go:98","msg":"waiting for first consumer to be created before binding","event":{"namespace":"default","name":"data-postgres-0.17c995ce178274dd","involvedObject":{"name":"PersistentVolumeClaim/data-postgres-0"},"reason":"WaitForFirstConsumer","source.component":"persistentvolume-controller","firstTimestamp":1714065845,"lastTimestamp":1714065845,"count":1,"reportingController":"persistentvolume-controller"}}
{"level":"info","ts":1714065862.4187648,"logger":"event","caller":"kube-event-tail/main.go:98","msg":"Waiting for a volume to be created either by the external provisioner 'rancher.io/local-path' or manually by the system administrator. If volume creation is delayed, please verify that the provisioner is running and correctly registered.","event":{"namespace":"default","name":"data-postgres-0.17c995ce89bbc596","involvedObject":{"name":"PersistentVolumeClaim/data-postgres-0"},"reason":"ExternalProvisioning","source.component":"persistentvolume-controller","firstTimestamp":1714065847,"lastTimestamp":1714065847,"count":1,"reportingController":"persistentvolume-controller"}}
{"level":"info","ts":1714065862.418773,"logger":"event","caller":"kube-event-tail/main.go:98","msg":"External provisioner is provisioning volume for claim \"default/data-postgres-0\"","event":{"namespace":"default","name":"data-postgres-0.17c995ceb051d517","involvedObject":{"name":"PersistentVolumeClaim/data-postgres-0"},"reason":"Provisioning","source.component":"rancher.io/local-path_local-path-provisioner-7577fdbbfb-ldff9_07bdbd19-02b2-4c93-a877-75c260fa3e3f","firstTimestamp":1714065848,"lastTimestamp":1714065848,"count":1}}
{"level":"info","ts":1714065862.4187815,"logger":"event","caller":"kube-event-tail/main.go:98","msg":"Successfully provisioned volume pvc-54fba6d6-16ea-447e-a0d3-f3efb5809454","event":{"namespace":"default","name":"data-postgres-0.17c995cf8cb27219","involvedObject":{"name":"PersistentVolumeClaim/data-postgres-0"},"reason":"ProvisioningSucceeded","source.component":"rancher.io/local-path_local-path-provisioner-7577fdbbfb-ldff9_07bdbd19-02b2-4c93-a877-75c260fa3e3f","firstTimestamp":1714065851,"lastTimestamp":1714065851,"count":1}}
{"level":"info","ts":1714065862.4187899,"logger":"event","caller":"kube-event-tail/main.go:98","msg":"0/1 nodes are available: 1 node(s) had untolerated taint {node.kubernetes.io/not-ready: }. preemption: 0/1 nodes are available: 1 Preemption is not helpful for scheduling.","event":{"namespace":"default","name":"etcd-0.17c995ce19242c87","involvedObject":{"name":"Pod/etcd-0"},"reason":"FailedScheduling","source.component":"default-scheduler","firstTimestamp":1714065845,"lastTimestamp":1714065845,"count":1,"reportingController":"default-scheduler","type":"Warning"}}
{"level":"info","ts":1714065862.4187968,"logger":"event","caller":"kube-event-tail/main.go:98","msg":"Successfully assigned default/etcd-0 to pach-control-plane","event":{"namespace":"default","name":"etcd-0.17c995ce88971826","involvedObject":{"name":"Pod/etcd-0"},"reason":"Scheduled","source.component":"default-scheduler","firstTimestamp":1714065847,"lastTimestamp":1714065847,"count":1,"reportingController":"default-scheduler"}}
{"level":"info","ts":1714065862.4188392,"logger":"event","caller":"kube-event-tail/main.go:98","msg":"Pulling image \"pachyderm/etcd:v3.5.12\"","event":{"namespace":"default","name":"etcd-0.17c995ceb40737e7","involvedObject":{"name":"Pod/etcd-0","fieldPath":"spec.containers{etcd}"},"reason":"Pulling","source.component":"kubelet","source.host":"pach-control-plane","firstTimestamp":1714065848,"lastTimestamp":1714065848,"count":1,"reportingController":"kubelet","reportingInstance":"pach-control-plane"}}
{"level":"info","ts":1714065862.4188488,"logger":"event","caller":"kube-event-tail/main.go:98","msg":"Successfully pulled image \"pachyderm/etcd:v3.5.12\" in 1.476s (5.633s including waiting)","event":{"namespace":"default","name":"etcd-0.17c995d003c9d032","involvedObject":{"name":"Pod/etcd-0","fieldPath":"spec.containers{etcd}"},"reason":"Pulled","source.component":"kubelet","source.host":"pach-control-plane","firstTimestamp":1714065853,"lastTimestamp":1714065853,"count":1,"reportingController":"kubelet","reportingInstance":"pach-control-plane"}}
{"level":"info","ts":1714065862.4188766,"logger":"event","caller":"kube-event-tail/main.go:98","msg":"Created container etcd","event":{"namespace":"default","name":"etcd-0.17c995d0088b6e77","involvedObject":{"name":"Pod/etcd-0","fieldPath":"spec.containers{etcd}"},"reason":"Created","source.component":"kubelet","source.host":"pach-control-plane","firstTimestamp":1714065853,"lastTimestamp":1714065853,"count":1,"reportingController":"kubelet","reportingInstance":"pach-control-plane"}}
{"level":"info","ts":1714065862.4188936,"logger":"event","caller":"kube-event-tail/main.go:98","msg":"Started container etcd","event":{"namespace":"default","name":"etcd-0.17c995d010a12ecb","involvedObject":{"name":"Pod/etcd-0","fieldPath":"spec.containers{etcd}"},"reason":"Started","source.component":"kubelet","source.host":"pach-control-plane","firstTimestamp":1714065854,"lastTimestamp":1714065854,"count":1,"reportingController":"kubelet","reportingInstance":"pach-control-plane"}}
{"level":"info","ts":1714065862.418898,"logger":"event","caller":"kube-event-tail/main.go:98","msg":"create Pod etcd-0 in StatefulSet etcd successful","event":{"namespace":"default","name":"etcd.17c995ce174cb2c7","involvedObject":{"name":"StatefulSet/etcd"},"reason":"SuccessfulCreate","source.component":"statefulset-controller","firstTimestamp":1714065845,"lastTimestamp":1714065845,"count":1,"reportingController":"statefulset-controller"}}
{"level":"info","ts":1714065862.4189026,"logger":"event","caller":"kube-event-tail/main.go:98","msg":"0/1 nodes are available: 1 node(s) had untolerated taint {node.kubernetes.io/not-ready: }. preemption: 0/1 nodes are available: 1 Preemption is not helpful for scheduling.","event":{"namespace":"default","name":"minio-0.17c995cda7dbcb93","involvedObject":{"name":"Pod/minio-0"},"reason":"FailedScheduling","source.component":"default-scheduler","firstTimestamp":1714065843,"lastTimestamp":1714065843,"count":1,"reportingController":"default-scheduler","type":"Warning"}}
{"level":"info","ts":1714065862.418908,"logger":"event","caller":"kube-event-tail/main.go:98","msg":"Successfully assigned default/minio-0 to pach-control-plane","event":{"namespace":"default","name":"minio-0.17c995cfc6da2ecb","involvedObject":{"name":"Pod/minio-0"},"reason":"Scheduled","source.component":"default-scheduler","firstTimestamp":1714065852,"lastTimestamp":1714065852,"count":1,"reportingController":"default-scheduler"}}
{"level":"info","ts":1714065862.4189138,"logger":"event","caller":"kube-event-tail/main.go:98","msg":"Pulling image \"docker.io/minio/minio:latest\"","event":{"namespace":"default","name":"minio-0.17c995cfe13ca954","involvedObject":{"name":"Pod/minio-0","fieldPath":"spec.containers{minio}"},"reason":"Pulling","source.component":"kubelet","source.host":"pach-control-plane","firstTimestamp":1714065853,"lastTimestamp":1714065853,"count":1,"reportingController":"kubelet","reportingInstance":"pach-control-plane"}}
{"level":"info","ts":1714065862.4189188,"logger":"event","caller":"kube-event-tail/main.go:98","msg":"waiting for first consumer to be created before binding","event":{"namespace":"default","name":"minio-data-minio-0.17c995cd773fd953","involvedObject":{"name":"PersistentVolumeClaim/minio-data-minio-0"},"reason":"WaitForFirstConsumer","source.component":"persistentvolume-controller","firstTimestamp":1714065842,"lastTimestamp":1714065842,"count":1,"reportingController":"persistentvolume-controller"}}
{"level":"info","ts":1714065862.4189236,"logger":"event","caller":"kube-event-tail/main.go:98","msg":"Waiting for a volume to be created either by the external provisioner 'rancher.io/local-path' or manually by the system administrator. If volume creation is delayed, please verify that the provisioner is running and correctly registered.","event":{"namespace":"default","name":"minio-data-minio-0.17c995ce258210a4","involvedObject":{"name":"PersistentVolumeClaim/minio-data-minio-0"},"reason":"ExternalProvisioning","source.component":"persistentvolume-controller","firstTimestamp":1714065845,"lastTimestamp":1714065845,"count":2,"reportingController":"persistentvolume-controller"}}
{"level":"info","ts":1714065862.418929,"logger":"event","caller":"kube-event-tail/main.go:98","msg":"External provisioner is provisioning volume for claim \"default/minio-data-minio-0\"","event":{"namespace":"default","name":"minio-data-minio-0.17c995ceb050205c","involvedObject":{"name":"PersistentVolumeClaim/minio-data-minio-0"},"reason":"Provisioning","source.component":"rancher.io/local-path_local-path-provisioner-7577fdbbfb-ldff9_07bdbd19-02b2-4c93-a877-75c260fa3e3f","firstTimestamp":1714065848,"lastTimestamp":1714065848,"count":1}}
{"level":"info","ts":1714065862.418934,"logger":"event","caller":"kube-event-tail/main.go:98","msg":"Successfully provisioned volume pvc-5e3389c7-4d2c-4933-b4cf-5a2f3aa8fe52","event":{"namespace":"default","name":"minio-data-minio-0.17c995cf8c96669c","involvedObject":{"name":"PersistentVolumeClaim/minio-data-minio-0"},"reason":"ProvisioningSucceeded","source.component":"rancher.io/local-path_local-path-provisioner-7577fdbbfb-ldff9_07bdbd19-02b2-4c93-a877-75c260fa3e3f","firstTimestamp":1714065851,"lastTimestamp":1714065851,"count":1}}
{"level":"info","ts":1714065862.4189427,"logger":"event","caller":"kube-event-tail/main.go:98","msg":"create Claim minio-data-minio-0 Pod minio-0 in StatefulSet minio success","event":{"namespace":"default","name":"minio.17c995cd771f5f0a","involvedObject":{"name":"StatefulSet/minio"},"reason":"SuccessfulCreate","source.component":"statefulset-controller","firstTimestamp":1714065842,"lastTimestamp":1714065842,"count":1,"reportingController":"statefulset-controller"}}
{"level":"info","ts":1714065862.4189477,"logger":"event","caller":"kube-event-tail/main.go:98","msg":"create Pod minio-0 in StatefulSet minio successful","event":{"namespace":"default","name":"minio.17c995cda7dae3ed","involvedObject":{"name":"StatefulSet/minio"},"reason":"SuccessfulCreate","source.component":"statefulset-controller","firstTimestamp":1714065843,"lastTimestamp":1714065843,"count":1,"reportingController":"statefulset-controller"}}
{"level":"info","ts":1714065862.4189556,"logger":"event","caller":"kube-event-tail/main.go:98","msg":"Starting kubelet.","event":{"namespace":"default","name":"pach-control-plane.17c995c8921b7ca3","involvedObject":{"namespace":"","name":"Node/pach-control-plane"},"reason":"Starting","source.component":"kubelet","source.host":"pach-control-plane","firstTimestamp":1714065821,"lastTimestamp":1714065821,"count":1,"reportingController":"kubelet","reportingInstance":"pach-control-plane"}}
{"level":"info","ts":1714065862.418964,"logger":"event","caller":"kube-event-tail/main.go:98","msg":"Node pach-control-plane status is now: NodeHasSufficientMemory","event":{"namespace":"default","name":"pach-control-plane.17c995c89295f4a5","involvedObject":{"namespace":"","name":"Node/pach-control-plane"},"reason":"NodeHasSufficientMemory","source.component":"kubelet","source.host":"pach-control-plane","firstTimestamp":1714065821,"lastTimestamp":1714065821,"count":8,"reportingController":"kubelet","reportingInstance":"pach-control-plane"}}
{"level":"info","ts":1714065862.418987,"logger":"event","caller":"kube-event-tail/main.go:98","msg":"Node pach-control-plane status is now: NodeHasNoDiskPressure","event":{"namespace":"default","name":"pach-control-plane.17c995c8929607c9","involvedObject":{"namespace":"","name":"Node/pach-control-plane"},"reason":"NodeHasNoDiskPressure","source.component":"kubelet","source.host":"pach-control-plane","firstTimestamp":1714065821,"lastTimestamp":1714065821,"count":8,"reportingController":"kubelet","reportingInstance":"pach-control-plane"}}
{"level":"info","ts":1714065862.4190016,"logger":"event","caller":"kube-event-tail/main.go:98","msg":"Node pach-control-plane status is now: NodeHasSufficientPID","event":{"namespace":"default","name":"pach-control-plane.17c995c89296131d","involvedObject":{"namespace":"","name":"Node/pach-control-plane"},"reason":"NodeHasSufficientPID","source.component":"kubelet","source.host":"pach-control-plane","firstTimestamp":1714065821,"lastTimestamp":1714065821,"count":7,"reportingController":"kubelet","reportingInstance":"pach-control-plane"}}
{"level":"info","ts":1714065862.4190063,"logger":"event","caller":"kube-event-tail/main.go:98","msg":"Updated Node Allocatable limit across pods","event":{"namespace":"default","name":"pach-control-plane.17c995c8955f0b38","involvedObject":{"namespace":"","name":"Node/pach-control-plane"},"reason":"NodeAllocatableEnforced","source.component":"kubelet","source.host":"pach-control-plane","firstTimestamp":1714065821,"lastTimestamp":1714065821,"count":1,"reportingController":"kubelet","reportingInstance":"pach-control-plane"}}
{"level":"info","ts":1714065862.4190114,"logger":"event","caller":"kube-event-tail/main.go:98","msg":"Starting kubelet.","event":{"namespace":"default","name":"pach-control-plane.17c995ca878f0e2f","involvedObject":{"namespace":"","name":"Node/pach-control-plane"},"reason":"Starting","source.component":"kubelet","source.host":"pach-control-plane","firstTimestamp":1714065830,"lastTimestamp":1714065830,"count":1,"reportingController":"kubelet","reportingInstance":"pach-control-plane"}}
{"level":"info","ts":1714065862.419258,"logger":"event","caller":"kube-event-tail/main.go:98","msg":"Updated Node Allocatable limit across pods","event":{"namespace":"default","name":"pach-control-plane.17c995ca8a6c8422","involvedObject":{"namespace":"","name":"Node/pach-control-plane"},"reason":"NodeAllocatableEnforced","source.component":"kubelet","source.host":"pach-control-plane","firstTimestamp":1714065830,"lastTimestamp":1714065830,"count":1,"reportingController":"kubelet","reportingInstance":"pach-control-plane"}}
{"level":"info","ts":1714065862.4193635,"logger":"event","caller":"kube-event-tail/main.go:98","msg":"Node pach-control-plane status is now: NodeHasSufficientMemory","event":{"namespace":"default","name":"pach-control-plane.17c995ca8dc838e9","involvedObject":{"namespace":"","name":"Node/pach-control-plane"},"reason":"NodeHasSufficientMemory","source.component":"kubelet","source.host":"pach-control-plane","firstTimestamp":1714065830,"lastTimestamp":1714065830,"count":1,"reportingController":"kubelet","reportingInstance":"pach-control-plane"}}
{"level":"info","ts":1714065862.4193754,"logger":"event","caller":"kube-event-tail/main.go:98","msg":"Node pach-control-plane status is now: NodeHasNoDiskPressure","event":{"namespace":"default","name":"pach-control-plane.17c995ca8dc8a00a","involvedObject":{"namespace":"","name":"Node/pach-control-plane"},"reason":"NodeHasNoDiskPressure","source.component":"kubelet","source.host":"pach-control-plane","firstTimestamp":1714065830,"lastTimestamp":1714065830,"count":1,"reportingController":"kubelet","reportingInstance":"pach-control-plane"}}
{"level":"info","ts":1714065862.4193826,"logger":"event","caller":"kube-event-tail/main.go:98","msg":"Node pach-control-plane status is now: NodeHasSufficientPID","event":{"namespace":"default","name":"pach-control-plane.17c995ca8dc8b13a","involvedObject":{"namespace":"","name":"Node/pach-control-plane"},"reason":"NodeHasSufficientPID","source.component":"kubelet","source.host":"pach-control-plane","firstTimestamp":1714065830,"lastTimestamp":1714065830,"count":1,"reportingController":"kubelet","reportingInstance":"pach-control-plane"}}
{"level":"info","ts":1714065862.419394,"logger":"event","caller":"kube-event-tail/main.go:98","msg":"Node pach-control-plane event: Registered Node pach-control-plane in Controller","event":{"namespace":"default","name":"pach-control-plane.17c995cd74245ec8","involvedObject":{"namespace":"","name":"Node/pach-control-plane"},"reason":"RegisteredNode","source.component":"node-controller","firstTimestamp":1714065842,"lastTimestamp":1714065842,"count":1,"reportingController":"node-controller"}}
{"level":"info","ts":1714065862.4194002,"logger":"event","caller":"kube-event-tail/main.go:98","msg":"event without message","event":{"namespace":"default","name":"pach-control-plane.17c995cdd74267d2","involvedObject":{"namespace":"","name":"Node/pach-control-plane"},"reason":"Starting","eventTime":1714065844.5034711,"action":"StartKubeProxy","reportingController":"kube-proxy","reportingInstance":"kube-proxy-pach-control-plane"}}
{"level":"info","ts":1714065862.4194062,"logger":"event","caller":"kube-event-tail/main.go:98","msg":"Node pach-control-plane status is now: NodeReady","event":{"namespace":"default","name":"pach-control-plane.17c995ce23d402b0","involvedObject":{"namespace":"","name":"Node/pach-control-plane"},"reason":"NodeReady","source.component":"kubelet","source.host":"pach-control-plane","firstTimestamp":1714065845,"lastTimestamp":1714065845,"count":1,"reportingController":"kubelet","reportingInstance":"pach-control-plane"}}
{"level":"info","ts":1714065862.4196153,"logger":"event","caller":"kube-event-tail/main.go:98","msg":"0/1 nodes are available: 1 node(s) had untolerated taint {node.kubernetes.io/not-ready: }. preemption: 0/1 nodes are available: 1 Preemption is not helpful for scheduling.","event":{"namespace":"default","name":"pachd-7cbd956bd-nqqsj.17c995ce1b3de680","involvedObject":{"name":"Pod/pachd-7cbd956bd-nqqsj"},"reason":"FailedScheduling","source.component":"default-scheduler","firstTimestamp":1714065845,"lastTimestamp":1714065845,"count":1,"reportingController":"default-scheduler","type":"Warning"}}
{"level":"info","ts":1714065862.4196846,"logger":"event","caller":"kube-event-tail/main.go:98","msg":"Successfully assigned default/pachd-7cbd956bd-nqqsj to pach-control-plane","event":{"namespace":"default","name":"pachd-7cbd956bd-nqqsj.17c995ce891f44d9","involvedObject":{"name":"Pod/pachd-7cbd956bd-nqqsj"},"reason":"Scheduled","source.component":"default-scheduler","firstTimestamp":1714065847,"lastTimestamp":1714065847,"count":1,"reportingController":"default-scheduler"}}
{"level":"info","ts":1714065862.4196992,"logger":"event","caller":"kube-event-tail/main.go:98","msg":"Pulling image \"localhost:5001/pachd:1bf46d7c60913e30814d1b58decdb3c63bef0f10b4177019cdb5cc872460f2f9\"","event":{"namespace":"default","name":"pachd-7cbd956bd-nqqsj.17c995ceb5885fcd","involvedObject":{"name":"Pod/pachd-7cbd956bd-nqqsj","fieldPath":"spec.containers{pachd}"},"reason":"Pulling","source.component":"kubelet","source.host":"pach-control-plane","firstTimestamp":1714065848,"lastTimestamp":1714065848,"count":1,"reportingController":"kubelet","reportingInstance":"pach-control-plane"}}
{"level":"info","ts":1714065862.4199023,"logger":"event","caller":"kube-event-tail/main.go:98","msg":"Successfully pulled image \"localhost:5001/pachd:1bf46d7c60913e30814d1b58decdb3c63bef0f10b4177019cdb5cc872460f2f9\" in 879ms (6.487s including waiting)","event":{"namespace":"default","name":"pachd-7cbd956bd-nqqsj.17c995d0383bfdb0","involvedObject":{"name":"Pod/pachd-7cbd956bd-nqqsj","fieldPath":"spec.containers{pachd}"},"reason":"Pulled","source.component":"kubelet","source.host":"pach-control-plane","firstTimestamp":1714065854,"lastTimestamp":1714065854,"count":1,"reportingController":"kubelet","reportingInstance":"pach-control-plane"}}
{"level":"info","ts":1714065862.4199374,"logger":"event","caller":"kube-event-tail/main.go:98","msg":"Created container pachd","event":{"namespace":"default","name":"pachd-7cbd956bd-nqqsj.17c995d03ad206c5","involvedObject":{"name":"Pod/pachd-7cbd956bd-nqqsj","fieldPath":"spec.containers{pachd}"},"reason":"Created","source.component":"kubelet","source.host":"pach-control-plane","firstTimestamp":1714065854,"lastTimestamp":1714065854,"count":1,"reportingController":"kubelet","reportingInstance":"pach-control-plane"}}
{"level":"info","ts":1714065862.4199471,"logger":"event","caller":"kube-event-tail/main.go:98","msg":"Started container pachd","event":{"namespace":"default","name":"pachd-7cbd956bd-nqqsj.17c995d0417c19c9","involvedObject":{"name":"Pod/pachd-7cbd956bd-nqqsj","fieldPath":"spec.containers{pachd}"},"reason":"Started","source.component":"kubelet","source.host":"pach-control-plane","firstTimestamp":1714065854,"lastTimestamp":1714065854,"count":1,"reportingController":"kubelet","reportingInstance":"pach-control-plane"}}
{"level":"info","ts":1714065862.419953,"logger":"event","caller":"kube-event-tail/main.go:98","msg":"Created pod: pachd-7cbd956bd-nqqsj","event":{"namespace":"default","name":"pachd-7cbd956bd.17c995ce1922048f","involvedObject":{"name":"ReplicaSet/pachd-7cbd956bd"},"reason":"SuccessfulCreate","source.component":"replicaset-controller","firstTimestamp":1714065845,"lastTimestamp":1714065845,"count":1,"reportingController":"replicaset-controller"}}
{"level":"info","ts":1714065862.419958,"logger":"event","caller":"kube-event-tail/main.go:98","msg":"Scaled up replica set pachd-7cbd956bd to 1","event":{"namespace":"default","name":"pachd.17c995ce18283be3","involvedObject":{"name":"Deployment/pachd"},"reason":"ScalingReplicaSet","source.component":"deployment-controller","firstTimestamp":1714065845,"lastTimestamp":1714065845,"count":1,"reportingController":"deployment-controller"}}
{"level":"info","ts":1714065862.4199631,"logger":"event","caller":"kube-event-tail/main.go:98","msg":"0/1 nodes are available: 1 node(s) had untolerated taint {node.kubernetes.io/not-ready: }. preemption: 0/1 nodes are available: 1 Preemption is not helpful for scheduling.","event":{"namespace":"default","name":"pachyderm-kube-event-tail-7d7764b7c6-dlqgb.17c995ce18240fe3","involvedObject":{"name":"Pod/pachyderm-kube-event-tail-7d7764b7c6-dlqgb"},"reason":"FailedScheduling","source.component":"default-scheduler","firstTimestamp":1714065845,"lastTimestamp":1714065845,"count":1,"reportingController":"default-scheduler","type":"Warning"}}
{"level":"info","ts":1714065862.4199696,"logger":"event","caller":"kube-event-tail/main.go:98","msg":"Successfully assigned default/pachyderm-kube-event-tail-7d7764b7c6-dlqgb to pach-control-plane","event":{"namespace":"default","name":"pachyderm-kube-event-tail-7d7764b7c6-dlqgb.17c995ce891b9bb6","involvedObject":{"name":"Pod/pachyderm-kube-event-tail-7d7764b7c6-dlqgb"},"reason":"Scheduled","source.component":"default-scheduler","firstTimestamp":1714065847,"lastTimestamp":1714065847,"count":1,"reportingController":"default-scheduler"}}
{"level":"info","ts":1714065862.419995,"logger":"event","caller":"kube-event-tail/main.go:98","msg":"Pulling image \"pachyderm/kube-event-tail:v0.0.7\"","event":{"namespace":"default","name":"pachyderm-kube-event-tail-7d7764b7c6-dlqgb.17c995ceb673275b","involvedObject":{"name":"Pod/pachyderm-kube-event-tail-7d7764b7c6-dlqgb","fieldPath":"spec.containers{kube-event-tail}"},"reason":"Pulling","source.component":"kubelet","source.host":"pach-control-plane","firstTimestamp":1714065848,"lastTimestamp":1714065848,"count":1,"reportingController":"kubelet","reportingInstance":"pach-control-plane"}}
{"level":"info","ts":1714065862.4200199,"logger":"event","caller":"kube-event-tail/main.go:98","msg":"Successfully pulled image \"pachyderm/kube-event-tail:v0.0.7\" in 1.378s (14s including waiting)","event":{"namespace":"default","name":"pachyderm-kube-event-tail-7d7764b7c6-dlqgb.17c995d1f8f8cb12","involvedObject":{"name":"Pod/pachyderm-kube-event-tail-7d7764b7c6-dlqgb","fieldPath":"spec.containers{kube-event-tail}"},"reason":"Pulled","source.component":"kubelet","source.host":"pach-control-plane","firstTimestamp":1714065862,"lastTimestamp":1714065862,"count":1,"reportingController":"kubelet","reportingInstance":"pach-control-plane"}}
{"level":"info","ts":1714065862.4200299,"logger":"event","caller":"kube-event-tail/main.go:98","msg":"Created container kube-event-tail","event":{"namespace":"default","name":"pachyderm-kube-event-tail-7d7764b7c6-dlqgb.17c995d1fb4c443f","involvedObject":{"name":"Pod/pachyderm-kube-event-tail-7d7764b7c6-dlqgb","fieldPath":"spec.containers{kube-event-tail}"},"reason":"Created","source.component":"kubelet","source.host":"pach-control-plane","firstTimestamp":1714065862,"lastTimestamp":1714065862,"count":1,"reportingController":"kubelet","reportingInstance":"pach-control-plane"}}
{"level":"info","ts":1714065862.4200382,"logger":"event","caller":"kube-event-tail/main.go:98","msg":"Started container kube-event-tail","event":{"namespace":"default","name":"pachyderm-kube-event-tail-7d7764b7c6-dlqgb.17c995d201a459a4","involvedObject":{"name":"Pod/pachyderm-kube-event-tail-7d7764b7c6-dlqgb","fieldPath":"spec.containers{kube-event-tail}"},"reason":"Started","source.component":"kubelet","source.host":"pach-control-plane","firstTimestamp":1714065862,"lastTimestamp":1714065862,"count":1,"reportingController":"kubelet","reportingInstance":"pach-control-plane"}}
{"level":"info","ts":1714065862.4200873,"logger":"event","caller":"kube-event-tail/main.go:98","msg":"Created pod: pachyderm-kube-event-tail-7d7764b7c6-dlqgb","event":{"namespace":"default","name":"pachyderm-kube-event-tail-7d7764b7c6.17c995ce16b0c616","involvedObject":{"name":"ReplicaSet/pachyderm-kube-event-tail-7d7764b7c6"},"reason":"SuccessfulCreate","source.component":"replicaset-controller","firstTimestamp":1714065845,"lastTimestamp":1714065845,"count":1,"reportingController":"replicaset-controller"}}
{"level":"info","ts":1714065862.4200969,"logger":"event","caller":"kube-event-tail/main.go:98","msg":"Scaled up replica set pachyderm-kube-event-tail-7d7764b7c6 to 1","event":{"namespace":"default","name":"pachyderm-kube-event-tail.17c995ce15bf174b","involvedObject":{"name":"Deployment/pachyderm-kube-event-tail"},"reason":"ScalingReplicaSet","source.component":"deployment-controller","firstTimestamp":1714065845,"lastTimestamp":1714065845,"count":1,"reportingController":"deployment-controller"}}
{"level":"info","ts":1714065862.4201016,"logger":"event","caller":"kube-event-tail/main.go:98","msg":"0/1 nodes are available: 1 node(s) had untolerated taint {node.kubernetes.io/not-ready: }. preemption: 0/1 nodes are available: 1 Preemption is not helpful for scheduling.","event":{"namespace":"default","name":"pachyderm-loki-0.17c995ce19a12d62","involvedObject":{"name":"Pod/pachyderm-loki-0"},"reason":"FailedScheduling","source.component":"default-scheduler","firstTimestamp":1714065845,"lastTimestamp":1714065845,"count":1,"reportingController":"default-scheduler","type":"Warning"}}
{"level":"info","ts":1714065862.4201076,"logger":"event","caller":"kube-event-tail/main.go:98","msg":"Successfully assigned default/pachyderm-loki-0 to pach-control-plane","event":{"namespace":"default","name":"pachyderm-loki-0.17c995cfb45bff4f","involvedObject":{"name":"Pod/pachyderm-loki-0"},"reason":"Scheduled","source.component":"default-scheduler","firstTimestamp":1714065852,"lastTimestamp":1714065852,"count":1,"reportingController":"default-scheduler"}}
{"level":"info","ts":1714065862.4201121,"logger":"event","caller":"kube-event-tail/main.go:98","msg":"Pulling image \"grafana/loki:2.6.1\"","event":{"namespace":"default","name":"pachyderm-loki-0.17c995cfd1459bfc","involvedObject":{"name":"Pod/pachyderm-loki-0","fieldPath":"spec.containers{loki}"},"reason":"Pulling","source.component":"kubelet","source.host":"pach-control-plane","firstTimestamp":1714065852,"lastTimestamp":1714065852,"count":1,"reportingController":"kubelet","reportingInstance":"pach-control-plane"}}
{"level":"info","ts":1714065862.420117,"logger":"event","caller":"kube-event-tail/main.go:98","msg":"create Claim storage-pachyderm-loki-0 Pod pachyderm-loki-0 in StatefulSet pachyderm-loki success","event":{"namespace":"default","name":"pachyderm-loki.17c995ce175235c0","involvedObject":{"name":"StatefulSet/pachyderm-loki"},"reason":"SuccessfulCreate","source.component":"statefulset-controller","firstTimestamp":1714065845,"lastTimestamp":1714065845,"count":1,"reportingController":"statefulset-controller"}}
{"level":"info","ts":1714065862.4201221,"logger":"event","caller":"kube-event-tail/main.go:98","msg":"create Pod pachyderm-loki-0 in StatefulSet pachyderm-loki successful","event":{"namespace":"default","name":"pachyderm-loki.17c995ce17cdf905","involvedObject":{"name":"StatefulSet/pachyderm-loki"},"reason":"SuccessfulCreate","source.component":"statefulset-controller","firstTimestamp":1714065845,"lastTimestamp":1714065845,"count":1,"reportingController":"statefulset-controller"}}
{"level":"info","ts":1714065862.4201267,"logger":"event","caller":"kube-event-tail/main.go:98","msg":"Successfully assigned default/pachyderm-promtail-27cx4 to pach-control-plane","event":{"namespace":"default","name":"pachyderm-promtail-27cx4.17c995ce2646943c","involvedObject":{"name":"Pod/pachyderm-promtail-27cx4"},"reason":"Scheduled","source.component":"default-scheduler","firstTimestamp":1714065845,"lastTimestamp":1714065845,"count":1,"reportingController":"default-scheduler"}}
{"level":"info","ts":1714065862.4201314,"logger":"event","caller":"kube-event-tail/main.go:98","msg":"Pulling image \"docker.io/grafana/promtail:2.6.1\"","event":{"namespace":"default","name":"pachyderm-promtail-27cx4.17c995ce4971b596","involvedObject":{"name":"Pod/pachyderm-promtail-27cx4","fieldPath":"spec.containers{promtail}"},"reason":"Pulling","source.component":"kubelet","source.host":"pach-control-plane","firstTimestamp":1714065846,"lastTimestamp":1714065846,"count":1,"reportingController":"kubelet","reportingInstance":"pach-control-plane"}}
{"level":"info","ts":1714065862.4201362,"logger":"event","caller":"kube-event-tail/main.go:98","msg":"Successfully pulled image \"docker.io/grafana/promtail:2.6.1\" in 4.104s (5.944s including waiting)","event":{"namespace":"default","name":"pachyderm-promtail-27cx4.17c995cfabc42693","involvedObject":{"name":"Pod/pachyderm-promtail-27cx4","fieldPath":"spec.containers{promtail}"},"reason":"Pulled","source.component":"kubelet","source.host":"pach-control-plane","firstTimestamp":1714065852,"lastTimestamp":1714065852,"count":1,"reportingController":"kubelet","reportingInstance":"pach-control-plane"}}
{"level":"info","ts":1714065862.420161,"logger":"event","caller":"kube-event-tail/main.go:98","msg":"Created container promtail","event":{"namespace":"default","name":"pachyderm-promtail-27cx4.17c995cfb0ef1f19","involvedObject":{"name":"Pod/pachyderm-promtail-27cx4","fieldPath":"spec.containers{promtail}"},"reason":"Created","source.component":"kubelet","source.host":"pach-control-plane","firstTimestamp":1714065852,"lastTimestamp":1714065852,"count":1,"reportingController":"kubelet","reportingInstance":"pach-control-plane"}}
{"level":"info","ts":1714065862.4201705,"logger":"event","caller":"kube-event-tail/main.go:98","msg":"Started container promtail","event":{"namespace":"default","name":"pachyderm-promtail-27cx4.17c995cfb76719f1","involvedObject":{"name":"Pod/pachyderm-promtail-27cx4","fieldPath":"spec.containers{promtail}"},"reason":"Started","source.component":"kubelet","source.host":"pach-control-plane","firstTimestamp":1714065852,"lastTimestamp":1714065852,"count":1,"reportingController":"kubelet","reportingInstance":"pach-control-plane"}}
{"level":"info","ts":1714065862.420193,"logger":"event","caller":"kube-event-tail/main.go:98","msg":"Created pod: pachyderm-promtail-27cx4","event":{"namespace":"default","name":"pachyderm-promtail.17c995ce2571a694","involvedObject":{"name":"DaemonSet/pachyderm-promtail"},"reason":"SuccessfulCreate","source.component":"daemonset-controller","firstTimestamp":1714065845,"lastTimestamp":1714065845,"count":1,"reportingController":"daemonset-controller"}}
{"level":"info","ts":1714065862.4202018,"logger":"event","caller":"kube-event-tail/main.go:98","msg":"0/1 nodes are available: 1 node(s) had untolerated taint {node.kubernetes.io/not-ready: }. preemption: 0/1 nodes are available: 1 Preemption is not helpful for scheduling.","event":{"namespace":"default","name":"pachyderm-proxy-5585cd764c-64hgc.17c995ce16472afd","involvedObject":{"name":"Pod/pachyderm-proxy-5585cd764c-64hgc"},"reason":"FailedScheduling","source.component":"default-scheduler","firstTimestamp":1714065845,"lastTimestamp":1714065845,"count":1,"reportingController":"default-scheduler","type":"Warning"}}
{"level":"info","ts":1714065862.4202073,"logger":"event","caller":"kube-event-tail/main.go:98","msg":"Successfully assigned default/pachyderm-proxy-5585cd764c-64hgc to pach-control-plane","event":{"namespace":"default","name":"pachyderm-proxy-5585cd764c-64hgc.17c995ce891b44fe","involvedObject":{"name":"Pod/pachyderm-proxy-5585cd764c-64hgc"},"reason":"Scheduled","source.component":"default-scheduler","firstTimestamp":1714065847,"lastTimestamp":1714065847,"count":1,"reportingController":"default-scheduler"}}
{"level":"info","ts":1714065862.4202125,"logger":"event","caller":"kube-event-tail/main.go:98","msg":"Pulling image \"envoyproxy/envoy-distroless:v1.29.3\"","event":{"namespace":"default","name":"pachyderm-proxy-5585cd764c-64hgc.17c995ceb69929b2","involvedObject":{"name":"Pod/pachyderm-proxy-5585cd764c-64hgc","fieldPath":"spec.containers{envoy}"},"reason":"Pulling","source.component":"kubelet","source.host":"pach-control-plane","firstTimestamp":1714065848,"lastTimestamp":1714065848,"count":1,"reportingController":"kubelet","reportingInstance":"pach-control-plane"}}
{"level":"info","ts":1714065862.4202173,"logger":"event","caller":"kube-event-tail/main.go:98","msg":"Created pod: pachyderm-proxy-5585cd764c-64hgc","event":{"namespace":"default","name":"pachyderm-proxy-5585cd764c.17c995ce16453e02","involvedObject":{"name":"ReplicaSet/pachyderm-proxy-5585cd764c"},"reason":"SuccessfulCreate","source.component":"replicaset-controller","firstTimestamp":1714065845,"lastTimestamp":1714065845,"count":1,"reportingController":"replicaset-controller"}}
{"level":"info","ts":1714065862.4202223,"logger":"event","caller":"kube-event-tail/main.go:98","msg":"Scaled up replica set pachyderm-proxy-5585cd764c to 1","event":{"namespace":"default","name":"pachyderm-proxy.17c995ce15c52fe2","involvedObject":{"name":"Deployment/pachyderm-proxy"},"reason":"ScalingReplicaSet","source.component":"deployment-controller","firstTimestamp":1714065845,"lastTimestamp":1714065845,"count":1,"reportingController":"deployment-controller"}}
{"level":"info","ts":1714065862.4202278,"logger":"event","caller":"kube-event-tail/main.go:98","msg":"0/1 nodes are available: 1 node(s) had untolerated taint {node.kubernetes.io/not-ready: }. preemption: 0/1 nodes are available: 1 Preemption is not helpful for scheduling.","event":{"namespace":"default","name":"pg-bouncer-7f45dc7865-cmrt7.17c995ce16f357f2","involvedObject":{"name":"Pod/pg-bouncer-7f45dc7865-cmrt7"},"reason":"FailedScheduling","source.component":"default-scheduler","firstTimestamp":1714065845,"lastTimestamp":1714065845,"count":1,"reportingController":"default-scheduler","type":"Warning"}}
{"level":"info","ts":1714065862.4202363,"logger":"event","caller":"kube-event-tail/main.go:98","msg":"Successfully assigned default/pg-bouncer-7f45dc7865-cmrt7 to pach-control-plane","event":{"namespace":"default","name":"pg-bouncer-7f45dc7865-cmrt7.17c995ce891b42a6","involvedObject":{"name":"Pod/pg-bouncer-7f45dc7865-cmrt7"},"reason":"Scheduled","source.component":"default-scheduler","firstTimestamp":1714065847,"lastTimestamp":1714065847,"count":1,"reportingController":"default-scheduler"}}
{"level":"info","ts":1714065862.4202414,"logger":"event","caller":"kube-event-tail/main.go:98","msg":"Pulling image \"pachyderm/pgbouncer:1.16.2\"","event":{"namespace":"default","name":"pg-bouncer-7f45dc7865-cmrt7.17c995ceb5a52e9b","involvedObject":{"name":"Pod/pg-bouncer-7f45dc7865-cmrt7","fieldPath":"spec.containers{pg-bouncer}"},"reason":"Pulling","source.component":"kubelet","source.host":"pach-control-plane","firstTimestamp":1714065848,"lastTimestamp":1714065848,"count":1,"reportingController":"kubelet","reportingInstance":"pach-control-plane"}}
{"level":"info","ts":1714065862.420247,"logger":"event","caller":"kube-event-tail/main.go:98","msg":"Successfully pulled image \"pachyderm/pgbouncer:1.16.2\" in 6.15s (12.636s including waiting)","event":{"namespace":"default","name":"pg-bouncer-7f45dc7865-cmrt7.17c995d1a6d25c21","involvedObject":{"name":"Pod/pg-bouncer-7f45dc7865-cmrt7","fieldPath":"spec.containers{pg-bouncer}"},"reason":"Pulled","source.component":"kubelet","source.host":"pach-control-plane","firstTimestamp":1714065860,"lastTimestamp":1714065860,"count":1,"reportingController":"kubelet","reportingInstance":"pach-control-plane"}}
{"level":"info","ts":1714065862.420253,"logger":"event","caller":"kube-event-tail/main.go:98","msg":"Created container pg-bouncer","event":{"namespace":"default","name":"pg-bouncer-7f45dc7865-cmrt7.17c995d1a94dcf2c","involvedObject":{"name":"Pod/pg-bouncer-7f45dc7865-cmrt7","fieldPath":"spec.containers{pg-bouncer}"},"reason":"Created","source.component":"kubelet","source.host":"pach-control-plane","firstTimestamp":1714065860,"lastTimestamp":1714065860,"count":1,"reportingController":"kubelet","reportingInstance":"pach-control-plane"}}
{"level":"info","ts":1714065862.4202578,"logger":"event","caller":"kube-event-tail/main.go:98","msg":"Started container pg-bouncer","event":{"namespace":"default","name":"pg-bouncer-7f45dc7865-cmrt7.17c995d1b0519d1d","involvedObject":{"name":"Pod/pg-bouncer-7f45dc7865-cmrt7","fieldPath":"spec.containers{pg-bouncer}"},"reason":"Started","source.component":"kubelet","source.host":"pach-control-plane","firstTimestamp":1714065861,"lastTimestamp":1714065861,"count":1,"reportingController":"kubelet","reportingInstance":"pach-control-plane"}}
{"level":"info","ts":1714065862.4202623,"logger":"event","caller":"kube-event-tail/main.go:98","msg":"Created pod: pg-bouncer-7f45dc7865-cmrt7","event":{"namespace":"default","name":"pg-bouncer-7f45dc7865.17c995ce16c45860","involvedObject":{"name":"ReplicaSet/pg-bouncer-7f45dc7865"},"reason":"SuccessfulCreate","source.component":"replicaset-controller","firstTimestamp":1714065845,"lastTimestamp":1714065845,"count":1,"reportingController":"replicaset-controller"}}
{"level":"info","ts":1714065862.420267,"logger":"event","caller":"kube-event-tail/main.go:98","msg":"Scaled up replica set pg-bouncer-7f45dc7865 to 1","event":{"namespace":"default","name":"pg-bouncer.17c995ce15c29f9d","involvedObject":{"name":"Deployment/pg-bouncer"},"reason":"ScalingReplicaSet","source.component":"deployment-controller","firstTimestamp":1714065845,"lastTimestamp":1714065845,"count":1,"reportingController":"deployment-controller"}}
{"level":"info","ts":1714065862.4202712,"logger":"event","caller":"kube-event-tail/main.go:98","msg":"0/1 nodes are available: 1 node(s) had untolerated taint {node.kubernetes.io/not-ready: }. preemption: 0/1 nodes are available: 1 Preemption is not helpful for scheduling.","event":{"namespace":"default","name":"postgres-0.17c995ce1a33333d","involvedObject":{"name":"Pod/postgres-0"},"reason":"FailedScheduling","source.component":"default-scheduler","firstTimestamp":1714065845,"lastTimestamp":1714065845,"count":1,"reportingController":"default-scheduler","type":"Warning"}}
{"level":"info","ts":1714065862.420276,"logger":"event","caller":"kube-event-tail/main.go:98","msg":"Successfully assigned default/postgres-0 to pach-control-plane","event":{"namespace":"default","name":"postgres-0.17c995cfb3cd809a","involvedObject":{"name":"Pod/postgres-0"},"reason":"Scheduled","source.component":"default-scheduler","firstTimestamp":1714065852,"lastTimestamp":1714065852,"count":1,"reportingController":"default-scheduler"}}
{"level":"info","ts":1714065862.4202802,"logger":"event","caller":"kube-event-tail/main.go:98","msg":"Pulling image \"docker.io/pachyderm/postgresql:13.3.0\"","event":{"namespace":"default","name":"postgres-0.17c995cfd0f35550","involvedObject":{"name":"Pod/postgres-0","fieldPath":"spec.containers{postgres}"},"reason":"Pulling","source.component":"kubelet","source.host":"pach-control-plane","firstTimestamp":1714065852,"lastTimestamp":1714065852,"count":1,"reportingController":"kubelet","reportingInstance":"pach-control-plane"}}
{"level":"info","ts":1714065862.4202852,"logger":"event","caller":"kube-event-tail/main.go:98","msg":"create Claim data-postgres-0 Pod postgres-0 in StatefulSet postgres success","event":{"namespace":"default","name":"postgres.17c995ce17879e62","involvedObject":{"name":"StatefulSet/postgres"},"reason":"SuccessfulCreate","source.component":"statefulset-controller","firstTimestamp":1714065845,"lastTimestamp":1714065845,"count":1,"reportingController":"statefulset-controller"}}
{"level":"info","ts":1714065862.4202917,"logger":"event","caller":"kube-event-tail/main.go:98","msg":"create Pod postgres-0 in StatefulSet postgres successful","event":{"namespace":"default","name":"postgres.17c995ce18264c8f","involvedObject":{"name":"StatefulSet/postgres"},"reason":"SuccessfulCreate","source.component":"statefulset-controller","firstTimestamp":1714065845,"lastTimestamp":1714065845,"count":1,"reportingController":"statefulset-controller"}}
{"level":"info","ts":1714065862.4202962,"logger":"event","caller":"kube-event-tail/main.go:98","msg":"waiting for first consumer to be created before binding","event":{"namespace":"default","name":"storage-pachyderm-loki-0.17c995ce17473739","involvedObject":{"name":"PersistentVolumeClaim/storage-pachyderm-loki-0"},"reason":"WaitForFirstConsumer","source.component":"persistentvolume-controller","firstTimestamp":1714065845,"lastTimestamp":1714065845,"count":1,"reportingController":"persistentvolume-controller"}}
{"level":"info","ts":1714065862.420316,"logger":"event","caller":"kube-event-tail/main.go:98","msg":"Waiting for a volume to be created either by the external provisioner 'rancher.io/local-path' or manually by the system administrator. If volume creation is delayed, please verify that the provisioner is running and correctly registered.","event":{"namespace":"default","name":"storage-pachyderm-loki-0.17c995ce89bae111","involvedObject":{"name":"PersistentVolumeClaim/storage-pachyderm-loki-0"},"reason":"ExternalProvisioning","source.component":"persistentvolume-controller","firstTimestamp":1714065847,"lastTimestamp":1714065847,"count":1,"reportingController":"persistentvolume-controller"}}
{"level":"info","ts":1714065862.4203255,"logger":"event","caller":"kube-event-tail/main.go:98","msg":"External provisioner is provisioning volume for claim \"default/storage-pachyderm-loki-0\"","event":{"namespace":"default","name":"storage-pachyderm-loki-0.17c995ceb052e174","involvedObject":{"name":"PersistentVolumeClaim/storage-pachyderm-loki-0"},"reason":"Provisioning","source.component":"rancher.io/local-path_local-path-provisioner-7577fdbbfb-ldff9_07bdbd19-02b2-4c93-a877-75c260fa3e3f","firstTimestamp":1714065848,"lastTimestamp":1714065848,"count":1}}
{"level":"info","ts":1714065862.420331,"logger":"event","caller":"kube-event-tail/main.go:98","msg":"Successfully provisioned volume pvc-9f17eee5-f857-47b7-963e-a092453c63b9","event":{"namespace":"default","name":"storage-pachyderm-loki-0.17c995cfaff7d649","involvedObject":{"name":"PersistentVolumeClaim/storage-pachyderm-loki-0"},"reason":"ProvisioningSucceeded","source.component":"rancher.io/local-path_local-path-provisioner-7577fdbbfb-ldff9_07bdbd19-02b2-4c93-a877-75c260fa3e3f","firstTimestamp":1714065852,"lastTimestamp":1714065852,"count":1}}
{"level":"info","ts":1714065864.8377068,"logger":"event","caller":"kube-event-tail/main.go:98","msg":"Successfully pulled image \"envoyproxy/envoy-distroless:v1.29.3\" in 2.583s (16.581s including waiting)","event":{"namespace":"default","name":"pachyderm-proxy-5585cd764c-64hgc.17c995d292f3eaf0","involvedObject":{"name":"Pod/pachyderm-proxy-5585cd764c-64hgc","fieldPath":"spec.containers{envoy}"},"reason":"Pulled","source.component":"kubelet","source.host":"pach-control-plane","firstTimestamp":1714065864,"lastTimestamp":1714065864,"count":1,"reportingController":"kubelet","reportingInstance":"pach-control-plane"}}
{"level":"info","ts":1714065864.8736277,"logger":"event","caller":"kube-event-tail/main.go:98","msg":"Created container envoy","event":{"namespace":"default","name":"pachyderm-proxy-5585cd764c-64hgc.17c995d295307ab9","involvedObject":{"name":"Pod/pachyderm-proxy-5585cd764c-64hgc","fieldPath":"spec.containers{envoy}"},"reason":"Created","source.component":"kubelet","source.host":"pach-control-plane","firstTimestamp":1714065864,"lastTimestamp":1714065864,"count":1,"reportingController":"kubelet","reportingInstance":"pach-control-plane"}}
{"level":"info","ts":1714065864.9929254,"logger":"event","caller":"kube-event-tail/main.go:98","msg":"Started container envoy","event":{"namespace":"default","name":"pachyderm-proxy-5585cd764c-64hgc.17c995d29c018add","involvedObject":{"name":"Pod/pachyderm-proxy-5585cd764c-64hgc","fieldPath":"spec.containers{envoy}"},"reason":"Started","source.component":"kubelet","source.host":"pach-control-plane","firstTimestamp":1714065864,"lastTimestamp":1714065864,"count":1,"reportingController":"kubelet","reportingInstance":"pach-control-plane"}}
{"level":"info","ts":1714065878.3138669,"logger":"event","caller":"kube-event-tail/main.go:98","msg":"Successfully pulled image \"pachyderm/haberdashery:2.8.0-alpha.5\" in 13.475s (30.054s including waiting)","event":{"namespace":"default","name":"console-75f9f5b8d8-qvkwn.17c995d5b62ef554","involvedObject":{"name":"Pod/console-75f9f5b8d8-qvkwn","fieldPath":"spec.containers{console}"},"reason":"Pulled","source.component":"kubelet","source.host":"pach-control-plane","firstTimestamp":1714065878,"lastTimestamp":1714065878,"count":1,"reportingController":"kubelet","reportingInstance":"pach-control-plane"}}
{"level":"info","ts":1714065878.3572898,"logger":"event","caller":"kube-event-tail/main.go:98","msg":"Created container console","event":{"namespace":"default","name":"console-75f9f5b8d8-qvkwn.17c995d5b8de059e","involvedObject":{"name":"Pod/console-75f9f5b8d8-qvkwn","fieldPath":"spec.containers{console}"},"reason":"Created","source.component":"kubelet","source.host":"pach-control-plane","firstTimestamp":1714065878,"lastTimestamp":1714065878,"count":1,"reportingController":"kubelet","reportingInstance":"pach-control-plane"}}
{"level":"info","ts":1714065878.4717104,"logger":"event","caller":"kube-event-tail/main.go:98","msg":"Started container console","event":{"namespace":"default","name":"console-75f9f5b8d8-qvkwn.17c995d5bf822a3b","involvedObject":{"name":"Pod/console-75f9f5b8d8-qvkwn","fieldPath":"spec.containers{console}"},"reason":"Started","source.component":"kubelet","source.host":"pach-control-plane","firstTimestamp":1714065878,"lastTimestamp":1714065878,"count":1,"reportingController":"kubelet","reportingInstance":"pach-control-plane"}}
{"level":"info","ts":1714065879.436044,"logger":"event","caller":"kube-event-tail/main.go:98","msg":"Readiness probe failed: Get \"http://10.244.0.12:4000/health\": dial tcp 10.244.0.12:4000: connect: connection refused","event":{"namespace":"default","name":"console-75f9f5b8d8-qvkwn.17c995d5f92d4d34","involvedObject":{"name":"Pod/console-75f9f5b8d8-qvkwn","fieldPath":"spec.containers{console}"},"reason":"Unhealthy","source.component":"kubelet","source.host":"pach-control-plane","firstTimestamp":1714065879,"lastTimestamp":1714065879,"count":1,"reportingController":"kubelet","reportingInstance":"pach-control-plane","type":"Warning"}}
{"level":"info","ts":1714065882.8880317,"logger":"event","caller":"kube-event-tail/main.go:98","msg":"Successfully pulled image \"docker.io/pachyderm/postgresql:13.3.0\" in 4.572s (29.892s including waiting)","event":{"namespace":"default","name":"postgres-0.17c995d6c6b5083e","involvedObject":{"name":"Pod/postgres-0","fieldPath":"spec.containers{postgres}"},"reason":"Pulled","source.component":"kubelet","source.host":"pach-control-plane","firstTimestamp":1714065882,"lastTimestamp":1714065882,"count":1,"reportingController":"kubelet","reportingInstance":"pach-control-plane"}}
{"level":"info","ts":1714065882.9345825,"logger":"event","caller":"kube-event-tail/main.go:98","msg":"Created container postgres","event":{"namespace":"default","name":"postgres-0.17c995d6c95a34d2","involvedObject":{"name":"Pod/postgres-0","fieldPath":"spec.containers{postgres}"},"reason":"Created","source.component":"kubelet","source.host":"pach-control-plane","firstTimestamp":1714065882,"lastTimestamp":1714065882,"count":1,"reportingController":"kubelet","reportingInstance":"pach-control-plane"}}
{"level":"info","ts":1714065883.0329616,"logger":"event","caller":"kube-event-tail/main.go:98","msg":"Started container postgres","event":{"namespace":"default","name":"postgres-0.17c995d6cf4d4a72","involvedObject":{"name":"Pod/postgres-0","fieldPath":"spec.containers{postgres}"},"reason":"Started","source.component":"kubelet","source.host":"pach-control-plane","firstTimestamp":1714065883,"lastTimestamp":1714065883,"count":1,"reportingController":"kubelet","reportingInstance":"pach-control-plane"}}
{"level":"info","ts":1714065884.7547612,"logger":"event","caller":"kube-event-tail/main.go:98","msg":"Successfully pulled image \"grafana/loki:2.6.1\" in 1.867s (31.754s including waiting)","event":{"namespace":"default","name":"pachyderm-loki-0.17c995d735fda647","involvedObject":{"name":"Pod/pachyderm-loki-0","fieldPath":"spec.containers{loki}"},"reason":"Pulled","source.component":"kubelet","source.host":"pach-control-plane","firstTimestamp":1714065884,"lastTimestamp":1714065884,"count":1,"reportingController":"kubelet","reportingInstance":"pach-control-plane"}}
{"level":"info","ts":1714065884.8272994,"logger":"event","caller":"kube-event-tail/main.go:98","msg":"Created container loki","event":{"namespace":"default","name":"pachyderm-loki-0.17c995d73a800a92","involvedObject":{"name":"Pod/pachyderm-loki-0","fieldPath":"spec.containers{loki}"},"reason":"Created","source.component":"kubelet","source.host":"pach-control-plane","firstTimestamp":1714065884,"lastTimestamp":1714065884,"count":1,"reportingController":"kubelet","reportingInstance":"pach-control-plane"}}
{"level":"info","ts":1714065884.9301229,"logger":"event","caller":"kube-event-tail/main.go:98","msg":"Started container loki","event":{"namespace":"default","name":"pachyderm-loki-0.17c995d74098c4c8","involvedObject":{"name":"Pod/pachyderm-loki-0","fieldPath":"spec.containers{loki}"},"reason":"Started","source.component":"kubelet","source.host":"pach-control-plane","firstTimestamp":1714065884,"lastTimestamp":1714065884,"count":1,"reportingController":"kubelet","reportingInstance":"pach-control-plane"}}
{"level":"info","ts":1714065886.9358776,"logger":"event","caller":"kube-event-tail/main.go:98","msg":"Successfully pulled image \"docker.io/minio/minio:latest\" in 2.182s (33.669s including waiting)","event":{"namespace":"default","name":"minio-0.17c995d7b81a3582","involvedObject":{"name":"Pod/minio-0","fieldPath":"spec.containers{minio}"},"reason":"Pulled","source.component":"kubelet","source.host":"pach-control-plane","firstTimestamp":1714065886,"lastTimestamp":1714065886,"count":1,"reportingController":"kubelet","reportingInstance":"pach-control-plane"}}
{"level":"info","ts":1714065886.9752934,"logger":"event","caller":"kube-event-tail/main.go:98","msg":"Created container minio","event":{"namespace":"default","name":"minio-0.17c995d7ba807511","involvedObject":{"name":"Pod/minio-0","fieldPath":"spec.containers{minio}"},"reason":"Created","source.component":"kubelet","source.host":"pach-control-plane","firstTimestamp":1714065886,"lastTimestamp":1714065886,"count":1,"reportingController":"kubelet","reportingInstance":"pach-control-plane"}}
{"level":"info","ts":1714065887.073897,"logger":"event","caller":"kube-event-tail/main.go:98","msg":"Started container minio","event":{"namespace":"default","name":"minio-0.17c995d7c0682f31","involvedObject":{"name":"Pod/minio-0","fieldPath":"spec.containers{minio}"},"reason":"Started","source.component":"kubelet","source.host":"pach-control-plane","firstTimestamp":1714065887,"lastTimestamp":1714065887,"count":1,"reportingController":"kubelet","reportingInstance":"pach-control-plane"}}
{"level":"info","ts":1714065888.0793614,"logger":"event","caller":"kube-event-tail/main.go:98","msg":"Startup probe failed: command \"/pachd --readiness\" timed out","event":{"namespace":"default","name":"pachd-7cbd956bd-nqqsj.17c995d7f1b76676","involvedObject":{"name":"Pod/pachd-7cbd956bd-nqqsj","fieldPath":"spec.containers{pachd}"},"reason":"Unhealthy","source.component":"kubelet","source.host":"pach-control-plane","firstTimestamp":1714065887,"lastTimestamp":1714065887,"count":1,"reportingController":"kubelet","reportingInstance":"pach-control-plane","type":"Warning"}}
{"level":"info","ts":1714065908.7243009,"logger":"event","caller":"kube-event-tail/main.go:98","msg":"Startup probe failed: {\"severity\":\"debug\",\"time\":\"2024-04-25T17:24:48.016828919Z\",\"logger\":\"serviceenv\",\"caller\":\"serviceenv/service_env.go:164\",\"message\":\"serviceenv: span start\"}\n{\"severity\":\"debug\",\"time\":\"2024-04-25T17:24:48.016982324Z\",\"logger\":\"serviceenv.initPachClient\",\"caller\":\"serviceenv/service_env.go:255\",\"message\":\"initPachClient: span start\"}\n{\"severity\":\"debug\",\"time\":\"2024-04-25T17:24:58.01800542Z\",\"caller\":\"proc/proc.go:203\",\"message\":\"meter: system_cpu_time_seconds\",\"type\":\"float\",\"value\":6490248.76,\"meter\":\"system_cpu_time_seconds\"}\n","event":{"namespace":"default","name":"pachd-7cbd956bd-nqqsj.17c995dccada320b","involvedObject":{"name":"Pod/pachd-7cbd956bd-nqqsj","fieldPath":"spec.containers{pachd}"},"reason":"Unhealthy","source.component":"kubelet","source.host":"pach-control-plane","firstTimestamp":1714065908,"lastTimestamp":1714065908,"count":1,"reportingController":"kubelet","reportingInstance":"pach-control-plane","type":"Warning"}}
{"level":"info","ts":1714065910.5206246,"logger":"event","caller":"kube-event-tail/main.go:98","msg":"Startup probe errored: rpc error: code = NotFound desc = failed to exec in container: failed to load task: no running task found: task cc233468ffdbd0a4cee4c1757038cef80cdac26f91fb3ad3695c050b2bb5fc62 not found: not found","event":{"namespace":"default","name":"pachd-7cbd956bd-nqqsj.17c995dd35804c21","involvedObject":{"name":"Pod/pachd-7cbd956bd-nqqsj","fieldPath":"spec.containers{pachd}"},"reason":"Unhealthy","source.component":"kubelet","source.host":"pach-control-plane","firstTimestamp":1714065910,"lastTimestamp":1714065910,"count":1,"reportingController":"kubelet","reportingInstance":"pach-control-plane","type":"Warning"}}
{"level":"info","ts":1714065911.505851,"logger":"event","caller":"kube-event-tail/main.go:98","msg":"Container image \"localhost:5001/pachd:1bf46d7c60913e30814d1b58decdb3c63bef0f10b4177019cdb5cc872460f2f9\" already present on machine","event":{"namespace":"default","name":"pachd-7cbd956bd-nqqsj.17c995dd70295fdd","involvedObject":{"name":"Pod/pachd-7cbd956bd-nqqsj","fieldPath":"spec.containers{pachd}"},"reason":"Pulled","source.component":"kubelet","source.host":"pach-control-plane","firstTimestamp":1714065911,"lastTimestamp":1714065911,"count":1,"reportingController":"kubelet","reportingInstance":"pach-control-plane"}}
{"level":"info","ts":1714065911.5472744,"logger":"event","caller":"kube-event-tail/main.go:98","msg":"Created container pachd","event":{"namespace":"default","name":"pachd-7cbd956bd-nqqsj.17c995d03ad206c5","involvedObject":{"name":"Pod/pachd-7cbd956bd-nqqsj","fieldPath":"spec.containers{pachd}"},"reason":"Created","source.component":"kubelet","source.host":"pach-control-plane","firstTimestamp":1714065854,"lastTimestamp":1714065911,"ongoingDuration":57,"count":2,"reportingController":"kubelet","reportingInstance":"pach-control-plane"}}
{"level":"info","ts":1714065911.6644008,"logger":"event","caller":"kube-event-tail/main.go:98","msg":"Started container pachd","event":{"namespace":"default","name":"pachd-7cbd956bd-nqqsj.17c995d0417c19c9","involvedObject":{"name":"Pod/pachd-7cbd956bd-nqqsj","fieldPath":"spec.containers{pachd}"},"reason":"Started","source.component":"kubelet","source.host":"pach-control-plane","firstTimestamp":1714065854,"lastTimestamp":1714065911,"ongoingDuration":57,"count":2,"reportingController":"kubelet","reportingInstance":"pach-control-plane"}}
{"level":"info","ts":1714065912.5022714,"logger":"event","caller":"kube-event-tail/main.go:98","msg":"Back-off restarting failed container pachd in pod pachd-7cbd956bd-nqqsj_default(e18b4ae5-8d48-4b22-b019-c03adcb56567)","event":{"namespace":"default","name":"pachd-7cbd956bd-nqqsj.17c995ddabf40d84","involvedObject":{"name":"Pod/pachd-7cbd956bd-nqqsj","fieldPath":"spec.containers{pachd}"},"reason":"BackOff","source.component":"kubelet","source.host":"pach-control-plane","firstTimestamp":1714065912,"lastTimestamp":1714065912,"count":1,"reportingController":"kubelet","reportingInstance":"pach-control-plane","type":"Warning"}}
{"level":"info","ts":1714065917.8109584,"logger":"event","caller":"kube-event-tail/main.go:98","msg":"Back-off restarting failed container pachd in pod pachd-7cbd956bd-nqqsj_default(e18b4ae5-8d48-4b22-b019-c03adcb56567)","event":{"namespace":"default","name":"pachd-7cbd956bd-nqqsj.17c995ddabf40d84","involvedObject":{"name":"Pod/pachd-7cbd956bd-nqqsj","fieldPath":"spec.containers{pachd}"},"reason":"BackOff","source.component":"kubelet","source.host":"pach-control-plane","firstTimestamp":1714065912,"lastTimestamp":1714065917,"ongoingDuration":5,"count":2,"reportingController":"kubelet","reportingInstance":"pach-control-plane","type":"Warning"}}
{"level":"info","ts":1714065918.5233557,"logger":"event","caller":"kube-event-tail/main.go:98","msg":"Back-off restarting failed container pachd in pod pachd-7cbd956bd-nqqsj_default(e18b4ae5-8d48-4b22-b019-c03adcb56567)","event":{"namespace":"default","name":"pachd-7cbd956bd-nqqsj.17c995ddabf40d84","involvedObject":{"name":"Pod/pachd-7cbd956bd-nqqsj","fieldPath":"spec.containers{pachd}"},"reason":"BackOff","source.component":"kubelet","source.host":"pach-control-plane","firstTimestamp":1714065912,"lastTimestamp":1714065918,"ongoingDuration":6,"count":3,"reportingController":"kubelet","reportingInstance":"pach-control-plane","type":"Warning"}}
{"level":"info","ts":1714065929.3094828,"logger":"event","caller":"kube-event-tail/main.go:98","msg":"Container image \"localhost:5001/pachd:1bf46d7c60913e30814d1b58decdb3c63bef0f10b4177019cdb5cc872460f2f9\" already present on machine","event":{"namespace":"default","name":"pachd-7cbd956bd-nqqsj.17c995dd70295fdd","involvedObject":{"name":"Pod/pachd-7cbd956bd-nqqsj","fieldPath":"spec.containers{pachd}"},"reason":"Pulled","source.component":"kubelet","source.host":"pach-control-plane","firstTimestamp":1714065911,"lastTimestamp":1714065929,"ongoingDuration":18,"count":2,"reportingController":"kubelet","reportingInstance":"pach-control-plane"}}
{"level":"info","ts":1714065929.3547256,"logger":"event","caller":"kube-event-tail/main.go:98","msg":"Created container pachd","event":{"namespace":"default","name":"pachd-7cbd956bd-nqqsj.17c995d03ad206c5","involvedObject":{"name":"Pod/pachd-7cbd956bd-nqqsj","fieldPath":"spec.containers{pachd}"},"reason":"Created","source.component":"kubelet","source.host":"pach-control-plane","firstTimestamp":1714065854,"lastTimestamp":1714065929,"ongoingDuration":75,"count":3,"reportingController":"kubelet","reportingInstance":"pach-control-plane"}}
{"level":"info","ts":1714065929.4693997,"logger":"event","caller":"kube-event-tail/main.go:98","msg":"Started container pachd","event":{"namespace":"default","name":"pachd-7cbd956bd-nqqsj.17c995d0417c19c9","involvedObject":{"name":"Pod/pachd-7cbd956bd-nqqsj","fieldPath":"spec.containers{pachd}"},"reason":"Started","source.component":"kubelet","source.host":"pach-control-plane","firstTimestamp":1714065854,"lastTimestamp":1714065929,"ongoingDuration":75,"count":3,"reportingController":"kubelet","reportingInstance":"pach-control-plane"}}
{"level":"info","ts":1714065930.5441277,"logger":"event","caller":"kube-event-tail/main.go:98","msg":"Back-off restarting failed container pachd in pod pachd-7cbd956bd-nqqsj_default(e18b4ae5-8d48-4b22-b019-c03adcb56567)","event":{"namespace":"default","name":"pachd-7cbd956bd-nqqsj.17c995ddabf40d84","involvedObject":{"name":"Pod/pachd-7cbd956bd-nqqsj","fieldPath":"spec.containers{pachd}"},"reason":"BackOff","source.component":"kubelet","source.host":"pach-control-plane","firstTimestamp":1714065912,"lastTimestamp":1714065930,"ongoingDuration":18,"count":4,"reportingController":"kubelet","reportingInstance":"pach-control-plane","type":"Warning"}}
{"level":"info","ts":1714065932.8245535,"logger":"event","caller":"kube-event-tail/main.go:98","msg":"Readiness probe failed: HTTP probe failed with statuscode: 503","event":{"namespace":"default","name":"pachyderm-loki-0.17c995e26754aa51","involvedObject":{"name":"Pod/pachyderm-loki-0","fieldPath":"spec.containers{loki}"},"reason":"Unhealthy","source.component":"kubelet","source.host":"pach-control-plane","firstTimestamp":1714065932,"lastTimestamp":1714065932,"count":1,"reportingController":"kubelet","reportingInstance":"pach-control-plane","type":"Warning"}}
{"level":"info","ts":1714065932.8287513,"logger":"event","caller":"kube-event-tail/main.go:98","msg":"Liveness probe failed: HTTP probe failed with statuscode: 503","event":{"namespace":"default","name":"pachyderm-loki-0.17c995e26755c9d3","involvedObject":{"name":"Pod/pachyderm-loki-0","fieldPath":"spec.containers{loki}"},"reason":"Unhealthy","source.component":"kubelet","source.host":"pach-control-plane","firstTimestamp":1714065932,"lastTimestamp":1714065932,"count":1,"reportingController":"kubelet","reportingInstance":"pach-control-plane","type":"Warning"}}
{"level":"info","ts":1714065937.190183,"logger":"event","caller":"kube-event-tail/main.go:98","msg":"Readiness probe failed: Get \"http://10.244.0.6:3101/ready\": context deadline exceeded (Client.Timeout exceeded while awaiting headers)","event":{"namespace":"default","name":"pachyderm-promtail-27cx4.17c995e36b119c6e","involvedObject":{"name":"Pod/pachyderm-promtail-27cx4","fieldPath":"spec.containers{promtail}"},"reason":"Unhealthy","source.component":"kubelet","source.host":"pach-control-plane","firstTimestamp":1714065937,"lastTimestamp":1714065937,"count":1,"reportingController":"kubelet","reportingInstance":"pach-control-plane","type":"Warning"}}
{"level":"info","ts":1714065937.8227234,"logger":"event","caller":"kube-event-tail/main.go:98","msg":"Back-off restarting failed container pachd in pod pachd-7cbd956bd-nqqsj_default(e18b4ae5-8d48-4b22-b019-c03adcb56567)","event":{"namespace":"default","name":"pachd-7cbd956bd-nqqsj.17c995ddabf40d84","involvedObject":{"name":"Pod/pachd-7cbd956bd-nqqsj","fieldPath":"spec.containers{pachd}"},"reason":"BackOff","source.component":"kubelet","source.host":"pach-control-plane","firstTimestamp":1714065912,"lastTimestamp":1714065937,"ongoingDuration":25,"count":5,"reportingController":"kubelet","reportingInstance":"pach-control-plane","type":"Warning"}}
{"level":"info","ts":1714065938.5533679,"logger":"event","caller":"kube-event-tail/main.go:98","msg":"Back-off restarting failed container pachd in pod pachd-7cbd956bd-nqqsj_default(e18b4ae5-8d48-4b22-b019-c03adcb56567)","event":{"namespace":"default","name":"pachd-7cbd956bd-nqqsj.17c995ddabf40d84","involvedObject":{"name":"Pod/pachd-7cbd956bd-nqqsj","fieldPath":"spec.containers{pachd}"},"reason":"BackOff","source.component":"kubelet","source.host":"pach-control-plane","firstTimestamp":1714065912,"lastTimestamp":1714065938,"ongoingDuration":26,"count":6,"reportingController":"kubelet","reportingInstance":"pach-control-plane","type":"Warning"}}
{"level":"info","ts":1714065942.827109,"logger":"event","caller":"kube-event-tail/main.go:98","msg":"Liveness probe failed: HTTP probe failed with statuscode: 503","event":{"namespace":"default","name":"pachyderm-loki-0.17c995e26755c9d3","involvedObject":{"name":"Pod/pachyderm-loki-0","fieldPath":"spec.containers{loki}"},"reason":"Unhealthy","source.component":"kubelet","source.host":"pach-control-plane","firstTimestamp":1714065932,"lastTimestamp":1714065942,"ongoingDuration":10,"count":2,"reportingController":"kubelet","reportingInstance":"pach-control-plane","type":"Warning"}}
{"level":"info","ts":1714065942.8331633,"logger":"event","caller":"kube-event-tail/main.go:98","msg":"Readiness probe failed: HTTP probe failed with statuscode: 503","event":{"namespace":"default","name":"pachyderm-loki-0.17c995e26754aa51","involvedObject":{"name":"Pod/pachyderm-loki-0","fieldPath":"spec.containers{loki}"},"reason":"Unhealthy","source.component":"kubelet","source.host":"pach-control-plane","firstTimestamp":1714065932,"lastTimestamp":1714065942,"ongoingDuration":10,"count":2,"reportingController":"kubelet","reportingInstance":"pach-control-plane","type":"Warning"}}
{"level":"info","ts":1714065947.1912975,"logger":"event","caller":"kube-event-tail/main.go:98","msg":"Readiness probe failed: Get \"http://10.244.0.6:3101/ready\": context deadline exceeded (Client.Timeout exceeded while awaiting headers)","event":{"namespace":"default","name":"pachyderm-promtail-27cx4.17c995e36b119c6e","involvedObject":{"name":"Pod/pachyderm-promtail-27cx4","fieldPath":"spec.containers{promtail}"},"reason":"Unhealthy","source.component":"kubelet","source.host":"pach-control-plane","firstTimestamp":1714065937,"lastTimestamp":1714065947,"ongoingDuration":10,"count":2,"reportingController":"kubelet","reportingInstance":"pach-control-plane","type":"Warning"}}
{"level":"info","ts":1714065952.328768,"logger":"event","caller":"kube-event-tail/main.go:98","msg":"Container image \"localhost:5001/pachd:1bf46d7c60913e30814d1b58decdb3c63bef0f10b4177019cdb5cc872460f2f9\" already present on machine","event":{"namespace":"default","name":"pachd-7cbd956bd-nqqsj.17c995dd70295fdd","involvedObject":{"name":"Pod/pachd-7cbd956bd-nqqsj","fieldPath":"spec.containers{pachd}"},"reason":"Pulled","source.component":"kubelet","source.host":"pach-control-plane","firstTimestamp":1714065911,"lastTimestamp":1714065952,"ongoingDuration":41,"count":3,"reportingController":"kubelet","reportingInstance":"pach-control-plane"}}
{"level":"info","ts":1714065952.35757,"logger":"event","caller":"kube-event-tail/main.go:98","msg":"Created container pachd","event":{"namespace":"default","name":"pachd-7cbd956bd-nqqsj.17c995d03ad206c5","involvedObject":{"name":"Pod/pachd-7cbd956bd-nqqsj","fieldPath":"spec.containers{pachd}"},"reason":"Created","source.component":"kubelet","source.host":"pach-control-plane","firstTimestamp":1714065854,"lastTimestamp":1714065952,"ongoingDuration":98,"count":4,"reportingController":"kubelet","reportingInstance":"pach-control-plane"}}
{"level":"info","ts":1714065952.457462,"logger":"event","caller":"kube-event-tail/main.go:98","msg":"Started container pachd","event":{"namespace":"default","name":"pachd-7cbd956bd-nqqsj.17c995d0417c19c9","involvedObject":{"name":"Pod/pachd-7cbd956bd-nqqsj","fieldPath":"spec.containers{pachd}"},"reason":"Started","source.component":"kubelet","source.host":"pach-control-plane","firstTimestamp":1714065854,"lastTimestamp":1714065952,"ongoingDuration":98,"count":4,"reportingController":"kubelet","reportingInstance":"pach-control-plane"}}
{"level":"info","ts":1714065953.5888026,"logger":"event","caller":"kube-event-tail/main.go:98","msg":"Back-off restarting failed container pachd in pod pachd-7cbd956bd-nqqsj_default(e18b4ae5-8d48-4b22-b019-c03adcb56567)","event":{"namespace":"default","name":"pachd-7cbd956bd-nqqsj.17c995ddabf40d84","involvedObject":{"name":"Pod/pachd-7cbd956bd-nqqsj","fieldPath":"spec.containers{pachd}"},"reason":"BackOff","source.component":"kubelet","source.host":"pach-control-plane","firstTimestamp":1714065912,"lastTimestamp":1714065953,"ongoingDuration":41,"count":7,"reportingController":"kubelet","reportingInstance":"pach-control-plane","type":"Warning"}}
{"level":"info","ts":1714065957.1856565,"logger":"event","caller":"kube-event-tail/main.go:98","msg":"Readiness probe failed: Get \"http://10.244.0.6:3101/ready\": context deadline exceeded (Client.Timeout exceeded while awaiting headers)","event":{"namespace":"default","name":"pachyderm-promtail-27cx4.17c995e36b119c6e","involvedObject":{"name":"Pod/pachyderm-promtail-27cx4","fieldPath":"spec.containers{promtail}"},"reason":"Unhealthy","source.component":"kubelet","source.host":"pach-control-plane","firstTimestamp":1714065937,"lastTimestamp":1714065957,"ongoingDuration":20,"count":3,"reportingController":"kubelet","reportingInstance":"pach-control-plane","type":"Warning"}}
{"level":"info","ts":1714065957.81943,"logger":"event","caller":"kube-event-tail/main.go:98","msg":"Back-off restarting failed container pachd in pod pachd-7cbd956bd-nqqsj_default(e18b4ae5-8d48-4b22-b019-c03adcb56567)","event":{"namespace":"default","name":"pachd-7cbd956bd-nqqsj.17c995ddabf40d84","involvedObject":{"name":"Pod/pachd-7cbd956bd-nqqsj","fieldPath":"spec.containers{pachd}"},"reason":"BackOff","source.component":"kubelet","source.host":"pach-control-plane","firstTimestamp":1714065912,"lastTimestamp":1714065957,"ongoingDuration":45,"count":8,"reportingController":"kubelet","reportingInstance":"pach-control-plane","type":"Warning"}}
{"level":"info","ts":1714065958.594835,"logger":"event","caller":"kube-event-tail/main.go:98","msg":"Back-off restarting failed container pachd in pod pachd-7cbd956bd-nqqsj_default(e18b4ae5-8d48-4b22-b019-c03adcb56567)","event":{"namespace":"default","name":"pachd-7cbd956bd-nqqsj.17c995ddabf40d84","involvedObject":{"name":"Pod/pachd-7cbd956bd-nqqsj","fieldPath":"spec.containers{pachd}"},"reason":"BackOff","source.component":"kubelet","source.host":"pach-control-plane","firstTimestamp":1714065912,"lastTimestamp":1714065958,"ongoingDuration":46,"count":9,"reportingController":"kubelet","reportingInstance":"pach-control-plane","type":"Warning"}}
{"level":"info","ts":1714065967.18988,"logger":"event","caller":"kube-event-tail/main.go:98","msg":"Readiness probe failed: Get \"http://10.244.0.6:3101/ready\": context deadline exceeded (Client.Timeout exceeded while awaiting headers)","event":{"namespace":"default","name":"pachyderm-promtail-27cx4.17c995e36b119c6e","involvedObject":{"name":"Pod/pachyderm-promtail-27cx4","fieldPath":"spec.containers{promtail}"},"reason":"Unhealthy","source.component":"kubelet","source.host":"pach-control-plane","firstTimestamp":1714065937,"lastTimestamp":1714065967,"ongoingDuration":30,"count":4,"reportingController":"kubelet","reportingInstance":"pach-control-plane","type":"Warning"}}
{"level":"info","ts":1714065977.1861086,"logger":"event","caller":"kube-event-tail/main.go:98","msg":"Readiness probe failed: Get \"http://10.244.0.6:3101/ready\": context deadline exceeded (Client.Timeout exceeded while awaiting headers)","event":{"namespace":"default","name":"pachyderm-promtail-27cx4.17c995e36b119c6e","involvedObject":{"name":"Pod/pachyderm-promtail-27cx4","fieldPath":"spec.containers{promtail}"},"reason":"Unhealthy","source.component":"kubelet","source.host":"pach-control-plane","firstTimestamp":1714065937,"lastTimestamp":1714065977,"ongoingDuration":40,"count":5,"reportingController":"kubelet","reportingInstance":"pach-control-plane","type":"Warning"}}
{"level":"info","ts":1714065978.239298,"logger":"event","caller":"kube-event-tail/main.go:98","msg":"Readiness probe failed: Get \"http://10.244.0.6:3101/ready\": context deadline exceeded (Client.Timeout exceeded while awaiting headers)","event":{"namespace":"default","name":"pachyderm-promtail-27cx4.17c995e36b119c6e","involvedObject":{"name":"Pod/pachyderm-promtail-27cx4","fieldPath":"spec.containers{promtail}"},"reason":"Unhealthy","source.component":"kubelet","source.host":"pach-control-plane","firstTimestamp":1714065937,"lastTimestamp":1714065978,"ongoingDuration":41,"count":6,"reportingController":"kubelet","reportingInstance":"pach-control-plane","type":"Warning"}}
{"level":"info","ts":1714065987.185924,"logger":"event","caller":"kube-event-tail/main.go:98","msg":"Readiness probe failed: Get \"http://10.244.0.6:3101/ready\": context deadline exceeded (Client.Timeout exceeded while awaiting headers)","event":{"namespace":"default","name":"pachyderm-promtail-27cx4.17c995e36b119c6e","involvedObject":{"name":"Pod/pachyderm-promtail-27cx4","fieldPath":"spec.containers{promtail}"},"reason":"Unhealthy","source.component":"kubelet","source.host":"pach-control-plane","firstTimestamp":1714065937,"lastTimestamp":1714065987,"ongoingDuration":50,"count":7,"reportingController":"kubelet","reportingInstance":"pach-control-plane","type":"Warning"}}
{"level":"info","ts":1714065997.1823223,"logger":"event","caller":"kube-event-tail/main.go:98","msg":"Readiness probe failed: Get \"http://10.244.0.6:3101/ready\": context deadline exceeded (Client.Timeout exceeded while awaiting headers)","event":{"namespace":"default","name":"pachyderm-promtail-27cx4.17c995e36b119c6e","involvedObject":{"name":"Pod/pachyderm-promtail-27cx4","fieldPath":"spec.containers{promtail}"},"reason":"Unhealthy","source.component":"kubelet","source.host":"pach-control-plane","firstTimestamp":1714065937,"lastTimestamp":1714065997,"ongoingDuration":60,"count":8,"reportingController":"kubelet","reportingInstance":"pach-control-plane","type":"Warning"}}
{"level":"info","ts":1714066007.1830356,"logger":"event","caller":"kube-event-tail/main.go:98","msg":"Readiness probe failed: Get \"http://10.244.0.6:3101/ready\": context deadline exceeded (Client.Timeout exceeded while awaiting headers)","event":{"namespace":"default","name":"pachyderm-promtail-27cx4.17c995e36b119c6e","involvedObject":{"name":"Pod/pachyderm-promtail-27cx4","fieldPath":"spec.containers{promtail}"},"reason":"Unhealthy","source.component":"kubelet","source.host":"pach-control-plane","firstTimestamp":1714065937,"lastTimestamp":1714066007,"ongoingDuration":70,"count":9,"reportingController":"kubelet","reportingInstance":"pach-control-plane","type":"Warning"}}
{"level":"info","ts":1714066017.1882036,"logger":"event","caller":"kube-event-tail/main.go:98","msg":"Readiness probe failed: Get \"http://10.244.0.6:3101/ready\": context deadline exceeded (Client.Timeout exceeded while awaiting headers)","event":{"namespace":"default","name":"pachyderm-promtail-27cx4.17c995e36b119c6e","involvedObject":{"name":"Pod/pachyderm-promtail-27cx4","fieldPath":"spec.containers{promtail}"},"reason":"Unhealthy","source.component":"kubelet","source.host":"pach-control-plane","firstTimestamp":1714065937,"lastTimestamp":1714066017,"ongoingDuration":80,"count":10,"reportingController":"kubelet","reportingInstance":"pach-control-plane","type":"Warning"}}
{"level":"info","ts":1714066027.1905785,"logger":"event","caller":"kube-event-tail/main.go:98","msg":"Readiness probe failed: Get \"http://10.244.0.6:3101/ready\": context deadline exceeded (Client.Timeout exceeded while awaiting headers)","event":{"namespace":"default","name":"pachyderm-promtail-27cx4.17c995e36b119c6e","involvedObject":{"name":"Pod/pachyderm-promtail-27cx4","fieldPath":"spec.containers{promtail}"},"reason":"Unhealthy","source.component":"kubelet","source.host":"pach-control-plane","firstTimestamp":1714065937,"lastTimestamp":1714066027,"ongoingDuration":90,"count":11,"reportingController":"kubelet","reportingInstance":"pach-control-plane","type":"Warning"}}
{"level":"info","ts":1714066154.3092184,"logger":"event","caller":"kube-event-tail/main.go:98","msg":"Back-off restarting failed container pachd in pod pachd-7cbd956bd-nqqsj_default(e18b4ae5-8d48-4b22-b019-c03adcb56567)","event":{"namespace":"default","name":"pachd-7cbd956bd-nqqsj.17c995ddabf40d84","involvedObject":{"name":"Pod/pachd-7cbd956bd-nqqsj","fieldPath":"spec.containers{pachd}"},"reason":"BackOff","source.component":"kubelet","source.host":"pach-control-plane","firstTimestamp":1714065912,"lastTimestamp":1714066154,"ongoingDuration":242,"count":27,"reportingController":"kubelet","reportingInstance":"pach-control-plane","type":"Warning"}}
{"level":"info","ts":1714066458.3062685,"logger":"event","caller":"kube-event-tail/main.go:98","msg":"Back-off restarting failed container pachd in pod pachd-7cbd956bd-nqqsj_default(e18b4ae5-8d48-4b22-b019-c03adcb56567)","event":{"namespace":"default","name":"pachd-7cbd956bd-nqqsj.17c995ddabf40d84","involvedObject":{"name":"Pod/pachd-7cbd956bd-nqqsj","fieldPath":"spec.containers{pachd}"},"reason":"BackOff","source.component":"kubelet","source.host":"pach-control-plane","firstTimestamp":1714065912,"lastTimestamp":1714066458,"ongoingDuration":546,"count":52,"reportingController":"kubelet","reportingInstance":"pach-control-plane","type":"Warning"}}
{"level":"info","ts":1714066691.386151,"logger":"event","caller":"kube-event-tail/main.go:98","msg":"Scaled up replica set console-967cf447d to 1","event":{"namespace":"default","name":"console.17c996930438729a","involvedObject":{"name":"Deployment/console"},"reason":"ScalingReplicaSet","source.component":"deployment-controller","firstTimestamp":1714066691,"lastTimestamp":1714066691,"count":1,"reportingController":"deployment-controller"}}
{"level":"info","ts":1714066691.4003847,"logger":"event","caller":"kube-event-tail/main.go:98","msg":"Created pod: console-967cf447d-t2cc6","event":{"namespace":"default","name":"console-967cf447d.17c9969305be0ef2","involvedObject":{"name":"ReplicaSet/console-967cf447d"},"reason":"SuccessfulCreate","source.component":"replicaset-controller","firstTimestamp":1714066691,"lastTimestamp":1714066691,"count":1,"reportingController":"replicaset-controller"}}
{"level":"info","ts":1714066691.4045565,"logger":"event","caller":"kube-event-tail/main.go:98","msg":"Successfully assigned default/console-967cf447d-t2cc6 to pach-control-plane","event":{"namespace":"default","name":"console-967cf447d-t2cc6.17c996930644d3cb","involvedObject":{"name":"Pod/console-967cf447d-t2cc6"},"reason":"Scheduled","source.component":"default-scheduler","firstTimestamp":1714066691,"lastTimestamp":1714066691,"count":1,"reportingController":"default-scheduler"}}
{"level":"info","ts":1714066691.4305253,"logger":"event","caller":"kube-event-tail/main.go:98","msg":"Scaled up replica set pachd-d868b489c to 1","event":{"namespace":"default","name":"pachd.17c9969307d3d0fa","involvedObject":{"name":"Deployment/pachd"},"reason":"ScalingReplicaSet","source.component":"deployment-controller","firstTimestamp":1714066691,"lastTimestamp":1714066691,"count":1,"reportingController":"deployment-controller"}}
{"level":"info","ts":1714066691.4499807,"logger":"event","caller":"kube-event-tail/main.go:98","msg":"Created pod: pachd-d868b489c-7s5xp","event":{"namespace":"default","name":"pachd-d868b489c.17c996930899a275","involvedObject":{"name":"ReplicaSet/pachd-d868b489c"},"reason":"SuccessfulCreate","source.component":"replicaset-controller","firstTimestamp":1714066691,"lastTimestamp":1714066691,"count":1,"reportingController":"replicaset-controller"}}
{"level":"info","ts":1714066691.4623497,"logger":"event","caller":"kube-event-tail/main.go:98","msg":"Successfully assigned default/pachd-d868b489c-7s5xp to pach-control-plane","event":{"namespace":"default","name":"pachd-d868b489c-7s5xp.17c99693093a9c75","involvedObject":{"name":"Pod/pachd-d868b489c-7s5xp"},"reason":"Scheduled","source.component":"default-scheduler","firstTimestamp":1714066691,"lastTimestamp":1714066691,"count":1,"reportingController":"default-scheduler"}}
{"level":"info","ts":1714066691.8493276,"logger":"event","caller":"kube-event-tail/main.go:98","msg":"Container image \"pachyderm/haberdashery:2.8.0-alpha.5\" already present on machine","event":{"namespace":"default","name":"console-967cf447d-t2cc6.17c9969320c0ffba","involvedObject":{"name":"Pod/console-967cf447d-t2cc6","fieldPath":"spec.containers{console}"},"reason":"Pulled","source.component":"kubelet","source.host":"pach-control-plane","firstTimestamp":1714066691,"lastTimestamp":1714066691,"count":1,"reportingController":"kubelet","reportingInstance":"pach-control-plane"}}
{"level":"info","ts":1714066691.872408,"logger":"event","caller":"kube-event-tail/main.go:98","msg":"Pulling image \"localhost:5001/pachd:81d74ab385fe002f0ca96b9b75509cb8f0ba65cf73262f4d020ecd2fc736c917\"","event":{"namespace":"default","name":"pachd-d868b489c-7s5xp.17c9969321dd2b38","involvedObject":{"name":"Pod/pachd-d868b489c-7s5xp","fieldPath":"spec.containers{pachd}"},"reason":"Pulling","source.component":"kubelet","source.host":"pach-control-plane","firstTimestamp":1714066691,"lastTimestamp":1714066691,"count":1,"reportingController":"kubelet","reportingInstance":"pach-control-plane"}}
{"level":"info","ts":1714066691.889376,"logger":"event","caller":"kube-event-tail/main.go:98","msg":"Created container console","event":{"namespace":"default","name":"console-967cf447d-t2cc6.17c99693231ff41c","involvedObject":{"name":"Pod/console-967cf447d-t2cc6","fieldPath":"spec.containers{console}"},"reason":"Created","source.component":"kubelet","source.host":"pach-control-plane","firstTimestamp":1714066691,"lastTimestamp":1714066691,"count":1,"reportingController":"kubelet","reportingInstance":"pach-control-plane"}}
{"level":"info","ts":1714066692.0099041,"logger":"event","caller":"kube-event-tail/main.go:98","msg":"Started container console","event":{"namespace":"default","name":"console-967cf447d-t2cc6.17c996932a55e813","involvedObject":{"name":"Pod/console-967cf447d-t2cc6","fieldPath":"spec.containers{console}"},"reason":"Started","source.component":"kubelet","source.host":"pach-control-plane","firstTimestamp":1714066692,"lastTimestamp":1714066692,"count":1,"reportingController":"kubelet","reportingInstance":"pach-control-plane"}}
{"level":"info","ts":1714066692.6261678,"logger":"event","caller":"kube-event-tail/main.go:98","msg":"Successfully pulled image \"localhost:5001/pachd:81d74ab385fe002f0ca96b9b75509cb8f0ba65cf73262f4d020ecd2fc736c917\" in 758ms (758ms including waiting)","event":{"namespace":"default","name":"pachd-d868b489c-7s5xp.17c996934f0e007b","involvedObject":{"name":"Pod/pachd-d868b489c-7s5xp","fieldPath":"spec.containers{pachd}"},"reason":"Pulled","source.component":"kubelet","source.host":"pach-control-plane","firstTimestamp":1714066692,"lastTimestamp":1714066692,"count":1,"reportingController":"kubelet","reportingInstance":"pach-control-plane"}}
{"level":"info","ts":1714066692.69042,"logger":"event","caller":"kube-event-tail/main.go:98","msg":"Created container pachd","event":{"namespace":"default","name":"pachd-d868b489c-7s5xp.17c9969352568d8e","involvedObject":{"name":"Pod/pachd-d868b489c-7s5xp","fieldPath":"spec.containers{pachd}"},"reason":"Created","source.component":"kubelet","source.host":"pach-control-plane","firstTimestamp":1714066692,"lastTimestamp":1714066692,"count":1,"reportingController":"kubelet","reportingInstance":"pach-control-plane"}}
{"level":"info","ts":1714066692.8065352,"logger":"event","caller":"kube-event-tail/main.go:98","msg":"Started container pachd","event":{"namespace":"default","name":"pachd-d868b489c-7s5xp.17c9969359c9242a","involvedObject":{"name":"Pod/pachd-d868b489c-7s5xp","fieldPath":"spec.containers{pachd}"},"reason":"Started","source.component":"kubelet","source.host":"pach-control-plane","firstTimestamp":1714066692,"lastTimestamp":1714066692,"count":1,"reportingController":"kubelet","reportingInstance":"pach-control-plane"}}
{"level":"info","ts":1714066692.9569533,"logger":"event","caller":"kube-event-tail/main.go:98","msg":"Readiness probe failed: Get \"http://10.244.0.19:4000/health\": dial tcp 10.244.0.19:4000: connect: connection refused","event":{"namespace":"default","name":"console-967cf447d-t2cc6.17c9969362ca39c9","involvedObject":{"name":"Pod/console-967cf447d-t2cc6","fieldPath":"spec.containers{console}"},"reason":"Unhealthy","source.component":"kubelet","source.host":"pach-control-plane","firstTimestamp":1714066692,"lastTimestamp":1714066692,"count":1,"reportingController":"kubelet","reportingInstance":"pach-control-plane","type":"Warning"}}
{"level":"info","ts":1714066693.9923794,"logger":"event","caller":"kube-event-tail/main.go:98","msg":"Scaled down replica set console-75f9f5b8d8 to 0 from 1","event":{"namespace":"default","name":"console.17c99693a088542d","involvedObject":{"name":"Deployment/console"},"reason":"ScalingReplicaSet","source.component":"deployment-controller","firstTimestamp":1714066693,"lastTimestamp":1714066693,"count":1,"reportingController":"deployment-controller"}}
{"level":"info","ts":1714066694.0024335,"logger":"event","caller":"kube-event-tail/main.go:98","msg":"Deleted pod: console-75f9f5b8d8-qvkwn","event":{"namespace":"default","name":"console-75f9f5b8d8.17c99693a1077906","involvedObject":{"name":"ReplicaSet/console-75f9f5b8d8"},"reason":"SuccessfulDelete","source.component":"replicaset-controller","firstTimestamp":1714066693,"lastTimestamp":1714066693,"count":1,"reportingController":"replicaset-controller"}}
{"level":"info","ts":1714066694.0130095,"logger":"event","caller":"kube-event-tail/main.go:98","msg":"Stopping container console","event":{"namespace":"default","name":"console-75f9f5b8d8-qvkwn.17c99693a1182004","involvedObject":{"name":"Pod/console-75f9f5b8d8-qvkwn","fieldPath":"spec.containers{console}"},"reason":"Killing","source.component":"kubelet","source.host":"pach-control-plane","firstTimestamp":1714066693,"lastTimestamp":1714066693,"count":1,"reportingController":"kubelet","reportingInstance":"pach-control-plane"}}
{"level":"info","ts":1714066702.149724,"logger":"event","caller":"kube-event-tail/main.go:98","msg":"Scaled down replica set pachd-7cbd956bd to 0 from 1","event":{"namespace":"default","name":"pachd.17c9969586b758e4","involvedObject":{"name":"Deployment/pachd"},"reason":"ScalingReplicaSet","source.component":"deployment-controller","firstTimestamp":1714066702,"lastTimestamp":1714066702,"count":1,"reportingController":"deployment-controller"}}
{"level":"info","ts":1714066702.1636465,"logger":"event","caller":"kube-event-tail/main.go:98","msg":"Deleted pod: pachd-7cbd956bd-nqqsj","event":{"namespace":"default","name":"pachd-7cbd956bd.17c99695878c83c3","involvedObject":{"name":"ReplicaSet/pachd-7cbd956bd"},"reason":"SuccessfulDelete","source.component":"replicaset-controller","firstTimestamp":1714066702,"lastTimestamp":1714066702,"count":1,"reportingController":"replicaset-controller"}}
{"level":"info","ts":1714067001.7675352,"logger":"event","caller":"kube-event-tail/main.go:98","msg":"Created pod: default-edges-v1-292m8","event":{"namespace":"default","name":"default-edges-v1.17c996db4810daac","involvedObject":{"name":"ReplicationController/default-edges-v1"},"reason":"SuccessfulCreate","source.component":"replication-controller","firstTimestamp":1714067001,"lastTimestamp":1714067001,"count":1,"reportingController":"replication-controller"}}
{"level":"info","ts":1714067001.7689912,"logger":"event","caller":"kube-event-tail/main.go:98","msg":"Successfully assigned default/default-edges-v1-292m8 to pach-control-plane","event":{"namespace":"default","name":"default-edges-v1-292m8.17c996db48c2e90b","involvedObject":{"name":"Pod/default-edges-v1-292m8"},"reason":"Scheduled","source.component":"default-scheduler","firstTimestamp":1714067001,"lastTimestamp":1714067001,"count":1,"reportingController":"default-scheduler"}}
{"level":"info","ts":1714067002.2151847,"logger":"event","caller":"kube-event-tail/main.go:98","msg":"Pulling image \"localhost:5001/worker:4c7a34a8ab1e1042228009ec967ec50633d4529c432711200feb360b8ef98ec3\"","event":{"namespace":"default","name":"default-edges-v1-292m8.17c996db63ecab2d","involvedObject":{"name":"Pod/default-edges-v1-292m8","fieldPath":"spec.initContainers{init}"},"reason":"Pulling","source.component":"kubelet","source.host":"pach-control-plane","firstTimestamp":1714067002,"lastTimestamp":1714067002,"count":1,"reportingController":"kubelet","reportingInstance":"pach-control-plane"}}
{"level":"info","ts":1714067002.7189527,"logger":"event","caller":"kube-event-tail/main.go:98","msg":"Created pod: default-montage-v1-57sqv","event":{"namespace":"default","name":"default-montage-v1.17c996db7dd2e245","involvedObject":{"name":"ReplicationController/default-montage-v1"},"reason":"SuccessfulCreate","source.component":"replication-controller","firstTimestamp":1714067002,"lastTimestamp":1714067002,"count":1,"reportingController":"replication-controller"}}
{"level":"info","ts":1714067002.7282915,"logger":"event","caller":"kube-event-tail/main.go:98","msg":"Successfully assigned default/default-montage-v1-57sqv to pach-control-plane","event":{"namespace":"default","name":"default-montage-v1-57sqv.17c996db828d13d8","involvedObject":{"name":"Pod/default-montage-v1-57sqv"},"reason":"Scheduled","source.component":"default-scheduler","firstTimestamp":1714067002,"lastTimestamp":1714067002,"count":1,"reportingController":"default-scheduler"}}
{"level":"info","ts":1714067003.1838183,"logger":"event","caller":"kube-event-tail/main.go:98","msg":"Pulling image \"localhost:5001/worker:4c7a34a8ab1e1042228009ec967ec50633d4529c432711200feb360b8ef98ec3\"","event":{"namespace":"default","name":"default-montage-v1-57sqv.17c996db9dbda629","involvedObject":{"name":"Pod/default-montage-v1-57sqv","fieldPath":"spec.initContainers{init}"},"reason":"Pulling","source.component":"kubelet","source.host":"pach-control-plane","firstTimestamp":1714067003,"lastTimestamp":1714067003,"count":1,"reportingController":"kubelet","reportingInstance":"pach-control-plane"}}
{"level":"info","ts":1714067003.580231,"logger":"event","caller":"kube-event-tail/main.go:98","msg":"Successfully pulled image \"localhost:5001/worker:4c7a34a8ab1e1042228009ec967ec50633d4529c432711200feb360b8ef98ec3\" in 1.365s (1.365s including waiting)","event":{"namespace":"default","name":"default-edges-v1-292m8.17c996dbb555ea7f","involvedObject":{"name":"Pod/default-edges-v1-292m8","fieldPath":"spec.initContainers{init}"},"reason":"Pulled","source.component":"kubelet","source.host":"pach-control-plane","firstTimestamp":1714067003,"lastTimestamp":1714067003,"count":1,"reportingController":"kubelet","reportingInstance":"pach-control-plane"}}
{"level":"info","ts":1714067003.6525319,"logger":"event","caller":"kube-event-tail/main.go:98","msg":"Created container init","event":{"namespace":"default","name":"default-edges-v1-292m8.17c996dbb92f47f7","involvedObject":{"name":"Pod/default-edges-v1-292m8","fieldPath":"spec.initContainers{init}"},"reason":"Created","source.component":"kubelet","source.host":"pach-control-plane","firstTimestamp":1714067003,"lastTimestamp":1714067003,"count":1,"reportingController":"kubelet","reportingInstance":"pach-control-plane"}}
{"level":"info","ts":1714067003.672134,"logger":"event","caller":"kube-event-tail/main.go:98","msg":"Successfully pulled image \"localhost:5001/worker:4c7a34a8ab1e1042228009ec967ec50633d4529c432711200feb360b8ef98ec3\" in 92ms (488ms including waiting)","event":{"namespace":"default","name":"default-montage-v1-57sqv.17c996dbbada15a3","involvedObject":{"name":"Pod/default-montage-v1-57sqv","fieldPath":"spec.initContainers{init}"},"reason":"Pulled","source.component":"kubelet","source.host":"pach-control-plane","firstTimestamp":1714067003,"lastTimestamp":1714067003,"count":1,"reportingController":"kubelet","reportingInstance":"pach-control-plane"}}
{"level":"info","ts":1714067003.7688107,"logger":"event","caller":"kube-event-tail/main.go:98","msg":"Started container init","event":{"namespace":"default","name":"default-edges-v1-292m8.17c996dbc06f9a4a","involvedObject":{"name":"Pod/default-edges-v1-292m8","fieldPath":"spec.initContainers{init}"},"reason":"Started","source.component":"kubelet","source.host":"pach-control-plane","firstTimestamp":1714067003,"lastTimestamp":1714067003,"count":1,"reportingController":"kubelet","reportingInstance":"pach-control-plane"}}
{"level":"info","ts":1714067003.8022635,"logger":"event","caller":"kube-event-tail/main.go:98","msg":"Created container init","event":{"namespace":"default","name":"default-montage-v1-57sqv.17c996dbc29a18a8","involvedObject":{"name":"Pod/default-montage-v1-57sqv","fieldPath":"spec.initContainers{init}"},"reason":"Created","source.component":"kubelet","source.host":"pach-control-plane","firstTimestamp":1714067003,"lastTimestamp":1714067003,"count":1,"reportingController":"kubelet","reportingInstance":"pach-control-plane"}}
{"level":"info","ts":1714067005.6224651,"logger":"event","caller":"kube-event-tail/main.go:98","msg":"Started container init","event":{"namespace":"default","name":"default-montage-v1-57sqv.17c996dc1e794aba","involvedObject":{"name":"Pod/default-montage-v1-57sqv","fieldPath":"spec.initContainers{init}"},"reason":"Started","source.component":"kubelet","source.host":"pach-control-plane","firstTimestamp":1714067005,"lastTimestamp":1714067005,"count":1,"reportingController":"kubelet","reportingInstance":"pach-control-plane"}}
{"level":"info","ts":1714067007.3544064,"logger":"event","caller":"kube-event-tail/main.go:98","msg":"Pulling image \"dpokidov/imagemagick:7.1.0-23\"","event":{"namespace":"default","name":"default-montage-v1-57sqv.17c996dc9634e4dd","involvedObject":{"name":"Pod/default-montage-v1-57sqv","fieldPath":"spec.containers{user}"},"reason":"Pulling","source.component":"kubelet","source.host":"pach-control-plane","firstTimestamp":1714067007,"lastTimestamp":1714067007,"count":1,"reportingController":"kubelet","reportingInstance":"pach-control-plane"}}
{"level":"info","ts":1714067007.3616552,"logger":"event","caller":"kube-event-tail/main.go:98","msg":"Pulling image \"pachyderm/opencv:1.0\"","event":{"namespace":"default","name":"default-edges-v1-292m8.17c996dc965430c8","involvedObject":{"name":"Pod/default-edges-v1-292m8","fieldPath":"spec.containers{user}"},"reason":"Pulling","source.component":"kubelet","source.host":"pach-control-plane","firstTimestamp":1714067007,"lastTimestamp":1714067007,"count":1,"reportingController":"kubelet","reportingInstance":"pach-control-plane"}}
{"level":"info","ts":1714067010.4103332,"logger":"event","caller":"kube-event-tail/main.go:98","msg":"Scaled up replica set console-75589574fd to 1","event":{"namespace":"default","name":"console.17c996dd4c7a1485","involvedObject":{"name":"Deployment/console"},"reason":"ScalingReplicaSet","source.component":"deployment-controller","firstTimestamp":1714067010,"lastTimestamp":1714067010,"count":1,"reportingController":"deployment-controller"}}
{"level":"info","ts":1714067010.435264,"logger":"event","caller":"kube-event-tail/main.go:98","msg":"Created pod: console-75589574fd-bbf9t","event":{"namespace":"default","name":"console-75589574fd.17c996dd4d7d949f","involvedObject":{"name":"ReplicaSet/console-75589574fd"},"reason":"SuccessfulCreate","source.component":"replicaset-controller","firstTimestamp":1714067010,"lastTimestamp":1714067010,"count":1,"reportingController":"replicaset-controller"}}
{"level":"info","ts":1714067010.4370868,"logger":"event","caller":"kube-event-tail/main.go:98","msg":"Successfully assigned default/console-75589574fd-bbf9t to pach-control-plane","event":{"namespace":"default","name":"console-75589574fd-bbf9t.17c996dd4dee45c5","involvedObject":{"name":"Pod/console-75589574fd-bbf9t"},"reason":"Scheduled","source.component":"default-scheduler","firstTimestamp":1714067010,"lastTimestamp":1714067010,"count":1,"reportingController":"default-scheduler"}}
{"level":"info","ts":1714067010.478469,"logger":"event","caller":"kube-event-tail/main.go:98","msg":"Scaled up replica set pachd-5bdcfbd65b to 1","event":{"namespace":"default","name":"pachd.17c996dd50848b0c","involvedObject":{"name":"Deployment/pachd"},"reason":"ScalingReplicaSet","source.component":"deployment-controller","firstTimestamp":1714067010,"lastTimestamp":1714067010,"count":1,"reportingController":"deployment-controller"}}
{"level":"info","ts":1714067010.4937484,"logger":"event","caller":"kube-event-tail/main.go:98","msg":"Created pod: pachd-5bdcfbd65b-m96lx","event":{"namespace":"default","name":"pachd-5bdcfbd65b.17c996dd51180cea","involvedObject":{"name":"ReplicaSet/pachd-5bdcfbd65b"},"reason":"SuccessfulCreate","source.component":"replicaset-controller","firstTimestamp":1714067010,"lastTimestamp":1714067010,"count":1,"reportingController":"replicaset-controller"}}
{"level":"info","ts":1714067010.5090094,"logger":"event","caller":"kube-event-tail/main.go:98","msg":"Successfully assigned default/pachd-5bdcfbd65b-m96lx to pach-control-plane","event":{"namespace":"default","name":"pachd-5bdcfbd65b-m96lx.17c996dd51b65125","involvedObject":{"name":"Pod/pachd-5bdcfbd65b-m96lx"},"reason":"Scheduled","source.component":"default-scheduler","firstTimestamp":1714067010,"lastTimestamp":1714067010,"count":1,"reportingController":"default-scheduler"}}
{"level":"info","ts":1714067010.925028,"logger":"event","caller":"kube-event-tail/main.go:98","msg":"Container image \"pachyderm/haberdashery:2.8.0-alpha.5\" already present on machine","event":{"namespace":"default","name":"console-75589574fd-bbf9t.17c996dd6b26b757","involvedObject":{"name":"Pod/console-75589574fd-bbf9t","fieldPath":"spec.containers{console}"},"reason":"Pulled","source.component":"kubelet","source.host":"pach-control-plane","firstTimestamp":1714067010,"lastTimestamp":1714067010,"count":1,"reportingController":"kubelet","reportingInstance":"pach-control-plane"}}
{"level":"info","ts":1714067010.9430077,"logger":"event","caller":"kube-event-tail/main.go:98","msg":"Pulling image \"localhost:5001/pachd:22f229cb51e294acfd461f8b751e2937cfc2054a080f5a6a5a74f4028c495dec\"","event":{"namespace":"default","name":"pachd-5bdcfbd65b-m96lx.17c996dd6c118cd6","involvedObject":{"name":"Pod/pachd-5bdcfbd65b-m96lx","fieldPath":"spec.containers{pachd}"},"reason":"Pulling","source.component":"kubelet","source.host":"pach-control-plane","firstTimestamp":1714067010,"lastTimestamp":1714067010,"count":1,"reportingController":"kubelet","reportingInstance":"pach-control-plane"}}
{"level":"info","ts":1714067010.9715931,"logger":"event","caller":"kube-event-tail/main.go:98","msg":"Created container console","event":{"namespace":"default","name":"console-75589574fd-bbf9t.17c996dd6df0e72e","involvedObject":{"name":"Pod/console-75589574fd-bbf9t","fieldPath":"spec.containers{console}"},"reason":"Created","source.component":"kubelet","source.host":"pach-control-plane","firstTimestamp":1714067010,"lastTimestamp":1714067010,"count":1,"reportingController":"kubelet","reportingInstance":"pach-control-plane"}}
{"level":"info","ts":1714067011.0936248,"logger":"event","caller":"kube-event-tail/main.go:98","msg":"Started container console","event":{"namespace":"default","name":"console-75589574fd-bbf9t.17c996dd7503e35d","involvedObject":{"name":"Pod/console-75589574fd-bbf9t","fieldPath":"spec.containers{console}"},"reason":"Started","source.component":"kubelet","source.host":"pach-control-plane","firstTimestamp":1714067011,"lastTimestamp":1714067011,"count":1,"reportingController":"kubelet","reportingInstance":"pach-control-plane"}}
{"level":"info","ts":1714067011.3634565,"logger":"event","caller":"kube-event-tail/main.go:98","msg":"Readiness probe failed: Get \"http://10.244.0.23:4000/health\": dial tcp 10.244.0.23:4000: connect: connection refused","event":{"namespace":"default","name":"console-75589574fd-bbf9t.17c996dd854bab61","involvedObject":{"name":"Pod/console-75589574fd-bbf9t","fieldPath":"spec.containers{console}"},"reason":"Unhealthy","source.component":"kubelet","source.host":"pach-control-plane","firstTimestamp":1714067011,"lastTimestamp":1714067011,"count":1,"reportingController":"kubelet","reportingInstance":"pach-control-plane","type":"Warning"}}
{"level":"info","ts":1714067012.121445,"logger":"event","caller":"kube-event-tail/main.go:98","msg":"Successfully pulled image \"dpokidov/imagemagick:7.1.0-23\" in 4.767s (4.767s including waiting)","event":{"namespace":"default","name":"default-montage-v1-57sqv.17c996ddb25a490e","involvedObject":{"name":"Pod/default-montage-v1-57sqv","fieldPath":"spec.containers{user}"},"reason":"Pulled","source.component":"kubelet","source.host":"pach-control-plane","firstTimestamp":1714067012,"lastTimestamp":1714067012,"count":1,"reportingController":"kubelet","reportingInstance":"pach-control-plane"}}
{"level":"info","ts":1714067012.17819,"logger":"event","caller":"kube-event-tail/main.go:98","msg":"Created container user","event":{"namespace":"default","name":"default-montage-v1-57sqv.17c996ddb5aaa0b5","involvedObject":{"name":"Pod/default-montage-v1-57sqv","fieldPath":"spec.containers{user}"},"reason":"Created","source.component":"kubelet","source.host":"pach-control-plane","firstTimestamp":1714067012,"lastTimestamp":1714067012,"count":1,"reportingController":"kubelet","reportingInstance":"pach-control-plane"}}
{"level":"info","ts":1714067012.2815135,"logger":"event","caller":"kube-event-tail/main.go:98","msg":"Started container user","event":{"namespace":"default","name":"default-montage-v1-57sqv.17c996ddbbb29d99","involvedObject":{"name":"Pod/default-montage-v1-57sqv","fieldPath":"spec.containers{user}"},"reason":"Started","source.component":"kubelet","source.host":"pach-control-plane","firstTimestamp":1714067012,"lastTimestamp":1714067012,"count":1,"reportingController":"kubelet","reportingInstance":"pach-control-plane"}}
{"level":"info","ts":1714067012.2864616,"logger":"event","caller":"kube-event-tail/main.go:98","msg":"Container image \"localhost:5001/pachd:81d74ab385fe002f0ca96b9b75509cb8f0ba65cf73262f4d020ecd2fc736c917\" already present on machine","event":{"namespace":"default","name":"default-montage-v1-57sqv.17c996ddbbbb00ea","involvedObject":{"name":"Pod/default-montage-v1-57sqv","fieldPath":"spec.containers{storage}"},"reason":"Pulled","source.component":"kubelet","source.host":"pach-control-plane","firstTimestamp":1714067012,"lastTimestamp":1714067012,"count":1,"reportingController":"kubelet","reportingInstance":"pach-control-plane"}}
{"level":"info","ts":1714067012.338751,"logger":"event","caller":"kube-event-tail/main.go:98","msg":"Created container storage","event":{"namespace":"default","name":"default-montage-v1-57sqv.17c996ddbf6cd5d3","involvedObject":{"name":"Pod/default-montage-v1-57sqv","fieldPath":"spec.containers{storage}"},"reason":"Created","source.component":"kubelet","source.host":"pach-control-plane","firstTimestamp":1714067012,"lastTimestamp":1714067012,"count":1,"reportingController":"kubelet","reportingInstance":"pach-control-plane"}}
{"level":"info","ts":1714067012.4038658,"logger":"event","caller":"kube-event-tail/main.go:98","msg":"Scaled down replica set console-967cf447d to 0 from 1","event":{"namespace":"default","name":"console.17c996ddc346c94c","involvedObject":{"name":"Deployment/console"},"reason":"ScalingReplicaSet","source.component":"deployment-controller","firstTimestamp":1714067012,"lastTimestamp":1714067012,"count":1,"reportingController":"deployment-controller"}}
{"level":"info","ts":1714067012.430489,"logger":"event","caller":"kube-event-tail/main.go:98","msg":"Deleted pod: console-967cf447d-t2cc6","event":{"namespace":"default","name":"console-967cf447d.17c996ddc43d7b31","involvedObject":{"name":"ReplicaSet/console-967cf447d"},"reason":"SuccessfulDelete","source.component":"replicaset-controller","firstTimestamp":1714067012,"lastTimestamp":1714067012,"count":1,"reportingController":"replicaset-controller"}}
{"level":"info","ts":1714067012.4306679,"logger":"event","caller":"kube-event-tail/main.go:98","msg":"Stopping container console","event":{"namespace":"default","name":"console-967cf447d-t2cc6.17c996ddc4450d85","involvedObject":{"name":"Pod/console-967cf447d-t2cc6","fieldPath":"spec.containers{console}"},"reason":"Killing","source.component":"kubelet","source.host":"pach-control-plane","firstTimestamp":1714067012,"lastTimestamp":1714067012,"count":1,"reportingController":"kubelet","reportingInstance":"pach-control-plane"}}
{"level":"info","ts":1714067012.44782,"logger":"event","caller":"kube-event-tail/main.go:98","msg":"Started container storage","event":{"namespace":"default","name":"default-montage-v1-57sqv.17c996ddc57ebb1b","involvedObject":{"name":"Pod/default-montage-v1-57sqv","fieldPath":"spec.containers{storage}"},"reason":"Started","source.component":"kubelet","source.host":"pach-control-plane","firstTimestamp":1714067012,"lastTimestamp":1714067012,"count":1,"reportingController":"kubelet","reportingInstance":"pach-control-plane"}}
{"level":"info","ts":1714067013.8994384,"logger":"event","caller":"kube-event-tail/main.go:98","msg":"Failed to pull image \"pachyderm/opencv:1.0\": failed to pull and unpack image \"docker.io/pachyderm/opencv:1.0\": failed to copy: httpReadSeeker: failed open: unexpected status code https://registry-1.docker.io/v2/pachyderm/opencv/blobs/sha256:9f13e0ac480c2c862ae7aca8536bf2250b4d410468e6d33dc2f8ade1d368e184: 500 Internal Server Error","event":{"namespace":"default","name":"default-edges-v1-292m8.17c996de1c492c9c","involvedObject":{"name":"Pod/default-edges-v1-292m8","fieldPath":"spec.containers{user}"},"reason":"Failed","source.component":"kubelet","source.host":"pach-control-plane","firstTimestamp":1714067013,"lastTimestamp":1714067013,"count":1,"reportingController":"kubelet","reportingInstance":"pach-control-plane","type":"Warning"}}
{"level":"info","ts":1714067013.903751,"logger":"event","caller":"kube-event-tail/main.go:98","msg":"Error: ErrImagePull","event":{"namespace":"default","name":"default-edges-v1-292m8.17c996de1c49715d","involvedObject":{"name":"Pod/default-edges-v1-292m8","fieldPath":"spec.containers{user}"},"reason":"Failed","source.component":"kubelet","source.host":"pach-control-plane","firstTimestamp":1714067013,"lastTimestamp":1714067013,"count":1,"reportingController":"kubelet","reportingInstance":"pach-control-plane","type":"Warning"}}
{"level":"info","ts":1714067013.9114046,"logger":"event","caller":"kube-event-tail/main.go:98","msg":"Container image \"localhost:5001/pachd:81d74ab385fe002f0ca96b9b75509cb8f0ba65cf73262f4d020ecd2fc736c917\" already present on machine","event":{"namespace":"default","name":"default-edges-v1-292m8.17c996de1c523e8b","involvedObject":{"name":"Pod/default-edges-v1-292m8","fieldPath":"spec.containers{storage}"},"reason":"Pulled","source.component":"kubelet","source.host":"pach-control-plane","firstTimestamp":1714067013,"lastTimestamp":1714067013,"count":1,"reportingController":"kubelet","reportingInstance":"pach-control-plane"}}
{"level":"info","ts":1714067014.04689,"logger":"event","caller":"kube-event-tail/main.go:98","msg":"Created container storage","event":{"namespace":"default","name":"default-edges-v1-292m8.17c996de24ed04e5","involvedObject":{"name":"Pod/default-edges-v1-292m8","fieldPath":"spec.containers{storage}"},"reason":"Created","source.component":"kubelet","source.host":"pach-control-plane","firstTimestamp":1714067014,"lastTimestamp":1714067014,"count":1,"reportingController":"kubelet","reportingInstance":"pach-control-plane"}}
{"level":"info","ts":1714067014.157579,"logger":"event","caller":"kube-event-tail/main.go:98","msg":"Started container storage","event":{"namespace":"default","name":"default-edges-v1-292m8.17c996de2b6ce9da","involvedObject":{"name":"Pod/default-edges-v1-292m8","fieldPath":"spec.containers{storage}"},"reason":"Started","source.component":"kubelet","source.host":"pach-control-plane","firstTimestamp":1714067014,"lastTimestamp":1714067014,"count":1,"reportingController":"kubelet","reportingInstance":"pach-control-plane"}}
{"level":"info","ts":1714067014.3781867,"logger":"event","caller":"kube-event-tail/main.go:98","msg":"Back-off pulling image \"pachyderm/opencv:1.0\"","event":{"namespace":"default","name":"default-edges-v1-292m8.17c996de38eb5495","involvedObject":{"name":"Pod/default-edges-v1-292m8","fieldPath":"spec.containers{user}"},"reason":"BackOff","source.component":"kubelet","source.host":"pach-control-plane","firstTimestamp":1714067014,"lastTimestamp":1714067014,"count":1,"reportingController":"kubelet","reportingInstance":"pach-control-plane"}}
{"level":"info","ts":1714067014.3885849,"logger":"event","caller":"kube-event-tail/main.go:98","msg":"Error: ImagePullBackOff","event":{"namespace":"default","name":"default-edges-v1-292m8.17c996de38eb7501","involvedObject":{"name":"Pod/default-edges-v1-292m8","fieldPath":"spec.containers{user}"},"reason":"Failed","source.component":"kubelet","source.host":"pach-control-plane","firstTimestamp":1714067014,"lastTimestamp":1714067014,"count":1,"reportingController":"kubelet","reportingInstance":"pach-control-plane","type":"Warning"}}
{"level":"info","ts":1714067014.6369038,"logger":"event","caller":"kube-event-tail/main.go:98","msg":"Successfully pulled image \"localhost:5001/pachd:22f229cb51e294acfd461f8b751e2937cfc2054a080f5a6a5a74f4028c495dec\" in 740ms (3.696s including waiting)","event":{"namespace":"default","name":"pachd-5bdcfbd65b-m96lx.17c996de4867ce66","involvedObject":{"name":"Pod/pachd-5bdcfbd65b-m96lx","fieldPath":"spec.containers{pachd}"},"reason":"Pulled","source.component":"kubelet","source.host":"pach-control-plane","firstTimestamp":1714067014,"lastTimestamp":1714067014,"count":1,"reportingController":"kubelet","reportingInstance":"pach-control-plane"}}
{"level":"info","ts":1714067014.6871824,"logger":"event","caller":"kube-event-tail/main.go:98","msg":"Created container pachd","event":{"namespace":"default","name":"pachd-5bdcfbd65b-m96lx.17c996de4b6d8161","involvedObject":{"name":"Pod/pachd-5bdcfbd65b-m96lx","fieldPath":"spec.containers{pachd}"},"reason":"Created","source.component":"kubelet","source.host":"pach-control-plane","firstTimestamp":1714067014,"lastTimestamp":1714067014,"count":1,"reportingController":"kubelet","reportingInstance":"pach-control-plane"}}
{"level":"info","ts":1714067014.8056087,"logger":"event","caller":"kube-event-tail/main.go:98","msg":"Started container pachd","event":{"namespace":"default","name":"pachd-5bdcfbd65b-m96lx.17c996de523b702c","involvedObject":{"name":"Pod/pachd-5bdcfbd65b-m96lx","fieldPath":"spec.containers{pachd}"},"reason":"Started","source.component":"kubelet","source.host":"pach-control-plane","firstTimestamp":1714067014,"lastTimestamp":1714067014,"count":1,"reportingController":"kubelet","reportingInstance":"pach-control-plane"}}
{"level":"info","ts":1714067021.5611444,"logger":"event","caller":"kube-event-tail/main.go:98","msg":"Scaled down replica set pachd-d868b489c to 0 from 1","event":{"namespace":"default","name":"pachd.17c996dfe5266367","involvedObject":{"name":"Deployment/pachd"},"reason":"ScalingReplicaSet","source.component":"deployment-controller","firstTimestamp":1714067021,"lastTimestamp":1714067021,"count":1,"reportingController":"deployment-controller"}}
{"level":"info","ts":1714067021.57538,"logger":"event","caller":"kube-event-tail/main.go:98","msg":"Deleted pod: pachd-d868b489c-7s5xp","event":{"namespace":"default","name":"pachd-d868b489c.17c996dfe5a80c68","involvedObject":{"name":"ReplicaSet/pachd-d868b489c"},"reason":"SuccessfulDelete","source.component":"replicaset-controller","firstTimestamp":1714067021,"lastTimestamp":1714067021,"count":1,"reportingController":"replicaset-controller"}}
{"level":"info","ts":1714067021.5756693,"logger":"event","caller":"kube-event-tail/main.go:98","msg":"Stopping container pachd","event":{"namespace":"default","name":"pachd-d868b489c-7s5xp.17c996dfe5c45e32","involvedObject":{"name":"Pod/pachd-d868b489c-7s5xp","fieldPath":"spec.containers{pachd}"},"reason":"Killing","source.component":"kubelet","source.host":"pach-control-plane","firstTimestamp":1714067021,"lastTimestamp":1714067021,"count":1,"reportingController":"kubelet","reportingInstance":"pach-control-plane"}}
{"level":"info","ts":1714067022.837788,"logger":"event","caller":"kube-event-tail/main.go:98","msg":"Readiness probe failed: command \"/pachd --readiness\" timed out","event":{"namespace":"default","name":"pachd-d868b489c-7s5xp.17c996e030ac8d55","involvedObject":{"name":"Pod/pachd-d868b489c-7s5xp","fieldPath":"spec.containers{pachd}"},"reason":"Unhealthy","source.component":"kubelet","source.host":"pach-control-plane","firstTimestamp":1714067022,"lastTimestamp":1714067022,"count":1,"reportingController":"kubelet","reportingInstance":"pach-control-plane","type":"Warning"}}
{"level":"info","ts":1714067029.3079832,"logger":"event","caller":"kube-event-tail/main.go:98","msg":"Pulling image \"pachyderm/opencv:1.0\"","event":{"namespace":"default","name":"default-edges-v1-292m8.17c996dc965430c8","involvedObject":{"name":"Pod/default-edges-v1-292m8","fieldPath":"spec.containers{user}"},"reason":"Pulling","source.component":"kubelet","source.host":"pach-control-plane","firstTimestamp":1714067007,"lastTimestamp":1714067029,"ongoingDuration":22,"count":2,"reportingController":"kubelet","reportingInstance":"pach-control-plane"}}
{"level":"info","ts":1714067032.1793776,"logger":"event","caller":"kube-event-tail/main.go:98","msg":"Readiness probe errored: rpc error: code = NotFound desc = failed to exec in container: failed to load task: no running task found: task f5988f204e341450fd28e563c703c160d4c42e37fb190fb226c4d17190cebd9b not found: not found","event":{"namespace":"default","name":"pachd-d868b489c-7s5xp.17c996e25d55d387","involvedObject":{"name":"Pod/pachd-d868b489c-7s5xp","fieldPath":"spec.containers{pachd}"},"reason":"Unhealthy","source.component":"kubelet","source.host":"pach-control-plane","firstTimestamp":1714067032,"lastTimestamp":1714067032,"count":1,"reportingController":"kubelet","reportingInstance":"pach-control-plane","type":"Warning"}}
{"level":"info","ts":1714067036.1905818,"logger":"event","caller":"kube-event-tail/main.go:98","msg":"Stopping container user","event":{"namespace":"default","name":"default-montage-v1-57sqv.17c996e34cc03f12","involvedObject":{"name":"Pod/default-montage-v1-57sqv","fieldPath":"spec.containers{user}"},"reason":"Killing","source.component":"kubelet","source.host":"pach-control-plane","firstTimestamp":1714067036,"lastTimestamp":1714067036,"count":1,"reportingController":"kubelet","reportingInstance":"pach-control-plane"}}
{"level":"info","ts":1714067036.199882,"logger":"event","caller":"kube-event-tail/main.go:98","msg":"Stopping container storage","event":{"namespace":"default","name":"default-montage-v1-57sqv.17c996e34cc20629","involvedObject":{"name":"Pod/default-montage-v1-57sqv","fieldPath":"spec.containers{storage}"},"reason":"Killing","source.component":"kubelet","source.host":"pach-control-plane","firstTimestamp":1714067036,"lastTimestamp":1714067036,"count":1,"reportingController":"kubelet","reportingInstance":"pach-control-plane"}}
{"level":"info","ts":1714067037.1984677,"logger":"event","caller":"kube-event-tail/main.go:98","msg":"Created pod: default-montage-v1-jsw2g","event":{"namespace":"default","name":"default-montage-v1.17c996e3886e1106","involvedObject":{"name":"ReplicationController/default-montage-v1"},"reason":"SuccessfulCreate","source.component":"replication-controller","firstTimestamp":1714067037,"lastTimestamp":1714067037,"count":1,"reportingController":"replication-controller"}}
{"level":"info","ts":1714067037.210093,"logger":"event","caller":"kube-event-tail/main.go:98","msg":"Successfully assigned default/default-montage-v1-jsw2g to pach-control-plane","event":{"namespace":"default","name":"default-montage-v1-jsw2g.17c996e3896ca8d9","involvedObject":{"name":"Pod/default-montage-v1-jsw2g"},"reason":"Scheduled","source.component":"default-scheduler","firstTimestamp":1714067037,"lastTimestamp":1714067037,"count":1,"reportingController":"default-scheduler"}}
{"level":"info","ts":1714067037.6443644,"logger":"event","caller":"kube-event-tail/main.go:98","msg":"Pulling image \"localhost:5001/worker:da5639b93a4589fe170d5a035b6d4255a0609ec6ed8031fd9c366e0fcb0deb8a\"","event":{"namespace":"default","name":"default-montage-v1-jsw2g.17c996e3a373aca2","involvedObject":{"name":"Pod/default-montage-v1-jsw2g","fieldPath":"spec.initContainers{init}"},"reason":"Pulling","source.component":"kubelet","source.host":"pach-control-plane","firstTimestamp":1714067037,"lastTimestamp":1714067037,"count":1,"reportingController":"kubelet","reportingInstance":"pach-control-plane"}}
{"level":"info","ts":1714067038.5766926,"logger":"event","caller":"kube-event-tail/main.go:98","msg":"Successfully pulled image \"pachyderm/opencv:1.0\" in 9.271s (9.271s including waiting)","event":{"namespace":"default","name":"default-edges-v1-292m8.17c996e3db04954a","involvedObject":{"name":"Pod/default-edges-v1-292m8","fieldPath":"spec.containers{user}"},"reason":"Pulled","source.component":"kubelet","source.host":"pach-control-plane","firstTimestamp":1714067038,"lastTimestamp":1714067038,"count":1,"reportingController":"kubelet","reportingInstance":"pach-control-plane"}}
{"level":"info","ts":1714067038.640211,"logger":"event","caller":"kube-event-tail/main.go:98","msg":"Created container user","event":{"namespace":"default","name":"default-edges-v1-292m8.17c996e3df0971cc","involvedObject":{"name":"Pod/default-edges-v1-292m8","fieldPath":"spec.containers{user}"},"reason":"Created","source.component":"kubelet","source.host":"pach-control-plane","firstTimestamp":1714067038,"lastTimestamp":1714067038,"count":1,"reportingController":"kubelet","reportingInstance":"pach-control-plane"}}
{"level":"info","ts":1714067038.7897577,"logger":"event","caller":"kube-event-tail/main.go:98","msg":"Started container user","event":{"namespace":"default","name":"default-edges-v1-292m8.17c996e3e7da41b1","involvedObject":{"name":"Pod/default-edges-v1-292m8","fieldPath":"spec.containers{user}"},"reason":"Started","source.component":"kubelet","source.host":"pach-control-plane","firstTimestamp":1714067038,"lastTimestamp":1714067038,"count":1,"reportingController":"kubelet","reportingInstance":"pach-control-plane"}}
{"level":"info","ts":1714067039.1691413,"logger":"event","caller":"kube-event-tail/main.go:98","msg":"Created pod: default-edges-v1-gqgbx","event":{"namespace":"default","name":"default-edges-v1.17c996e3fea673ba","involvedObject":{"name":"ReplicationController/default-edges-v1"},"reason":"SuccessfulCreate","source.component":"replication-controller","firstTimestamp":1714067039,"lastTimestamp":1714067039,"count":1,"reportingController":"replication-controller"}}
{"level":"info","ts":1714067039.1895804,"logger":"event","caller":"kube-event-tail/main.go:98","msg":"Successfully assigned default/default-edges-v1-gqgbx to pach-control-plane","event":{"namespace":"default","name":"default-edges-v1-gqgbx.17c996e3ff463600","involvedObject":{"name":"Pod/default-edges-v1-gqgbx"},"reason":"Scheduled","source.component":"default-scheduler","firstTimestamp":1714067039,"lastTimestamp":1714067039,"count":1,"reportingController":"default-scheduler"}}
{"level":"info","ts":1714067039.441524,"logger":"event","caller":"kube-event-tail/main.go:98","msg":"Stopping container storage","event":{"namespace":"default","name":"default-edges-v1-292m8.17c996e40eda3cde","involvedObject":{"name":"Pod/default-edges-v1-292m8","fieldPath":"spec.containers{storage}"},"reason":"Killing","source.component":"kubelet","source.host":"pach-control-plane","firstTimestamp":1714067039,"lastTimestamp":1714067039,"count":1,"reportingController":"kubelet","reportingInstance":"pach-control-plane"}}
{"level":"info","ts":1714067039.4464188,"logger":"event","caller":"kube-event-tail/main.go:98","msg":"Stopping container user","event":{"namespace":"default","name":"default-edges-v1-292m8.17c996e40edab7eb","involvedObject":{"name":"Pod/default-edges-v1-292m8","fieldPath":"spec.containers{user}"},"reason":"Killing","source.component":"kubelet","source.host":"pach-control-plane","firstTimestamp":1714067039,"lastTimestamp":1714067039,"count":1,"reportingController":"kubelet","reportingInstance":"pach-control-plane"}}
{"level":"info","ts":1714067040.3813117,"logger":"event","caller":"kube-event-tail/main.go:98","msg":"Successfully pulled image \"localhost:5001/worker:da5639b93a4589fe170d5a035b6d4255a0609ec6ed8031fd9c366e0fcb0deb8a\" in 1.809s (2.741s including waiting)","event":{"namespace":"default","name":"default-montage-v1-jsw2g.17c996e446e0ff68","involvedObject":{"name":"Pod/default-montage-v1-jsw2g","fieldPath":"spec.initContainers{init}"},"reason":"Pulled","source.component":"kubelet","source.host":"pach-control-plane","firstTimestamp":1714067040,"lastTimestamp":1714067040,"count":1,"reportingController":"kubelet","reportingInstance":"pach-control-plane"}}
{"level":"info","ts":1714067040.4239337,"logger":"event","caller":"kube-event-tail/main.go:98","msg":"Created container init","event":{"namespace":"default","name":"default-montage-v1-jsw2g.17c996e4495f7345","involvedObject":{"name":"Pod/default-montage-v1-jsw2g","fieldPath":"spec.initContainers{init}"},"reason":"Created","source.component":"kubelet","source.host":"pach-control-plane","firstTimestamp":1714067040,"lastTimestamp":1714067040,"count":1,"reportingController":"kubelet","reportingInstance":"pach-control-plane"}}
{"level":"info","ts":1714067040.480404,"logger":"event","caller":"kube-event-tail/main.go:98","msg":"Container image \"localhost:5001/worker:da5639b93a4589fe170d5a035b6d4255a0609ec6ed8031fd9c366e0fcb0deb8a\" already present on machine","event":{"namespace":"default","name":"default-edges-v1-gqgbx.17c996e44cca747b","involvedObject":{"name":"Pod/default-edges-v1-gqgbx","fieldPath":"spec.initContainers{init}"},"reason":"Pulled","source.component":"kubelet","source.host":"pach-control-plane","firstTimestamp":1714067040,"lastTimestamp":1714067040,"count":1,"reportingController":"kubelet","reportingInstance":"pach-control-plane"}}
{"level":"info","ts":1714067040.5172436,"logger":"event","caller":"kube-event-tail/main.go:98","msg":"Started container init","event":{"namespace":"default","name":"default-montage-v1-jsw2g.17c996e44e5c707b","involvedObject":{"name":"Pod/default-montage-v1-jsw2g","fieldPath":"spec.initContainers{init}"},"reason":"Started","source.component":"kubelet","source.host":"pach-control-plane","firstTimestamp":1714067040,"lastTimestamp":1714067040,"count":1,"reportingController":"kubelet","reportingInstance":"pach-control-plane"}}
{"level":"info","ts":1714067040.5398347,"logger":"event","caller":"kube-event-tail/main.go:98","msg":"Created container init","event":{"namespace":"default","name":"default-edges-v1-gqgbx.17c996e45056406e","involvedObject":{"name":"Pod/default-edges-v1-gqgbx","fieldPath":"spec.initContainers{init}"},"reason":"Created","source.component":"kubelet","source.host":"pach-control-plane","firstTimestamp":1714067040,"lastTimestamp":1714067040,"count":1,"reportingController":"kubelet","reportingInstance":"pach-control-plane"}}
{"level":"info","ts":1714067041.4690754,"logger":"event","caller":"kube-event-tail/main.go:98","msg":"Started container init","event":{"namespace":"default","name":"default-edges-v1-gqgbx.17c996e470dd9e5e","involvedObject":{"name":"Pod/default-edges-v1-gqgbx","fieldPath":"spec.initContainers{init}"},"reason":"Started","source.component":"kubelet","source.host":"pach-control-plane","firstTimestamp":1714067041,"lastTimestamp":1714067041,"count":1,"reportingController":"kubelet","reportingInstance":"pach-control-plane"}}
{"level":"info","ts":1714067042.4553108,"logger":"event","caller":"kube-event-tail/main.go:98","msg":"Container image \"pachyderm/opencv:1.0\" already present on machine","event":{"namespace":"default","name":"default-edges-v1-gqgbx.17c996e4c2784e3f","involvedObject":{"name":"Pod/default-edges-v1-gqgbx","fieldPath":"spec.containers{user}"},"reason":"Pulled","source.component":"kubelet","source.host":"pach-control-plane","firstTimestamp":1714067042,"lastTimestamp":1714067042,"count":1,"reportingController":"kubelet","reportingInstance":"pach-control-plane"}}
{"level":"info","ts":1714067042.4626865,"logger":"event","caller":"kube-event-tail/main.go:98","msg":"Container image \"dpokidov/imagemagick:7.1.0-23\" already present on machine","event":{"namespace":"default","name":"default-montage-v1-jsw2g.17c996e4c2921925","involvedObject":{"name":"Pod/default-montage-v1-jsw2g","fieldPath":"spec.containers{user}"},"reason":"Pulled","source.component":"kubelet","source.host":"pach-control-plane","firstTimestamp":1714067042,"lastTimestamp":1714067042,"count":1,"reportingController":"kubelet","reportingInstance":"pach-control-plane"}}
{"level":"info","ts":1714067042.5423841,"logger":"event","caller":"kube-event-tail/main.go:98","msg":"Created container user","event":{"namespace":"default","name":"default-edges-v1-gqgbx.17c996e4c7b52b08","involvedObject":{"name":"Pod/default-edges-v1-gqgbx","fieldPath":"spec.containers{user}"},"reason":"Created","source.component":"kubelet","source.host":"pach-control-plane","firstTimestamp":1714067042,"lastTimestamp":1714067042,"count":1,"reportingController":"kubelet","reportingInstance":"pach-control-plane"}}
{"level":"info","ts":1714067042.5890193,"logger":"event","caller":"kube-event-tail/main.go:98","msg":"Created container user","event":{"namespace":"default","name":"default-montage-v1-jsw2g.17c996e4ca0777e2","involvedObject":{"name":"Pod/default-montage-v1-jsw2g","fieldPath":"spec.containers{user}"},"reason":"Created","source.component":"kubelet","source.host":"pach-control-plane","firstTimestamp":1714067042,"lastTimestamp":1714067042,"count":1,"reportingController":"kubelet","reportingInstance":"pach-control-plane"}}
{"level":"info","ts":1714067042.6566982,"logger":"event","caller":"kube-event-tail/main.go:98","msg":"Started container user","event":{"namespace":"default","name":"default-edges-v1-gqgbx.17c996e4ce8160cd","involvedObject":{"name":"Pod/default-edges-v1-gqgbx","fieldPath":"spec.containers{user}"},"reason":"Started","source.component":"kubelet","source.host":"pach-control-plane","firstTimestamp":1714067042,"lastTimestamp":1714067042,"count":1,"reportingController":"kubelet","reportingInstance":"pach-control-plane"}}
{"level":"info","ts":1714067042.6624656,"logger":"event","caller":"kube-event-tail/main.go:98","msg":"Started container user","event":{"namespace":"default","name":"default-montage-v1-jsw2g.17c996e4ce821d7a","involvedObject":{"name":"Pod/default-montage-v1-jsw2g","fieldPath":"spec.containers{user}"},"reason":"Started","source.component":"kubelet","source.host":"pach-control-plane","firstTimestamp":1714067042,"lastTimestamp":1714067042,"count":1,"reportingController":"kubelet","reportingInstance":"pach-control-plane"}}
{"level":"info","ts":1714067042.670576,"logger":"event","caller":"kube-event-tail/main.go:98","msg":"Container image \"localhost:5001/pachd:22f229cb51e294acfd461f8b751e2937cfc2054a080f5a6a5a74f4028c495dec\" already present on machine","event":{"namespace":"default","name":"default-montage-v1-jsw2g.17c996e4ce8b7b31","involvedObject":{"name":"Pod/default-montage-v1-jsw2g","fieldPath":"spec.containers{storage}"},"reason":"Pulled","source.component":"kubelet","source.host":"pach-control-plane","firstTimestamp":1714067042,"lastTimestamp":1714067042,"count":1,"reportingController":"kubelet","reportingInstance":"pach-control-plane"}}
{"level":"info","ts":1714067042.6781232,"logger":"event","caller":"kube-event-tail/main.go:98","msg":"Container image \"localhost:5001/pachd:22f229cb51e294acfd461f8b751e2937cfc2054a080f5a6a5a74f4028c495dec\" already present on machine","event":{"namespace":"default","name":"default-edges-v1-gqgbx.17c996e4ce8b9ad5","involvedObject":{"name":"Pod/default-edges-v1-gqgbx","fieldPath":"spec.containers{storage}"},"reason":"Pulled","source.component":"kubelet","source.host":"pach-control-plane","firstTimestamp":1714067042,"lastTimestamp":1714067042,"count":1,"reportingController":"kubelet","reportingInstance":"pach-control-plane"}}
{"level":"info","ts":1714067042.7724001,"logger":"event","caller":"kube-event-tail/main.go:98","msg":"Created container storage","event":{"namespace":"default","name":"default-edges-v1-gqgbx.17c996e4d53ea12d","involvedObject":{"name":"Pod/default-edges-v1-gqgbx","fieldPath":"spec.containers{storage}"},"reason":"Created","source.component":"kubelet","source.host":"pach-control-plane","firstTimestamp":1714067042,"lastTimestamp":1714067042,"count":1,"reportingController":"kubelet","reportingInstance":"pach-control-plane"}}
{"level":"info","ts":1714067042.804759,"logger":"event","caller":"kube-event-tail/main.go:98","msg":"Created container storage","event":{"namespace":"default","name":"default-montage-v1-jsw2g.17c996e4d75effae","involvedObject":{"name":"Pod/default-montage-v1-jsw2g","fieldPath":"spec.containers{storage}"},"reason":"Created","source.component":"kubelet","source.host":"pach-control-plane","firstTimestamp":1714067042,"lastTimestamp":1714067042,"count":1,"reportingController":"kubelet","reportingInstance":"pach-control-plane"}}
{"level":"info","ts":1714067042.887008,"logger":"event","caller":"kube-event-tail/main.go:98","msg":"Started container storage","event":{"namespace":"default","name":"default-montage-v1-jsw2g.17c996e4dc3a03cd","involvedObject":{"name":"Pod/default-montage-v1-jsw2g","fieldPath":"spec.containers{storage}"},"reason":"Started","source.component":"kubelet","source.host":"pach-control-plane","firstTimestamp":1714067042,"lastTimestamp":1714067042,"count":1,"reportingController":"kubelet","reportingInstance":"pach-control-plane"}}
{"level":"info","ts":1714067042.8912485,"logger":"event","caller":"kube-event-tail/main.go:98","msg":"Started container storage","event":{"namespace":"default","name":"default-edges-v1-gqgbx.17c996e4dc3a7f3e","involvedObject":{"name":"Pod/default-edges-v1-gqgbx","fieldPath":"spec.containers{storage}"},"reason":"Started","source.component":"kubelet","source.host":"pach-control-plane","firstTimestamp":1714067042,"lastTimestamp":1714067042,"count":1,"reportingController":"kubelet","reportingInstance":"pach-control-plane"}}
{"level":"info","ts":1714067059.0484114,"logger":"event","caller":"kube-event-tail/main.go:98","msg":"Scaled up replica set pachw-6f8fb9fd9c to 1 from 0","event":{"namespace":"default","name":"pachw.17c996e89f19d0ef","involvedObject":{"name":"Deployment/pachw"},"reason":"ScalingReplicaSet","source.component":"deployment-controller","firstTimestamp":1714067059,"lastTimestamp":1714067059,"count":1,"reportingController":"deployment-controller"}}
{"level":"info","ts":1714067059.0642135,"logger":"event","caller":"kube-event-tail/main.go:98","msg":"Created pod: pachw-6f8fb9fd9c-gg69j","event":{"namespace":"default","name":"pachw-6f8fb9fd9c.17c996e8a05e8b7e","involvedObject":{"name":"ReplicaSet/pachw-6f8fb9fd9c"},"reason":"SuccessfulCreate","source.component":"replicaset-controller","firstTimestamp":1714067059,"lastTimestamp":1714067059,"count":1,"reportingController":"replicaset-controller"}}
{"level":"info","ts":1714067059.077471,"logger":"event","caller":"kube-event-tail/main.go:98","msg":"Successfully assigned default/pachw-6f8fb9fd9c-gg69j to pach-control-plane","event":{"namespace":"default","name":"pachw-6f8fb9fd9c-gg69j.17c996e8a1455632","involvedObject":{"name":"Pod/pachw-6f8fb9fd9c-gg69j"},"reason":"Scheduled","source.component":"default-scheduler","firstTimestamp":1714067059,"lastTimestamp":1714067059,"count":1,"reportingController":"default-scheduler"}}
{"level":"info","ts":1714067059.5360062,"logger":"event","caller":"kube-event-tail/main.go:98","msg":"Container image \"localhost:5001/pachd:22f229cb51e294acfd461f8b751e2937cfc2054a080f5a6a5a74f4028c495dec\" already present on machine","event":{"namespace":"default","name":"pachw-6f8fb9fd9c-gg69j.17c996e8bc2a08fd","involvedObject":{"name":"Pod/pachw-6f8fb9fd9c-gg69j","fieldPath":"spec.containers{pachw}"},"reason":"Pulled","source.component":"kubelet","source.host":"pach-control-plane","firstTimestamp":1714067059,"lastTimestamp":1714067059,"count":1,"reportingController":"kubelet","reportingInstance":"pach-control-plane"}}
{"level":"info","ts":1714067059.5826468,"logger":"event","caller":"kube-event-tail/main.go:98","msg":"Created container pachw","event":{"namespace":"default","name":"pachw-6f8fb9fd9c-gg69j.17c996e8bf49edfe","involvedObject":{"name":"Pod/pachw-6f8fb9fd9c-gg69j","fieldPath":"spec.containers{pachw}"},"reason":"Created","source.component":"kubelet","source.host":"pach-control-plane","firstTimestamp":1714067059,"lastTimestamp":1714067059,"count":1,"reportingController":"kubelet","reportingInstance":"pach-control-plane"}}
{"level":"info","ts":1714067059.702461,"logger":"event","caller":"kube-event-tail/main.go:98","msg":"Started container pachw","event":{"namespace":"default","name":"pachw-6f8fb9fd9c-gg69j.17c996e8c6847dac","involvedObject":{"name":"Pod/pachw-6f8fb9fd9c-gg69j","fieldPath":"spec.containers{pachw}"},"reason":"Started","source.component":"kubelet","source.host":"pach-control-plane","firstTimestamp":1714067059,"lastTimestamp":1714067059,"count":1,"reportingController":"kubelet","reportingInstance":"pach-control-plane"}}
{"level":"info","ts":1714067119.042827,"logger":"event","caller":"kube-event-tail/main.go:98","msg":"Scaled down replica set pachw-6f8fb9fd9c to 0 from 1","event":{"namespace":"default","name":"pachw.17c996f696d371e2","involvedObject":{"name":"Deployment/pachw"},"reason":"ScalingReplicaSet","source.component":"deployment-controller","firstTimestamp":1714067119,"lastTimestamp":1714067119,"count":1,"reportingController":"deployment-controller"}}
{"level":"info","ts":1714067119.0466752,"logger":"event","caller":"kube-event-tail/main.go:98","msg":"Deleted pod: pachw-6f8fb9fd9c-gg69j","event":{"namespace":"default","name":"pachw-6f8fb9fd9c.17c996f697ac7e24","involvedObject":{"name":"ReplicaSet/pachw-6f8fb9fd9c"},"reason":"SuccessfulDelete","source.component":"replicaset-controller","firstTimestamp":1714067119,"lastTimestamp":1714067119,"count":1,"reportingController":"replicaset-controller"}}
{"level":"info","ts":1714067119.0512464,"logger":"event","caller":"kube-event-tail/main.go:98","msg":"Stopping container pachw","event":{"namespace":"default","name":"pachw-6f8fb9fd9c-gg69j.17c996f697af952d","involvedObject":{"name":"Pod/pachw-6f8fb9fd9c-gg69j","fieldPath":"spec.containers{pachw}"},"reason":"Killing","source.component":"kubelet","source.host":"pach-control-plane","firstTimestamp":1714067119,"lastTimestamp":1714067119,"count":1,"reportingController":"kubelet","reportingInstance":"pach-control-plane"}}
{"level":"info","ts":1714067179.6112838,"logger":"event","caller":"kube-event-tail/main.go:98","msg":"Stopping container user","event":{"namespace":"default","name":"default-edges-v1-gqgbx.17c99704b14143a3","involvedObject":{"name":"Pod/default-edges-v1-gqgbx","fieldPath":"spec.containers{user}"},"reason":"Killing","source.component":"kubelet","source.host":"pach-control-plane","firstTimestamp":1714067179,"lastTimestamp":1714067179,"count":1,"reportingController":"kubelet","reportingInstance":"pach-control-plane"}}
{"level":"info","ts":1714067179.6240528,"logger":"event","caller":"kube-event-tail/main.go:98","msg":"Stopping container storage","event":{"namespace":"default","name":"default-edges-v1-gqgbx.17c99704b142576c","involvedObject":{"name":"Pod/default-edges-v1-gqgbx","fieldPath":"spec.containers{storage}"},"reason":"Killing","source.component":"kubelet","source.host":"pach-control-plane","firstTimestamp":1714067179,"lastTimestamp":1714067179,"count":1,"reportingController":"kubelet","reportingInstance":"pach-control-plane"}}
{"level":"info","ts":1714067180.1568952,"logger":"event","caller":"kube-event-tail/main.go:98","msg":"Created pod: default-edges-v2-9f22j","event":{"namespace":"default","name":"default-edges-v2.17c99704d231f5e8","involvedObject":{"name":"ReplicationController/default-edges-v2"},"reason":"SuccessfulCreate","source.component":"replication-controller","firstTimestamp":1714067180,"lastTimestamp":1714067180,"count":1,"reportingController":"replication-controller"}}
{"level":"info","ts":1714067180.1704335,"logger":"event","caller":"kube-event-tail/main.go:98","msg":"Successfully assigned default/default-edges-v2-9f22j to pach-control-plane","event":{"namespace":"default","name":"default-edges-v2-9f22j.17c99704d2b4881f","involvedObject":{"name":"Pod/default-edges-v2-9f22j"},"reason":"Scheduled","source.component":"default-scheduler","firstTimestamp":1714067180,"lastTimestamp":1714067180,"count":1,"reportingController":"default-scheduler"}}
{"level":"info","ts":1714067180.5907114,"logger":"event","caller":"kube-event-tail/main.go:98","msg":"Container image \"localhost:5001/worker:da5639b93a4589fe170d5a035b6d4255a0609ec6ed8031fd9c366e0fcb0deb8a\" already present on machine","event":{"namespace":"default","name":"default-edges-v2-9f22j.17c99704ebfaf266","involvedObject":{"name":"Pod/default-edges-v2-9f22j","fieldPath":"spec.initContainers{init}"},"reason":"Pulled","source.component":"kubelet","source.host":"pach-control-plane","firstTimestamp":1714067180,"lastTimestamp":1714067180,"count":1,"reportingController":"kubelet","reportingInstance":"pach-control-plane"}}
{"level":"info","ts":1714067180.6368666,"logger":"event","caller":"kube-event-tail/main.go:98","msg":"Created container init","event":{"namespace":"default","name":"default-edges-v2-9f22j.17c99704eeca1a89","involvedObject":{"name":"Pod/default-edges-v2-9f22j","fieldPath":"spec.initContainers{init}"},"reason":"Created","source.component":"kubelet","source.host":"pach-control-plane","firstTimestamp":1714067180,"lastTimestamp":1714067180,"count":1,"reportingController":"kubelet","reportingInstance":"pach-control-plane"}}
{"level":"info","ts":1714067180.7493718,"logger":"event","caller":"kube-event-tail/main.go:98","msg":"Started container init","event":{"namespace":"default","name":"default-edges-v2-9f22j.17c99704f53a1338","involvedObject":{"name":"Pod/default-edges-v2-9f22j","fieldPath":"spec.initContainers{init}"},"reason":"Started","source.component":"kubelet","source.host":"pach-control-plane","firstTimestamp":1714067180,"lastTimestamp":1714067180,"count":1,"reportingController":"kubelet","reportingInstance":"pach-control-plane"}}
{"level":"info","ts":1714067181.7420092,"logger":"event","caller":"kube-event-tail/main.go:98","msg":"Container image \"pachyderm/opencv:1.0\" already present on machine","event":{"namespace":"default","name":"default-edges-v2-9f22j.17c99705307c4f7c","involvedObject":{"name":"Pod/default-edges-v2-9f22j","fieldPath":"spec.containers{user}"},"reason":"Pulled","source.component":"kubelet","source.host":"pach-control-plane","firstTimestamp":1714067181,"lastTimestamp":1714067181,"count":1,"reportingController":"kubelet","reportingInstance":"pach-control-plane"}}
{"level":"info","ts":1714067181.8031034,"logger":"event","caller":"kube-event-tail/main.go:98","msg":"Created container user","event":{"namespace":"default","name":"default-edges-v2-9f22j.17c997053451ffea","involvedObject":{"name":"Pod/default-edges-v2-9f22j","fieldPath":"spec.containers{user}"},"reason":"Created","source.component":"kubelet","source.host":"pach-control-plane","firstTimestamp":1714067181,"lastTimestamp":1714067181,"count":1,"reportingController":"kubelet","reportingInstance":"pach-control-plane"}}
{"level":"info","ts":1714067181.9138067,"logger":"event","caller":"kube-event-tail/main.go:98","msg":"Started container user","event":{"namespace":"default","name":"default-edges-v2-9f22j.17c997053a97f8c6","involvedObject":{"name":"Pod/default-edges-v2-9f22j","fieldPath":"spec.containers{user}"},"reason":"Started","source.component":"kubelet","source.host":"pach-control-plane","firstTimestamp":1714067181,"lastTimestamp":1714067181,"count":1,"reportingController":"kubelet","reportingInstance":"pach-control-plane"}}
{"level":"info","ts":1714067181.9207902,"logger":"event","caller":"kube-event-tail/main.go:98","msg":"Container image \"localhost:5001/pachd:22f229cb51e294acfd461f8b751e2937cfc2054a080f5a6a5a74f4028c495dec\" already present on machine","event":{"namespace":"default","name":"default-edges-v2-9f22j.17c997053aa11f04","involvedObject":{"name":"Pod/default-edges-v2-9f22j","fieldPath":"spec.containers{storage}"},"reason":"Pulled","source.component":"kubelet","source.host":"pach-control-plane","firstTimestamp":1714067181,"lastTimestamp":1714067181,"count":1,"reportingController":"kubelet","reportingInstance":"pach-control-plane"}}
{"level":"info","ts":1714067181.9550683,"logger":"event","caller":"kube-event-tail/main.go:98","msg":"Created container storage","event":{"namespace":"default","name":"default-edges-v2-9f22j.17c997053d4ea339","involvedObject":{"name":"Pod/default-edges-v2-9f22j","fieldPath":"spec.containers{storage}"},"reason":"Created","source.component":"kubelet","source.host":"pach-control-plane","firstTimestamp":1714067181,"lastTimestamp":1714067181,"count":1,"reportingController":"kubelet","reportingInstance":"pach-control-plane"}}
{"level":"info","ts":1714067182.0623186,"logger":"event","caller":"kube-event-tail/main.go:98","msg":"Started container storage","event":{"namespace":"default","name":"default-edges-v2-9f22j.17c9970543bbc48c","involvedObject":{"name":"Pod/default-edges-v2-9f22j","fieldPath":"spec.containers{storage}"},"reason":"Started","source.component":"kubelet","source.host":"pach-control-plane","firstTimestamp":1714067182,"lastTimestamp":1714067182,"count":1,"reportingController":"kubelet","reportingInstance":"pach-control-plane"}}
{"level":"info","ts":1714067856.8186297,"logger":"event","caller":"kube-event-tail/main.go:98","msg":"Successfully assigned default/console-75589574fd-bbf9t to pach-control-plane","event":{"namespace":"default","name":"console-75589574fd-bbf9t.17c996dd4dee45c5","involvedObject":{"name":"Pod/console-75589574fd-bbf9t"},"reason":"Scheduled","source.component":"default-scheduler","firstTimestamp":1714067010,"lastTimestamp":1714067010,"count":1,"reportingController":"default-scheduler"}}
{"level":"info","ts":1714067856.818677,"logger":"event","caller":"kube-event-tail/main.go:98","msg":"Container image \"pachyderm/haberdashery:2.8.0-alpha.5\" already present on machine","event":{"namespace":"default","name":"console-75589574fd-bbf9t.17c996dd6b26b757","involvedObject":{"name":"Pod/console-75589574fd-bbf9t","fieldPath":"spec.containers{console}"},"reason":"Pulled","source.component":"kubelet","source.host":"pach-control-plane","firstTimestamp":1714067010,"lastTimestamp":1714067010,"count":1,"reportingController":"kubelet","reportingInstance":"pach-control-plane"}}
{"level":"info","ts":1714067856.8186874,"logger":"event","caller":"kube-event-tail/main.go:98","msg":"Created container console","event":{"namespace":"default","name":"console-75589574fd-bbf9t.17c996dd6df0e72e","involvedObject":{"name":"Pod/console-75589574fd-bbf9t","fieldPath":"spec.containers{console}"},"reason":"Created","source.component":"kubelet","source.host":"pach-control-plane","firstTimestamp":1714067010,"lastTimestamp":1714067010,"count":1,"reportingController":"kubelet","reportingInstance":"pach-control-plane"}}
{"level":"info","ts":1714067856.8186932,"logger":"event","caller":"kube-event-tail/main.go:98","msg":"Started container console","event":{"namespace":"default","name":"console-75589574fd-bbf9t.17c996dd7503e35d","involvedObject":{"name":"Pod/console-75589574fd-bbf9t","fieldPath":"spec.containers{console}"},"reason":"Started","source.component":"kubelet","source.host":"pach-control-plane","firstTimestamp":1714067011,"lastTimestamp":1714067011,"count":1,"reportingController":"kubelet","reportingInstance":"pach-control-plane"}}
{"level":"info","ts":1714067856.8186977,"logger":"event","caller":"kube-event-tail/main.go:98","msg":"Readiness probe failed: Get \"http://10.244.0.23:4000/health\": dial tcp 10.244.0.23:4000: connect: connection refused","event":{"namespace":"default","name":"console-75589574fd-bbf9t.17c996dd854bab61","involvedObject":{"name":"Pod/console-75589574fd-bbf9t","fieldPath":"spec.containers{console}"},"reason":"Unhealthy","source.component":"kubelet","source.host":"pach-control-plane","firstTimestamp":1714067011,"lastTimestamp":1714067011,"count":1,"reportingController":"kubelet","reportingInstance":"pach-control-plane","type":"Warning"}}
{"level":"info","ts":1714067856.818703,"logger":"event","caller":"kube-event-tail/main.go:98","msg":"Created pod: console-75589574fd-bbf9t","event":{"namespace":"default","name":"console-75589574fd.17c996dd4d7d949f","involvedObject":{"name":"ReplicaSet/console-75589574fd"},"reason":"SuccessfulCreate","source.component":"replicaset-controller","firstTimestamp":1714067010,"lastTimestamp":1714067010,"count":1,"reportingController":"replicaset-controller"}}
{"level":"info","ts":1714067856.8187075,"logger":"event","caller":"kube-event-tail/main.go:98","msg":"0/1 nodes are available: 1 node(s) had untolerated taint {node.kubernetes.io/not-ready: }. preemption: 0/1 nodes are available: 1 Preemption is not helpful for scheduling.","event":{"namespace":"default","name":"console-75f9f5b8d8-qvkwn.17c995ce1786fb19","involvedObject":{"name":"Pod/console-75f9f5b8d8-qvkwn"},"reason":"FailedScheduling","source.component":"default-scheduler","firstTimestamp":1714065845,"lastTimestamp":1714065845,"count":1,"reportingController":"default-scheduler","type":"Warning"}}
{"level":"info","ts":1714067856.8187125,"logger":"event","caller":"kube-event-tail/main.go:98","msg":"Successfully assigned default/console-75f9f5b8d8-qvkwn to pach-control-plane","event":{"namespace":"default","name":"console-75f9f5b8d8-qvkwn.17c995ce891cdec4","involvedObject":{"name":"Pod/console-75f9f5b8d8-qvkwn"},"reason":"Scheduled","source.component":"default-scheduler","firstTimestamp":1714065847,"lastTimestamp":1714065847,"count":1,"reportingController":"default-scheduler"}}
{"level":"info","ts":1714067856.818718,"logger":"event","caller":"kube-event-tail/main.go:98","msg":"Pulling image \"pachyderm/haberdashery:2.8.0-alpha.5\"","event":{"namespace":"default","name":"console-75f9f5b8d8-qvkwn.17c995ceb6ca8b70","involvedObject":{"name":"Pod/console-75f9f5b8d8-qvkwn","fieldPath":"spec.containers{console}"},"reason":"Pulling","source.component":"kubelet","source.host":"pach-control-plane","firstTimestamp":1714065848,"lastTimestamp":1714065848,"count":1,"reportingController":"kubelet","reportingInstance":"pach-control-plane"}}
{"level":"info","ts":1714067856.818724,"logger":"event","caller":"kube-event-tail/main.go:98","msg":"Successfully pulled image \"pachyderm/haberdashery:2.8.0-alpha.5\" in 13.475s (30.054s including waiting)","event":{"namespace":"default","name":"console-75f9f5b8d8-qvkwn.17c995d5b62ef554","involvedObject":{"name":"Pod/console-75f9f5b8d8-qvkwn","fieldPath":"spec.containers{console}"},"reason":"Pulled","source.component":"kubelet","source.host":"pach-control-plane","firstTimestamp":1714065878,"lastTimestamp":1714065878,"count":1,"reportingController":"kubelet","reportingInstance":"pach-control-plane"}}
{"level":"info","ts":1714067856.8187292,"logger":"event","caller":"kube-event-tail/main.go:98","msg":"Created container console","event":{"namespace":"default","name":"console-75f9f5b8d8-qvkwn.17c995d5b8de059e","involvedObject":{"name":"Pod/console-75f9f5b8d8-qvkwn","fieldPath":"spec.containers{console}"},"reason":"Created","source.component":"kubelet","source.host":"pach-control-plane","firstTimestamp":1714065878,"lastTimestamp":1714065878,"count":1,"reportingController":"kubelet","reportingInstance":"pach-control-plane"}}
{"level":"info","ts":1714067856.8187344,"logger":"event","caller":"kube-event-tail/main.go:98","msg":"Started container console","event":{"namespace":"default","name":"console-75f9f5b8d8-qvkwn.17c995d5bf822a3b","involvedObject":{"name":"Pod/console-75f9f5b8d8-qvkwn","fieldPath":"spec.containers{console}"},"reason":"Started","source.component":"kubelet","source.host":"pach-control-plane","firstTimestamp":1714065878,"lastTimestamp":1714065878,"count":1,"reportingController":"kubelet","reportingInstance":"pach-control-plane"}}
{"level":"info","ts":1714067856.8187397,"logger":"event","caller":"kube-event-tail/main.go:98","msg":"Readiness probe failed: Get \"http://10.244.0.12:4000/health\": dial tcp 10.244.0.12:4000: connect: connection refused","event":{"namespace":"default","name":"console-75f9f5b8d8-qvkwn.17c995d5f92d4d34","involvedObject":{"name":"Pod/console-75f9f5b8d8-qvkwn","fieldPath":"spec.containers{console}"},"reason":"Unhealthy","source.component":"kubelet","source.host":"pach-control-plane","firstTimestamp":1714065879,"lastTimestamp":1714065879,"count":1,"reportingController":"kubelet","reportingInstance":"pach-control-plane","type":"Warning"}}
{"level":"info","ts":1714067856.8187463,"logger":"event","caller":"kube-event-tail/main.go:98","msg":"Stopping container console","event":{"namespace":"default","name":"console-75f9f5b8d8-qvkwn.17c99693a1182004","involvedObject":{"name":"Pod/console-75f9f5b8d8-qvkwn","fieldPath":"spec.containers{console}"},"reason":"Killing","source.component":"kubelet","source.host":"pach-control-plane","firstTimestamp":1714066693,"lastTimestamp":1714066693,"count":1,"reportingController":"kubelet","reportingInstance":"pach-control-plane"}}
{"level":"info","ts":1714067856.8187542,"logger":"event","caller":"kube-event-tail/main.go:98","msg":"Created pod: console-75f9f5b8d8-qvkwn","event":{"namespace":"default","name":"console-75f9f5b8d8.17c995ce16ad3e28","involvedObject":{"name":"ReplicaSet/console-75f9f5b8d8"},"reason":"SuccessfulCreate","source.component":"replicaset-controller","firstTimestamp":1714065845,"lastTimestamp":1714065845,"count":1,"reportingController":"replicaset-controller"}}
{"level":"info","ts":1714067856.8187597,"logger":"event","caller":"kube-event-tail/main.go:98","msg":"Deleted pod: console-75f9f5b8d8-qvkwn","event":{"namespace":"default","name":"console-75f9f5b8d8.17c99693a1077906","involvedObject":{"name":"ReplicaSet/console-75f9f5b8d8"},"reason":"SuccessfulDelete","source.component":"replicaset-controller","firstTimestamp":1714066693,"lastTimestamp":1714066693,"count":1,"reportingController":"replicaset-controller"}}
{"level":"info","ts":1714067856.8187826,"logger":"event","caller":"kube-event-tail/main.go:98","msg":"Successfully assigned default/console-967cf447d-t2cc6 to pach-control-plane","event":{"namespace":"default","name":"console-967cf447d-t2cc6.17c996930644d3cb","involvedObject":{"name":"Pod/console-967cf447d-t2cc6"},"reason":"Scheduled","source.component":"default-scheduler","firstTimestamp":1714066691,"lastTimestamp":1714066691,"count":1,"reportingController":"default-scheduler"}}
{"level":"info","ts":1714067856.8187919,"logger":"event","caller":"kube-event-tail/main.go:98","msg":"Container image \"pachyderm/haberdashery:2.8.0-alpha.5\" already present on machine","event":{"namespace":"default","name":"console-967cf447d-t2cc6.17c9969320c0ffba","involvedObject":{"name":"Pod/console-967cf447d-t2cc6","fieldPath":"spec.containers{console}"},"reason":"Pulled","source.component":"kubelet","source.host":"pach-control-plane","firstTimestamp":1714066691,"lastTimestamp":1714066691,"count":1,"reportingController":"kubelet","reportingInstance":"pach-control-plane"}}
{"level":"info","ts":1714067856.818797,"logger":"event","caller":"kube-event-tail/main.go:98","msg":"Created container console","event":{"namespace":"default","name":"console-967cf447d-t2cc6.17c99693231ff41c","involvedObject":{"name":"Pod/console-967cf447d-t2cc6","fieldPath":"spec.containers{console}"},"reason":"Created","source.component":"kubelet","source.host":"pach-control-plane","firstTimestamp":1714066691,"lastTimestamp":1714066691,"count":1,"reportingController":"kubelet","reportingInstance":"pach-control-plane"}}
{"level":"info","ts":1714067856.8188016,"logger":"event","caller":"kube-event-tail/main.go:98","msg":"Started container console","event":{"namespace":"default","name":"console-967cf447d-t2cc6.17c996932a55e813","involvedObject":{"name":"Pod/console-967cf447d-t2cc6","fieldPath":"spec.containers{console}"},"reason":"Started","source.component":"kubelet","source.host":"pach-control-plane","firstTimestamp":1714066692,"lastTimestamp":1714066692,"count":1,"reportingController":"kubelet","reportingInstance":"pach-control-plane"}}
{"level":"info","ts":1714067856.8188062,"logger":"event","caller":"kube-event-tail/main.go:98","msg":"Readiness probe failed: Get \"http://10.244.0.19:4000/health\": dial tcp 10.244.0.19:4000: connect: connection refused","event":{"namespace":"default","name":"console-967cf447d-t2cc6.17c9969362ca39c9","involvedObject":{"name":"Pod/console-967cf447d-t2cc6","fieldPath":"spec.containers{console}"},"reason":"Unhealthy","source.component":"kubelet","source.host":"pach-control-plane","firstTimestamp":1714066692,"lastTimestamp":1714066692,"count":1,"reportingController":"kubelet","reportingInstance":"pach-control-plane","type":"Warning"}}
{"level":"info","ts":1714067856.818812,"logger":"event","caller":"kube-event-tail/main.go:98","msg":"Stopping container console","event":{"namespace":"default","name":"console-967cf447d-t2cc6.17c996ddc4450d85","involvedObject":{"name":"Pod/console-967cf447d-t2cc6","fieldPath":"spec.containers{console}"},"reason":"Killing","source.component":"kubelet","source.host":"pach-control-plane","firstTimestamp":1714067012,"lastTimestamp":1714067012,"count":1,"reportingController":"kubelet","reportingInstance":"pach-control-plane"}}
{"level":"info","ts":1714067856.818819,"logger":"event","caller":"kube-event-tail/main.go:98","msg":"Created pod: console-967cf447d-t2cc6","event":{"namespace":"default","name":"console-967cf447d.17c9969305be0ef2","involvedObject":{"name":"ReplicaSet/console-967cf447d"},"reason":"SuccessfulCreate","source.component":"replicaset-controller","firstTimestamp":1714066691,"lastTimestamp":1714066691,"count":1,"reportingController":"replicaset-controller"}}
{"level":"info","ts":1714067856.8188236,"logger":"event","caller":"kube-event-tail/main.go:98","msg":"Deleted pod: console-967cf447d-t2cc6","event":{"namespace":"default","name":"console-967cf447d.17c996ddc43d7b31","involvedObject":{"name":"ReplicaSet/console-967cf447d"},"reason":"SuccessfulDelete","source.component":"replicaset-controller","firstTimestamp":1714067012,"lastTimestamp":1714067012,"count":1,"reportingController":"replicaset-controller"}}
{"level":"info","ts":1714067856.8188312,"logger":"event","caller":"kube-event-tail/main.go:98","msg":"Scaled up replica set console-75f9f5b8d8 to 1","event":{"namespace":"default","name":"console.17c995ce15bf41e0","involvedObject":{"name":"Deployment/console"},"reason":"ScalingReplicaSet","source.component":"deployment-controller","firstTimestamp":1714065845,"lastTimestamp":1714065845,"count":1,"reportingController":"deployment-controller"}}
{"level":"info","ts":1714067856.8188357,"logger":"event","caller":"kube-event-tail/main.go:98","msg":"Scaled up replica set console-967cf447d to 1","event":{"namespace":"default","name":"console.17c996930438729a","involvedObject":{"name":"Deployment/console"},"reason":"ScalingReplicaSet","source.component":"deployment-controller","firstTimestamp":1714066691,"lastTimestamp":1714066691,"count":1,"reportingController":"deployment-controller"}}
{"level":"info","ts":1714067856.8188565,"logger":"event","caller":"kube-event-tail/main.go:98","msg":"Scaled down replica set console-75f9f5b8d8 to 0 from 1","event":{"namespace":"default","name":"console.17c99693a088542d","involvedObject":{"name":"Deployment/console"},"reason":"ScalingReplicaSet","source.component":"deployment-controller","firstTimestamp":1714066693,"lastTimestamp":1714066693,"count":1,"reportingController":"deployment-controller"}}
{"level":"info","ts":1714067856.8188653,"logger":"event","caller":"kube-event-tail/main.go:98","msg":"Scaled up replica set console-75589574fd to 1","event":{"namespace":"default","name":"console.17c996dd4c7a1485","involvedObject":{"name":"Deployment/console"},"reason":"ScalingReplicaSet","source.component":"deployment-controller","firstTimestamp":1714067010,"lastTimestamp":1714067010,"count":1,"reportingController":"deployment-controller"}}
{"level":"info","ts":1714067856.81887,"logger":"event","caller":"kube-event-tail/main.go:98","msg":"Scaled down replica set console-967cf447d to 0 from 1","event":{"namespace":"default","name":"console.17c996ddc346c94c","involvedObject":{"name":"Deployment/console"},"reason":"ScalingReplicaSet","source.component":"deployment-controller","firstTimestamp":1714067012,"lastTimestamp":1714067012,"count":1,"reportingController":"deployment-controller"}}
{"level":"info","ts":1714067856.8188744,"logger":"event","caller":"kube-event-tail/main.go:98","msg":"waiting for first consumer to be created before binding","event":{"namespace":"default","name":"data-postgres-0.17c995ce178274dd","involvedObject":{"name":"PersistentVolumeClaim/data-postgres-0"},"reason":"WaitForFirstConsumer","source.component":"persistentvolume-controller","firstTimestamp":1714065845,"lastTimestamp":1714065845,"count":1,"reportingController":"persistentvolume-controller"}}
{"level":"info","ts":1714067856.818879,"logger":"event","caller":"kube-event-tail/main.go:98","msg":"Waiting for a volume to be created either by the external provisioner 'rancher.io/local-path' or manually by the system administrator. If volume creation is delayed, please verify that the provisioner is running and correctly registered.","event":{"namespace":"default","name":"data-postgres-0.17c995ce89bbc596","involvedObject":{"name":"PersistentVolumeClaim/data-postgres-0"},"reason":"ExternalProvisioning","source.component":"persistentvolume-controller","firstTimestamp":1714065847,"lastTimestamp":1714065847,"count":1,"reportingController":"persistentvolume-controller"}}
{"level":"info","ts":1714067856.8188846,"logger":"event","caller":"kube-event-tail/main.go:98","msg":"External provisioner is provisioning volume for claim \"default/data-postgres-0\"","event":{"namespace":"default","name":"data-postgres-0.17c995ceb051d517","involvedObject":{"name":"PersistentVolumeClaim/data-postgres-0"},"reason":"Provisioning","source.component":"rancher.io/local-path_local-path-provisioner-7577fdbbfb-ldff9_07bdbd19-02b2-4c93-a877-75c260fa3e3f","firstTimestamp":1714065848,"lastTimestamp":1714065848,"count":1}}
{"level":"info","ts":1714067856.8188906,"logger":"event","caller":"kube-event-tail/main.go:98","msg":"Successfully provisioned volume pvc-54fba6d6-16ea-447e-a0d3-f3efb5809454","event":{"namespace":"default","name":"data-postgres-0.17c995cf8cb27219","involvedObject":{"name":"PersistentVolumeClaim/data-postgres-0"},"reason":"ProvisioningSucceeded","source.component":"rancher.io/local-path_local-path-provisioner-7577fdbbfb-ldff9_07bdbd19-02b2-4c93-a877-75c260fa3e3f","firstTimestamp":1714065851,"lastTimestamp":1714065851,"count":1}}
{"level":"info","ts":1714067856.818897,"logger":"event","caller":"kube-event-tail/main.go:98","msg":"Successfully assigned default/default-edges-v1-292m8 to pach-control-plane","event":{"namespace":"default","name":"default-edges-v1-292m8.17c996db48c2e90b","involvedObject":{"name":"Pod/default-edges-v1-292m8"},"reason":"Scheduled","source.component":"default-scheduler","firstTimestamp":1714067001,"lastTimestamp":1714067001,"count":1,"reportingController":"default-scheduler"}}
{"level":"info","ts":1714067856.8189015,"logger":"event","caller":"kube-event-tail/main.go:98","msg":"Pulling image \"localhost:5001/worker:4c7a34a8ab1e1042228009ec967ec50633d4529c432711200feb360b8ef98ec3\"","event":{"namespace":"default","name":"default-edges-v1-292m8.17c996db63ecab2d","involvedObject":{"name":"Pod/default-edges-v1-292m8","fieldPath":"spec.initContainers{init}"},"reason":"Pulling","source.component":"kubelet","source.host":"pach-control-plane","firstTimestamp":1714067002,"lastTimestamp":1714067002,"count":1,"reportingController":"kubelet","reportingInstance":"pach-control-plane"}}
{"level":"info","ts":1714067856.8189065,"logger":"event","caller":"kube-event-tail/main.go:98","msg":"Successfully pulled image \"localhost:5001/worker:4c7a34a8ab1e1042228009ec967ec50633d4529c432711200feb360b8ef98ec3\" in 1.365s (1.365s including waiting)","event":{"namespace":"default","name":"default-edges-v1-292m8.17c996dbb555ea7f","involvedObject":{"name":"Pod/default-edges-v1-292m8","fieldPath":"spec.initContainers{init}"},"reason":"Pulled","source.component":"kubelet","source.host":"pach-control-plane","firstTimestamp":1714067003,"lastTimestamp":1714067003,"count":1,"reportingController":"kubelet","reportingInstance":"pach-control-plane"}}
{"level":"info","ts":1714067856.8189118,"logger":"event","caller":"kube-event-tail/main.go:98","msg":"Created container init","event":{"namespace":"default","name":"default-edges-v1-292m8.17c996dbb92f47f7","involvedObject":{"name":"Pod/default-edges-v1-292m8","fieldPath":"spec.initContainers{init}"},"reason":"Created","source.component":"kubelet","source.host":"pach-control-plane","firstTimestamp":1714067003,"lastTimestamp":1714067003,"count":1,"reportingController":"kubelet","reportingInstance":"pach-control-plane"}}
{"level":"info","ts":1714067856.818916,"logger":"event","caller":"kube-event-tail/main.go:98","msg":"Started container init","event":{"namespace":"default","name":"default-edges-v1-292m8.17c996dbc06f9a4a","involvedObject":{"name":"Pod/default-edges-v1-292m8","fieldPath":"spec.initContainers{init}"},"reason":"Started","source.component":"kubelet","source.host":"pach-control-plane","firstTimestamp":1714067003,"lastTimestamp":1714067003,"count":1,"reportingController":"kubelet","reportingInstance":"pach-control-plane"}}
{"level":"info","ts":1714067856.8189206,"logger":"event","caller":"kube-event-tail/main.go:98","msg":"Pulling image \"pachyderm/opencv:1.0\"","event":{"namespace":"default","name":"default-edges-v1-292m8.17c996dc965430c8","involvedObject":{"name":"Pod/default-edges-v1-292m8","fieldPath":"spec.containers{user}"},"reason":"Pulling","source.component":"kubelet","source.host":"pach-control-plane","firstTimestamp":1714067007,"lastTimestamp":1714067029,"ongoingDuration":22,"count":2,"reportingController":"kubelet","reportingInstance":"pach-control-plane"}}
{"level":"info","ts":1714067856.8189275,"logger":"event","caller":"kube-event-tail/main.go:98","msg":"Failed to pull image \"pachyderm/opencv:1.0\": failed to pull and unpack image \"docker.io/pachyderm/opencv:1.0\": failed to copy: httpReadSeeker: failed open: unexpected status code https://registry-1.docker.io/v2/pachyderm/opencv/blobs/sha256:9f13e0ac480c2c862ae7aca8536bf2250b4d410468e6d33dc2f8ade1d368e184: 500 Internal Server Error","event":{"namespace":"default","name":"default-edges-v1-292m8.17c996de1c492c9c","involvedObject":{"name":"Pod/default-edges-v1-292m8","fieldPath":"spec.containers{user}"},"reason":"Failed","source.component":"kubelet","source.host":"pach-control-plane","firstTimestamp":1714067013,"lastTimestamp":1714067013,"count":1,"reportingController":"kubelet","reportingInstance":"pach-control-plane","type":"Warning"}}
{"level":"info","ts":1714067856.8189335,"logger":"event","caller":"kube-event-tail/main.go:98","msg":"Error: ErrImagePull","event":{"namespace":"default","name":"default-edges-v1-292m8.17c996de1c49715d","involvedObject":{"name":"Pod/default-edges-v1-292m8","fieldPath":"spec.containers{user}"},"reason":"Failed","source.component":"kubelet","source.host":"pach-control-plane","firstTimestamp":1714067013,"lastTimestamp":1714067013,"count":1,"reportingController":"kubelet","reportingInstance":"pach-control-plane","type":"Warning"}}
{"level":"info","ts":1714067856.8189397,"logger":"event","caller":"kube-event-tail/main.go:98","msg":"Container image \"localhost:5001/pachd:81d74ab385fe002f0ca96b9b75509cb8f0ba65cf73262f4d020ecd2fc736c917\" already present on machine","event":{"namespace":"default","name":"default-edges-v1-292m8.17c996de1c523e8b","involvedObject":{"name":"Pod/default-edges-v1-292m8","fieldPath":"spec.containers{storage}"},"reason":"Pulled","source.component":"kubelet","source.host":"pach-control-plane","firstTimestamp":1714067013,"lastTimestamp":1714067013,"count":1,"reportingController":"kubelet","reportingInstance":"pach-control-plane"}}
{"level":"info","ts":1714067856.818947,"logger":"event","caller":"kube-event-tail/main.go:98","msg":"Created container storage","event":{"namespace":"default","name":"default-edges-v1-292m8.17c996de24ed04e5","involvedObject":{"name":"Pod/default-edges-v1-292m8","fieldPath":"spec.containers{storage}"},"reason":"Created","source.component":"kubelet","source.host":"pach-control-plane","firstTimestamp":1714067014,"lastTimestamp":1714067014,"count":1,"reportingController":"kubelet","reportingInstance":"pach-control-plane"}}
{"level":"info","ts":1714067856.8189518,"logger":"event","caller":"kube-event-tail/main.go:98","msg":"Started container storage","event":{"namespace":"default","name":"default-edges-v1-292m8.17c996de2b6ce9da","involvedObject":{"name":"Pod/default-edges-v1-292m8","fieldPath":"spec.containers{storage}"},"reason":"Started","source.component":"kubelet","source.host":"pach-control-plane","firstTimestamp":1714067014,"lastTimestamp":1714067014,"count":1,"reportingController":"kubelet","reportingInstance":"pach-control-plane"}}
{"level":"info","ts":1714067856.8189569,"logger":"event","caller":"kube-event-tail/main.go:98","msg":"Back-off pulling image \"pachyderm/opencv:1.0\"","event":{"namespace":"default","name":"default-edges-v1-292m8.17c996de38eb5495","involvedObject":{"name":"Pod/default-edges-v1-292m8","fieldPath":"spec.containers{user}"},"reason":"BackOff","source.component":"kubelet","source.host":"pach-control-plane","firstTimestamp":1714067014,"lastTimestamp":1714067014,"count":1,"reportingController":"kubelet","reportingInstance":"pach-control-plane"}}
{"level":"info","ts":1714067856.8189776,"logger":"event","caller":"kube-event-tail/main.go:98","msg":"Error: ImagePullBackOff","event":{"namespace":"default","name":"default-edges-v1-292m8.17c996de38eb7501","involvedObject":{"name":"Pod/default-edges-v1-292m8","fieldPath":"spec.containers{user}"},"reason":"Failed","source.component":"kubelet","source.host":"pach-control-plane","firstTimestamp":1714067014,"lastTimestamp":1714067014,"count":1,"reportingController":"kubelet","reportingInstance":"pach-control-plane","type":"Warning"}}
{"level":"info","ts":1714067856.8189864,"logger":"event","caller":"kube-event-tail/main.go:98","msg":"Successfully pulled image \"pachyderm/opencv:1.0\" in 9.271s (9.271s including waiting)","event":{"namespace":"default","name":"default-edges-v1-292m8.17c996e3db04954a","involvedObject":{"name":"Pod/default-edges-v1-292m8","fieldPath":"spec.containers{user}"},"reason":"Pulled","source.component":"kubelet","source.host":"pach-control-plane","firstTimestamp":1714067038,"lastTimestamp":1714067038,"count":1,"reportingController":"kubelet","reportingInstance":"pach-control-plane"}}
{"level":"info","ts":1714067856.818992,"logger":"event","caller":"kube-event-tail/main.go:98","msg":"Created container user","event":{"namespace":"default","name":"default-edges-v1-292m8.17c996e3df0971cc","involvedObject":{"name":"Pod/default-edges-v1-292m8","fieldPath":"spec.containers{user}"},"reason":"Created","source.component":"kubelet","source.host":"pach-control-plane","firstTimestamp":1714067038,"lastTimestamp":1714067038,"count":1,"reportingController":"kubelet","reportingInstance":"pach-control-plane"}}
{"level":"info","ts":1714067856.8189964,"logger":"event","caller":"kube-event-tail/main.go:98","msg":"Started container user","event":{"namespace":"default","name":"default-edges-v1-292m8.17c996e3e7da41b1","involvedObject":{"name":"Pod/default-edges-v1-292m8","fieldPath":"spec.containers{user}"},"reason":"Started","source.component":"kubelet","source.host":"pach-control-plane","firstTimestamp":1714067038,"lastTimestamp":1714067038,"count":1,"reportingController":"kubelet","reportingInstance":"pach-control-plane"}}
{"level":"info","ts":1714067856.8190017,"logger":"event","caller":"kube-event-tail/main.go:98","msg":"Stopping container storage","event":{"namespace":"default","name":"default-edges-v1-292m8.17c996e40eda3cde","involvedObject":{"name":"Pod/default-edges-v1-292m8","fieldPath":"spec.containers{storage}"},"reason":"Killing","source.component":"kubelet","source.host":"pach-control-plane","firstTimestamp":1714067039,"lastTimestamp":1714067039,"count":1,"reportingController":"kubelet","reportingInstance":"pach-control-plane"}}
{"level":"info","ts":1714067856.8190062,"logger":"event","caller":"kube-event-tail/main.go:98","msg":"Stopping container user","event":{"namespace":"default","name":"default-edges-v1-292m8.17c996e40edab7eb","involvedObject":{"name":"Pod/default-edges-v1-292m8","fieldPath":"spec.containers{user}"},"reason":"Killing","source.component":"kubelet","source.host":"pach-control-plane","firstTimestamp":1714067039,"lastTimestamp":1714067039,"count":1,"reportingController":"kubelet","reportingInstance":"pach-control-plane"}}
{"level":"info","ts":1714067856.8190117,"logger":"event","caller":"kube-event-tail/main.go:98","msg":"Successfully assigned default/default-edges-v1-gqgbx to pach-control-plane","event":{"namespace":"default","name":"default-edges-v1-gqgbx.17c996e3ff463600","involvedObject":{"name":"Pod/default-edges-v1-gqgbx"},"reason":"Scheduled","source.component":"default-scheduler","firstTimestamp":1714067039,"lastTimestamp":1714067039,"count":1,"reportingController":"default-scheduler"}}
{"level":"info","ts":1714067856.8190186,"logger":"event","caller":"kube-event-tail/main.go:98","msg":"Container image \"localhost:5001/worker:da5639b93a4589fe170d5a035b6d4255a0609ec6ed8031fd9c366e0fcb0deb8a\" already present on machine","event":{"namespace":"default","name":"default-edges-v1-gqgbx.17c996e44cca747b","involvedObject":{"name":"Pod/default-edges-v1-gqgbx","fieldPath":"spec.initContainers{init}"},"reason":"Pulled","source.component":"kubelet","source.host":"pach-control-plane","firstTimestamp":1714067040,"lastTimestamp":1714067040,"count":1,"reportingController":"kubelet","reportingInstance":"pach-control-plane"}}
{"level":"info","ts":1714067856.819024,"logger":"event","caller":"kube-event-tail/main.go:98","msg":"Created container init","event":{"namespace":"default","name":"default-edges-v1-gqgbx.17c996e45056406e","involvedObject":{"name":"Pod/default-edges-v1-gqgbx","fieldPath":"spec.initContainers{init}"},"reason":"Created","source.component":"kubelet","source.host":"pach-control-plane","firstTimestamp":1714067040,"lastTimestamp":1714067040,"count":1,"reportingController":"kubelet","reportingInstance":"pach-control-plane"}}
{"level":"info","ts":1714067856.8190444,"logger":"event","caller":"kube-event-tail/main.go:98","msg":"Started container init","event":{"namespace":"default","name":"default-edges-v1-gqgbx.17c996e470dd9e5e","involvedObject":{"name":"Pod/default-edges-v1-gqgbx","fieldPath":"spec.initContainers{init}"},"reason":"Started","source.component":"kubelet","source.host":"pach-control-plane","firstTimestamp":1714067041,"lastTimestamp":1714067041,"count":1,"reportingController":"kubelet","reportingInstance":"pach-control-plane"}}
{"level":"info","ts":1714067856.8190646,"logger":"event","caller":"kube-event-tail/main.go:98","msg":"Container image \"pachyderm/opencv:1.0\" already present on machine","event":{"namespace":"default","name":"default-edges-v1-gqgbx.17c996e4c2784e3f","involvedObject":{"name":"Pod/default-edges-v1-gqgbx","fieldPath":"spec.containers{user}"},"reason":"Pulled","source.component":"kubelet","source.host":"pach-control-plane","firstTimestamp":1714067042,"lastTimestamp":1714067042,"count":1,"reportingController":"kubelet","reportingInstance":"pach-control-plane"}}
{"level":"info","ts":1714067856.8190696,"logger":"event","caller":"kube-event-tail/main.go:98","msg":"Created container user","event":{"namespace":"default","name":"default-edges-v1-gqgbx.17c996e4c7b52b08","involvedObject":{"name":"Pod/default-edges-v1-gqgbx","fieldPath":"spec.containers{user}"},"reason":"Created","source.component":"kubelet","source.host":"pach-control-plane","firstTimestamp":1714067042,"lastTimestamp":1714067042,"count":1,"reportingController":"kubelet","reportingInstance":"pach-control-plane"}}
{"level":"info","ts":1714067856.819075,"logger":"event","caller":"kube-event-tail/main.go:98","msg":"Started container user","event":{"namespace":"default","name":"default-edges-v1-gqgbx.17c996e4ce8160cd","involvedObject":{"name":"Pod/default-edges-v1-gqgbx","fieldPath":"spec.containers{user}"},"reason":"Started","source.component":"kubelet","source.host":"pach-control-plane","firstTimestamp":1714067042,"lastTimestamp":1714067042,"count":1,"reportingController":"kubelet","reportingInstance":"pach-control-plane"}}
{"level":"info","ts":1714067856.8190799,"logger":"event","caller":"kube-event-tail/main.go:98","msg":"Container image \"localhost:5001/pachd:22f229cb51e294acfd461f8b751e2937cfc2054a080f5a6a5a74f4028c495dec\" already present on machine","event":{"namespace":"default","name":"default-edges-v1-gqgbx.17c996e4ce8b9ad5","involvedObject":{"name":"Pod/default-edges-v1-gqgbx","fieldPath":"spec.containers{storage}"},"reason":"Pulled","source.component":"kubelet","source.host":"pach-control-plane","firstTimestamp":1714067042,"lastTimestamp":1714067042,"count":1,"reportingController":"kubelet","reportingInstance":"pach-control-plane"}}
{"level":"info","ts":1714067856.8190851,"logger":"event","caller":"kube-event-tail/main.go:98","msg":"Created container storage","event":{"namespace":"default","name":"default-edges-v1-gqgbx.17c996e4d53ea12d","involvedObject":{"name":"Pod/default-edges-v1-gqgbx","fieldPath":"spec.containers{storage}"},"reason":"Created","source.component":"kubelet","source.host":"pach-control-plane","firstTimestamp":1714067042,"lastTimestamp":1714067042,"count":1,"reportingController":"kubelet","reportingInstance":"pach-control-plane"}}
{"level":"info","ts":1714067856.8190897,"logger":"event","caller":"kube-event-tail/main.go:98","msg":"Started container storage","event":{"namespace":"default","name":"default-edges-v1-gqgbx.17c996e4dc3a7f3e","involvedObject":{"name":"Pod/default-edges-v1-gqgbx","fieldPath":"spec.containers{storage}"},"reason":"Started","source.component":"kubelet","source.host":"pach-control-plane","firstTimestamp":1714067042,"lastTimestamp":1714067042,"count":1,"reportingController":"kubelet","reportingInstance":"pach-control-plane"}}
{"level":"info","ts":1714067856.8190956,"logger":"event","caller":"kube-event-tail/main.go:98","msg":"Stopping container user","event":{"namespace":"default","name":"default-edges-v1-gqgbx.17c99704b14143a3","involvedObject":{"name":"Pod/default-edges-v1-gqgbx","fieldPath":"spec.containers{user}"},"reason":"Killing","source.component":"kubelet","source.host":"pach-control-plane","firstTimestamp":1714067179,"lastTimestamp":1714067179,"count":1,"reportingController":"kubelet","reportingInstance":"pach-control-plane"}}
{"level":"info","ts":1714067856.8191,"logger":"event","caller":"kube-event-tail/main.go:98","msg":"Stopping container storage","event":{"namespace":"default","name":"default-edges-v1-gqgbx.17c99704b142576c","involvedObject":{"name":"Pod/default-edges-v1-gqgbx","fieldPath":"spec.containers{storage}"},"reason":"Killing","source.component":"kubelet","source.host":"pach-control-plane","firstTimestamp":1714067179,"lastTimestamp":1714067179,"count":1,"reportingController":"kubelet","reportingInstance":"pach-control-plane"}}
{"level":"info","ts":1714067856.8191044,"logger":"event","caller":"kube-event-tail/main.go:98","msg":"Created pod: default-edges-v1-292m8","event":{"namespace":"default","name":"default-edges-v1.17c996db4810daac","involvedObject":{"name":"ReplicationController/default-edges-v1"},"reason":"SuccessfulCreate","source.component":"replication-controller","firstTimestamp":1714067001,"lastTimestamp":1714067001,"count":1,"reportingController":"replication-controller"}}
{"level":"info","ts":1714067856.8191092,"logger":"event","caller":"kube-event-tail/main.go:98","msg":"Created pod: default-edges-v1-gqgbx","event":{"namespace":"default","name":"default-edges-v1.17c996e3fea673ba","involvedObject":{"name":"ReplicationController/default-edges-v1"},"reason":"SuccessfulCreate","source.component":"replication-controller","firstTimestamp":1714067039,"lastTimestamp":1714067039,"count":1,"reportingController":"replication-controller"}}
{"level":"info","ts":1714067856.8191135,"logger":"event","caller":"kube-event-tail/main.go:98","msg":"Successfully assigned default/default-edges-v2-9f22j to pach-control-plane","event":{"namespace":"default","name":"default-edges-v2-9f22j.17c99704d2b4881f","involvedObject":{"name":"Pod/default-edges-v2-9f22j"},"reason":"Scheduled","source.component":"default-scheduler","firstTimestamp":1714067180,"lastTimestamp":1714067180,"count":1,"reportingController":"default-scheduler"}}
{"level":"info","ts":1714067856.8191178,"logger":"event","caller":"kube-event-tail/main.go:98","msg":"Container image \"localhost:5001/worker:da5639b93a4589fe170d5a035b6d4255a0609ec6ed8031fd9c366e0fcb0deb8a\" already present on machine","event":{"namespace":"default","name":"default-edges-v2-9f22j.17c99704ebfaf266","involvedObject":{"name":"Pod/default-edges-v2-9f22j","fieldPath":"spec.initContainers{init}"},"reason":"Pulled","source.component":"kubelet","source.host":"pach-control-plane","firstTimestamp":1714067180,"lastTimestamp":1714067180,"count":1,"reportingController":"kubelet","reportingInstance":"pach-control-plane"}}
{"level":"info","ts":1714067856.8191228,"logger":"event","caller":"kube-event-tail/main.go:98","msg":"Created container init","event":{"namespace":"default","name":"default-edges-v2-9f22j.17c99704eeca1a89","involvedObject":{"name":"Pod/default-edges-v2-9f22j","fieldPath":"spec.initContainers{init}"},"reason":"Created","source.component":"kubelet","source.host":"pach-control-plane","firstTimestamp":1714067180,"lastTimestamp":1714067180,"count":1,"reportingController":"kubelet","reportingInstance":"pach-control-plane"}}
{"level":"info","ts":1714067856.8191283,"logger":"event","caller":"kube-event-tail/main.go:98","msg":"Started container init","event":{"namespace":"default","name":"default-edges-v2-9f22j.17c99704f53a1338","involvedObject":{"name":"Pod/default-edges-v2-9f22j","fieldPath":"spec.initContainers{init}"},"reason":"Started","source.component":"kubelet","source.host":"pach-control-plane","firstTimestamp":1714067180,"lastTimestamp":1714067180,"count":1,"reportingController":"kubelet","reportingInstance":"pach-control-plane"}}
{"level":"info","ts":1714067856.8191335,"logger":"event","caller":"kube-event-tail/main.go:98","msg":"Container image \"pachyderm/opencv:1.0\" already present on machine","event":{"namespace":"default","name":"default-edges-v2-9f22j.17c99705307c4f7c","involvedObject":{"name":"Pod/default-edges-v2-9f22j","fieldPath":"spec.containers{user}"},"reason":"Pulled","source.component":"kubelet","source.host":"pach-control-plane","firstTimestamp":1714067181,"lastTimestamp":1714067181,"count":1,"reportingController":"kubelet","reportingInstance":"pach-control-plane"}}
{"level":"info","ts":1714067856.8191388,"logger":"event","caller":"kube-event-tail/main.go:98","msg":"Created container user","event":{"namespace":"default","name":"default-edges-v2-9f22j.17c997053451ffea","involvedObject":{"name":"Pod/default-edges-v2-9f22j","fieldPath":"spec.containers{user}"},"reason":"Created","source.component":"kubelet","source.host":"pach-control-plane","firstTimestamp":1714067181,"lastTimestamp":1714067181,"count":1,"reportingController":"kubelet","reportingInstance":"pach-control-plane"}}
{"level":"info","ts":1714067856.8191473,"logger":"event","caller":"kube-event-tail/main.go:98","msg":"Started container user","event":{"namespace":"default","name":"default-edges-v2-9f22j.17c997053a97f8c6","involvedObject":{"name":"Pod/default-edges-v2-9f22j","fieldPath":"spec.containers{user}"},"reason":"Started","source.component":"kubelet","source.host":"pach-control-plane","firstTimestamp":1714067181,"lastTimestamp":1714067181,"count":1,"reportingController":"kubelet","reportingInstance":"pach-control-plane"}}
{"level":"info","ts":1714067856.8191519,"logger":"event","caller":"kube-event-tail/main.go:98","msg":"Container image \"localhost:5001/pachd:22f229cb51e294acfd461f8b751e2937cfc2054a080f5a6a5a74f4028c495dec\" already present on machine","event":{"namespace":"default","name":"default-edges-v2-9f22j.17c997053aa11f04","involvedObject":{"name":"Pod/default-edges-v2-9f22j","fieldPath":"spec.containers{storage}"},"reason":"Pulled","source.component":"kubelet","source.host":"pach-control-plane","firstTimestamp":1714067181,"lastTimestamp":1714067181,"count":1,"reportingController":"kubelet","reportingInstance":"pach-control-plane"}}
{"level":"info","ts":1714067856.8191597,"logger":"event","caller":"kube-event-tail/main.go:98","msg":"Created container storage","event":{"namespace":"default","name":"default-edges-v2-9f22j.17c997053d4ea339","involvedObject":{"name":"Pod/default-edges-v2-9f22j","fieldPath":"spec.containers{storage}"},"reason":"Created","source.component":"kubelet","source.host":"pach-control-plane","firstTimestamp":1714067181,"lastTimestamp":1714067181,"count":1,"reportingController":"kubelet","reportingInstance":"pach-control-plane"}}
{"level":"info","ts":1714067856.8191648,"logger":"event","caller":"kube-event-tail/main.go:98","msg":"Started container storage","event":{"namespace":"default","name":"default-edges-v2-9f22j.17c9970543bbc48c","involvedObject":{"name":"Pod/default-edges-v2-9f22j","fieldPath":"spec.containers{storage}"},"reason":"Started","source.component":"kubelet","source.host":"pach-control-plane","firstTimestamp":1714067182,"lastTimestamp":1714067182,"count":1,"reportingController":"kubelet","reportingInstance":"pach-control-plane"}}
{"level":"info","ts":1714067856.8191695,"logger":"event","caller":"kube-event-tail/main.go:98","msg":"Created pod: default-edges-v2-9f22j","event":{"namespace":"default","name":"default-edges-v2.17c99704d231f5e8","involvedObject":{"name":"ReplicationController/default-edges-v2"},"reason":"SuccessfulCreate","source.component":"replication-controller","firstTimestamp":1714067180,"lastTimestamp":1714067180,"count":1,"reportingController":"replication-controller"}}
{"level":"info","ts":1714067856.8191738,"logger":"event","caller":"kube-event-tail/main.go:98","msg":"Successfully assigned default/default-montage-v1-57sqv to pach-control-plane","event":{"namespace":"default","name":"default-montage-v1-57sqv.17c996db828d13d8","involvedObject":{"name":"Pod/default-montage-v1-57sqv"},"reason":"Scheduled","source.component":"default-scheduler","firstTimestamp":1714067002,"lastTimestamp":1714067002,"count":1,"reportingController":"default-scheduler"}}
{"level":"info","ts":1714067856.8191786,"logger":"event","caller":"kube-event-tail/main.go:98","msg":"Pulling image \"localhost:5001/worker:4c7a34a8ab1e1042228009ec967ec50633d4529c432711200feb360b8ef98ec3\"","event":{"namespace":"default","name":"default-montage-v1-57sqv.17c996db9dbda629","involvedObject":{"name":"Pod/default-montage-v1-57sqv","fieldPath":"spec.initContainers{init}"},"reason":"Pulling","source.component":"kubelet","source.host":"pach-control-plane","firstTimestamp":1714067003,"lastTimestamp":1714067003,"count":1,"reportingController":"kubelet","reportingInstance":"pach-control-plane"}}
{"level":"info","ts":1714067856.8191836,"logger":"event","caller":"kube-event-tail/main.go:98","msg":"Successfully pulled image \"localhost:5001/worker:4c7a34a8ab1e1042228009ec967ec50633d4529c432711200feb360b8ef98ec3\" in 92ms (488ms including waiting)","event":{"namespace":"default","name":"default-montage-v1-57sqv.17c996dbbada15a3","involvedObject":{"name":"Pod/default-montage-v1-57sqv","fieldPath":"spec.initContainers{init}"},"reason":"Pulled","source.component":"kubelet","source.host":"pach-control-plane","firstTimestamp":1714067003,"lastTimestamp":1714067003,"count":1,"reportingController":"kubelet","reportingInstance":"pach-control-plane"}}
{"level":"info","ts":1714067856.8191903,"logger":"event","caller":"kube-event-tail/main.go:98","msg":"Created container init","event":{"namespace":"default","name":"default-montage-v1-57sqv.17c996dbc29a18a8","involvedObject":{"name":"Pod/default-montage-v1-57sqv","fieldPath":"spec.initContainers{init}"},"reason":"Created","source.component":"kubelet","source.host":"pach-control-plane","firstTimestamp":1714067003,"lastTimestamp":1714067003,"count":1,"reportingController":"kubelet","reportingInstance":"pach-control-plane"}}
{"level":"info","ts":1714067856.8191977,"logger":"event","caller":"kube-event-tail/main.go:98","msg":"Started container init","event":{"namespace":"default","name":"default-montage-v1-57sqv.17c996dc1e794aba","involvedObject":{"name":"Pod/default-montage-v1-57sqv","fieldPath":"spec.initContainers{init}"},"reason":"Started","source.component":"kubelet","source.host":"pach-control-plane","firstTimestamp":1714067005,"lastTimestamp":1714067005,"count":1,"reportingController":"kubelet","reportingInstance":"pach-control-plane"}}
{"level":"info","ts":1714067856.819203,"logger":"event","caller":"kube-event-tail/main.go:98","msg":"Pulling image \"dpokidov/imagemagick:7.1.0-23\"","event":{"namespace":"default","name":"default-montage-v1-57sqv.17c996dc9634e4dd","involvedObject":{"name":"Pod/default-montage-v1-57sqv","fieldPath":"spec.containers{user}"},"reason":"Pulling","source.component":"kubelet","source.host":"pach-control-plane","firstTimestamp":1714067007,"lastTimestamp":1714067007,"count":1,"reportingController":"kubelet","reportingInstance":"pach-control-plane"}}
{"level":"info","ts":1714067856.819228,"logger":"event","caller":"kube-event-tail/main.go:98","msg":"Successfully pulled image \"dpokidov/imagemagick:7.1.0-23\" in 4.767s (4.767s including waiting)","event":{"namespace":"default","name":"default-montage-v1-57sqv.17c996ddb25a490e","involvedObject":{"name":"Pod/default-montage-v1-57sqv","fieldPath":"spec.containers{user}"},"reason":"Pulled","source.component":"kubelet","source.host":"pach-control-plane","firstTimestamp":1714067012,"lastTimestamp":1714067012,"count":1,"reportingController":"kubelet","reportingInstance":"pach-control-plane"}}
{"level":"info","ts":1714067856.8192377,"logger":"event","caller":"kube-event-tail/main.go:98","msg":"Created container user","event":{"namespace":"default","name":"default-montage-v1-57sqv.17c996ddb5aaa0b5","involvedObject":{"name":"Pod/default-montage-v1-57sqv","fieldPath":"spec.containers{user}"},"reason":"Created","source.component":"kubelet","source.host":"pach-control-plane","firstTimestamp":1714067012,"lastTimestamp":1714067012,"count":1,"reportingController":"kubelet","reportingInstance":"pach-control-plane"}}
{"level":"info","ts":1714067856.819243,"logger":"event","caller":"kube-event-tail/main.go:98","msg":"Started container user","event":{"namespace":"default","name":"default-montage-v1-57sqv.17c996ddbbb29d99","involvedObject":{"name":"Pod/default-montage-v1-57sqv","fieldPath":"spec.containers{user}"},"reason":"Started","source.component":"kubelet","source.host":"pach-control-plane","firstTimestamp":1714067012,"lastTimestamp":1714067012,"count":1,"reportingController":"kubelet","reportingInstance":"pach-control-plane"}}
{"level":"info","ts":1714067856.8192477,"logger":"event","caller":"kube-event-tail/main.go:98","msg":"Container image \"localhost:5001/pachd:81d74ab385fe002f0ca96b9b75509cb8f0ba65cf73262f4d020ecd2fc736c917\" already present on machine","event":{"namespace":"default","name":"default-montage-v1-57sqv.17c996ddbbbb00ea","involvedObject":{"name":"Pod/default-montage-v1-57sqv","fieldPath":"spec.containers{storage}"},"reason":"Pulled","source.component":"kubelet","source.host":"pach-control-plane","firstTimestamp":1714067012,"lastTimestamp":1714067012,"count":1,"reportingController":"kubelet","reportingInstance":"pach-control-plane"}}
{"level":"info","ts":1714067856.819253,"logger":"event","caller":"kube-event-tail/main.go:98","msg":"Created container storage","event":{"namespace":"default","name":"default-montage-v1-57sqv.17c996ddbf6cd5d3","involvedObject":{"name":"Pod/default-montage-v1-57sqv","fieldPath":"spec.containers{storage}"},"reason":"Created","source.component":"kubelet","source.host":"pach-control-plane","firstTimestamp":1714067012,"lastTimestamp":1714067012,"count":1,"reportingController":"kubelet","reportingInstance":"pach-control-plane"}}
{"level":"info","ts":1714067856.819258,"logger":"event","caller":"kube-event-tail/main.go:98","msg":"Started container storage","event":{"namespace":"default","name":"default-montage-v1-57sqv.17c996ddc57ebb1b","involvedObject":{"name":"Pod/default-montage-v1-57sqv","fieldPath":"spec.containers{storage}"},"reason":"Started","source.component":"kubelet","source.host":"pach-control-plane","firstTimestamp":1714067012,"lastTimestamp":1714067012,"count":1,"reportingController":"kubelet","reportingInstance":"pach-control-plane"}}
{"level":"info","ts":1714067856.8192627,"logger":"event","caller":"kube-event-tail/main.go:98","msg":"Stopping container user","event":{"namespace":"default","name":"default-montage-v1-57sqv.17c996e34cc03f12","involvedObject":{"name":"Pod/default-montage-v1-57sqv","fieldPath":"spec.containers{user}"},"reason":"Killing","source.component":"kubelet","source.host":"pach-control-plane","firstTimestamp":1714067036,"lastTimestamp":1714067036,"count":1,"reportingController":"kubelet","reportingInstance":"pach-control-plane"}}
{"level":"info","ts":1714067856.8192673,"logger":"event","caller":"kube-event-tail/main.go:98","msg":"Stopping container storage","event":{"namespace":"default","name":"default-montage-v1-57sqv.17c996e34cc20629","involvedObject":{"name":"Pod/default-montage-v1-57sqv","fieldPath":"spec.containers{storage}"},"reason":"Killing","source.component":"kubelet","source.host":"pach-control-plane","firstTimestamp":1714067036,"lastTimestamp":1714067036,"count":1,"reportingController":"kubelet","reportingInstance":"pach-control-plane"}}
{"level":"info","ts":1714067856.8192716,"logger":"event","caller":"kube-event-tail/main.go:98","msg":"Successfully assigned default/default-montage-v1-jsw2g to pach-control-plane","event":{"namespace":"default","name":"default-montage-v1-jsw2g.17c996e3896ca8d9","involvedObject":{"name":"Pod/default-montage-v1-jsw2g"},"reason":"Scheduled","source.component":"default-scheduler","firstTimestamp":1714067037,"lastTimestamp":1714067037,"count":1,"reportingController":"default-scheduler"}}
{"level":"info","ts":1714067856.819276,"logger":"event","caller":"kube-event-tail/main.go:98","msg":"Pulling image \"localhost:5001/worker:da5639b93a4589fe170d5a035b6d4255a0609ec6ed8031fd9c366e0fcb0deb8a\"","event":{"namespace":"default","name":"default-montage-v1-jsw2g.17c996e3a373aca2","involvedObject":{"name":"Pod/default-montage-v1-jsw2g","fieldPath":"spec.initContainers{init}"},"reason":"Pulling","source.component":"kubelet","source.host":"pach-control-plane","firstTimestamp":1714067037,"lastTimestamp":1714067037,"count":1,"reportingController":"kubelet","reportingInstance":"pach-control-plane"}}
{"level":"info","ts":1714067856.8192816,"logger":"event","caller":"kube-event-tail/main.go:98","msg":"Successfully pulled image \"localhost:5001/worker:da5639b93a4589fe170d5a035b6d4255a0609ec6ed8031fd9c366e0fcb0deb8a\" in 1.809s (2.741s including waiting)","event":{"namespace":"default","name":"default-montage-v1-jsw2g.17c996e446e0ff68","involvedObject":{"name":"Pod/default-montage-v1-jsw2g","fieldPath":"spec.initContainers{init}"},"reason":"Pulled","source.component":"kubelet","source.host":"pach-control-plane","firstTimestamp":1714067040,"lastTimestamp":1714067040,"count":1,"reportingController":"kubelet","reportingInstance":"pach-control-plane"}}
{"level":"info","ts":1714067856.819287,"logger":"event","caller":"kube-event-tail/main.go:98","msg":"Created container init","event":{"namespace":"default","name":"default-montage-v1-jsw2g.17c996e4495f7345","involvedObject":{"name":"Pod/default-montage-v1-jsw2g","fieldPath":"spec.initContainers{init}"},"reason":"Created","source.component":"kubelet","source.host":"pach-control-plane","firstTimestamp":1714067040,"lastTimestamp":1714067040,"count":1,"reportingController":"kubelet","reportingInstance":"pach-control-plane"}}
{"level":"info","ts":1714067856.8192937,"logger":"event","caller":"kube-event-tail/main.go:98","msg":"Started container init","event":{"namespace":"default","name":"default-montage-v1-jsw2g.17c996e44e5c707b","involvedObject":{"name":"Pod/default-montage-v1-jsw2g","fieldPath":"spec.initContainers{init}"},"reason":"Started","source.component":"kubelet","source.host":"pach-control-plane","firstTimestamp":1714067040,"lastTimestamp":1714067040,"count":1,"reportingController":"kubelet","reportingInstance":"pach-control-plane"}}
{"level":"info","ts":1714067856.8192983,"logger":"event","caller":"kube-event-tail/main.go:98","msg":"Container image \"dpokidov/imagemagick:7.1.0-23\" already present on machine","event":{"namespace":"default","name":"default-montage-v1-jsw2g.17c996e4c2921925","involvedObject":{"name":"Pod/default-montage-v1-jsw2g","fieldPath":"spec.containers{user}"},"reason":"Pulled","source.component":"kubelet","source.host":"pach-control-plane","firstTimestamp":1714067042,"lastTimestamp":1714067042,"count":1,"reportingController":"kubelet","reportingInstance":"pach-control-plane"}}
{"level":"info","ts":1714067856.8193197,"logger":"event","caller":"kube-event-tail/main.go:98","msg":"Created container user","event":{"namespace":"default","name":"default-montage-v1-jsw2g.17c996e4ca0777e2","involvedObject":{"name":"Pod/default-montage-v1-jsw2g","fieldPath":"spec.containers{user}"},"reason":"Created","source.component":"kubelet","source.host":"pach-control-plane","firstTimestamp":1714067042,"lastTimestamp":1714067042,"count":1,"reportingController":"kubelet","reportingInstance":"pach-control-plane"}}
{"level":"info","ts":1714067856.819329,"logger":"event","caller":"kube-event-tail/main.go:98","msg":"Started container user","event":{"namespace":"default","name":"default-montage-v1-jsw2g.17c996e4ce821d7a","involvedObject":{"name":"Pod/default-montage-v1-jsw2g","fieldPath":"spec.containers{user}"},"reason":"Started","source.component":"kubelet","source.host":"pach-control-plane","firstTimestamp":1714067042,"lastTimestamp":1714067042,"count":1,"reportingController":"kubelet","reportingInstance":"pach-control-plane"}}
{"level":"info","ts":1714067856.8193338,"logger":"event","caller":"kube-event-tail/main.go:98","msg":"Container image \"localhost:5001/pachd:22f229cb51e294acfd461f8b751e2937cfc2054a080f5a6a5a74f4028c495dec\" already present on machine","event":{"namespace":"default","name":"default-montage-v1-jsw2g.17c996e4ce8b7b31","involvedObject":{"name":"Pod/default-montage-v1-jsw2g","fieldPath":"spec.containers{storage}"},"reason":"Pulled","source.component":"kubelet","source.host":"pach-control-plane","firstTimestamp":1714067042,"lastTimestamp":1714067042,"count":1,"reportingController":"kubelet","reportingInstance":"pach-control-plane"}}
{"level":"info","ts":1714067856.819339,"logger":"event","caller":"kube-event-tail/main.go:98","msg":"Created container storage","event":{"namespace":"default","name":"default-montage-v1-jsw2g.17c996e4d75effae","involvedObject":{"name":"Pod/default-montage-v1-jsw2g","fieldPath":"spec.containers{storage}"},"reason":"Created","source.component":"kubelet","source.host":"pach-control-plane","firstTimestamp":1714067042,"lastTimestamp":1714067042,"count":1,"reportingController":"kubelet","reportingInstance":"pach-control-plane"}}
{"level":"info","ts":1714067856.8193436,"logger":"event","caller":"kube-event-tail/main.go:98","msg":"Started container storage","event":{"namespace":"default","name":"default-montage-v1-jsw2g.17c996e4dc3a03cd","involvedObject":{"name":"Pod/default-montage-v1-jsw2g","fieldPath":"spec.containers{storage}"},"reason":"Started","source.component":"kubelet","source.host":"pach-control-plane","firstTimestamp":1714067042,"lastTimestamp":1714067042,"count":1,"reportingController":"kubelet","reportingInstance":"pach-control-plane"}}
{"level":"info","ts":1714067856.8193483,"logger":"event","caller":"kube-event-tail/main.go:98","msg":"Created pod: default-montage-v1-57sqv","event":{"namespace":"default","name":"default-montage-v1.17c996db7dd2e245","involvedObject":{"name":"ReplicationController/default-montage-v1"},"reason":"SuccessfulCreate","source.component":"replication-controller","firstTimestamp":1714067002,"lastTimestamp":1714067002,"count":1,"reportingController":"replication-controller"}}
{"level":"info","ts":1714067856.8193552,"logger":"event","caller":"kube-event-tail/main.go:98","msg":"Created pod: default-montage-v1-jsw2g","event":{"namespace":"default","name":"default-montage-v1.17c996e3886e1106","involvedObject":{"name":"ReplicationController/default-montage-v1"},"reason":"SuccessfulCreate","source.component":"replication-controller","firstTimestamp":1714067037,"lastTimestamp":1714067037,"count":1,"reportingController":"replication-controller"}}
{"level":"info","ts":1714067856.8193598,"logger":"event","caller":"kube-event-tail/main.go:98","msg":"0/1 nodes are available: 1 node(s) had untolerated taint {node.kubernetes.io/not-ready: }. preemption: 0/1 nodes are available: 1 Preemption is not helpful for scheduling.","event":{"namespace":"default","name":"etcd-0.17c995ce19242c87","involvedObject":{"name":"Pod/etcd-0"},"reason":"FailedScheduling","source.component":"default-scheduler","firstTimestamp":1714065845,"lastTimestamp":1714065845,"count":1,"reportingController":"default-scheduler","type":"Warning"}}
{"level":"info","ts":1714067856.8193645,"logger":"event","caller":"kube-event-tail/main.go:98","msg":"Successfully assigned default/etcd-0 to pach-control-plane","event":{"namespace":"default","name":"etcd-0.17c995ce88971826","involvedObject":{"name":"Pod/etcd-0"},"reason":"Scheduled","source.component":"default-scheduler","firstTimestamp":1714065847,"lastTimestamp":1714065847,"count":1,"reportingController":"default-scheduler"}}
{"level":"info","ts":1714067856.8193867,"logger":"event","caller":"kube-event-tail/main.go:98","msg":"Pulling image \"pachyderm/etcd:v3.5.12\"","event":{"namespace":"default","name":"etcd-0.17c995ceb40737e7","involvedObject":{"name":"Pod/etcd-0","fieldPath":"spec.containers{etcd}"},"reason":"Pulling","source.component":"kubelet","source.host":"pach-control-plane","firstTimestamp":1714065848,"lastTimestamp":1714065848,"count":1,"reportingController":"kubelet","reportingInstance":"pach-control-plane"}}
{"level":"info","ts":1714067856.8193955,"logger":"event","caller":"kube-event-tail/main.go:98","msg":"Successfully pulled image \"pachyderm/etcd:v3.5.12\" in 1.476s (5.633s including waiting)","event":{"namespace":"default","name":"etcd-0.17c995d003c9d032","involvedObject":{"name":"Pod/etcd-0","fieldPath":"spec.containers{etcd}"},"reason":"Pulled","source.component":"kubelet","source.host":"pach-control-plane","firstTimestamp":1714065853,"lastTimestamp":1714065853,"count":1,"reportingController":"kubelet","reportingInstance":"pach-control-plane"}}
{"level":"info","ts":1714067856.8194008,"logger":"event","caller":"kube-event-tail/main.go:98","msg":"Created container etcd","event":{"namespace":"default","name":"etcd-0.17c995d0088b6e77","involvedObject":{"name":"Pod/etcd-0","fieldPath":"spec.containers{etcd}"},"reason":"Created","source.component":"kubelet","source.host":"pach-control-plane","firstTimestamp":1714065853,"lastTimestamp":1714065853,"count":1,"reportingController":"kubelet","reportingInstance":"pach-control-plane"}}
{"level":"info","ts":1714067856.8194058,"logger":"event","caller":"kube-event-tail/main.go:98","msg":"Started container etcd","event":{"namespace":"default","name":"etcd-0.17c995d010a12ecb","involvedObject":{"name":"Pod/etcd-0","fieldPath":"spec.containers{etcd}"},"reason":"Started","source.component":"kubelet","source.host":"pach-control-plane","firstTimestamp":1714065854,"lastTimestamp":1714065854,"count":1,"reportingController":"kubelet","reportingInstance":"pach-control-plane"}}
{"level":"info","ts":1714067856.8194103,"logger":"event","caller":"kube-event-tail/main.go:98","msg":"create Pod etcd-0 in StatefulSet etcd successful","event":{"namespace":"default","name":"etcd.17c995ce174cb2c7","involvedObject":{"name":"StatefulSet/etcd"},"reason":"SuccessfulCreate","source.component":"statefulset-controller","firstTimestamp":1714065845,"lastTimestamp":1714065845,"count":1,"reportingController":"statefulset-controller"}}
{"level":"info","ts":1714067856.819415,"logger":"event","caller":"kube-event-tail/main.go:98","msg":"0/1 nodes are available: 1 node(s) had untolerated taint {node.kubernetes.io/not-ready: }. preemption: 0/1 nodes are available: 1 Preemption is not helpful for scheduling.","event":{"namespace":"default","name":"minio-0.17c995cda7dbcb93","involvedObject":{"name":"Pod/minio-0"},"reason":"FailedScheduling","source.component":"default-scheduler","firstTimestamp":1714065843,"lastTimestamp":1714065843,"count":1,"reportingController":"default-scheduler","type":"Warning"}}
{"level":"info","ts":1714067856.8194206,"logger":"event","caller":"kube-event-tail/main.go:98","msg":"Successfully assigned default/minio-0 to pach-control-plane","event":{"namespace":"default","name":"minio-0.17c995cfc6da2ecb","involvedObject":{"name":"Pod/minio-0"},"reason":"Scheduled","source.component":"default-scheduler","firstTimestamp":1714065852,"lastTimestamp":1714065852,"count":1,"reportingController":"default-scheduler"}}
{"level":"info","ts":1714067856.819425,"logger":"event","caller":"kube-event-tail/main.go:98","msg":"Pulling image \"docker.io/minio/minio:latest\"","event":{"namespace":"default","name":"minio-0.17c995cfe13ca954","involvedObject":{"name":"Pod/minio-0","fieldPath":"spec.containers{minio}"},"reason":"Pulling","source.component":"kubelet","source.host":"pach-control-plane","firstTimestamp":1714065853,"lastTimestamp":1714065853,"count":1,"reportingController":"kubelet","reportingInstance":"pach-control-plane"}}
{"level":"info","ts":1714067856.8194296,"logger":"event","caller":"kube-event-tail/main.go:98","msg":"Successfully pulled image \"docker.io/minio/minio:latest\" in 2.182s (33.669s including waiting)","event":{"namespace":"default","name":"minio-0.17c995d7b81a3582","involvedObject":{"name":"Pod/minio-0","fieldPath":"spec.containers{minio}"},"reason":"Pulled","source.component":"kubelet","source.host":"pach-control-plane","firstTimestamp":1714065886,"lastTimestamp":1714065886,"count":1,"reportingController":"kubelet","reportingInstance":"pach-control-plane"}}
{"level":"info","ts":1714067856.8194344,"logger":"event","caller":"kube-event-tail/main.go:98","msg":"Created container minio","event":{"namespace":"default","name":"minio-0.17c995d7ba807511","involvedObject":{"name":"Pod/minio-0","fieldPath":"spec.containers{minio}"},"reason":"Created","source.component":"kubelet","source.host":"pach-control-plane","firstTimestamp":1714065886,"lastTimestamp":1714065886,"count":1,"reportingController":"kubelet","reportingInstance":"pach-control-plane"}}
{"level":"info","ts":1714067856.819439,"logger":"event","caller":"kube-event-tail/main.go:98","msg":"Started container minio","event":{"namespace":"default","name":"minio-0.17c995d7c0682f31","involvedObject":{"name":"Pod/minio-0","fieldPath":"spec.containers{minio}"},"reason":"Started","source.component":"kubelet","source.host":"pach-control-plane","firstTimestamp":1714065887,"lastTimestamp":1714065887,"count":1,"reportingController":"kubelet","reportingInstance":"pach-control-plane"}}
{"level":"info","ts":1714067856.8194432,"logger":"event","caller":"kube-event-tail/main.go:98","msg":"waiting for first consumer to be created before binding","event":{"namespace":"default","name":"minio-data-minio-0.17c995cd773fd953","involvedObject":{"name":"PersistentVolumeClaim/minio-data-minio-0"},"reason":"WaitForFirstConsumer","source.component":"persistentvolume-controller","firstTimestamp":1714065842,"lastTimestamp":1714065842,"count":1,"reportingController":"persistentvolume-controller"}}
{"level":"info","ts":1714067856.8194478,"logger":"event","caller":"kube-event-tail/main.go:98","msg":"Waiting for a volume to be created either by the external provisioner 'rancher.io/local-path' or manually by the system administrator. If volume creation is delayed, please verify that the provisioner is running and correctly registered.","event":{"namespace":"default","name":"minio-data-minio-0.17c995ce258210a4","involvedObject":{"name":"PersistentVolumeClaim/minio-data-minio-0"},"reason":"ExternalProvisioning","source.component":"persistentvolume-controller","firstTimestamp":1714065845,"lastTimestamp":1714065845,"count":2,"reportingController":"persistentvolume-controller"}}
{"level":"info","ts":1714067856.8194559,"logger":"event","caller":"kube-event-tail/main.go:98","msg":"External provisioner is provisioning volume for claim \"default/minio-data-minio-0\"","event":{"namespace":"default","name":"minio-data-minio-0.17c995ceb050205c","involvedObject":{"name":"PersistentVolumeClaim/minio-data-minio-0"},"reason":"Provisioning","source.component":"rancher.io/local-path_local-path-provisioner-7577fdbbfb-ldff9_07bdbd19-02b2-4c93-a877-75c260fa3e3f","firstTimestamp":1714065848,"lastTimestamp":1714065848,"count":1}}
{"level":"info","ts":1714067856.8194604,"logger":"event","caller":"kube-event-tail/main.go:98","msg":"Successfully provisioned volume pvc-5e3389c7-4d2c-4933-b4cf-5a2f3aa8fe52","event":{"namespace":"default","name":"minio-data-minio-0.17c995cf8c96669c","involvedObject":{"name":"PersistentVolumeClaim/minio-data-minio-0"},"reason":"ProvisioningSucceeded","source.component":"rancher.io/local-path_local-path-provisioner-7577fdbbfb-ldff9_07bdbd19-02b2-4c93-a877-75c260fa3e3f","firstTimestamp":1714065851,"lastTimestamp":1714065851,"count":1}}
{"level":"info","ts":1714067856.8194818,"logger":"event","caller":"kube-event-tail/main.go:98","msg":"create Claim minio-data-minio-0 Pod minio-0 in StatefulSet minio success","event":{"namespace":"default","name":"minio.17c995cd771f5f0a","involvedObject":{"name":"StatefulSet/minio"},"reason":"SuccessfulCreate","source.component":"statefulset-controller","firstTimestamp":1714065842,"lastTimestamp":1714065842,"count":1,"reportingController":"statefulset-controller"}}
{"level":"info","ts":1714067856.8194923,"logger":"event","caller":"kube-event-tail/main.go:98","msg":"create Pod minio-0 in StatefulSet minio successful","event":{"namespace":"default","name":"minio.17c995cda7dae3ed","involvedObject":{"name":"StatefulSet/minio"},"reason":"SuccessfulCreate","source.component":"statefulset-controller","firstTimestamp":1714065843,"lastTimestamp":1714065843,"count":1,"reportingController":"statefulset-controller"}}
{"level":"info","ts":1714067856.819514,"logger":"event","caller":"kube-event-tail/main.go:98","msg":"Starting kubelet.","event":{"namespace":"default","name":"pach-control-plane.17c995c8921b7ca3","involvedObject":{"namespace":"","name":"Node/pach-control-plane"},"reason":"Starting","source.component":"kubelet","source.host":"pach-control-plane","firstTimestamp":1714065821,"lastTimestamp":1714065821,"count":1,"reportingController":"kubelet","reportingInstance":"pach-control-plane"}}
{"level":"info","ts":1714067856.8195238,"logger":"event","caller":"kube-event-tail/main.go:98","msg":"Node pach-control-plane status is now: NodeHasSufficientMemory","event":{"namespace":"default","name":"pach-control-plane.17c995c89295f4a5","involvedObject":{"namespace":"","name":"Node/pach-control-plane"},"reason":"NodeHasSufficientMemory","source.component":"kubelet","source.host":"pach-control-plane","firstTimestamp":1714065821,"lastTimestamp":1714065821,"count":8,"reportingController":"kubelet","reportingInstance":"pach-control-plane"}}
{"level":"info","ts":1714067856.8195293,"logger":"event","caller":"kube-event-tail/main.go:98","msg":"Node pach-control-plane status is now: NodeHasNoDiskPressure","event":{"namespace":"default","name":"pach-control-plane.17c995c8929607c9","involvedObject":{"namespace":"","name":"Node/pach-control-plane"},"reason":"NodeHasNoDiskPressure","source.component":"kubelet","source.host":"pach-control-plane","firstTimestamp":1714065821,"lastTimestamp":1714065821,"count":8,"reportingController":"kubelet","reportingInstance":"pach-control-plane"}}
{"level":"info","ts":1714067856.8195343,"logger":"event","caller":"kube-event-tail/main.go:98","msg":"Node pach-control-plane status is now: NodeHasSufficientPID","event":{"namespace":"default","name":"pach-control-plane.17c995c89296131d","involvedObject":{"namespace":"","name":"Node/pach-control-plane"},"reason":"NodeHasSufficientPID","source.component":"kubelet","source.host":"pach-control-plane","firstTimestamp":1714065821,"lastTimestamp":1714065821,"count":7,"reportingController":"kubelet","reportingInstance":"pach-control-plane"}}
{"level":"info","ts":1714067856.8195393,"logger":"event","caller":"kube-event-tail/main.go:98","msg":"Updated Node Allocatable limit across pods","event":{"namespace":"default","name":"pach-control-plane.17c995c8955f0b38","involvedObject":{"namespace":"","name":"Node/pach-control-plane"},"reason":"NodeAllocatableEnforced","source.component":"kubelet","source.host":"pach-control-plane","firstTimestamp":1714065821,"lastTimestamp":1714065821,"count":1,"reportingController":"kubelet","reportingInstance":"pach-control-plane"}}
{"level":"info","ts":1714067856.8195438,"logger":"event","caller":"kube-event-tail/main.go:98","msg":"Starting kubelet.","event":{"namespace":"default","name":"pach-control-plane.17c995ca878f0e2f","involvedObject":{"namespace":"","name":"Node/pach-control-plane"},"reason":"Starting","source.component":"kubelet","source.host":"pach-control-plane","firstTimestamp":1714065830,"lastTimestamp":1714065830,"count":1,"reportingController":"kubelet","reportingInstance":"pach-control-plane"}}
{"level":"info","ts":1714067856.8195505,"logger":"event","caller":"kube-event-tail/main.go:98","msg":"Updated Node Allocatable limit across pods","event":{"namespace":"default","name":"pach-control-plane.17c995ca8a6c8422","involvedObject":{"namespace":"","name":"Node/pach-control-plane"},"reason":"NodeAllocatableEnforced","source.component":"kubelet","source.host":"pach-control-plane","firstTimestamp":1714065830,"lastTimestamp":1714065830,"count":1,"reportingController":"kubelet","reportingInstance":"pach-control-plane"}}
{"level":"info","ts":1714067856.819555,"logger":"event","caller":"kube-event-tail/main.go:98","msg":"Node pach-control-plane status is now: NodeHasSufficientMemory","event":{"namespace":"default","name":"pach-control-plane.17c995ca8dc838e9","involvedObject":{"namespace":"","name":"Node/pach-control-plane"},"reason":"NodeHasSufficientMemory","source.component":"kubelet","source.host":"pach-control-plane","firstTimestamp":1714065830,"lastTimestamp":1714065830,"count":1,"reportingController":"kubelet","reportingInstance":"pach-control-plane"}}
{"level":"info","ts":1714067856.8195765,"logger":"event","caller":"kube-event-tail/main.go:98","msg":"Node pach-control-plane status is now: NodeHasNoDiskPressure","event":{"namespace":"default","name":"pach-control-plane.17c995ca8dc8a00a","involvedObject":{"namespace":"","name":"Node/pach-control-plane"},"reason":"NodeHasNoDiskPressure","source.component":"kubelet","source.host":"pach-control-plane","firstTimestamp":1714065830,"lastTimestamp":1714065830,"count":1,"reportingController":"kubelet","reportingInstance":"pach-control-plane"}}
{"level":"info","ts":1714067856.8195856,"logger":"event","caller":"kube-event-tail/main.go:98","msg":"Node pach-control-plane status is now: NodeHasSufficientPID","event":{"namespace":"default","name":"pach-control-plane.17c995ca8dc8b13a","involvedObject":{"namespace":"","name":"Node/pach-control-plane"},"reason":"NodeHasSufficientPID","source.component":"kubelet","source.host":"pach-control-plane","firstTimestamp":1714065830,"lastTimestamp":1714065830,"count":1,"reportingController":"kubelet","reportingInstance":"pach-control-plane"}}
{"level":"info","ts":1714067856.8195918,"logger":"event","caller":"kube-event-tail/main.go:98","msg":"Node pach-control-plane event: Registered Node pach-control-plane in Controller","event":{"namespace":"default","name":"pach-control-plane.17c995cd74245ec8","involvedObject":{"namespace":"","name":"Node/pach-control-plane"},"reason":"RegisteredNode","source.component":"node-controller","firstTimestamp":1714065842,"lastTimestamp":1714065842,"count":1,"reportingController":"node-controller"}}
{"level":"info","ts":1714067856.8195963,"logger":"event","caller":"kube-event-tail/main.go:98","msg":"event without message","event":{"namespace":"default","name":"pach-control-plane.17c995cdd74267d2","involvedObject":{"namespace":"","name":"Node/pach-control-plane"},"reason":"Starting","eventTime":1714065844.5034711,"action":"StartKubeProxy","reportingController":"kube-proxy","reportingInstance":"kube-proxy-pach-control-plane"}}
{"level":"info","ts":1714067856.8196008,"logger":"event","caller":"kube-event-tail/main.go:98","msg":"Node pach-control-plane status is now: NodeReady","event":{"namespace":"default","name":"pach-control-plane.17c995ce23d402b0","involvedObject":{"namespace":"","name":"Node/pach-control-plane"},"reason":"NodeReady","source.component":"kubelet","source.host":"pach-control-plane","firstTimestamp":1714065845,"lastTimestamp":1714065845,"count":1,"reportingController":"kubelet","reportingInstance":"pach-control-plane"}}
{"level":"info","ts":1714067856.8196056,"logger":"event","caller":"kube-event-tail/main.go:98","msg":"Successfully assigned default/pachd-5bdcfbd65b-m96lx to pach-control-plane","event":{"namespace":"default","name":"pachd-5bdcfbd65b-m96lx.17c996dd51b65125","involvedObject":{"name":"Pod/pachd-5bdcfbd65b-m96lx"},"reason":"Scheduled","source.component":"default-scheduler","firstTimestamp":1714067010,"lastTimestamp":1714067010,"count":1,"reportingController":"default-scheduler"}}
{"level":"info","ts":1714067856.8196106,"logger":"event","caller":"kube-event-tail/main.go:98","msg":"Pulling image \"localhost:5001/pachd:22f229cb51e294acfd461f8b751e2937cfc2054a080f5a6a5a74f4028c495dec\"","event":{"namespace":"default","name":"pachd-5bdcfbd65b-m96lx.17c996dd6c118cd6","involvedObject":{"name":"Pod/pachd-5bdcfbd65b-m96lx","fieldPath":"spec.containers{pachd}"},"reason":"Pulling","source.component":"kubelet","source.host":"pach-control-plane","firstTimestamp":1714067010,"lastTimestamp":1714067010,"count":1,"reportingController":"kubelet","reportingInstance":"pach-control-plane"}}
{"level":"info","ts":1714067856.8196177,"logger":"event","caller":"kube-event-tail/main.go:98","msg":"Successfully pulled image \"localhost:5001/pachd:22f229cb51e294acfd461f8b751e2937cfc2054a080f5a6a5a74f4028c495dec\" in 740ms (3.696s including waiting)","event":{"namespace":"default","name":"pachd-5bdcfbd65b-m96lx.17c996de4867ce66","involvedObject":{"name":"Pod/pachd-5bdcfbd65b-m96lx","fieldPath":"spec.containers{pachd}"},"reason":"Pulled","source.component":"kubelet","source.host":"pach-control-plane","firstTimestamp":1714067014,"lastTimestamp":1714067014,"count":1,"reportingController":"kubelet","reportingInstance":"pach-control-plane"}}
{"level":"info","ts":1714067856.8196232,"logger":"event","caller":"kube-event-tail/main.go:98","msg":"Created container pachd","event":{"namespace":"default","name":"pachd-5bdcfbd65b-m96lx.17c996de4b6d8161","involvedObject":{"name":"Pod/pachd-5bdcfbd65b-m96lx","fieldPath":"spec.containers{pachd}"},"reason":"Created","source.component":"kubelet","source.host":"pach-control-plane","firstTimestamp":1714067014,"lastTimestamp":1714067014,"count":1,"reportingController":"kubelet","reportingInstance":"pach-control-plane"}}
{"level":"info","ts":1714067856.819645,"logger":"event","caller":"kube-event-tail/main.go:98","msg":"Started container pachd","event":{"namespace":"default","name":"pachd-5bdcfbd65b-m96lx.17c996de523b702c","involvedObject":{"name":"Pod/pachd-5bdcfbd65b-m96lx","fieldPath":"spec.containers{pachd}"},"reason":"Started","source.component":"kubelet","source.host":"pach-control-plane","firstTimestamp":1714067014,"lastTimestamp":1714067014,"count":1,"reportingController":"kubelet","reportingInstance":"pach-control-plane"}}
{"level":"info","ts":1714067856.8196545,"logger":"event","caller":"kube-event-tail/main.go:98","msg":"Created pod: pachd-5bdcfbd65b-m96lx","event":{"namespace":"default","name":"pachd-5bdcfbd65b.17c996dd51180cea","involvedObject":{"name":"ReplicaSet/pachd-5bdcfbd65b"},"reason":"SuccessfulCreate","source.component":"replicaset-controller","firstTimestamp":1714067010,"lastTimestamp":1714067010,"count":1,"reportingController":"replicaset-controller"}}
{"level":"info","ts":1714067856.8196592,"logger":"event","caller":"kube-event-tail/main.go:98","msg":"0/1 nodes are available: 1 node(s) had untolerated taint {node.kubernetes.io/not-ready: }. preemption: 0/1 nodes are available: 1 Preemption is not helpful for scheduling.","event":{"namespace":"default","name":"pachd-7cbd956bd-nqqsj.17c995ce1b3de680","involvedObject":{"name":"Pod/pachd-7cbd956bd-nqqsj"},"reason":"FailedScheduling","source.component":"default-scheduler","firstTimestamp":1714065845,"lastTimestamp":1714065845,"count":1,"reportingController":"default-scheduler","type":"Warning"}}
{"level":"info","ts":1714067856.8196645,"logger":"event","caller":"kube-event-tail/main.go:98","msg":"Successfully assigned default/pachd-7cbd956bd-nqqsj to pach-control-plane","event":{"namespace":"default","name":"pachd-7cbd956bd-nqqsj.17c995ce891f44d9","involvedObject":{"name":"Pod/pachd-7cbd956bd-nqqsj"},"reason":"Scheduled","source.component":"default-scheduler","firstTimestamp":1714065847,"lastTimestamp":1714065847,"count":1,"reportingController":"default-scheduler"}}
{"level":"info","ts":1714067856.819669,"logger":"event","caller":"kube-event-tail/main.go:98","msg":"Pulling image \"localhost:5001/pachd:1bf46d7c60913e30814d1b58decdb3c63bef0f10b4177019cdb5cc872460f2f9\"","event":{"namespace":"default","name":"pachd-7cbd956bd-nqqsj.17c995ceb5885fcd","involvedObject":{"name":"Pod/pachd-7cbd956bd-nqqsj","fieldPath":"spec.containers{pachd}"},"reason":"Pulling","source.component":"kubelet","source.host":"pach-control-plane","firstTimestamp":1714065848,"lastTimestamp":1714065848,"count":1,"reportingController":"kubelet","reportingInstance":"pach-control-plane"}}
{"level":"info","ts":1714067856.8196743,"logger":"event","caller":"kube-event-tail/main.go:98","msg":"Successfully pulled image \"localhost:5001/pachd:1bf46d7c60913e30814d1b58decdb3c63bef0f10b4177019cdb5cc872460f2f9\" in 879ms (6.487s including waiting)","event":{"namespace":"default","name":"pachd-7cbd956bd-nqqsj.17c995d0383bfdb0","involvedObject":{"name":"Pod/pachd-7cbd956bd-nqqsj","fieldPath":"spec.containers{pachd}"},"reason":"Pulled","source.component":"kubelet","source.host":"pach-control-plane","firstTimestamp":1714065854,"lastTimestamp":1714065854,"count":1,"reportingController":"kubelet","reportingInstance":"pach-control-plane"}}
{"level":"info","ts":1714067856.8196797,"logger":"event","caller":"kube-event-tail/main.go:98","msg":"Created container pachd","event":{"namespace":"default","name":"pachd-7cbd956bd-nqqsj.17c995d03ad206c5","involvedObject":{"name":"Pod/pachd-7cbd956bd-nqqsj","fieldPath":"spec.containers{pachd}"},"reason":"Created","source.component":"kubelet","source.host":"pach-control-plane","firstTimestamp":1714065854,"lastTimestamp":1714065952,"ongoingDuration":98,"count":4,"reportingController":"kubelet","reportingInstance":"pach-control-plane"}}
{"level":"info","ts":1714067856.8196845,"logger":"event","caller":"kube-event-tail/main.go:98","msg":"Started container pachd","event":{"namespace":"default","name":"pachd-7cbd956bd-nqqsj.17c995d0417c19c9","involvedObject":{"name":"Pod/pachd-7cbd956bd-nqqsj","fieldPath":"spec.containers{pachd}"},"reason":"Started","source.component":"kubelet","source.host":"pach-control-plane","firstTimestamp":1714065854,"lastTimestamp":1714065952,"ongoingDuration":98,"count":4,"reportingController":"kubelet","reportingInstance":"pach-control-plane"}}
{"level":"info","ts":1714067856.8196898,"logger":"event","caller":"kube-event-tail/main.go:98","msg":"Startup probe failed: command \"/pachd --readiness\" timed out","event":{"namespace":"default","name":"pachd-7cbd956bd-nqqsj.17c995d7f1b76676","involvedObject":{"name":"Pod/pachd-7cbd956bd-nqqsj","fieldPath":"spec.containers{pachd}"},"reason":"Unhealthy","source.component":"kubelet","source.host":"pach-control-plane","firstTimestamp":1714065887,"lastTimestamp":1714065887,"count":1,"reportingController":"kubelet","reportingInstance":"pach-control-plane","type":"Warning"}}
{"level":"info","ts":1714067856.819695,"logger":"event","caller":"kube-event-tail/main.go:98","msg":"Startup probe failed: {\"severity\":\"debug\",\"time\":\"2024-04-25T17:24:48.016828919Z\",\"logger\":\"serviceenv\",\"caller\":\"serviceenv/service_env.go:164\",\"message\":\"serviceenv: span start\"}\n{\"severity\":\"debug\",\"time\":\"2024-04-25T17:24:48.016982324Z\",\"logger\":\"serviceenv.initPachClient\",\"caller\":\"serviceenv/service_env.go:255\",\"message\":\"initPachClient: span start\"}\n{\"severity\":\"debug\",\"time\":\"2024-04-25T17:24:58.01800542Z\",\"caller\":\"proc/proc.go:203\",\"message\":\"meter: system_cpu_time_seconds\",\"type\":\"float\",\"value\":6490248.76,\"meter\":\"system_cpu_time_seconds\"}\n","event":{"namespace":"default","name":"pachd-7cbd956bd-nqqsj.17c995dccada320b","involvedObject":{"name":"Pod/pachd-7cbd956bd-nqqsj","fieldPath":"spec.containers{pachd}"},"reason":"Unhealthy","source.component":"kubelet","source.host":"pach-control-plane","firstTimestamp":1714065908,"lastTimestamp":1714065908,"count":1,"reportingController":"kubelet","reportingInstance":"pach-control-plane","type":"Warning"}}
{"level":"info","ts":1714067856.8197212,"logger":"event","caller":"kube-event-tail/main.go:98","msg":"Startup probe errored: rpc error: code = NotFound desc = failed to exec in container: failed to load task: no running task found: task cc233468ffdbd0a4cee4c1757038cef80cdac26f91fb3ad3695c050b2bb5fc62 not found: not found","event":{"namespace":"default","name":"pachd-7cbd956bd-nqqsj.17c995dd35804c21","involvedObject":{"name":"Pod/pachd-7cbd956bd-nqqsj","fieldPath":"spec.containers{pachd}"},"reason":"Unhealthy","source.component":"kubelet","source.host":"pach-control-plane","firstTimestamp":1714065910,"lastTimestamp":1714065910,"count":1,"reportingController":"kubelet","reportingInstance":"pach-control-plane","type":"Warning"}}
{"level":"info","ts":1714067856.8197315,"logger":"event","caller":"kube-event-tail/main.go:98","msg":"Container image \"localhost:5001/pachd:1bf46d7c60913e30814d1b58decdb3c63bef0f10b4177019cdb5cc872460f2f9\" already present on machine","event":{"namespace":"default","name":"pachd-7cbd956bd-nqqsj.17c995dd70295fdd","involvedObject":{"name":"Pod/pachd-7cbd956bd-nqqsj","fieldPath":"spec.containers{pachd}"},"reason":"Pulled","source.component":"kubelet","source.host":"pach-control-plane","firstTimestamp":1714065911,"lastTimestamp":1714065952,"ongoingDuration":41,"count":3,"reportingController":"kubelet","reportingInstance":"pach-control-plane"}}
{"level":"info","ts":1714067856.8197377,"logger":"event","caller":"kube-event-tail/main.go:98","msg":"Back-off restarting failed container pachd in pod pachd-7cbd956bd-nqqsj_default(e18b4ae5-8d48-4b22-b019-c03adcb56567)","event":{"namespace":"default","name":"pachd-7cbd956bd-nqqsj.17c995ddabf40d84","involvedObject":{"name":"Pod/pachd-7cbd956bd-nqqsj","fieldPath":"spec.containers{pachd}"},"reason":"BackOff","source.component":"kubelet","source.host":"pach-control-plane","firstTimestamp":1714065912,"lastTimestamp":1714066458,"ongoingDuration":546,"count":52,"reportingController":"kubelet","reportingInstance":"pach-control-plane","type":"Warning"}}
{"level":"info","ts":1714067856.819743,"logger":"event","caller":"kube-event-tail/main.go:98","msg":"Created pod: pachd-7cbd956bd-nqqsj","event":{"namespace":"default","name":"pachd-7cbd956bd.17c995ce1922048f","involvedObject":{"name":"ReplicaSet/pachd-7cbd956bd"},"reason":"SuccessfulCreate","source.component":"replicaset-controller","firstTimestamp":1714065845,"lastTimestamp":1714065845,"count":1,"reportingController":"replicaset-controller"}}
{"level":"info","ts":1714067856.8197477,"logger":"event","caller":"kube-event-tail/main.go:98","msg":"Deleted pod: pachd-7cbd956bd-nqqsj","event":{"namespace":"default","name":"pachd-7cbd956bd.17c99695878c83c3","involvedObject":{"name":"ReplicaSet/pachd-7cbd956bd"},"reason":"SuccessfulDelete","source.component":"replicaset-controller","firstTimestamp":1714066702,"lastTimestamp":1714066702,"count":1,"reportingController":"replicaset-controller"}}
{"level":"info","ts":1714067856.819752,"logger":"event","caller":"kube-event-tail/main.go:98","msg":"Successfully assigned default/pachd-d868b489c-7s5xp to pach-control-plane","event":{"namespace":"default","name":"pachd-d868b489c-7s5xp.17c99693093a9c75","involvedObject":{"name":"Pod/pachd-d868b489c-7s5xp"},"reason":"Scheduled","source.component":"default-scheduler","firstTimestamp":1714066691,"lastTimestamp":1714066691,"count":1,"reportingController":"default-scheduler"}}
{"level":"info","ts":1714067856.8197565,"logger":"event","caller":"kube-event-tail/main.go:98","msg":"Pulling image \"localhost:5001/pachd:81d74ab385fe002f0ca96b9b75509cb8f0ba65cf73262f4d020ecd2fc736c917\"","event":{"namespace":"default","name":"pachd-d868b489c-7s5xp.17c9969321dd2b38","involvedObject":{"name":"Pod/pachd-d868b489c-7s5xp","fieldPath":"spec.containers{pachd}"},"reason":"Pulling","source.component":"kubelet","source.host":"pach-control-plane","firstTimestamp":1714066691,"lastTimestamp":1714066691,"count":1,"reportingController":"kubelet","reportingInstance":"pach-control-plane"}}
{"level":"info","ts":1714067856.8197618,"logger":"event","caller":"kube-event-tail/main.go:98","msg":"Successfully pulled image \"localhost:5001/pachd:81d74ab385fe002f0ca96b9b75509cb8f0ba65cf73262f4d020ecd2fc736c917\" in 758ms (758ms including waiting)","event":{"namespace":"default","name":"pachd-d868b489c-7s5xp.17c996934f0e007b","involvedObject":{"name":"Pod/pachd-d868b489c-7s5xp","fieldPath":"spec.containers{pachd}"},"reason":"Pulled","source.component":"kubelet","source.host":"pach-control-plane","firstTimestamp":1714066692,"lastTimestamp":1714066692,"count":1,"reportingController":"kubelet","reportingInstance":"pach-control-plane"}}
{"level":"info","ts":1714067856.8197875,"logger":"event","caller":"kube-event-tail/main.go:98","msg":"Created container pachd","event":{"namespace":"default","name":"pachd-d868b489c-7s5xp.17c9969352568d8e","involvedObject":{"name":"Pod/pachd-d868b489c-7s5xp","fieldPath":"spec.containers{pachd}"},"reason":"Created","source.component":"kubelet","source.host":"pach-control-plane","firstTimestamp":1714066692,"lastTimestamp":1714066692,"count":1,"reportingController":"kubelet","reportingInstance":"pach-control-plane"}}
{"level":"info","ts":1714067856.8197968,"logger":"event","caller":"kube-event-tail/main.go:98","msg":"Started container pachd","event":{"namespace":"default","name":"pachd-d868b489c-7s5xp.17c9969359c9242a","involvedObject":{"name":"Pod/pachd-d868b489c-7s5xp","fieldPath":"spec.containers{pachd}"},"reason":"Started","source.component":"kubelet","source.host":"pach-control-plane","firstTimestamp":1714066692,"lastTimestamp":1714066692,"count":1,"reportingController":"kubelet","reportingInstance":"pach-control-plane"}}
{"level":"info","ts":1714067856.8198013,"logger":"event","caller":"kube-event-tail/main.go:98","msg":"Stopping container pachd","event":{"namespace":"default","name":"pachd-d868b489c-7s5xp.17c996dfe5c45e32","involvedObject":{"name":"Pod/pachd-d868b489c-7s5xp","fieldPath":"spec.containers{pachd}"},"reason":"Killing","source.component":"kubelet","source.host":"pach-control-plane","firstTimestamp":1714067021,"lastTimestamp":1714067021,"count":1,"reportingController":"kubelet","reportingInstance":"pach-control-plane"}}
{"level":"info","ts":1714067856.8198059,"logger":"event","caller":"kube-event-tail/main.go:98","msg":"Readiness probe failed: command \"/pachd --readiness\" timed out","event":{"namespace":"default","name":"pachd-d868b489c-7s5xp.17c996e030ac8d55","involvedObject":{"name":"Pod/pachd-d868b489c-7s5xp","fieldPath":"spec.containers{pachd}"},"reason":"Unhealthy","source.component":"kubelet","source.host":"pach-control-plane","firstTimestamp":1714067022,"lastTimestamp":1714067022,"count":1,"reportingController":"kubelet","reportingInstance":"pach-control-plane","type":"Warning"}}
{"level":"info","ts":1714067856.8198109,"logger":"event","caller":"kube-event-tail/main.go:98","msg":"Readiness probe errored: rpc error: code = NotFound desc = failed to exec in container: failed to load task: no running task found: task f5988f204e341450fd28e563c703c160d4c42e37fb190fb226c4d17190cebd9b not found: not found","event":{"namespace":"default","name":"pachd-d868b489c-7s5xp.17c996e25d55d387","involvedObject":{"name":"Pod/pachd-d868b489c-7s5xp","fieldPath":"spec.containers{pachd}"},"reason":"Unhealthy","source.component":"kubelet","source.host":"pach-control-plane","firstTimestamp":1714067032,"lastTimestamp":1714067032,"count":1,"reportingController":"kubelet","reportingInstance":"pach-control-plane","type":"Warning"}}
{"level":"info","ts":1714067856.819816,"logger":"event","caller":"kube-event-tail/main.go:98","msg":"Created pod: pachd-d868b489c-7s5xp","event":{"namespace":"default","name":"pachd-d868b489c.17c996930899a275","involvedObject":{"name":"ReplicaSet/pachd-d868b489c"},"reason":"SuccessfulCreate","source.component":"replicaset-controller","firstTimestamp":1714066691,"lastTimestamp":1714066691,"count":1,"reportingController":"replicaset-controller"}}
{"level":"info","ts":1714067856.8198206,"logger":"event","caller":"kube-event-tail/main.go:98","msg":"Deleted pod: pachd-d868b489c-7s5xp","event":{"namespace":"default","name":"pachd-d868b489c.17c996dfe5a80c68","involvedObject":{"name":"ReplicaSet/pachd-d868b489c"},"reason":"SuccessfulDelete","source.component":"replicaset-controller","firstTimestamp":1714067021,"lastTimestamp":1714067021,"count":1,"reportingController":"replicaset-controller"}}
{"level":"info","ts":1714067856.8198252,"logger":"event","caller":"kube-event-tail/main.go:98","msg":"Scaled up replica set pachd-7cbd956bd to 1","event":{"namespace":"default","name":"pachd.17c995ce18283be3","involvedObject":{"name":"Deployment/pachd"},"reason":"ScalingReplicaSet","source.component":"deployment-controller","firstTimestamp":1714065845,"lastTimestamp":1714065845,"count":1,"reportingController":"deployment-controller"}}
{"level":"info","ts":1714067856.8198295,"logger":"event","caller":"kube-event-tail/main.go:98","msg":"Scaled up replica set pachd-d868b489c to 1","event":{"namespace":"default","name":"pachd.17c9969307d3d0fa","involvedObject":{"name":"Deployment/pachd"},"reason":"ScalingReplicaSet","source.component":"deployment-controller","firstTimestamp":1714066691,"lastTimestamp":1714066691,"count":1,"reportingController":"deployment-controller"}}
{"level":"info","ts":1714067856.8198338,"logger":"event","caller":"kube-event-tail/main.go:98","msg":"Scaled down replica set pachd-7cbd956bd to 0 from 1","event":{"namespace":"default","name":"pachd.17c9969586b758e4","involvedObject":{"name":"Deployment/pachd"},"reason":"ScalingReplicaSet","source.component":"deployment-controller","firstTimestamp":1714066702,"lastTimestamp":1714066702,"count":1,"reportingController":"deployment-controller"}}
{"level":"info","ts":1714067856.8198383,"logger":"event","caller":"kube-event-tail/main.go:98","msg":"Scaled up replica set pachd-5bdcfbd65b to 1","event":{"namespace":"default","name":"pachd.17c996dd50848b0c","involvedObject":{"name":"Deployment/pachd"},"reason":"ScalingReplicaSet","source.component":"deployment-controller","firstTimestamp":1714067010,"lastTimestamp":1714067010,"count":1,"reportingController":"deployment-controller"}}
{"level":"info","ts":1714067856.8198423,"logger":"event","caller":"kube-event-tail/main.go:98","msg":"Scaled down replica set pachd-d868b489c to 0 from 1","event":{"namespace":"default","name":"pachd.17c996dfe5266367","involvedObject":{"name":"Deployment/pachd"},"reason":"ScalingReplicaSet","source.component":"deployment-controller","firstTimestamp":1714067021,"lastTimestamp":1714067021,"count":1,"reportingController":"deployment-controller"}}
{"level":"info","ts":1714067856.8198469,"logger":"event","caller":"kube-event-tail/main.go:98","msg":"Successfully assigned default/pachw-6f8fb9fd9c-gg69j to pach-control-plane","event":{"namespace":"default","name":"pachw-6f8fb9fd9c-gg69j.17c996e8a1455632","involvedObject":{"name":"Pod/pachw-6f8fb9fd9c-gg69j"},"reason":"Scheduled","source.component":"default-scheduler","firstTimestamp":1714067059,"lastTimestamp":1714067059,"count":1,"reportingController":"default-scheduler"}}
{"level":"info","ts":1714067856.8198516,"logger":"event","caller":"kube-event-tail/main.go:98","msg":"Container image \"localhost:5001/pachd:22f229cb51e294acfd461f8b751e2937cfc2054a080f5a6a5a74f4028c495dec\" already present on machine","event":{"namespace":"default","name":"pachw-6f8fb9fd9c-gg69j.17c996e8bc2a08fd","involvedObject":{"name":"Pod/pachw-6f8fb9fd9c-gg69j","fieldPath":"spec.containers{pachw}"},"reason":"Pulled","source.component":"kubelet","source.host":"pach-control-plane","firstTimestamp":1714067059,"lastTimestamp":1714067059,"count":1,"reportingController":"kubelet","reportingInstance":"pach-control-plane"}}
{"level":"info","ts":1714067856.8198597,"logger":"event","caller":"kube-event-tail/main.go:98","msg":"Created container pachw","event":{"namespace":"default","name":"pachw-6f8fb9fd9c-gg69j.17c996e8bf49edfe","involvedObject":{"name":"Pod/pachw-6f8fb9fd9c-gg69j","fieldPath":"spec.containers{pachw}"},"reason":"Created","source.component":"kubelet","source.host":"pach-control-plane","firstTimestamp":1714067059,"lastTimestamp":1714067059,"count":1,"reportingController":"kubelet","reportingInstance":"pach-control-plane"}}
{"level":"info","ts":1714067856.8198645,"logger":"event","caller":"kube-event-tail/main.go:98","msg":"Started container pachw","event":{"namespace":"default","name":"pachw-6f8fb9fd9c-gg69j.17c996e8c6847dac","involvedObject":{"name":"Pod/pachw-6f8fb9fd9c-gg69j","fieldPath":"spec.containers{pachw}"},"reason":"Started","source.component":"kubelet","source.host":"pach-control-plane","firstTimestamp":1714067059,"lastTimestamp":1714067059,"count":1,"reportingController":"kubelet","reportingInstance":"pach-control-plane"}}
{"level":"info","ts":1714067856.8198717,"logger":"event","caller":"kube-event-tail/main.go:98","msg":"Stopping container pachw","event":{"namespace":"default","name":"pachw-6f8fb9fd9c-gg69j.17c996f697af952d","involvedObject":{"name":"Pod/pachw-6f8fb9fd9c-gg69j","fieldPath":"spec.containers{pachw}"},"reason":"Killing","source.component":"kubelet","source.host":"pach-control-plane","firstTimestamp":1714067119,"lastTimestamp":1714067119,"count":1,"reportingController":"kubelet","reportingInstance":"pach-control-plane"}}
{"level":"info","ts":1714067856.8198764,"logger":"event","caller":"kube-event-tail/main.go:98","msg":"Created pod: pachw-6f8fb9fd9c-gg69j","event":{"namespace":"default","name":"pachw-6f8fb9fd9c.17c996e8a05e8b7e","involvedObject":{"name":"ReplicaSet/pachw-6f8fb9fd9c"},"reason":"SuccessfulCreate","source.component":"replicaset-controller","firstTimestamp":1714067059,"lastTimestamp":1714067059,"count":1,"reportingController":"replicaset-controller"}}
{"level":"info","ts":1714067856.8198807,"logger":"event","caller":"kube-event-tail/main.go:98","msg":"Deleted pod: pachw-6f8fb9fd9c-gg69j","event":{"namespace":"default","name":"pachw-6f8fb9fd9c.17c996f697ac7e24","involvedObject":{"name":"ReplicaSet/pachw-6f8fb9fd9c"},"reason":"SuccessfulDelete","source.component":"replicaset-controller","firstTimestamp":1714067119,"lastTimestamp":1714067119,"count":1,"reportingController":"replicaset-controller"}}
{"level":"info","ts":1714067856.8198848,"logger":"event","caller":"kube-event-tail/main.go:98","msg":"Scaled up replica set pachw-6f8fb9fd9c to 1 from 0","event":{"namespace":"default","name":"pachw.17c996e89f19d0ef","involvedObject":{"name":"Deployment/pachw"},"reason":"ScalingReplicaSet","source.component":"deployment-controller","firstTimestamp":1714067059,"lastTimestamp":1714067059,"count":1,"reportingController":"deployment-controller"}}
{"level":"info","ts":1714067856.819889,"logger":"event","caller":"kube-event-tail/main.go:98","msg":"Scaled down replica set pachw-6f8fb9fd9c to 0 from 1","event":{"namespace":"default","name":"pachw.17c996f696d371e2","involvedObject":{"name":"Deployment/pachw"},"reason":"ScalingReplicaSet","source.component":"deployment-controller","firstTimestamp":1714067119,"lastTimestamp":1714067119,"count":1,"reportingController":"deployment-controller"}}
{"level":"info","ts":1714067856.8198955,"logger":"event","caller":"kube-event-tail/main.go:98","msg":"0/1 nodes are available: 1 node(s) had untolerated taint {node.kubernetes.io/not-ready: }. preemption: 0/1 nodes are available: 1 Preemption is not helpful for scheduling.","event":{"namespace":"default","name":"pachyderm-kube-event-tail-7d7764b7c6-dlqgb.17c995ce18240fe3","involvedObject":{"name":"Pod/pachyderm-kube-event-tail-7d7764b7c6-dlqgb"},"reason":"FailedScheduling","source.component":"default-scheduler","firstTimestamp":1714065845,"lastTimestamp":1714065845,"count":1,"reportingController":"default-scheduler","type":"Warning"}}
{"level":"info","ts":1714067856.819901,"logger":"event","caller":"kube-event-tail/main.go:98","msg":"Successfully assigned default/pachyderm-kube-event-tail-7d7764b7c6-dlqgb to pach-control-plane","event":{"namespace":"default","name":"pachyderm-kube-event-tail-7d7764b7c6-dlqgb.17c995ce891b9bb6","involvedObject":{"name":"Pod/pachyderm-kube-event-tail-7d7764b7c6-dlqgb"},"reason":"Scheduled","source.component":"default-scheduler","firstTimestamp":1714065847,"lastTimestamp":1714065847,"count":1,"reportingController":"default-scheduler"}}
{"level":"info","ts":1714067856.819906,"logger":"event","caller":"kube-event-tail/main.go:98","msg":"Pulling image \"pachyderm/kube-event-tail:v0.0.7\"","event":{"namespace":"default","name":"pachyderm-kube-event-tail-7d7764b7c6-dlqgb.17c995ceb673275b","involvedObject":{"name":"Pod/pachyderm-kube-event-tail-7d7764b7c6-dlqgb","fieldPath":"spec.containers{kube-event-tail}"},"reason":"Pulling","source.component":"kubelet","source.host":"pach-control-plane","firstTimestamp":1714065848,"lastTimestamp":1714065848,"count":1,"reportingController":"kubelet","reportingInstance":"pach-control-plane"}}
{"level":"info","ts":1714067856.8199277,"logger":"event","caller":"kube-event-tail/main.go:98","msg":"Successfully pulled image \"pachyderm/kube-event-tail:v0.0.7\" in 1.378s (14s including waiting)","event":{"namespace":"default","name":"pachyderm-kube-event-tail-7d7764b7c6-dlqgb.17c995d1f8f8cb12","involvedObject":{"name":"Pod/pachyderm-kube-event-tail-7d7764b7c6-dlqgb","fieldPath":"spec.containers{kube-event-tail}"},"reason":"Pulled","source.component":"kubelet","source.host":"pach-control-plane","firstTimestamp":1714065862,"lastTimestamp":1714065862,"count":1,"reportingController":"kubelet","reportingInstance":"pach-control-plane"}}
{"level":"info","ts":1714067856.819938,"logger":"event","caller":"kube-event-tail/main.go:98","msg":"Created container kube-event-tail","event":{"namespace":"default","name":"pachyderm-kube-event-tail-7d7764b7c6-dlqgb.17c995d1fb4c443f","involvedObject":{"name":"Pod/pachyderm-kube-event-tail-7d7764b7c6-dlqgb","fieldPath":"spec.containers{kube-event-tail}"},"reason":"Created","source.component":"kubelet","source.host":"pach-control-plane","firstTimestamp":1714065862,"lastTimestamp":1714065862,"count":1,"reportingController":"kubelet","reportingInstance":"pach-control-plane"}}
{"level":"info","ts":1714067856.819944,"logger":"event","caller":"kube-event-tail/main.go:98","msg":"Started container kube-event-tail","event":{"namespace":"default","name":"pachyderm-kube-event-tail-7d7764b7c6-dlqgb.17c995d201a459a4","involvedObject":{"name":"Pod/pachyderm-kube-event-tail-7d7764b7c6-dlqgb","fieldPath":"spec.containers{kube-event-tail}"},"reason":"Started","source.component":"kubelet","source.host":"pach-control-plane","firstTimestamp":1714065862,"lastTimestamp":1714065862,"count":1,"reportingController":"kubelet","reportingInstance":"pach-control-plane"}}
{"level":"info","ts":1714067856.819949,"logger":"event","caller":"kube-event-tail/main.go:98","msg":"Created pod: pachyderm-kube-event-tail-7d7764b7c6-dlqgb","event":{"namespace":"default","name":"pachyderm-kube-event-tail-7d7764b7c6.17c995ce16b0c616","involvedObject":{"name":"ReplicaSet/pachyderm-kube-event-tail-7d7764b7c6"},"reason":"SuccessfulCreate","source.component":"replicaset-controller","firstTimestamp":1714065845,"lastTimestamp":1714065845,"count":1,"reportingController":"replicaset-controller"}}
{"level":"info","ts":1714067856.8199534,"logger":"event","caller":"kube-event-tail/main.go:98","msg":"Scaled up replica set pachyderm-kube-event-tail-7d7764b7c6 to 1","event":{"namespace":"default","name":"pachyderm-kube-event-tail.17c995ce15bf174b","involvedObject":{"name":"Deployment/pachyderm-kube-event-tail"},"reason":"ScalingReplicaSet","source.component":"deployment-controller","firstTimestamp":1714065845,"lastTimestamp":1714065845,"count":1,"reportingController":"deployment-controller"}}
{"level":"info","ts":1714067856.819958,"logger":"event","caller":"kube-event-tail/main.go:98","msg":"0/1 nodes are available: 1 node(s) had untolerated taint {node.kubernetes.io/not-ready: }. preemption: 0/1 nodes are available: 1 Preemption is not helpful for scheduling.","event":{"namespace":"default","name":"pachyderm-loki-0.17c995ce19a12d62","involvedObject":{"name":"Pod/pachyderm-loki-0"},"reason":"FailedScheduling","source.component":"default-scheduler","firstTimestamp":1714065845,"lastTimestamp":1714065845,"count":1,"reportingController":"default-scheduler","type":"Warning"}}
{"level":"info","ts":1714067856.8199632,"logger":"event","caller":"kube-event-tail/main.go:98","msg":"Successfully assigned default/pachyderm-loki-0 to pach-control-plane","event":{"namespace":"default","name":"pachyderm-loki-0.17c995cfb45bff4f","involvedObject":{"name":"Pod/pachyderm-loki-0"},"reason":"Scheduled","source.component":"default-scheduler","firstTimestamp":1714065852,"lastTimestamp":1714065852,"count":1,"reportingController":"default-scheduler"}}
{"level":"info","ts":1714067856.8199704,"logger":"event","caller":"kube-event-tail/main.go:98","msg":"Pulling image \"grafana/loki:2.6.1\"","event":{"namespace":"default","name":"pachyderm-loki-0.17c995cfd1459bfc","involvedObject":{"name":"Pod/pachyderm-loki-0","fieldPath":"spec.containers{loki}"},"reason":"Pulling","source.component":"kubelet","source.host":"pach-control-plane","firstTimestamp":1714065852,"lastTimestamp":1714065852,"count":1,"reportingController":"kubelet","reportingInstance":"pach-control-plane"}}
{"level":"info","ts":1714067856.8199754,"logger":"event","caller":"kube-event-tail/main.go:98","msg":"Successfully pulled image \"grafana/loki:2.6.1\" in 1.867s (31.754s including waiting)","event":{"namespace":"default","name":"pachyderm-loki-0.17c995d735fda647","involvedObject":{"name":"Pod/pachyderm-loki-0","fieldPath":"spec.containers{loki}"},"reason":"Pulled","source.component":"kubelet","source.host":"pach-control-plane","firstTimestamp":1714065884,"lastTimestamp":1714065884,"count":1,"reportingController":"kubelet","reportingInstance":"pach-control-plane"}}
{"level":"info","ts":1714067856.8199806,"logger":"event","caller":"kube-event-tail/main.go:98","msg":"Created container loki","event":{"namespace":"default","name":"pachyderm-loki-0.17c995d73a800a92","involvedObject":{"name":"Pod/pachyderm-loki-0","fieldPath":"spec.containers{loki}"},"reason":"Created","source.component":"kubelet","source.host":"pach-control-plane","firstTimestamp":1714065884,"lastTimestamp":1714065884,"count":1,"reportingController":"kubelet","reportingInstance":"pach-control-plane"}}
{"level":"info","ts":1714067856.8199852,"logger":"event","caller":"kube-event-tail/main.go:98","msg":"Started container loki","event":{"namespace":"default","name":"pachyderm-loki-0.17c995d74098c4c8","involvedObject":{"name":"Pod/pachyderm-loki-0","fieldPath":"spec.containers{loki}"},"reason":"Started","source.component":"kubelet","source.host":"pach-control-plane","firstTimestamp":1714065884,"lastTimestamp":1714065884,"count":1,"reportingController":"kubelet","reportingInstance":"pach-control-plane"}}
{"level":"info","ts":1714067856.81999,"logger":"event","caller":"kube-event-tail/main.go:98","msg":"Readiness probe failed: HTTP probe failed with statuscode: 503","event":{"namespace":"default","name":"pachyderm-loki-0.17c995e26754aa51","involvedObject":{"name":"Pod/pachyderm-loki-0","fieldPath":"spec.containers{loki}"},"reason":"Unhealthy","source.component":"kubelet","source.host":"pach-control-plane","firstTimestamp":1714065932,"lastTimestamp":1714065942,"ongoingDuration":10,"count":2,"reportingController":"kubelet","reportingInstance":"pach-control-plane","type":"Warning"}}
{"level":"info","ts":1714067856.8199952,"logger":"event","caller":"kube-event-tail/main.go:98","msg":"Liveness probe failed: HTTP probe failed with statuscode: 503","event":{"namespace":"default","name":"pachyderm-loki-0.17c995e26755c9d3","involvedObject":{"name":"Pod/pachyderm-loki-0","fieldPath":"spec.containers{loki}"},"reason":"Unhealthy","source.component":"kubelet","source.host":"pach-control-plane","firstTimestamp":1714065932,"lastTimestamp":1714065942,"ongoingDuration":10,"count":2,"reportingController":"kubelet","reportingInstance":"pach-control-plane","type":"Warning"}}
{"level":"info","ts":1714067856.820002,"logger":"event","caller":"kube-event-tail/main.go:98","msg":"create Claim storage-pachyderm-loki-0 Pod pachyderm-loki-0 in StatefulSet pachyderm-loki success","event":{"namespace":"default","name":"pachyderm-loki.17c995ce175235c0","involvedObject":{"name":"StatefulSet/pachyderm-loki"},"reason":"SuccessfulCreate","source.component":"statefulset-controller","firstTimestamp":1714065845,"lastTimestamp":1714065845,"count":1,"reportingController":"statefulset-controller"}}
{"level":"info","ts":1714067856.8200066,"logger":"event","caller":"kube-event-tail/main.go:98","msg":"create Pod pachyderm-loki-0 in StatefulSet pachyderm-loki successful","event":{"namespace":"default","name":"pachyderm-loki.17c995ce17cdf905","involvedObject":{"name":"StatefulSet/pachyderm-loki"},"reason":"SuccessfulCreate","source.component":"statefulset-controller","firstTimestamp":1714065845,"lastTimestamp":1714065845,"count":1,"reportingController":"statefulset-controller"}}
{"level":"info","ts":1714067856.8200114,"logger":"event","caller":"kube-event-tail/main.go:98","msg":"Successfully assigned default/pachyderm-promtail-27cx4 to pach-control-plane","event":{"namespace":"default","name":"pachyderm-promtail-27cx4.17c995ce2646943c","involvedObject":{"name":"Pod/pachyderm-promtail-27cx4"},"reason":"Scheduled","source.component":"default-scheduler","firstTimestamp":1714065845,"lastTimestamp":1714065845,"count":1,"reportingController":"default-scheduler"}}
{"level":"info","ts":1714067856.8200324,"logger":"event","caller":"kube-event-tail/main.go:98","msg":"Pulling image \"docker.io/grafana/promtail:2.6.1\"","event":{"namespace":"default","name":"pachyderm-promtail-27cx4.17c995ce4971b596","involvedObject":{"name":"Pod/pachyderm-promtail-27cx4","fieldPath":"spec.containers{promtail}"},"reason":"Pulling","source.component":"kubelet","source.host":"pach-control-plane","firstTimestamp":1714065846,"lastTimestamp":1714065846,"count":1,"reportingController":"kubelet","reportingInstance":"pach-control-plane"}}
{"level":"info","ts":1714067856.8200414,"logger":"event","caller":"kube-event-tail/main.go:98","msg":"Successfully pulled image \"docker.io/grafana/promtail:2.6.1\" in 4.104s (5.944s including waiting)","event":{"namespace":"default","name":"pachyderm-promtail-27cx4.17c995cfabc42693","involvedObject":{"name":"Pod/pachyderm-promtail-27cx4","fieldPath":"spec.containers{promtail}"},"reason":"Pulled","source.component":"kubelet","source.host":"pach-control-plane","firstTimestamp":1714065852,"lastTimestamp":1714065852,"count":1,"reportingController":"kubelet","reportingInstance":"pach-control-plane"}}
{"level":"info","ts":1714067856.820047,"logger":"event","caller":"kube-event-tail/main.go:98","msg":"Created container promtail","event":{"namespace":"default","name":"pachyderm-promtail-27cx4.17c995cfb0ef1f19","involvedObject":{"name":"Pod/pachyderm-promtail-27cx4","fieldPath":"spec.containers{promtail}"},"reason":"Created","source.component":"kubelet","source.host":"pach-control-plane","firstTimestamp":1714065852,"lastTimestamp":1714065852,"count":1,"reportingController":"kubelet","reportingInstance":"pach-control-plane"}}
{"level":"info","ts":1714067856.8200684,"logger":"event","caller":"kube-event-tail/main.go:98","msg":"Started container promtail","event":{"namespace":"default","name":"pachyderm-promtail-27cx4.17c995cfb76719f1","involvedObject":{"name":"Pod/pachyderm-promtail-27cx4","fieldPath":"spec.containers{promtail}"},"reason":"Started","source.component":"kubelet","source.host":"pach-control-plane","firstTimestamp":1714065852,"lastTimestamp":1714065852,"count":1,"reportingController":"kubelet","reportingInstance":"pach-control-plane"}}
{"level":"info","ts":1714067856.8200734,"logger":"event","caller":"kube-event-tail/main.go:98","msg":"Readiness probe failed: Get \"http://10.244.0.6:3101/ready\": context deadline exceeded (Client.Timeout exceeded while awaiting headers)","event":{"namespace":"default","name":"pachyderm-promtail-27cx4.17c995e36b119c6e","involvedObject":{"name":"Pod/pachyderm-promtail-27cx4","fieldPath":"spec.containers{promtail}"},"reason":"Unhealthy","source.component":"kubelet","source.host":"pach-control-plane","firstTimestamp":1714065937,"lastTimestamp":1714066027,"ongoingDuration":90,"count":11,"reportingController":"kubelet","reportingInstance":"pach-control-plane","type":"Warning"}}
{"level":"info","ts":1714067856.8200793,"logger":"event","caller":"kube-event-tail/main.go:98","msg":"Created pod: pachyderm-promtail-27cx4","event":{"namespace":"default","name":"pachyderm-promtail.17c995ce2571a694","involvedObject":{"name":"DaemonSet/pachyderm-promtail"},"reason":"SuccessfulCreate","source.component":"daemonset-controller","firstTimestamp":1714065845,"lastTimestamp":1714065845,"count":1,"reportingController":"daemonset-controller"}}
{"level":"info","ts":1714067856.8200836,"logger":"event","caller":"kube-event-tail/main.go:98","msg":"0/1 nodes are available: 1 node(s) had untolerated taint {node.kubernetes.io/not-ready: }. preemption: 0/1 nodes are available: 1 Preemption is not helpful for scheduling.","event":{"namespace":"default","name":"pachyderm-proxy-5585cd764c-64hgc.17c995ce16472afd","involvedObject":{"name":"Pod/pachyderm-proxy-5585cd764c-64hgc"},"reason":"FailedScheduling","source.component":"default-scheduler","firstTimestamp":1714065845,"lastTimestamp":1714065845,"count":1,"reportingController":"default-scheduler","type":"Warning"}}
{"level":"info","ts":1714067856.82009,"logger":"event","caller":"kube-event-tail/main.go:98","msg":"Successfully assigned default/pachyderm-proxy-5585cd764c-64hgc to pach-control-plane","event":{"namespace":"default","name":"pachyderm-proxy-5585cd764c-64hgc.17c995ce891b44fe","involvedObject":{"name":"Pod/pachyderm-proxy-5585cd764c-64hgc"},"reason":"Scheduled","source.component":"default-scheduler","firstTimestamp":1714065847,"lastTimestamp":1714065847,"count":1,"reportingController":"default-scheduler"}}
{"level":"info","ts":1714067856.820095,"logger":"event","caller":"kube-event-tail/main.go:98","msg":"Pulling image \"envoyproxy/envoy-distroless:v1.29.3\"","event":{"namespace":"default","name":"pachyderm-proxy-5585cd764c-64hgc.17c995ceb69929b2","involvedObject":{"name":"Pod/pachyderm-proxy-5585cd764c-64hgc","fieldPath":"spec.containers{envoy}"},"reason":"Pulling","source.component":"kubelet","source.host":"pach-control-plane","firstTimestamp":1714065848,"lastTimestamp":1714065848,"count":1,"reportingController":"kubelet","reportingInstance":"pach-control-plane"}}
{"level":"info","ts":1714067856.8200998,"logger":"event","caller":"kube-event-tail/main.go:98","msg":"Successfully pulled image \"envoyproxy/envoy-distroless:v1.29.3\" in 2.583s (16.581s including waiting)","event":{"namespace":"default","name":"pachyderm-proxy-5585cd764c-64hgc.17c995d292f3eaf0","involvedObject":{"name":"Pod/pachyderm-proxy-5585cd764c-64hgc","fieldPath":"spec.containers{envoy}"},"reason":"Pulled","source.component":"kubelet","source.host":"pach-control-plane","firstTimestamp":1714065864,"lastTimestamp":1714065864,"count":1,"reportingController":"kubelet","reportingInstance":"pach-control-plane"}}
{"level":"info","ts":1714067856.8201058,"logger":"event","caller":"kube-event-tail/main.go:98","msg":"Created container envoy","event":{"namespace":"default","name":"pachyderm-proxy-5585cd764c-64hgc.17c995d295307ab9","involvedObject":{"name":"Pod/pachyderm-proxy-5585cd764c-64hgc","fieldPath":"spec.containers{envoy}"},"reason":"Created","source.component":"kubelet","source.host":"pach-control-plane","firstTimestamp":1714065864,"lastTimestamp":1714065864,"count":1,"reportingController":"kubelet","reportingInstance":"pach-control-plane"}}
{"level":"info","ts":1714067856.8201115,"logger":"event","caller":"kube-event-tail/main.go:98","msg":"Started container envoy","event":{"namespace":"default","name":"pachyderm-proxy-5585cd764c-64hgc.17c995d29c018add","involvedObject":{"name":"Pod/pachyderm-proxy-5585cd764c-64hgc","fieldPath":"spec.containers{envoy}"},"reason":"Started","source.component":"kubelet","source.host":"pach-control-plane","firstTimestamp":1714065864,"lastTimestamp":1714065864,"count":1,"reportingController":"kubelet","reportingInstance":"pach-control-plane"}}
{"level":"info","ts":1714067856.8201165,"logger":"event","caller":"kube-event-tail/main.go:98","msg":"Created pod: pachyderm-proxy-5585cd764c-64hgc","event":{"namespace":"default","name":"pachyderm-proxy-5585cd764c.17c995ce16453e02","involvedObject":{"name":"ReplicaSet/pachyderm-proxy-5585cd764c"},"reason":"SuccessfulCreate","source.component":"replicaset-controller","firstTimestamp":1714065845,"lastTimestamp":1714065845,"count":1,"reportingController":"replicaset-controller"}}
{"level":"info","ts":1714067856.8201232,"logger":"event","caller":"kube-event-tail/main.go:98","msg":"Scaled up replica set pachyderm-proxy-5585cd764c to 1","event":{"namespace":"default","name":"pachyderm-proxy.17c995ce15c52fe2","involvedObject":{"name":"Deployment/pachyderm-proxy"},"reason":"ScalingReplicaSet","source.component":"deployment-controller","firstTimestamp":1714065845,"lastTimestamp":1714065845,"count":1,"reportingController":"deployment-controller"}}
{"level":"info","ts":1714067856.8201282,"logger":"event","caller":"kube-event-tail/main.go:98","msg":"0/1 nodes are available: 1 node(s) had untolerated taint {node.kubernetes.io/not-ready: }. preemption: 0/1 nodes are available: 1 Preemption is not helpful for scheduling.","event":{"namespace":"default","name":"pg-bouncer-7f45dc7865-cmrt7.17c995ce16f357f2","involvedObject":{"name":"Pod/pg-bouncer-7f45dc7865-cmrt7"},"reason":"FailedScheduling","source.component":"default-scheduler","firstTimestamp":1714065845,"lastTimestamp":1714065845,"count":1,"reportingController":"default-scheduler","type":"Warning"}}
{"level":"info","ts":1714067856.8201542,"logger":"event","caller":"kube-event-tail/main.go:98","msg":"Successfully assigned default/pg-bouncer-7f45dc7865-cmrt7 to pach-control-plane","event":{"namespace":"default","name":"pg-bouncer-7f45dc7865-cmrt7.17c995ce891b42a6","involvedObject":{"name":"Pod/pg-bouncer-7f45dc7865-cmrt7"},"reason":"Scheduled","source.component":"default-scheduler","firstTimestamp":1714065847,"lastTimestamp":1714065847,"count":1,"reportingController":"default-scheduler"}}
{"level":"info","ts":1714067856.8201632,"logger":"event","caller":"kube-event-tail/main.go:98","msg":"Pulling image \"pachyderm/pgbouncer:1.16.2\"","event":{"namespace":"default","name":"pg-bouncer-7f45dc7865-cmrt7.17c995ceb5a52e9b","involvedObject":{"name":"Pod/pg-bouncer-7f45dc7865-cmrt7","fieldPath":"spec.containers{pg-bouncer}"},"reason":"Pulling","source.component":"kubelet","source.host":"pach-control-plane","firstTimestamp":1714065848,"lastTimestamp":1714065848,"count":1,"reportingController":"kubelet","reportingInstance":"pach-control-plane"}}
{"level":"info","ts":1714067856.8201697,"logger":"event","caller":"kube-event-tail/main.go:98","msg":"Successfully pulled image \"pachyderm/pgbouncer:1.16.2\" in 6.15s (12.636s including waiting)","event":{"namespace":"default","name":"pg-bouncer-7f45dc7865-cmrt7.17c995d1a6d25c21","involvedObject":{"name":"Pod/pg-bouncer-7f45dc7865-cmrt7","fieldPath":"spec.containers{pg-bouncer}"},"reason":"Pulled","source.component":"kubelet","source.host":"pach-control-plane","firstTimestamp":1714065860,"lastTimestamp":1714065860,"count":1,"reportingController":"kubelet","reportingInstance":"pach-control-plane"}}
{"level":"info","ts":1714067856.8201768,"logger":"event","caller":"kube-event-tail/main.go:98","msg":"Created container pg-bouncer","event":{"namespace":"default","name":"pg-bouncer-7f45dc7865-cmrt7.17c995d1a94dcf2c","involvedObject":{"name":"Pod/pg-bouncer-7f45dc7865-cmrt7","fieldPath":"spec.containers{pg-bouncer}"},"reason":"Created","source.component":"kubelet","source.host":"pach-control-plane","firstTimestamp":1714065860,"lastTimestamp":1714065860,"count":1,"reportingController":"kubelet","reportingInstance":"pach-control-plane"}}
{"level":"info","ts":1714067856.8201818,"logger":"event","caller":"kube-event-tail/main.go:98","msg":"Started container pg-bouncer","event":{"namespace":"default","name":"pg-bouncer-7f45dc7865-cmrt7.17c995d1b0519d1d","involvedObject":{"name":"Pod/pg-bouncer-7f45dc7865-cmrt7","fieldPath":"spec.containers{pg-bouncer}"},"reason":"Started","source.component":"kubelet","source.host":"pach-control-plane","firstTimestamp":1714065861,"lastTimestamp":1714065861,"count":1,"reportingController":"kubelet","reportingInstance":"pach-control-plane"}}
{"level":"info","ts":1714067856.8201869,"logger":"event","caller":"kube-event-tail/main.go:98","msg":"Created pod: pg-bouncer-7f45dc7865-cmrt7","event":{"namespace":"default","name":"pg-bouncer-7f45dc7865.17c995ce16c45860","involvedObject":{"name":"ReplicaSet/pg-bouncer-7f45dc7865"},"reason":"SuccessfulCreate","source.component":"replicaset-controller","firstTimestamp":1714065845,"lastTimestamp":1714065845,"count":1,"reportingController":"replicaset-controller"}}
{"level":"info","ts":1714067856.8201911,"logger":"event","caller":"kube-event-tail/main.go:98","msg":"Scaled up replica set pg-bouncer-7f45dc7865 to 1","event":{"namespace":"default","name":"pg-bouncer.17c995ce15c29f9d","involvedObject":{"name":"Deployment/pg-bouncer"},"reason":"ScalingReplicaSet","source.component":"deployment-controller","firstTimestamp":1714065845,"lastTimestamp":1714065845,"count":1,"reportingController":"deployment-controller"}}
{"level":"info","ts":1714067856.8201957,"logger":"event","caller":"kube-event-tail/main.go:98","msg":"0/1 nodes are available: 1 node(s) had untolerated taint {node.kubernetes.io/not-ready: }. preemption: 0/1 nodes are available: 1 Preemption is not helpful for scheduling.","event":{"namespace":"default","name":"postgres-0.17c995ce1a33333d","involvedObject":{"name":"Pod/postgres-0"},"reason":"FailedScheduling","source.component":"default-scheduler","firstTimestamp":1714065845,"lastTimestamp":1714065845,"count":1,"reportingController":"default-scheduler","type":"Warning"}}
{"level":"info","ts":1714067856.8202004,"logger":"event","caller":"kube-event-tail/main.go:98","msg":"Successfully assigned default/postgres-0 to pach-control-plane","event":{"namespace":"default","name":"postgres-0.17c995cfb3cd809a","involvedObject":{"name":"Pod/postgres-0"},"reason":"Scheduled","source.component":"default-scheduler","firstTimestamp":1714065852,"lastTimestamp":1714065852,"count":1,"reportingController":"default-scheduler"}}
{"level":"info","ts":1714067856.8202047,"logger":"event","caller":"kube-event-tail/main.go:98","msg":"Pulling image \"docker.io/pachyderm/postgresql:13.3.0\"","event":{"namespace":"default","name":"postgres-0.17c995cfd0f35550","involvedObject":{"name":"Pod/postgres-0","fieldPath":"spec.containers{postgres}"},"reason":"Pulling","source.component":"kubelet","source.host":"pach-control-plane","firstTimestamp":1714065852,"lastTimestamp":1714065852,"count":1,"reportingController":"kubelet","reportingInstance":"pach-control-plane"}}
{"level":"info","ts":1714067856.8202095,"logger":"event","caller":"kube-event-tail/main.go:98","msg":"Successfully pulled image \"docker.io/pachyderm/postgresql:13.3.0\" in 4.572s (29.892s including waiting)","event":{"namespace":"default","name":"postgres-0.17c995d6c6b5083e","involvedObject":{"name":"Pod/postgres-0","fieldPath":"spec.containers{postgres}"},"reason":"Pulled","source.component":"kubelet","source.host":"pach-control-plane","firstTimestamp":1714065882,"lastTimestamp":1714065882,"count":1,"reportingController":"kubelet","reportingInstance":"pach-control-plane"}}
{"level":"info","ts":1714067856.8202143,"logger":"event","caller":"kube-event-tail/main.go:98","msg":"Created container postgres","event":{"namespace":"default","name":"postgres-0.17c995d6c95a34d2","involvedObject":{"name":"Pod/postgres-0","fieldPath":"spec.containers{postgres}"},"reason":"Created","source.component":"kubelet","source.host":"pach-control-plane","firstTimestamp":1714065882,"lastTimestamp":1714065882,"count":1,"reportingController":"kubelet","reportingInstance":"pach-control-plane"}}
{"level":"info","ts":1714067856.820219,"logger":"event","caller":"kube-event-tail/main.go:98","msg":"Started container postgres","event":{"namespace":"default","name":"postgres-0.17c995d6cf4d4a72","involvedObject":{"name":"Pod/postgres-0","fieldPath":"spec.containers{postgres}"},"reason":"Started","source.component":"kubelet","source.host":"pach-control-plane","firstTimestamp":1714065883,"lastTimestamp":1714065883,"count":1,"reportingController":"kubelet","reportingInstance":"pach-control-plane"}}
{"level":"info","ts":1714067856.8202238,"logger":"event","caller":"kube-event-tail/main.go:98","msg":"create Claim data-postgres-0 Pod postgres-0 in StatefulSet postgres success","event":{"namespace":"default","name":"postgres.17c995ce17879e62","involvedObject":{"name":"StatefulSet/postgres"},"reason":"SuccessfulCreate","source.component":"statefulset-controller","firstTimestamp":1714065845,"lastTimestamp":1714065845,"count":1,"reportingController":"statefulset-controller"}}
{"level":"info","ts":1714067856.8202302,"logger":"event","caller":"kube-event-tail/main.go:98","msg":"create Pod postgres-0 in StatefulSet postgres successful","event":{"namespace":"default","name":"postgres.17c995ce18264c8f","involvedObject":{"name":"StatefulSet/postgres"},"reason":"SuccessfulCreate","source.component":"statefulset-controller","firstTimestamp":1714065845,"lastTimestamp":1714065845,"count":1,"reportingController":"statefulset-controller"}}
{"level":"info","ts":1714067856.8202345,"logger":"event","caller":"kube-event-tail/main.go:98","msg":"waiting for first consumer to be created before binding","event":{"namespace":"default","name":"storage-pachyderm-loki-0.17c995ce17473739","involvedObject":{"name":"PersistentVolumeClaim/storage-pachyderm-loki-0"},"reason":"WaitForFirstConsumer","source.component":"persistentvolume-controller","firstTimestamp":1714065845,"lastTimestamp":1714065845,"count":1,"reportingController":"persistentvolume-controller"}}
{"level":"info","ts":1714067856.8202562,"logger":"event","caller":"kube-event-tail/main.go:98","msg":"Waiting for a volume to be created either by the external provisioner 'rancher.io/local-path' or manually by the system administrator. If volume creation is delayed, please verify that the provisioner is running and correctly registered.","event":{"namespace":"default","name":"storage-pachyderm-loki-0.17c995ce89bae111","involvedObject":{"name":"PersistentVolumeClaim/storage-pachyderm-loki-0"},"reason":"ExternalProvisioning","source.component":"persistentvolume-controller","firstTimestamp":1714065847,"lastTimestamp":1714065847,"count":1,"reportingController":"persistentvolume-controller"}}
{"level":"info","ts":1714067856.8202658,"logger":"event","caller":"kube-event-tail/main.go:98","msg":"External provisioner is provisioning volume for claim \"default/storage-pachyderm-loki-0\"","event":{"namespace":"default","name":"storage-pachyderm-loki-0.17c995ceb052e174","involvedObject":{"name":"PersistentVolumeClaim/storage-pachyderm-loki-0"},"reason":"Provisioning","source.component":"rancher.io/local-path_local-path-provisioner-7577fdbbfb-ldff9_07bdbd19-02b2-4c93-a877-75c260fa3e3f","firstTimestamp":1714065848,"lastTimestamp":1714065848,"count":1}}
{"level":"info","ts":1714067856.8202708,"logger":"event","caller":"kube-event-tail/main.go:98","msg":"Successfully provisioned volume pvc-9f17eee5-f857-47b7-963e-a092453c63b9","event":{"namespace":"default","name":"storage-pachyderm-loki-0.17c995cfaff7d649","involvedObject":{"name":"PersistentVolumeClaim/storage-pachyderm-loki-0"},"reason":"ProvisioningSucceeded","source.component":"rancher.io/local-path_local-path-provisioner-7577fdbbfb-ldff9_07bdbd19-02b2-4c93-a877-75c260fa3e3f","firstTimestamp":1714065852,"lastTimestamp":1714065852,"count":1}}
{"level":"info","ts":1714068522.9034555,"logger":"event","caller":"kube-event-tail/main.go:98","msg":"Successfully assigned default/console-75589574fd-bbf9t to pach-control-plane","event":{"namespace":"default","name":"console-75589574fd-bbf9t.17c996dd4dee45c5","involvedObject":{"name":"Pod/console-75589574fd-bbf9t"},"reason":"Scheduled","source.component":"default-scheduler","firstTimestamp":1714067010,"lastTimestamp":1714067010,"count":1,"reportingController":"default-scheduler"}}
{"level":"info","ts":1714068522.9035046,"logger":"event","caller":"kube-event-tail/main.go:98","msg":"Container image \"pachyderm/haberdashery:2.8.0-alpha.5\" already present on machine","event":{"namespace":"default","name":"console-75589574fd-bbf9t.17c996dd6b26b757","involvedObject":{"name":"Pod/console-75589574fd-bbf9t","fieldPath":"spec.containers{console}"},"reason":"Pulled","source.component":"kubelet","source.host":"pach-control-plane","firstTimestamp":1714067010,"lastTimestamp":1714067010,"count":1,"reportingController":"kubelet","reportingInstance":"pach-control-plane"}}
{"level":"info","ts":1714068522.9035153,"logger":"event","caller":"kube-event-tail/main.go:98","msg":"Created container console","event":{"namespace":"default","name":"console-75589574fd-bbf9t.17c996dd6df0e72e","involvedObject":{"name":"Pod/console-75589574fd-bbf9t","fieldPath":"spec.containers{console}"},"reason":"Created","source.component":"kubelet","source.host":"pach-control-plane","firstTimestamp":1714067010,"lastTimestamp":1714067010,"count":1,"reportingController":"kubelet","reportingInstance":"pach-control-plane"}}
{"level":"info","ts":1714068522.9035206,"logger":"event","caller":"kube-event-tail/main.go:98","msg":"Started container console","event":{"namespace":"default","name":"console-75589574fd-bbf9t.17c996dd7503e35d","involvedObject":{"name":"Pod/console-75589574fd-bbf9t","fieldPath":"spec.containers{console}"},"reason":"Started","source.component":"kubelet","source.host":"pach-control-plane","firstTimestamp":1714067011,"lastTimestamp":1714067011,"count":1,"reportingController":"kubelet","reportingInstance":"pach-control-plane"}}
{"level":"info","ts":1714068522.9035254,"logger":"event","caller":"kube-event-tail/main.go:98","msg":"Readiness probe failed: Get \"http://10.244.0.23:4000/health\": dial tcp 10.244.0.23:4000: connect: connection refused","event":{"namespace":"default","name":"console-75589574fd-bbf9t.17c996dd854bab61","involvedObject":{"name":"Pod/console-75589574fd-bbf9t","fieldPath":"spec.containers{console}"},"reason":"Unhealthy","source.component":"kubelet","source.host":"pach-control-plane","firstTimestamp":1714067011,"lastTimestamp":1714067011,"count":1,"reportingController":"kubelet","reportingInstance":"pach-control-plane","type":"Warning"}}
{"level":"info","ts":1714068522.9035306,"logger":"event","caller":"kube-event-tail/main.go:98","msg":"Created pod: console-75589574fd-bbf9t","event":{"namespace":"default","name":"console-75589574fd.17c996dd4d7d949f","involvedObject":{"name":"ReplicaSet/console-75589574fd"},"reason":"SuccessfulCreate","source.component":"replicaset-controller","firstTimestamp":1714067010,"lastTimestamp":1714067010,"count":1,"reportingController":"replicaset-controller"}}
{"level":"info","ts":1714068522.9035351,"logger":"event","caller":"kube-event-tail/main.go:98","msg":"0/1 nodes are available: 1 node(s) had untolerated taint {node.kubernetes.io/not-ready: }. preemption: 0/1 nodes are available: 1 Preemption is not helpful for scheduling.","event":{"namespace":"default","name":"console-75f9f5b8d8-qvkwn.17c995ce1786fb19","involvedObject":{"name":"Pod/console-75f9f5b8d8-qvkwn"},"reason":"FailedScheduling","source.component":"default-scheduler","firstTimestamp":1714065845,"lastTimestamp":1714065845,"count":1,"reportingController":"default-scheduler","type":"Warning"}}
{"level":"info","ts":1714068522.9035401,"logger":"event","caller":"kube-event-tail/main.go:98","msg":"Successfully assigned default/console-75f9f5b8d8-qvkwn to pach-control-plane","event":{"namespace":"default","name":"console-75f9f5b8d8-qvkwn.17c995ce891cdec4","involvedObject":{"name":"Pod/console-75f9f5b8d8-qvkwn"},"reason":"Scheduled","source.component":"default-scheduler","firstTimestamp":1714065847,"lastTimestamp":1714065847,"count":1,"reportingController":"default-scheduler"}}
{"level":"info","ts":1714068522.9035451,"logger":"event","caller":"kube-event-tail/main.go:98","msg":"Pulling image \"pachyderm/haberdashery:2.8.0-alpha.5\"","event":{"namespace":"default","name":"console-75f9f5b8d8-qvkwn.17c995ceb6ca8b70","involvedObject":{"name":"Pod/console-75f9f5b8d8-qvkwn","fieldPath":"spec.containers{console}"},"reason":"Pulling","source.component":"kubelet","source.host":"pach-control-plane","firstTimestamp":1714065848,"lastTimestamp":1714065848,"count":1,"reportingController":"kubelet","reportingInstance":"pach-control-plane"}}
{"level":"info","ts":1714068522.90355,"logger":"event","caller":"kube-event-tail/main.go:98","msg":"Successfully pulled image \"pachyderm/haberdashery:2.8.0-alpha.5\" in 13.475s (30.054s including waiting)","event":{"namespace":"default","name":"console-75f9f5b8d8-qvkwn.17c995d5b62ef554","involvedObject":{"name":"Pod/console-75f9f5b8d8-qvkwn","fieldPath":"spec.containers{console}"},"reason":"Pulled","source.component":"kubelet","source.host":"pach-control-plane","firstTimestamp":1714065878,"lastTimestamp":1714065878,"count":1,"reportingController":"kubelet","reportingInstance":"pach-control-plane"}}
{"level":"info","ts":1714068522.9035552,"logger":"event","caller":"kube-event-tail/main.go:98","msg":"Created container console","event":{"namespace":"default","name":"console-75f9f5b8d8-qvkwn.17c995d5b8de059e","involvedObject":{"name":"Pod/console-75f9f5b8d8-qvkwn","fieldPath":"spec.containers{console}"},"reason":"Created","source.component":"kubelet","source.host":"pach-control-plane","firstTimestamp":1714065878,"lastTimestamp":1714065878,"count":1,"reportingController":"kubelet","reportingInstance":"pach-control-plane"}}
{"level":"info","ts":1714068522.9035594,"logger":"event","caller":"kube-event-tail/main.go:98","msg":"Started container console","event":{"namespace":"default","name":"console-75f9f5b8d8-qvkwn.17c995d5bf822a3b","involvedObject":{"name":"Pod/console-75f9f5b8d8-qvkwn","fieldPath":"spec.containers{console}"},"reason":"Started","source.component":"kubelet","source.host":"pach-control-plane","firstTimestamp":1714065878,"lastTimestamp":1714065878,"count":1,"reportingController":"kubelet","reportingInstance":"pach-control-plane"}}
{"level":"info","ts":1714068522.9035647,"logger":"event","caller":"kube-event-tail/main.go:98","msg":"Readiness probe failed: Get \"http://10.244.0.12:4000/health\": dial tcp 10.244.0.12:4000: connect: connection refused","event":{"namespace":"default","name":"console-75f9f5b8d8-qvkwn.17c995d5f92d4d34","involvedObject":{"name":"Pod/console-75f9f5b8d8-qvkwn","fieldPath":"spec.containers{console}"},"reason":"Unhealthy","source.component":"kubelet","source.host":"pach-control-plane","firstTimestamp":1714065879,"lastTimestamp":1714065879,"count":1,"reportingController":"kubelet","reportingInstance":"pach-control-plane","type":"Warning"}}
{"level":"info","ts":1714068522.90357,"logger":"event","caller":"kube-event-tail/main.go:98","msg":"Stopping container console","event":{"namespace":"default","name":"console-75f9f5b8d8-qvkwn.17c99693a1182004","involvedObject":{"name":"Pod/console-75f9f5b8d8-qvkwn","fieldPath":"spec.containers{console}"},"reason":"Killing","source.component":"kubelet","source.host":"pach-control-plane","firstTimestamp":1714066693,"lastTimestamp":1714066693,"count":1,"reportingController":"kubelet","reportingInstance":"pach-control-plane"}}
{"level":"info","ts":1714068522.9035745,"logger":"event","caller":"kube-event-tail/main.go:98","msg":"Created pod: console-75f9f5b8d8-qvkwn","event":{"namespace":"default","name":"console-75f9f5b8d8.17c995ce16ad3e28","involvedObject":{"name":"ReplicaSet/console-75f9f5b8d8"},"reason":"SuccessfulCreate","source.component":"replicaset-controller","firstTimestamp":1714065845,"lastTimestamp":1714065845,"count":1,"reportingController":"replicaset-controller"}}
{"level":"info","ts":1714068522.903581,"logger":"event","caller":"kube-event-tail/main.go:98","msg":"Deleted pod: console-75f9f5b8d8-qvkwn","event":{"namespace":"default","name":"console-75f9f5b8d8.17c99693a1077906","involvedObject":{"name":"ReplicaSet/console-75f9f5b8d8"},"reason":"SuccessfulDelete","source.component":"replicaset-controller","firstTimestamp":1714066693,"lastTimestamp":1714066693,"count":1,"reportingController":"replicaset-controller"}}
{"level":"info","ts":1714068522.9035854,"logger":"event","caller":"kube-event-tail/main.go:98","msg":"Successfully assigned default/console-967cf447d-t2cc6 to pach-control-plane","event":{"namespace":"default","name":"console-967cf447d-t2cc6.17c996930644d3cb","involvedObject":{"name":"Pod/console-967cf447d-t2cc6"},"reason":"Scheduled","source.component":"default-scheduler","firstTimestamp":1714066691,"lastTimestamp":1714066691,"count":1,"reportingController":"default-scheduler"}}
{"level":"info","ts":1714068522.9036064,"logger":"event","caller":"kube-event-tail/main.go:98","msg":"Container image \"pachyderm/haberdashery:2.8.0-alpha.5\" already present on machine","event":{"namespace":"default","name":"console-967cf447d-t2cc6.17c9969320c0ffba","involvedObject":{"name":"Pod/console-967cf447d-t2cc6","fieldPath":"spec.containers{console}"},"reason":"Pulled","source.component":"kubelet","source.host":"pach-control-plane","firstTimestamp":1714066691,"lastTimestamp":1714066691,"count":1,"reportingController":"kubelet","reportingInstance":"pach-control-plane"}}
{"level":"info","ts":1714068522.9036164,"logger":"event","caller":"kube-event-tail/main.go:98","msg":"Created container console","event":{"namespace":"default","name":"console-967cf447d-t2cc6.17c99693231ff41c","involvedObject":{"name":"Pod/console-967cf447d-t2cc6","fieldPath":"spec.containers{console}"},"reason":"Created","source.component":"kubelet","source.host":"pach-control-plane","firstTimestamp":1714066691,"lastTimestamp":1714066691,"count":1,"reportingController":"kubelet","reportingInstance":"pach-control-plane"}}
{"level":"info","ts":1714068522.9036238,"logger":"event","caller":"kube-event-tail/main.go:98","msg":"Started container console","event":{"namespace":"default","name":"console-967cf447d-t2cc6.17c996932a55e813","involvedObject":{"name":"Pod/console-967cf447d-t2cc6","fieldPath":"spec.containers{console}"},"reason":"Started","source.component":"kubelet","source.host":"pach-control-plane","firstTimestamp":1714066692,"lastTimestamp":1714066692,"count":1,"reportingController":"kubelet","reportingInstance":"pach-control-plane"}}
{"level":"info","ts":1714068522.9036288,"logger":"event","caller":"kube-event-tail/main.go:98","msg":"Readiness probe failed: Get \"http://10.244.0.19:4000/health\": dial tcp 10.244.0.19:4000: connect: connection refused","event":{"namespace":"default","name":"console-967cf447d-t2cc6.17c9969362ca39c9","involvedObject":{"name":"Pod/console-967cf447d-t2cc6","fieldPath":"spec.containers{console}"},"reason":"Unhealthy","source.component":"kubelet","source.host":"pach-control-plane","firstTimestamp":1714066692,"lastTimestamp":1714066692,"count":1,"reportingController":"kubelet","reportingInstance":"pach-control-plane","type":"Warning"}}
{"level":"info","ts":1714068522.9036496,"logger":"event","caller":"kube-event-tail/main.go:98","msg":"Stopping container console","event":{"namespace":"default","name":"console-967cf447d-t2cc6.17c996ddc4450d85","involvedObject":{"name":"Pod/console-967cf447d-t2cc6","fieldPath":"spec.containers{console}"},"reason":"Killing","source.component":"kubelet","source.host":"pach-control-plane","firstTimestamp":1714067012,"lastTimestamp":1714067012,"count":1,"reportingController":"kubelet","reportingInstance":"pach-control-plane"}}
{"level":"info","ts":1714068522.9036589,"logger":"event","caller":"kube-event-tail/main.go:98","msg":"Created pod: console-967cf447d-t2cc6","event":{"namespace":"default","name":"console-967cf447d.17c9969305be0ef2","involvedObject":{"name":"ReplicaSet/console-967cf447d"},"reason":"SuccessfulCreate","source.component":"replicaset-controller","firstTimestamp":1714066691,"lastTimestamp":1714066691,"count":1,"reportingController":"replicaset-controller"}}
{"level":"info","ts":1714068522.9036634,"logger":"event","caller":"kube-event-tail/main.go:98","msg":"Deleted pod: console-967cf447d-t2cc6","event":{"namespace":"default","name":"console-967cf447d.17c996ddc43d7b31","involvedObject":{"name":"ReplicaSet/console-967cf447d"},"reason":"SuccessfulDelete","source.component":"replicaset-controller","firstTimestamp":1714067012,"lastTimestamp":1714067012,"count":1,"reportingController":"replicaset-controller"}}
{"level":"info","ts":1714068522.9036705,"logger":"event","caller":"kube-event-tail/main.go:98","msg":"Scaled up replica set console-75f9f5b8d8 to 1","event":{"namespace":"default","name":"console.17c995ce15bf41e0","involvedObject":{"name":"Deployment/console"},"reason":"ScalingReplicaSet","source.component":"deployment-controller","firstTimestamp":1714065845,"lastTimestamp":1714065845,"count":1,"reportingController":"deployment-controller"}}
{"level":"info","ts":1714068522.903675,"logger":"event","caller":"kube-event-tail/main.go:98","msg":"Scaled up replica set console-967cf447d to 1","event":{"namespace":"default","name":"console.17c996930438729a","involvedObject":{"name":"Deployment/console"},"reason":"ScalingReplicaSet","source.component":"deployment-controller","firstTimestamp":1714066691,"lastTimestamp":1714066691,"count":1,"reportingController":"deployment-controller"}}
{"level":"info","ts":1714068522.9036813,"logger":"event","caller":"kube-event-tail/main.go:98","msg":"Scaled down replica set console-75f9f5b8d8 to 0 from 1","event":{"namespace":"default","name":"console.17c99693a088542d","involvedObject":{"name":"Deployment/console"},"reason":"ScalingReplicaSet","source.component":"deployment-controller","firstTimestamp":1714066693,"lastTimestamp":1714066693,"count":1,"reportingController":"deployment-controller"}}
{"level":"info","ts":1714068522.903686,"logger":"event","caller":"kube-event-tail/main.go:98","msg":"Scaled up replica set console-75589574fd to 1","event":{"namespace":"default","name":"console.17c996dd4c7a1485","involvedObject":{"name":"Deployment/console"},"reason":"ScalingReplicaSet","source.component":"deployment-controller","firstTimestamp":1714067010,"lastTimestamp":1714067010,"count":1,"reportingController":"deployment-controller"}}
{"level":"info","ts":1714068522.903707,"logger":"event","caller":"kube-event-tail/main.go:98","msg":"Scaled down replica set console-967cf447d to 0 from 1","event":{"namespace":"default","name":"console.17c996ddc346c94c","involvedObject":{"name":"Deployment/console"},"reason":"ScalingReplicaSet","source.component":"deployment-controller","firstTimestamp":1714067012,"lastTimestamp":1714067012,"count":1,"reportingController":"deployment-controller"}}
{"level":"info","ts":1714068522.9037158,"logger":"event","caller":"kube-event-tail/main.go:98","msg":"waiting for first consumer to be created before binding","event":{"namespace":"default","name":"data-postgres-0.17c995ce178274dd","involvedObject":{"name":"PersistentVolumeClaim/data-postgres-0"},"reason":"WaitForFirstConsumer","source.component":"persistentvolume-controller","firstTimestamp":1714065845,"lastTimestamp":1714065845,"count":1,"reportingController":"persistentvolume-controller"}}
{"level":"info","ts":1714068522.9037209,"logger":"event","caller":"kube-event-tail/main.go:98","msg":"Waiting for a volume to be created either by the external provisioner 'rancher.io/local-path' or manually by the system administrator. If volume creation is delayed, please verify that the provisioner is running and correctly registered.","event":{"namespace":"default","name":"data-postgres-0.17c995ce89bbc596","involvedObject":{"name":"PersistentVolumeClaim/data-postgres-0"},"reason":"ExternalProvisioning","source.component":"persistentvolume-controller","firstTimestamp":1714065847,"lastTimestamp":1714065847,"count":1,"reportingController":"persistentvolume-controller"}}
{"level":"info","ts":1714068522.9037268,"logger":"event","caller":"kube-event-tail/main.go:98","msg":"External provisioner is provisioning volume for claim \"default/data-postgres-0\"","event":{"namespace":"default","name":"data-postgres-0.17c995ceb051d517","involvedObject":{"name":"PersistentVolumeClaim/data-postgres-0"},"reason":"Provisioning","source.component":"rancher.io/local-path_local-path-provisioner-7577fdbbfb-ldff9_07bdbd19-02b2-4c93-a877-75c260fa3e3f","firstTimestamp":1714065848,"lastTimestamp":1714065848,"count":1}}
{"level":"info","ts":1714068522.903732,"logger":"event","caller":"kube-event-tail/main.go:98","msg":"Successfully provisioned volume pvc-54fba6d6-16ea-447e-a0d3-f3efb5809454","event":{"namespace":"default","name":"data-postgres-0.17c995cf8cb27219","involvedObject":{"name":"PersistentVolumeClaim/data-postgres-0"},"reason":"ProvisioningSucceeded","source.component":"rancher.io/local-path_local-path-provisioner-7577fdbbfb-ldff9_07bdbd19-02b2-4c93-a877-75c260fa3e3f","firstTimestamp":1714065851,"lastTimestamp":1714065851,"count":1}}
{"level":"info","ts":1714068522.9037366,"logger":"event","caller":"kube-event-tail/main.go:98","msg":"Successfully assigned default/default-edges-v1-292m8 to pach-control-plane","event":{"namespace":"default","name":"default-edges-v1-292m8.17c996db48c2e90b","involvedObject":{"name":"Pod/default-edges-v1-292m8"},"reason":"Scheduled","source.component":"default-scheduler","firstTimestamp":1714067001,"lastTimestamp":1714067001,"count":1,"reportingController":"default-scheduler"}}
{"level":"info","ts":1714068522.9037411,"logger":"event","caller":"kube-event-tail/main.go:98","msg":"Pulling image \"localhost:5001/worker:4c7a34a8ab1e1042228009ec967ec50633d4529c432711200feb360b8ef98ec3\"","event":{"namespace":"default","name":"default-edges-v1-292m8.17c996db63ecab2d","involvedObject":{"name":"Pod/default-edges-v1-292m8","fieldPath":"spec.initContainers{init}"},"reason":"Pulling","source.component":"kubelet","source.host":"pach-control-plane","firstTimestamp":1714067002,"lastTimestamp":1714067002,"count":1,"reportingController":"kubelet","reportingInstance":"pach-control-plane"}}
{"level":"info","ts":1714068522.9037464,"logger":"event","caller":"kube-event-tail/main.go:98","msg":"Successfully pulled image \"localhost:5001/worker:4c7a34a8ab1e1042228009ec967ec50633d4529c432711200feb360b8ef98ec3\" in 1.365s (1.365s including waiting)","event":{"namespace":"default","name":"default-edges-v1-292m8.17c996dbb555ea7f","involvedObject":{"name":"Pod/default-edges-v1-292m8","fieldPath":"spec.initContainers{init}"},"reason":"Pulled","source.component":"kubelet","source.host":"pach-control-plane","firstTimestamp":1714067003,"lastTimestamp":1714067003,"count":1,"reportingController":"kubelet","reportingInstance":"pach-control-plane"}}
{"level":"info","ts":1714068522.9037519,"logger":"event","caller":"kube-event-tail/main.go:98","msg":"Created container init","event":{"namespace":"default","name":"default-edges-v1-292m8.17c996dbb92f47f7","involvedObject":{"name":"Pod/default-edges-v1-292m8","fieldPath":"spec.initContainers{init}"},"reason":"Created","source.component":"kubelet","source.host":"pach-control-plane","firstTimestamp":1714067003,"lastTimestamp":1714067003,"count":1,"reportingController":"kubelet","reportingInstance":"pach-control-plane"}}
{"level":"info","ts":1714068522.9037623,"logger":"event","caller":"kube-event-tail/main.go:98","msg":"Started container init","event":{"namespace":"default","name":"default-edges-v1-292m8.17c996dbc06f9a4a","involvedObject":{"name":"Pod/default-edges-v1-292m8","fieldPath":"spec.initContainers{init}"},"reason":"Started","source.component":"kubelet","source.host":"pach-control-plane","firstTimestamp":1714067003,"lastTimestamp":1714067003,"count":1,"reportingController":"kubelet","reportingInstance":"pach-control-plane"}}
{"level":"info","ts":1714068522.9037676,"logger":"event","caller":"kube-event-tail/main.go:98","msg":"Pulling image \"pachyderm/opencv:1.0\"","event":{"namespace":"default","name":"default-edges-v1-292m8.17c996dc965430c8","involvedObject":{"name":"Pod/default-edges-v1-292m8","fieldPath":"spec.containers{user}"},"reason":"Pulling","source.component":"kubelet","source.host":"pach-control-plane","firstTimestamp":1714067007,"lastTimestamp":1714067029,"ongoingDuration":22,"count":2,"reportingController":"kubelet","reportingInstance":"pach-control-plane"}}
{"level":"info","ts":1714068522.9037914,"logger":"event","caller":"kube-event-tail/main.go:98","msg":"Failed to pull image \"pachyderm/opencv:1.0\": failed to pull and unpack image \"docker.io/pachyderm/opencv:1.0\": failed to copy: httpReadSeeker: failed open: unexpected status code https://registry-1.docker.io/v2/pachyderm/opencv/blobs/sha256:9f13e0ac480c2c862ae7aca8536bf2250b4d410468e6d33dc2f8ade1d368e184: 500 Internal Server Error","event":{"namespace":"default","name":"default-edges-v1-292m8.17c996de1c492c9c","involvedObject":{"name":"Pod/default-edges-v1-292m8","fieldPath":"spec.containers{user}"},"reason":"Failed","source.component":"kubelet","source.host":"pach-control-plane","firstTimestamp":1714067013,"lastTimestamp":1714067013,"count":1,"reportingController":"kubelet","reportingInstance":"pach-control-plane","type":"Warning"}}
{"level":"info","ts":1714068522.9038022,"logger":"event","caller":"kube-event-tail/main.go:98","msg":"Error: ErrImagePull","event":{"namespace":"default","name":"default-edges-v1-292m8.17c996de1c49715d","involvedObject":{"name":"Pod/default-edges-v1-292m8","fieldPath":"spec.containers{user}"},"reason":"Failed","source.component":"kubelet","source.host":"pach-control-plane","firstTimestamp":1714067013,"lastTimestamp":1714067013,"count":1,"reportingController":"kubelet","reportingInstance":"pach-control-plane","type":"Warning"}}
{"level":"info","ts":1714068522.9038072,"logger":"event","caller":"kube-event-tail/main.go:98","msg":"Container image \"localhost:5001/pachd:81d74ab385fe002f0ca96b9b75509cb8f0ba65cf73262f4d020ecd2fc736c917\" already present on machine","event":{"namespace":"default","name":"default-edges-v1-292m8.17c996de1c523e8b","involvedObject":{"name":"Pod/default-edges-v1-292m8","fieldPath":"spec.containers{storage}"},"reason":"Pulled","source.component":"kubelet","source.host":"pach-control-plane","firstTimestamp":1714067013,"lastTimestamp":1714067013,"count":1,"reportingController":"kubelet","reportingInstance":"pach-control-plane"}}
{"level":"info","ts":1714068522.9038126,"logger":"event","caller":"kube-event-tail/main.go:98","msg":"Created container storage","event":{"namespace":"default","name":"default-edges-v1-292m8.17c996de24ed04e5","involvedObject":{"name":"Pod/default-edges-v1-292m8","fieldPath":"spec.containers{storage}"},"reason":"Created","source.component":"kubelet","source.host":"pach-control-plane","firstTimestamp":1714067014,"lastTimestamp":1714067014,"count":1,"reportingController":"kubelet","reportingInstance":"pach-control-plane"}}
{"level":"info","ts":1714068522.9038172,"logger":"event","caller":"kube-event-tail/main.go:98","msg":"Started container storage","event":{"namespace":"default","name":"default-edges-v1-292m8.17c996de2b6ce9da","involvedObject":{"name":"Pod/default-edges-v1-292m8","fieldPath":"spec.containers{storage}"},"reason":"Started","source.component":"kubelet","source.host":"pach-control-plane","firstTimestamp":1714067014,"lastTimestamp":1714067014,"count":1,"reportingController":"kubelet","reportingInstance":"pach-control-plane"}}
{"level":"info","ts":1714068522.9038224,"logger":"event","caller":"kube-event-tail/main.go:98","msg":"Back-off pulling image \"pachyderm/opencv:1.0\"","event":{"namespace":"default","name":"default-edges-v1-292m8.17c996de38eb5495","involvedObject":{"name":"Pod/default-edges-v1-292m8","fieldPath":"spec.containers{user}"},"reason":"BackOff","source.component":"kubelet","source.host":"pach-control-plane","firstTimestamp":1714067014,"lastTimestamp":1714067014,"count":1,"reportingController":"kubelet","reportingInstance":"pach-control-plane"}}
{"level":"info","ts":1714068522.903827,"logger":"event","caller":"kube-event-tail/main.go:98","msg":"Error: ImagePullBackOff","event":{"namespace":"default","name":"default-edges-v1-292m8.17c996de38eb7501","involvedObject":{"name":"Pod/default-edges-v1-292m8","fieldPath":"spec.containers{user}"},"reason":"Failed","source.component":"kubelet","source.host":"pach-control-plane","firstTimestamp":1714067014,"lastTimestamp":1714067014,"count":1,"reportingController":"kubelet","reportingInstance":"pach-control-plane","type":"Warning"}}
{"level":"info","ts":1714068522.9038317,"logger":"event","caller":"kube-event-tail/main.go:98","msg":"Successfully pulled image \"pachyderm/opencv:1.0\" in 9.271s (9.271s including waiting)","event":{"namespace":"default","name":"default-edges-v1-292m8.17c996e3db04954a","involvedObject":{"name":"Pod/default-edges-v1-292m8","fieldPath":"spec.containers{user}"},"reason":"Pulled","source.component":"kubelet","source.host":"pach-control-plane","firstTimestamp":1714067038,"lastTimestamp":1714067038,"count":1,"reportingController":"kubelet","reportingInstance":"pach-control-plane"}}
{"level":"info","ts":1714068522.9038367,"logger":"event","caller":"kube-event-tail/main.go:98","msg":"Created container user","event":{"namespace":"default","name":"default-edges-v1-292m8.17c996e3df0971cc","involvedObject":{"name":"Pod/default-edges-v1-292m8","fieldPath":"spec.containers{user}"},"reason":"Created","source.component":"kubelet","source.host":"pach-control-plane","firstTimestamp":1714067038,"lastTimestamp":1714067038,"count":1,"reportingController":"kubelet","reportingInstance":"pach-control-plane"}}
{"level":"info","ts":1714068522.903842,"logger":"event","caller":"kube-event-tail/main.go:98","msg":"Started container user","event":{"namespace":"default","name":"default-edges-v1-292m8.17c996e3e7da41b1","involvedObject":{"name":"Pod/default-edges-v1-292m8","fieldPath":"spec.containers{user}"},"reason":"Started","source.component":"kubelet","source.host":"pach-control-plane","firstTimestamp":1714067038,"lastTimestamp":1714067038,"count":1,"reportingController":"kubelet","reportingInstance":"pach-control-plane"}}
{"level":"info","ts":1714068522.9038475,"logger":"event","caller":"kube-event-tail/main.go:98","msg":"Stopping container storage","event":{"namespace":"default","name":"default-edges-v1-292m8.17c996e40eda3cde","involvedObject":{"name":"Pod/default-edges-v1-292m8","fieldPath":"spec.containers{storage}"},"reason":"Killing","source.component":"kubelet","source.host":"pach-control-plane","firstTimestamp":1714067039,"lastTimestamp":1714067039,"count":1,"reportingController":"kubelet","reportingInstance":"pach-control-plane"}}
{"level":"info","ts":1714068522.9038556,"logger":"event","caller":"kube-event-tail/main.go:98","msg":"Stopping container user","event":{"namespace":"default","name":"default-edges-v1-292m8.17c996e40edab7eb","involvedObject":{"name":"Pod/default-edges-v1-292m8","fieldPath":"spec.containers{user}"},"reason":"Killing","source.component":"kubelet","source.host":"pach-control-plane","firstTimestamp":1714067039,"lastTimestamp":1714067039,"count":1,"reportingController":"kubelet","reportingInstance":"pach-control-plane"}}
{"level":"info","ts":1714068522.9038603,"logger":"event","caller":"kube-event-tail/main.go:98","msg":"Successfully assigned default/default-edges-v1-gqgbx to pach-control-plane","event":{"namespace":"default","name":"default-edges-v1-gqgbx.17c996e3ff463600","involvedObject":{"name":"Pod/default-edges-v1-gqgbx"},"reason":"Scheduled","source.component":"default-scheduler","firstTimestamp":1714067039,"lastTimestamp":1714067039,"count":1,"reportingController":"default-scheduler"}}
{"level":"info","ts":1714068522.9038656,"logger":"event","caller":"kube-event-tail/main.go:98","msg":"Container image \"localhost:5001/worker:da5639b93a4589fe170d5a035b6d4255a0609ec6ed8031fd9c366e0fcb0deb8a\" already present on machine","event":{"namespace":"default","name":"default-edges-v1-gqgbx.17c996e44cca747b","involvedObject":{"name":"Pod/default-edges-v1-gqgbx","fieldPath":"spec.initContainers{init}"},"reason":"Pulled","source.component":"kubelet","source.host":"pach-control-plane","firstTimestamp":1714067040,"lastTimestamp":1714067040,"count":1,"reportingController":"kubelet","reportingInstance":"pach-control-plane"}}
{"level":"info","ts":1714068522.903871,"logger":"event","caller":"kube-event-tail/main.go:98","msg":"Created container init","event":{"namespace":"default","name":"default-edges-v1-gqgbx.17c996e45056406e","involvedObject":{"name":"Pod/default-edges-v1-gqgbx","fieldPath":"spec.initContainers{init}"},"reason":"Created","source.component":"kubelet","source.host":"pach-control-plane","firstTimestamp":1714067040,"lastTimestamp":1714067040,"count":1,"reportingController":"kubelet","reportingInstance":"pach-control-plane"}}
{"level":"info","ts":1714068522.9038758,"logger":"event","caller":"kube-event-tail/main.go:98","msg":"Started container init","event":{"namespace":"default","name":"default-edges-v1-gqgbx.17c996e470dd9e5e","involvedObject":{"name":"Pod/default-edges-v1-gqgbx","fieldPath":"spec.initContainers{init}"},"reason":"Started","source.component":"kubelet","source.host":"pach-control-plane","firstTimestamp":1714067041,"lastTimestamp":1714067041,"count":1,"reportingController":"kubelet","reportingInstance":"pach-control-plane"}}
{"level":"info","ts":1714068522.9038801,"logger":"event","caller":"kube-event-tail/main.go:98","msg":"Container image \"pachyderm/opencv:1.0\" already present on machine","event":{"namespace":"default","name":"default-edges-v1-gqgbx.17c996e4c2784e3f","involvedObject":{"name":"Pod/default-edges-v1-gqgbx","fieldPath":"spec.containers{user}"},"reason":"Pulled","source.component":"kubelet","source.host":"pach-control-plane","firstTimestamp":1714067042,"lastTimestamp":1714067042,"count":1,"reportingController":"kubelet","reportingInstance":"pach-control-plane"}}
{"level":"info","ts":1714068522.903889,"logger":"event","caller":"kube-event-tail/main.go:98","msg":"Created container user","event":{"namespace":"default","name":"default-edges-v1-gqgbx.17c996e4c7b52b08","involvedObject":{"name":"Pod/default-edges-v1-gqgbx","fieldPath":"spec.containers{user}"},"reason":"Created","source.component":"kubelet","source.host":"pach-control-plane","firstTimestamp":1714067042,"lastTimestamp":1714067042,"count":1,"reportingController":"kubelet","reportingInstance":"pach-control-plane"}}
{"level":"info","ts":1714068522.9038942,"logger":"event","caller":"kube-event-tail/main.go:98","msg":"Started container user","event":{"namespace":"default","name":"default-edges-v1-gqgbx.17c996e4ce8160cd","involvedObject":{"name":"Pod/default-edges-v1-gqgbx","fieldPath":"spec.containers{user}"},"reason":"Started","source.component":"kubelet","source.host":"pach-control-plane","firstTimestamp":1714067042,"lastTimestamp":1714067042,"count":1,"reportingController":"kubelet","reportingInstance":"pach-control-plane"}}
{"level":"info","ts":1714068522.9038994,"logger":"event","caller":"kube-event-tail/main.go:98","msg":"Container image \"localhost:5001/pachd:22f229cb51e294acfd461f8b751e2937cfc2054a080f5a6a5a74f4028c495dec\" already present on machine","event":{"namespace":"default","name":"default-edges-v1-gqgbx.17c996e4ce8b9ad5","involvedObject":{"name":"Pod/default-edges-v1-gqgbx","fieldPath":"spec.containers{storage}"},"reason":"Pulled","source.component":"kubelet","source.host":"pach-control-plane","firstTimestamp":1714067042,"lastTimestamp":1714067042,"count":1,"reportingController":"kubelet","reportingInstance":"pach-control-plane"}}
{"level":"info","ts":1714068522.9039235,"logger":"event","caller":"kube-event-tail/main.go:98","msg":"Created container storage","event":{"namespace":"default","name":"default-edges-v1-gqgbx.17c996e4d53ea12d","involvedObject":{"name":"Pod/default-edges-v1-gqgbx","fieldPath":"spec.containers{storage}"},"reason":"Created","source.component":"kubelet","source.host":"pach-control-plane","firstTimestamp":1714067042,"lastTimestamp":1714067042,"count":1,"reportingController":"kubelet","reportingInstance":"pach-control-plane"}}
{"level":"info","ts":1714068522.9039328,"logger":"event","caller":"kube-event-tail/main.go:98","msg":"Started container storage","event":{"namespace":"default","name":"default-edges-v1-gqgbx.17c996e4dc3a7f3e","involvedObject":{"name":"Pod/default-edges-v1-gqgbx","fieldPath":"spec.containers{storage}"},"reason":"Started","source.component":"kubelet","source.host":"pach-control-plane","firstTimestamp":1714067042,"lastTimestamp":1714067042,"count":1,"reportingController":"kubelet","reportingInstance":"pach-control-plane"}}
{"level":"info","ts":1714068522.903938,"logger":"event","caller":"kube-event-tail/main.go:98","msg":"Stopping container user","event":{"namespace":"default","name":"default-edges-v1-gqgbx.17c99704b14143a3","involvedObject":{"name":"Pod/default-edges-v1-gqgbx","fieldPath":"spec.containers{user}"},"reason":"Killing","source.component":"kubelet","source.host":"pach-control-plane","firstTimestamp":1714067179,"lastTimestamp":1714067179,"count":1,"reportingController":"kubelet","reportingInstance":"pach-control-plane"}}
{"level":"info","ts":1714068522.9039426,"logger":"event","caller":"kube-event-tail/main.go:98","msg":"Stopping container storage","event":{"namespace":"default","name":"default-edges-v1-gqgbx.17c99704b142576c","involvedObject":{"name":"Pod/default-edges-v1-gqgbx","fieldPath":"spec.containers{storage}"},"reason":"Killing","source.component":"kubelet","source.host":"pach-control-plane","firstTimestamp":1714067179,"lastTimestamp":1714067179,"count":1,"reportingController":"kubelet","reportingInstance":"pach-control-plane"}}
{"level":"info","ts":1714068522.9039474,"logger":"event","caller":"kube-event-tail/main.go:98","msg":"Created pod: default-edges-v1-292m8","event":{"namespace":"default","name":"default-edges-v1.17c996db4810daac","involvedObject":{"name":"ReplicationController/default-edges-v1"},"reason":"SuccessfulCreate","source.component":"replication-controller","firstTimestamp":1714067001,"lastTimestamp":1714067001,"count":1,"reportingController":"replication-controller"}}
{"level":"info","ts":1714068522.9039524,"logger":"event","caller":"kube-event-tail/main.go:98","msg":"Created pod: default-edges-v1-gqgbx","event":{"namespace":"default","name":"default-edges-v1.17c996e3fea673ba","involvedObject":{"name":"ReplicationController/default-edges-v1"},"reason":"SuccessfulCreate","source.component":"replication-controller","firstTimestamp":1714067039,"lastTimestamp":1714067039,"count":1,"reportingController":"replication-controller"}}
{"level":"info","ts":1714068522.9039574,"logger":"event","caller":"kube-event-tail/main.go:98","msg":"Successfully assigned default/default-edges-v2-9f22j to pach-control-plane","event":{"namespace":"default","name":"default-edges-v2-9f22j.17c99704d2b4881f","involvedObject":{"name":"Pod/default-edges-v2-9f22j"},"reason":"Scheduled","source.component":"default-scheduler","firstTimestamp":1714067180,"lastTimestamp":1714067180,"count":1,"reportingController":"default-scheduler"}}
{"level":"info","ts":1714068522.9039657,"logger":"event","caller":"kube-event-tail/main.go:98","msg":"Container image \"localhost:5001/worker:da5639b93a4589fe170d5a035b6d4255a0609ec6ed8031fd9c366e0fcb0deb8a\" already present on machine","event":{"namespace":"default","name":"default-edges-v2-9f22j.17c99704ebfaf266","involvedObject":{"name":"Pod/default-edges-v2-9f22j","fieldPath":"spec.initContainers{init}"},"reason":"Pulled","source.component":"kubelet","source.host":"pach-control-plane","firstTimestamp":1714067180,"lastTimestamp":1714067180,"count":1,"reportingController":"kubelet","reportingInstance":"pach-control-plane"}}
{"level":"info","ts":1714068522.9039707,"logger":"event","caller":"kube-event-tail/main.go:98","msg":"Created container init","event":{"namespace":"default","name":"default-edges-v2-9f22j.17c99704eeca1a89","involvedObject":{"name":"Pod/default-edges-v2-9f22j","fieldPath":"spec.initContainers{init}"},"reason":"Created","source.component":"kubelet","source.host":"pach-control-plane","firstTimestamp":1714067180,"lastTimestamp":1714067180,"count":1,"reportingController":"kubelet","reportingInstance":"pach-control-plane"}}
{"level":"info","ts":1714068522.903976,"logger":"event","caller":"kube-event-tail/main.go:98","msg":"Started container init","event":{"namespace":"default","name":"default-edges-v2-9f22j.17c99704f53a1338","involvedObject":{"name":"Pod/default-edges-v2-9f22j","fieldPath":"spec.initContainers{init}"},"reason":"Started","source.component":"kubelet","source.host":"pach-control-plane","firstTimestamp":1714067180,"lastTimestamp":1714067180,"count":1,"reportingController":"kubelet","reportingInstance":"pach-control-plane"}}
{"level":"info","ts":1714068522.9039984,"logger":"event","caller":"kube-event-tail/main.go:98","msg":"Container image \"pachyderm/opencv:1.0\" already present on machine","event":{"namespace":"default","name":"default-edges-v2-9f22j.17c99705307c4f7c","involvedObject":{"name":"Pod/default-edges-v2-9f22j","fieldPath":"spec.containers{user}"},"reason":"Pulled","source.component":"kubelet","source.host":"pach-control-plane","firstTimestamp":1714067181,"lastTimestamp":1714067181,"count":1,"reportingController":"kubelet","reportingInstance":"pach-control-plane"}}
{"level":"info","ts":1714068522.9040077,"logger":"event","caller":"kube-event-tail/main.go:98","msg":"Created container user","event":{"namespace":"default","name":"default-edges-v2-9f22j.17c997053451ffea","involvedObject":{"name":"Pod/default-edges-v2-9f22j","fieldPath":"spec.containers{user}"},"reason":"Created","source.component":"kubelet","source.host":"pach-control-plane","firstTimestamp":1714067181,"lastTimestamp":1714067181,"count":1,"reportingController":"kubelet","reportingInstance":"pach-control-plane"}}
{"level":"info","ts":1714068522.9040124,"logger":"event","caller":"kube-event-tail/main.go:98","msg":"Started container user","event":{"namespace":"default","name":"default-edges-v2-9f22j.17c997053a97f8c6","involvedObject":{"name":"Pod/default-edges-v2-9f22j","fieldPath":"spec.containers{user}"},"reason":"Started","source.component":"kubelet","source.host":"pach-control-plane","firstTimestamp":1714067181,"lastTimestamp":1714067181,"count":1,"reportingController":"kubelet","reportingInstance":"pach-control-plane"}}
{"level":"info","ts":1714068522.904017,"logger":"event","caller":"kube-event-tail/main.go:98","msg":"Container image \"localhost:5001/pachd:22f229cb51e294acfd461f8b751e2937cfc2054a080f5a6a5a74f4028c495dec\" already present on machine","event":{"namespace":"default","name":"default-edges-v2-9f22j.17c997053aa11f04","involvedObject":{"name":"Pod/default-edges-v2-9f22j","fieldPath":"spec.containers{storage}"},"reason":"Pulled","source.component":"kubelet","source.host":"pach-control-plane","firstTimestamp":1714067181,"lastTimestamp":1714067181,"count":1,"reportingController":"kubelet","reportingInstance":"pach-control-plane"}}
{"level":"info","ts":1714068522.904022,"logger":"event","caller":"kube-event-tail/main.go:98","msg":"Created container storage","event":{"namespace":"default","name":"default-edges-v2-9f22j.17c997053d4ea339","involvedObject":{"name":"Pod/default-edges-v2-9f22j","fieldPath":"spec.containers{storage}"},"reason":"Created","source.component":"kubelet","source.host":"pach-control-plane","firstTimestamp":1714067181,"lastTimestamp":1714067181,"count":1,"reportingController":"kubelet","reportingInstance":"pach-control-plane"}}
{"level":"info","ts":1714068522.904027,"logger":"event","caller":"kube-event-tail/main.go:98","msg":"Started container storage","event":{"namespace":"default","name":"default-edges-v2-9f22j.17c9970543bbc48c","involvedObject":{"name":"Pod/default-edges-v2-9f22j","fieldPath":"spec.containers{storage}"},"reason":"Started","source.component":"kubelet","source.host":"pach-control-plane","firstTimestamp":1714067182,"lastTimestamp":1714067182,"count":1,"reportingController":"kubelet","reportingInstance":"pach-control-plane"}}
{"level":"info","ts":1714068522.9040313,"logger":"event","caller":"kube-event-tail/main.go:98","msg":"Created pod: default-edges-v2-9f22j","event":{"namespace":"default","name":"default-edges-v2.17c99704d231f5e8","involvedObject":{"name":"ReplicationController/default-edges-v2"},"reason":"SuccessfulCreate","source.component":"replication-controller","firstTimestamp":1714067180,"lastTimestamp":1714067180,"count":1,"reportingController":"replication-controller"}}
{"level":"info","ts":1714068522.9040358,"logger":"event","caller":"kube-event-tail/main.go:98","msg":"Successfully assigned default/default-montage-v1-57sqv to pach-control-plane","event":{"namespace":"default","name":"default-montage-v1-57sqv.17c996db828d13d8","involvedObject":{"name":"Pod/default-montage-v1-57sqv"},"reason":"Scheduled","source.component":"default-scheduler","firstTimestamp":1714067002,"lastTimestamp":1714067002,"count":1,"reportingController":"default-scheduler"}}
{"level":"info","ts":1714068522.9040403,"logger":"event","caller":"kube-event-tail/main.go:98","msg":"Pulling image \"localhost:5001/worker:4c7a34a8ab1e1042228009ec967ec50633d4529c432711200feb360b8ef98ec3\"","event":{"namespace":"default","name":"default-montage-v1-57sqv.17c996db9dbda629","involvedObject":{"name":"Pod/default-montage-v1-57sqv","fieldPath":"spec.initContainers{init}"},"reason":"Pulling","source.component":"kubelet","source.host":"pach-control-plane","firstTimestamp":1714067003,"lastTimestamp":1714067003,"count":1,"reportingController":"kubelet","reportingInstance":"pach-control-plane"}}
{"level":"info","ts":1714068522.9040456,"logger":"event","caller":"kube-event-tail/main.go:98","msg":"Successfully pulled image \"localhost:5001/worker:4c7a34a8ab1e1042228009ec967ec50633d4529c432711200feb360b8ef98ec3\" in 92ms (488ms including waiting)","event":{"namespace":"default","name":"default-montage-v1-57sqv.17c996dbbada15a3","involvedObject":{"name":"Pod/default-montage-v1-57sqv","fieldPath":"spec.initContainers{init}"},"reason":"Pulled","source.component":"kubelet","source.host":"pach-control-plane","firstTimestamp":1714067003,"lastTimestamp":1714067003,"count":1,"reportingController":"kubelet","reportingInstance":"pach-control-plane"}}
{"level":"info","ts":1714068522.9040504,"logger":"event","caller":"kube-event-tail/main.go:98","msg":"Created container init","event":{"namespace":"default","name":"default-montage-v1-57sqv.17c996dbc29a18a8","involvedObject":{"name":"Pod/default-montage-v1-57sqv","fieldPath":"spec.initContainers{init}"},"reason":"Created","source.component":"kubelet","source.host":"pach-control-plane","firstTimestamp":1714067003,"lastTimestamp":1714067003,"count":1,"reportingController":"kubelet","reportingInstance":"pach-control-plane"}}
{"level":"info","ts":1714068522.9040587,"logger":"event","caller":"kube-event-tail/main.go:98","msg":"Started container init","event":{"namespace":"default","name":"default-montage-v1-57sqv.17c996dc1e794aba","involvedObject":{"name":"Pod/default-montage-v1-57sqv","fieldPath":"spec.initContainers{init}"},"reason":"Started","source.component":"kubelet","source.host":"pach-control-plane","firstTimestamp":1714067005,"lastTimestamp":1714067005,"count":1,"reportingController":"kubelet","reportingInstance":"pach-control-plane"}}
{"level":"info","ts":1714068522.9040637,"logger":"event","caller":"kube-event-tail/main.go:98","msg":"Pulling image \"dpokidov/imagemagick:7.1.0-23\"","event":{"namespace":"default","name":"default-montage-v1-57sqv.17c996dc9634e4dd","involvedObject":{"name":"Pod/default-montage-v1-57sqv","fieldPath":"spec.containers{user}"},"reason":"Pulling","source.component":"kubelet","source.host":"pach-control-plane","firstTimestamp":1714067007,"lastTimestamp":1714067007,"count":1,"reportingController":"kubelet","reportingInstance":"pach-control-plane"}}
{"level":"info","ts":1714068522.9040685,"logger":"event","caller":"kube-event-tail/main.go:98","msg":"Successfully pulled image \"dpokidov/imagemagick:7.1.0-23\" in 4.767s (4.767s including waiting)","event":{"namespace":"default","name":"default-montage-v1-57sqv.17c996ddb25a490e","involvedObject":{"name":"Pod/default-montage-v1-57sqv","fieldPath":"spec.containers{user}"},"reason":"Pulled","source.component":"kubelet","source.host":"pach-control-plane","firstTimestamp":1714067012,"lastTimestamp":1714067012,"count":1,"reportingController":"kubelet","reportingInstance":"pach-control-plane"}}
{"level":"info","ts":1714068522.9040732,"logger":"event","caller":"kube-event-tail/main.go:98","msg":"Created container user","event":{"namespace":"default","name":"default-montage-v1-57sqv.17c996ddb5aaa0b5","involvedObject":{"name":"Pod/default-montage-v1-57sqv","fieldPath":"spec.containers{user}"},"reason":"Created","source.component":"kubelet","source.host":"pach-control-plane","firstTimestamp":1714067012,"lastTimestamp":1714067012,"count":1,"reportingController":"kubelet","reportingInstance":"pach-control-plane"}}
{"level":"info","ts":1714068522.9040778,"logger":"event","caller":"kube-event-tail/main.go:98","msg":"Started container user","event":{"namespace":"default","name":"default-montage-v1-57sqv.17c996ddbbb29d99","involvedObject":{"name":"Pod/default-montage-v1-57sqv","fieldPath":"spec.containers{user}"},"reason":"Started","source.component":"kubelet","source.host":"pach-control-plane","firstTimestamp":1714067012,"lastTimestamp":1714067012,"count":1,"reportingController":"kubelet","reportingInstance":"pach-control-plane"}}
{"level":"info","ts":1714068522.9040828,"logger":"event","caller":"kube-event-tail/main.go:98","msg":"Container image \"localhost:5001/pachd:81d74ab385fe002f0ca96b9b75509cb8f0ba65cf73262f4d020ecd2fc736c917\" already present on machine","event":{"namespace":"default","name":"default-montage-v1-57sqv.17c996ddbbbb00ea","involvedObject":{"name":"Pod/default-montage-v1-57sqv","fieldPath":"spec.containers{storage}"},"reason":"Pulled","source.component":"kubelet","source.host":"pach-control-plane","firstTimestamp":1714067012,"lastTimestamp":1714067012,"count":1,"reportingController":"kubelet","reportingInstance":"pach-control-plane"}}
{"level":"info","ts":1714068522.9040902,"logger":"event","caller":"kube-event-tail/main.go:98","msg":"Created container storage","event":{"namespace":"default","name":"default-montage-v1-57sqv.17c996ddbf6cd5d3","involvedObject":{"name":"Pod/default-montage-v1-57sqv","fieldPath":"spec.containers{storage}"},"reason":"Created","source.component":"kubelet","source.host":"pach-control-plane","firstTimestamp":1714067012,"lastTimestamp":1714067012,"count":1,"reportingController":"kubelet","reportingInstance":"pach-control-plane"}}
{"level":"info","ts":1714068522.9041054,"logger":"event","caller":"kube-event-tail/main.go:98","msg":"Started container storage","event":{"namespace":"default","name":"default-montage-v1-57sqv.17c996ddc57ebb1b","involvedObject":{"name":"Pod/default-montage-v1-57sqv","fieldPath":"spec.containers{storage}"},"reason":"Started","source.component":"kubelet","source.host":"pach-control-plane","firstTimestamp":1714067012,"lastTimestamp":1714067012,"count":1,"reportingController":"kubelet","reportingInstance":"pach-control-plane"}}
{"level":"info","ts":1714068522.9041326,"logger":"event","caller":"kube-event-tail/main.go:98","msg":"Stopping container user","event":{"namespace":"default","name":"default-montage-v1-57sqv.17c996e34cc03f12","involvedObject":{"name":"Pod/default-montage-v1-57sqv","fieldPath":"spec.containers{user}"},"reason":"Killing","source.component":"kubelet","source.host":"pach-control-plane","firstTimestamp":1714067036,"lastTimestamp":1714067036,"count":1,"reportingController":"kubelet","reportingInstance":"pach-control-plane"}}
{"level":"info","ts":1714068522.904142,"logger":"event","caller":"kube-event-tail/main.go:98","msg":"Stopping container storage","event":{"namespace":"default","name":"default-montage-v1-57sqv.17c996e34cc20629","involvedObject":{"name":"Pod/default-montage-v1-57sqv","fieldPath":"spec.containers{storage}"},"reason":"Killing","source.component":"kubelet","source.host":"pach-control-plane","firstTimestamp":1714067036,"lastTimestamp":1714067036,"count":1,"reportingController":"kubelet","reportingInstance":"pach-control-plane"}}
{"level":"info","ts":1714068522.9041467,"logger":"event","caller":"kube-event-tail/main.go:98","msg":"Successfully assigned default/default-montage-v1-jsw2g to pach-control-plane","event":{"namespace":"default","name":"default-montage-v1-jsw2g.17c996e3896ca8d9","involvedObject":{"name":"Pod/default-montage-v1-jsw2g"},"reason":"Scheduled","source.component":"default-scheduler","firstTimestamp":1714067037,"lastTimestamp":1714067037,"count":1,"reportingController":"default-scheduler"}}
{"level":"info","ts":1714068522.9041512,"logger":"event","caller":"kube-event-tail/main.go:98","msg":"Pulling image \"localhost:5001/worker:da5639b93a4589fe170d5a035b6d4255a0609ec6ed8031fd9c366e0fcb0deb8a\"","event":{"namespace":"default","name":"default-montage-v1-jsw2g.17c996e3a373aca2","involvedObject":{"name":"Pod/default-montage-v1-jsw2g","fieldPath":"spec.initContainers{init}"},"reason":"Pulling","source.component":"kubelet","source.host":"pach-control-plane","firstTimestamp":1714067037,"lastTimestamp":1714067037,"count":1,"reportingController":"kubelet","reportingInstance":"pach-control-plane"}}
{"level":"info","ts":1714068522.9041562,"logger":"event","caller":"kube-event-tail/main.go:98","msg":"Successfully pulled image \"localhost:5001/worker:da5639b93a4589fe170d5a035b6d4255a0609ec6ed8031fd9c366e0fcb0deb8a\" in 1.809s (2.741s including waiting)","event":{"namespace":"default","name":"default-montage-v1-jsw2g.17c996e446e0ff68","involvedObject":{"name":"Pod/default-montage-v1-jsw2g","fieldPath":"spec.initContainers{init}"},"reason":"Pulled","source.component":"kubelet","source.host":"pach-control-plane","firstTimestamp":1714067040,"lastTimestamp":1714067040,"count":1,"reportingController":"kubelet","reportingInstance":"pach-control-plane"}}
{"level":"info","ts":1714068522.9041615,"logger":"event","caller":"kube-event-tail/main.go:98","msg":"Created container init","event":{"namespace":"default","name":"default-montage-v1-jsw2g.17c996e4495f7345","involvedObject":{"name":"Pod/default-montage-v1-jsw2g","fieldPath":"spec.initContainers{init}"},"reason":"Created","source.component":"kubelet","source.host":"pach-control-plane","firstTimestamp":1714067040,"lastTimestamp":1714067040,"count":1,"reportingController":"kubelet","reportingInstance":"pach-control-plane"}}
{"level":"info","ts":1714068522.9041665,"logger":"event","caller":"kube-event-tail/main.go:98","msg":"Started container init","event":{"namespace":"default","name":"default-montage-v1-jsw2g.17c996e44e5c707b","involvedObject":{"name":"Pod/default-montage-v1-jsw2g","fieldPath":"spec.initContainers{init}"},"reason":"Started","source.component":"kubelet","source.host":"pach-control-plane","firstTimestamp":1714067040,"lastTimestamp":1714067040,"count":1,"reportingController":"kubelet","reportingInstance":"pach-control-plane"}}
{"level":"info","ts":1714068522.9041708,"logger":"event","caller":"kube-event-tail/main.go:98","msg":"Container image \"dpokidov/imagemagick:7.1.0-23\" already present on machine","event":{"namespace":"default","name":"default-montage-v1-jsw2g.17c996e4c2921925","involvedObject":{"name":"Pod/default-montage-v1-jsw2g","fieldPath":"spec.containers{user}"},"reason":"Pulled","source.component":"kubelet","source.host":"pach-control-plane","firstTimestamp":1714067042,"lastTimestamp":1714067042,"count":1,"reportingController":"kubelet","reportingInstance":"pach-control-plane"}}
{"level":"info","ts":1714068522.9041758,"logger":"event","caller":"kube-event-tail/main.go:98","msg":"Created container user","event":{"namespace":"default","name":"default-montage-v1-jsw2g.17c996e4ca0777e2","involvedObject":{"name":"Pod/default-montage-v1-jsw2g","fieldPath":"spec.containers{user}"},"reason":"Created","source.component":"kubelet","source.host":"pach-control-plane","firstTimestamp":1714067042,"lastTimestamp":1714067042,"count":1,"reportingController":"kubelet","reportingInstance":"pach-control-plane"}}
{"level":"info","ts":1714068522.9041805,"logger":"event","caller":"kube-event-tail/main.go:98","msg":"Started container user","event":{"namespace":"default","name":"default-montage-v1-jsw2g.17c996e4ce821d7a","involvedObject":{"name":"Pod/default-montage-v1-jsw2g","fieldPath":"spec.containers{user}"},"reason":"Started","source.component":"kubelet","source.host":"pach-control-plane","firstTimestamp":1714067042,"lastTimestamp":1714067042,"count":1,"reportingController":"kubelet","reportingInstance":"pach-control-plane"}}
{"level":"info","ts":1714068522.9041874,"logger":"event","caller":"kube-event-tail/main.go:98","msg":"Container image \"localhost:5001/pachd:22f229cb51e294acfd461f8b751e2937cfc2054a080f5a6a5a74f4028c495dec\" already present on machine","event":{"namespace":"default","name":"default-montage-v1-jsw2g.17c996e4ce8b7b31","involvedObject":{"name":"Pod/default-montage-v1-jsw2g","fieldPath":"spec.containers{storage}"},"reason":"Pulled","source.component":"kubelet","source.host":"pach-control-plane","firstTimestamp":1714067042,"lastTimestamp":1714067042,"count":1,"reportingController":"kubelet","reportingInstance":"pach-control-plane"}}
{"level":"info","ts":1714068522.9041936,"logger":"event","caller":"kube-event-tail/main.go:98","msg":"Created container storage","event":{"namespace":"default","name":"default-montage-v1-jsw2g.17c996e4d75effae","involvedObject":{"name":"Pod/default-montage-v1-jsw2g","fieldPath":"spec.containers{storage}"},"reason":"Created","source.component":"kubelet","source.host":"pach-control-plane","firstTimestamp":1714067042,"lastTimestamp":1714067042,"count":1,"reportingController":"kubelet","reportingInstance":"pach-control-plane"}}
{"level":"info","ts":1714068522.9042156,"logger":"event","caller":"kube-event-tail/main.go:98","msg":"Started container storage","event":{"namespace":"default","name":"default-montage-v1-jsw2g.17c996e4dc3a03cd","involvedObject":{"name":"Pod/default-montage-v1-jsw2g","fieldPath":"spec.containers{storage}"},"reason":"Started","source.component":"kubelet","source.host":"pach-control-plane","firstTimestamp":1714067042,"lastTimestamp":1714067042,"count":1,"reportingController":"kubelet","reportingInstance":"pach-control-plane"}}
{"level":"info","ts":1714068522.9042242,"logger":"event","caller":"kube-event-tail/main.go:98","msg":"Created pod: default-montage-v1-57sqv","event":{"namespace":"default","name":"default-montage-v1.17c996db7dd2e245","involvedObject":{"name":"ReplicationController/default-montage-v1"},"reason":"SuccessfulCreate","source.component":"replication-controller","firstTimestamp":1714067002,"lastTimestamp":1714067002,"count":1,"reportingController":"replication-controller"}}
{"level":"info","ts":1714068522.9042294,"logger":"event","caller":"kube-event-tail/main.go:98","msg":"Created pod: default-montage-v1-jsw2g","event":{"namespace":"default","name":"default-montage-v1.17c996e3886e1106","involvedObject":{"name":"ReplicationController/default-montage-v1"},"reason":"SuccessfulCreate","source.component":"replication-controller","firstTimestamp":1714067037,"lastTimestamp":1714067037,"count":1,"reportingController":"replication-controller"}}
{"level":"info","ts":1714068522.9042342,"logger":"event","caller":"kube-event-tail/main.go:98","msg":"0/1 nodes are available: 1 node(s) had untolerated taint {node.kubernetes.io/not-ready: }. preemption: 0/1 nodes are available: 1 Preemption is not helpful for scheduling.","event":{"namespace":"default","name":"etcd-0.17c995ce19242c87","involvedObject":{"name":"Pod/etcd-0"},"reason":"FailedScheduling","source.component":"default-scheduler","firstTimestamp":1714065845,"lastTimestamp":1714065845,"count":1,"reportingController":"default-scheduler","type":"Warning"}}
{"level":"info","ts":1714068522.90424,"logger":"event","caller":"kube-event-tail/main.go:98","msg":"Successfully assigned default/etcd-0 to pach-control-plane","event":{"namespace":"default","name":"etcd-0.17c995ce88971826","involvedObject":{"name":"Pod/etcd-0"},"reason":"Scheduled","source.component":"default-scheduler","firstTimestamp":1714065847,"lastTimestamp":1714065847,"count":1,"reportingController":"default-scheduler"}}
{"level":"info","ts":1714068522.9042475,"logger":"event","caller":"kube-event-tail/main.go:98","msg":"Pulling image \"pachyderm/etcd:v3.5.12\"","event":{"namespace":"default","name":"etcd-0.17c995ceb40737e7","involvedObject":{"name":"Pod/etcd-0","fieldPath":"spec.containers{etcd}"},"reason":"Pulling","source.component":"kubelet","source.host":"pach-control-plane","firstTimestamp":1714065848,"lastTimestamp":1714065848,"count":1,"reportingController":"kubelet","reportingInstance":"pach-control-plane"}}
{"level":"info","ts":1714068522.9042528,"logger":"event","caller":"kube-event-tail/main.go:98","msg":"Successfully pulled image \"pachyderm/etcd:v3.5.12\" in 1.476s (5.633s including waiting)","event":{"namespace":"default","name":"etcd-0.17c995d003c9d032","involvedObject":{"name":"Pod/etcd-0","fieldPath":"spec.containers{etcd}"},"reason":"Pulled","source.component":"kubelet","source.host":"pach-control-plane","firstTimestamp":1714065853,"lastTimestamp":1714065853,"count":1,"reportingController":"kubelet","reportingInstance":"pach-control-plane"}}
{"level":"info","ts":1714068522.9042761,"logger":"event","caller":"kube-event-tail/main.go:98","msg":"Created container etcd","event":{"namespace":"default","name":"etcd-0.17c995d0088b6e77","involvedObject":{"name":"Pod/etcd-0","fieldPath":"spec.containers{etcd}"},"reason":"Created","source.component":"kubelet","source.host":"pach-control-plane","firstTimestamp":1714065853,"lastTimestamp":1714065853,"count":1,"reportingController":"kubelet","reportingInstance":"pach-control-plane"}}
{"level":"info","ts":1714068522.9042857,"logger":"event","caller":"kube-event-tail/main.go:98","msg":"Started container etcd","event":{"namespace":"default","name":"etcd-0.17c995d010a12ecb","involvedObject":{"name":"Pod/etcd-0","fieldPath":"spec.containers{etcd}"},"reason":"Started","source.component":"kubelet","source.host":"pach-control-plane","firstTimestamp":1714065854,"lastTimestamp":1714065854,"count":1,"reportingController":"kubelet","reportingInstance":"pach-control-plane"}}
{"level":"info","ts":1714068522.9042907,"logger":"event","caller":"kube-event-tail/main.go:98","msg":"create Pod etcd-0 in StatefulSet etcd successful","event":{"namespace":"default","name":"etcd.17c995ce174cb2c7","involvedObject":{"name":"StatefulSet/etcd"},"reason":"SuccessfulCreate","source.component":"statefulset-controller","firstTimestamp":1714065845,"lastTimestamp":1714065845,"count":1,"reportingController":"statefulset-controller"}}
{"level":"info","ts":1714068522.9042957,"logger":"event","caller":"kube-event-tail/main.go:98","msg":"0/1 nodes are available: 1 node(s) had untolerated taint {node.kubernetes.io/not-ready: }. preemption: 0/1 nodes are available: 1 Preemption is not helpful for scheduling.","event":{"namespace":"default","name":"minio-0.17c995cda7dbcb93","involvedObject":{"name":"Pod/minio-0"},"reason":"FailedScheduling","source.component":"default-scheduler","firstTimestamp":1714065843,"lastTimestamp":1714065843,"count":1,"reportingController":"default-scheduler","type":"Warning"}}
{"level":"info","ts":1714068522.9043012,"logger":"event","caller":"kube-event-tail/main.go:98","msg":"Successfully assigned default/minio-0 to pach-control-plane","event":{"namespace":"default","name":"minio-0.17c995cfc6da2ecb","involvedObject":{"name":"Pod/minio-0"},"reason":"Scheduled","source.component":"default-scheduler","firstTimestamp":1714065852,"lastTimestamp":1714065852,"count":1,"reportingController":"default-scheduler"}}
{"level":"info","ts":1714068522.9043062,"logger":"event","caller":"kube-event-tail/main.go:98","msg":"Pulling image \"docker.io/minio/minio:latest\"","event":{"namespace":"default","name":"minio-0.17c995cfe13ca954","involvedObject":{"name":"Pod/minio-0","fieldPath":"spec.containers{minio}"},"reason":"Pulling","source.component":"kubelet","source.host":"pach-control-plane","firstTimestamp":1714065853,"lastTimestamp":1714065853,"count":1,"reportingController":"kubelet","reportingInstance":"pach-control-plane"}}
{"level":"info","ts":1714068522.904311,"logger":"event","caller":"kube-event-tail/main.go:98","msg":"Successfully pulled image \"docker.io/minio/minio:latest\" in 2.182s (33.669s including waiting)","event":{"namespace":"default","name":"minio-0.17c995d7b81a3582","involvedObject":{"name":"Pod/minio-0","fieldPath":"spec.containers{minio}"},"reason":"Pulled","source.component":"kubelet","source.host":"pach-control-plane","firstTimestamp":1714065886,"lastTimestamp":1714065886,"count":1,"reportingController":"kubelet","reportingInstance":"pach-control-plane"}}
{"level":"info","ts":1714068522.9043162,"logger":"event","caller":"kube-event-tail/main.go:98","msg":"Created container minio","event":{"namespace":"default","name":"minio-0.17c995d7ba807511","involvedObject":{"name":"Pod/minio-0","fieldPath":"spec.containers{minio}"},"reason":"Created","source.component":"kubelet","source.host":"pach-control-plane","firstTimestamp":1714065886,"lastTimestamp":1714065886,"count":1,"reportingController":"kubelet","reportingInstance":"pach-control-plane"}}
{"level":"info","ts":1714068522.9043205,"logger":"event","caller":"kube-event-tail/main.go:98","msg":"Started container minio","event":{"namespace":"default","name":"minio-0.17c995d7c0682f31","involvedObject":{"name":"Pod/minio-0","fieldPath":"spec.containers{minio}"},"reason":"Started","source.component":"kubelet","source.host":"pach-control-plane","firstTimestamp":1714065887,"lastTimestamp":1714065887,"count":1,"reportingController":"kubelet","reportingInstance":"pach-control-plane"}}
{"level":"info","ts":1714068522.904326,"logger":"event","caller":"kube-event-tail/main.go:98","msg":"waiting for first consumer to be created before binding","event":{"namespace":"default","name":"minio-data-minio-0.17c995cd773fd953","involvedObject":{"name":"PersistentVolumeClaim/minio-data-minio-0"},"reason":"WaitForFirstConsumer","source.component":"persistentvolume-controller","firstTimestamp":1714065842,"lastTimestamp":1714065842,"count":1,"reportingController":"persistentvolume-controller"}}
{"level":"info","ts":1714068522.9043343,"logger":"event","caller":"kube-event-tail/main.go:98","msg":"Waiting for a volume to be created either by the external provisioner 'rancher.io/local-path' or manually by the system administrator. If volume creation is delayed, please verify that the provisioner is running and correctly registered.","event":{"namespace":"default","name":"minio-data-minio-0.17c995ce258210a4","involvedObject":{"name":"PersistentVolumeClaim/minio-data-minio-0"},"reason":"ExternalProvisioning","source.component":"persistentvolume-controller","firstTimestamp":1714065845,"lastTimestamp":1714065845,"count":2,"reportingController":"persistentvolume-controller"}}
{"level":"info","ts":1714068522.9043398,"logger":"event","caller":"kube-event-tail/main.go:98","msg":"External provisioner is provisioning volume for claim \"default/minio-data-minio-0\"","event":{"namespace":"default","name":"minio-data-minio-0.17c995ceb050205c","involvedObject":{"name":"PersistentVolumeClaim/minio-data-minio-0"},"reason":"Provisioning","source.component":"rancher.io/local-path_local-path-provisioner-7577fdbbfb-ldff9_07bdbd19-02b2-4c93-a877-75c260fa3e3f","firstTimestamp":1714065848,"lastTimestamp":1714065848,"count":1}}
{"level":"info","ts":1714068522.9043472,"logger":"event","caller":"kube-event-tail/main.go:98","msg":"Successfully provisioned volume pvc-5e3389c7-4d2c-4933-b4cf-5a2f3aa8fe52","event":{"namespace":"default","name":"minio-data-minio-0.17c995cf8c96669c","involvedObject":{"name":"PersistentVolumeClaim/minio-data-minio-0"},"reason":"ProvisioningSucceeded","source.component":"rancher.io/local-path_local-path-provisioner-7577fdbbfb-ldff9_07bdbd19-02b2-4c93-a877-75c260fa3e3f","firstTimestamp":1714065851,"lastTimestamp":1714065851,"count":1}}
{"level":"info","ts":1714068522.9043527,"logger":"event","caller":"kube-event-tail/main.go:98","msg":"create Claim minio-data-minio-0 Pod minio-0 in StatefulSet minio success","event":{"namespace":"default","name":"minio.17c995cd771f5f0a","involvedObject":{"name":"StatefulSet/minio"},"reason":"SuccessfulCreate","source.component":"statefulset-controller","firstTimestamp":1714065842,"lastTimestamp":1714065842,"count":1,"reportingController":"statefulset-controller"}}
{"level":"info","ts":1714068522.9043577,"logger":"event","caller":"kube-event-tail/main.go:98","msg":"create Pod minio-0 in StatefulSet minio successful","event":{"namespace":"default","name":"minio.17c995cda7dae3ed","involvedObject":{"name":"StatefulSet/minio"},"reason":"SuccessfulCreate","source.component":"statefulset-controller","firstTimestamp":1714065843,"lastTimestamp":1714065843,"count":1,"reportingController":"statefulset-controller"}}
{"level":"info","ts":1714068522.904362,"logger":"event","caller":"kube-event-tail/main.go:98","msg":"Starting kubelet.","event":{"namespace":"default","name":"pach-control-plane.17c995c8921b7ca3","involvedObject":{"namespace":"","name":"Node/pach-control-plane"},"reason":"Starting","source.component":"kubelet","source.host":"pach-control-plane","firstTimestamp":1714065821,"lastTimestamp":1714065821,"count":1,"reportingController":"kubelet","reportingInstance":"pach-control-plane"}}
{"level":"info","ts":1714068522.9043667,"logger":"event","caller":"kube-event-tail/main.go:98","msg":"Node pach-control-plane status is now: NodeHasSufficientMemory","event":{"namespace":"default","name":"pach-control-plane.17c995c89295f4a5","involvedObject":{"namespace":"","name":"Node/pach-control-plane"},"reason":"NodeHasSufficientMemory","source.component":"kubelet","source.host":"pach-control-plane","firstTimestamp":1714065821,"lastTimestamp":1714065821,"count":8,"reportingController":"kubelet","reportingInstance":"pach-control-plane"}}
{"level":"info","ts":1714068522.904372,"logger":"event","caller":"kube-event-tail/main.go:98","msg":"Node pach-control-plane status is now: NodeHasNoDiskPressure","event":{"namespace":"default","name":"pach-control-plane.17c995c8929607c9","involvedObject":{"namespace":"","name":"Node/pach-control-plane"},"reason":"NodeHasNoDiskPressure","source.component":"kubelet","source.host":"pach-control-plane","firstTimestamp":1714065821,"lastTimestamp":1714065821,"count":8,"reportingController":"kubelet","reportingInstance":"pach-control-plane"}}
{"level":"info","ts":1714068522.904377,"logger":"event","caller":"kube-event-tail/main.go:98","msg":"Node pach-control-plane status is now: NodeHasSufficientPID","event":{"namespace":"default","name":"pach-control-plane.17c995c89296131d","involvedObject":{"namespace":"","name":"Node/pach-control-plane"},"reason":"NodeHasSufficientPID","source.component":"kubelet","source.host":"pach-control-plane","firstTimestamp":1714065821,"lastTimestamp":1714065821,"count":7,"reportingController":"kubelet","reportingInstance":"pach-control-plane"}}
{"level":"info","ts":1714068522.9044018,"logger":"event","caller":"kube-event-tail/main.go:98","msg":"Updated Node Allocatable limit across pods","event":{"namespace":"default","name":"pach-control-plane.17c995c8955f0b38","involvedObject":{"namespace":"","name":"Node/pach-control-plane"},"reason":"NodeAllocatableEnforced","source.component":"kubelet","source.host":"pach-control-plane","firstTimestamp":1714065821,"lastTimestamp":1714065821,"count":1,"reportingController":"kubelet","reportingInstance":"pach-control-plane"}}
{"level":"info","ts":1714068522.9044108,"logger":"event","caller":"kube-event-tail/main.go:98","msg":"Starting kubelet.","event":{"namespace":"default","name":"pach-control-plane.17c995ca878f0e2f","involvedObject":{"namespace":"","name":"Node/pach-control-plane"},"reason":"Starting","source.component":"kubelet","source.host":"pach-control-plane","firstTimestamp":1714065830,"lastTimestamp":1714065830,"count":1,"reportingController":"kubelet","reportingInstance":"pach-control-plane"}}
{"level":"info","ts":1714068522.9044158,"logger":"event","caller":"kube-event-tail/main.go:98","msg":"Updated Node Allocatable limit across pods","event":{"namespace":"default","name":"pach-control-plane.17c995ca8a6c8422","involvedObject":{"namespace":"","name":"Node/pach-control-plane"},"reason":"NodeAllocatableEnforced","source.component":"kubelet","source.host":"pach-control-plane","firstTimestamp":1714065830,"lastTimestamp":1714065830,"count":1,"reportingController":"kubelet","reportingInstance":"pach-control-plane"}}
{"level":"info","ts":1714068522.9044204,"logger":"event","caller":"kube-event-tail/main.go:98","msg":"Node pach-control-plane status is now: NodeHasSufficientMemory","event":{"namespace":"default","name":"pach-control-plane.17c995ca8dc838e9","involvedObject":{"namespace":"","name":"Node/pach-control-plane"},"reason":"NodeHasSufficientMemory","source.component":"kubelet","source.host":"pach-control-plane","firstTimestamp":1714065830,"lastTimestamp":1714065830,"count":1,"reportingController":"kubelet","reportingInstance":"pach-control-plane"}}
{"level":"info","ts":1714068522.9044251,"logger":"event","caller":"kube-event-tail/main.go:98","msg":"Node pach-control-plane status is now: NodeHasNoDiskPressure","event":{"namespace":"default","name":"pach-control-plane.17c995ca8dc8a00a","involvedObject":{"namespace":"","name":"Node/pach-control-plane"},"reason":"NodeHasNoDiskPressure","source.component":"kubelet","source.host":"pach-control-plane","firstTimestamp":1714065830,"lastTimestamp":1714065830,"count":1,"reportingController":"kubelet","reportingInstance":"pach-control-plane"}}
{"level":"info","ts":1714068522.90443,"logger":"event","caller":"kube-event-tail/main.go:98","msg":"Node pach-control-plane status is now: NodeHasSufficientPID","event":{"namespace":"default","name":"pach-control-plane.17c995ca8dc8b13a","involvedObject":{"namespace":"","name":"Node/pach-control-plane"},"reason":"NodeHasSufficientPID","source.component":"kubelet","source.host":"pach-control-plane","firstTimestamp":1714065830,"lastTimestamp":1714065830,"count":1,"reportingController":"kubelet","reportingInstance":"pach-control-plane"}}
{"level":"info","ts":1714068522.904435,"logger":"event","caller":"kube-event-tail/main.go:98","msg":"Node pach-control-plane event: Registered Node pach-control-plane in Controller","event":{"namespace":"default","name":"pach-control-plane.17c995cd74245ec8","involvedObject":{"namespace":"","name":"Node/pach-control-plane"},"reason":"RegisteredNode","source.component":"node-controller","firstTimestamp":1714065842,"lastTimestamp":1714065842,"count":1,"reportingController":"node-controller"}}
{"level":"info","ts":1714068522.9044435,"logger":"event","caller":"kube-event-tail/main.go:98","msg":"event without message","event":{"namespace":"default","name":"pach-control-plane.17c995cdd74267d2","involvedObject":{"namespace":"","name":"Node/pach-control-plane"},"reason":"Starting","eventTime":1714065844.5034711,"action":"StartKubeProxy","reportingController":"kube-proxy","reportingInstance":"kube-proxy-pach-control-plane"}}
{"level":"info","ts":1714068522.9044483,"logger":"event","caller":"kube-event-tail/main.go:98","msg":"Node pach-control-plane status is now: NodeReady","event":{"namespace":"default","name":"pach-control-plane.17c995ce23d402b0","involvedObject":{"namespace":"","name":"Node/pach-control-plane"},"reason":"NodeReady","source.component":"kubelet","source.host":"pach-control-plane","firstTimestamp":1714065845,"lastTimestamp":1714065845,"count":1,"reportingController":"kubelet","reportingInstance":"pach-control-plane"}}
{"level":"info","ts":1714068522.9044533,"logger":"event","caller":"kube-event-tail/main.go:98","msg":"Successfully assigned default/pachd-5bdcfbd65b-m96lx to pach-control-plane","event":{"namespace":"default","name":"pachd-5bdcfbd65b-m96lx.17c996dd51b65125","involvedObject":{"name":"Pod/pachd-5bdcfbd65b-m96lx"},"reason":"Scheduled","source.component":"default-scheduler","firstTimestamp":1714067010,"lastTimestamp":1714067010,"count":1,"reportingController":"default-scheduler"}}
{"level":"info","ts":1714068522.9044583,"logger":"event","caller":"kube-event-tail/main.go:98","msg":"Pulling image \"localhost:5001/pachd:22f229cb51e294acfd461f8b751e2937cfc2054a080f5a6a5a74f4028c495dec\"","event":{"namespace":"default","name":"pachd-5bdcfbd65b-m96lx.17c996dd6c118cd6","involvedObject":{"name":"Pod/pachd-5bdcfbd65b-m96lx","fieldPath":"spec.containers{pachd}"},"reason":"Pulling","source.component":"kubelet","source.host":"pach-control-plane","firstTimestamp":1714067010,"lastTimestamp":1714067010,"count":1,"reportingController":"kubelet","reportingInstance":"pach-control-plane"}}
{"level":"info","ts":1714068522.904463,"logger":"event","caller":"kube-event-tail/main.go:98","msg":"Successfully pulled image \"localhost:5001/pachd:22f229cb51e294acfd461f8b751e2937cfc2054a080f5a6a5a74f4028c495dec\" in 740ms (3.696s including waiting)","event":{"namespace":"default","name":"pachd-5bdcfbd65b-m96lx.17c996de4867ce66","involvedObject":{"name":"Pod/pachd-5bdcfbd65b-m96lx","fieldPath":"spec.containers{pachd}"},"reason":"Pulled","source.component":"kubelet","source.host":"pach-control-plane","firstTimestamp":1714067014,"lastTimestamp":1714067014,"count":1,"reportingController":"kubelet","reportingInstance":"pach-control-plane"}}
{"level":"info","ts":1714068522.9044688,"logger":"event","caller":"kube-event-tail/main.go:98","msg":"Created container pachd","event":{"namespace":"default","name":"pachd-5bdcfbd65b-m96lx.17c996de4b6d8161","involvedObject":{"name":"Pod/pachd-5bdcfbd65b-m96lx","fieldPath":"spec.containers{pachd}"},"reason":"Created","source.component":"kubelet","source.host":"pach-control-plane","firstTimestamp":1714067014,"lastTimestamp":1714067014,"count":1,"reportingController":"kubelet","reportingInstance":"pach-control-plane"}}
{"level":"info","ts":1714068522.9044735,"logger":"event","caller":"kube-event-tail/main.go:98","msg":"Started container pachd","event":{"namespace":"default","name":"pachd-5bdcfbd65b-m96lx.17c996de523b702c","involvedObject":{"name":"Pod/pachd-5bdcfbd65b-m96lx","fieldPath":"spec.containers{pachd}"},"reason":"Started","source.component":"kubelet","source.host":"pach-control-plane","firstTimestamp":1714067014,"lastTimestamp":1714067014,"count":1,"reportingController":"kubelet","reportingInstance":"pach-control-plane"}}
{"level":"info","ts":1714068522.9044812,"logger":"event","caller":"kube-event-tail/main.go:98","msg":"Created pod: pachd-5bdcfbd65b-m96lx","event":{"namespace":"default","name":"pachd-5bdcfbd65b.17c996dd51180cea","involvedObject":{"name":"ReplicaSet/pachd-5bdcfbd65b"},"reason":"SuccessfulCreate","source.component":"replicaset-controller","firstTimestamp":1714067010,"lastTimestamp":1714067010,"count":1,"reportingController":"replicaset-controller"}}
{"level":"info","ts":1714068522.9044864,"logger":"event","caller":"kube-event-tail/main.go:98","msg":"0/1 nodes are available: 1 node(s) had untolerated taint {node.kubernetes.io/not-ready: }. preemption: 0/1 nodes are available: 1 Preemption is not helpful for scheduling.","event":{"namespace":"default","name":"pachd-7cbd956bd-nqqsj.17c995ce1b3de680","involvedObject":{"name":"Pod/pachd-7cbd956bd-nqqsj"},"reason":"FailedScheduling","source.component":"default-scheduler","firstTimestamp":1714065845,"lastTimestamp":1714065845,"count":1,"reportingController":"default-scheduler","type":"Warning"}}
{"level":"info","ts":1714068522.9045117,"logger":"event","caller":"kube-event-tail/main.go:98","msg":"Successfully assigned default/pachd-7cbd956bd-nqqsj to pach-control-plane","event":{"namespace":"default","name":"pachd-7cbd956bd-nqqsj.17c995ce891f44d9","involvedObject":{"name":"Pod/pachd-7cbd956bd-nqqsj"},"reason":"Scheduled","source.component":"default-scheduler","firstTimestamp":1714065847,"lastTimestamp":1714065847,"count":1,"reportingController":"default-scheduler"}}
{"level":"info","ts":1714068522.9045208,"logger":"event","caller":"kube-event-tail/main.go:98","msg":"Pulling image \"localhost:5001/pachd:1bf46d7c60913e30814d1b58decdb3c63bef0f10b4177019cdb5cc872460f2f9\"","event":{"namespace":"default","name":"pachd-7cbd956bd-nqqsj.17c995ceb5885fcd","involvedObject":{"name":"Pod/pachd-7cbd956bd-nqqsj","fieldPath":"spec.containers{pachd}"},"reason":"Pulling","source.component":"kubelet","source.host":"pach-control-plane","firstTimestamp":1714065848,"lastTimestamp":1714065848,"count":1,"reportingController":"kubelet","reportingInstance":"pach-control-plane"}}
{"level":"info","ts":1714068522.9045272,"logger":"event","caller":"kube-event-tail/main.go:98","msg":"Successfully pulled image \"localhost:5001/pachd:1bf46d7c60913e30814d1b58decdb3c63bef0f10b4177019cdb5cc872460f2f9\" in 879ms (6.487s including waiting)","event":{"namespace":"default","name":"pachd-7cbd956bd-nqqsj.17c995d0383bfdb0","involvedObject":{"name":"Pod/pachd-7cbd956bd-nqqsj","fieldPath":"spec.containers{pachd}"},"reason":"Pulled","source.component":"kubelet","source.host":"pach-control-plane","firstTimestamp":1714065854,"lastTimestamp":1714065854,"count":1,"reportingController":"kubelet","reportingInstance":"pach-control-plane"}}
{"level":"info","ts":1714068522.9045346,"logger":"event","caller":"kube-event-tail/main.go:98","msg":"Created container pachd","event":{"namespace":"default","name":"pachd-7cbd956bd-nqqsj.17c995d03ad206c5","involvedObject":{"name":"Pod/pachd-7cbd956bd-nqqsj","fieldPath":"spec.containers{pachd}"},"reason":"Created","source.component":"kubelet","source.host":"pach-control-plane","firstTimestamp":1714065854,"lastTimestamp":1714065952,"ongoingDuration":98,"count":4,"reportingController":"kubelet","reportingInstance":"pach-control-plane"}}
{"level":"info","ts":1714068522.9045393,"logger":"event","caller":"kube-event-tail/main.go:98","msg":"Started container pachd","event":{"namespace":"default","name":"pachd-7cbd956bd-nqqsj.17c995d0417c19c9","involvedObject":{"name":"Pod/pachd-7cbd956bd-nqqsj","fieldPath":"spec.containers{pachd}"},"reason":"Started","source.component":"kubelet","source.host":"pach-control-plane","firstTimestamp":1714065854,"lastTimestamp":1714065952,"ongoingDuration":98,"count":4,"reportingController":"kubelet","reportingInstance":"pach-control-plane"}}
{"level":"info","ts":1714068522.9045444,"logger":"event","caller":"kube-event-tail/main.go:98","msg":"Startup probe failed: command \"/pachd --readiness\" timed out","event":{"namespace":"default","name":"pachd-7cbd956bd-nqqsj.17c995d7f1b76676","involvedObject":{"name":"Pod/pachd-7cbd956bd-nqqsj","fieldPath":"spec.containers{pachd}"},"reason":"Unhealthy","source.component":"kubelet","source.host":"pach-control-plane","firstTimestamp":1714065887,"lastTimestamp":1714065887,"count":1,"reportingController":"kubelet","reportingInstance":"pach-control-plane","type":"Warning"}}
{"level":"info","ts":1714068522.9045494,"logger":"event","caller":"kube-event-tail/main.go:98","msg":"Startup probe failed: {\"severity\":\"debug\",\"time\":\"2024-04-25T17:24:48.016828919Z\",\"logger\":\"serviceenv\",\"caller\":\"serviceenv/service_env.go:164\",\"message\":\"serviceenv: span start\"}\n{\"severity\":\"debug\",\"time\":\"2024-04-25T17:24:48.016982324Z\",\"logger\":\"serviceenv.initPachClient\",\"caller\":\"serviceenv/service_env.go:255\",\"message\":\"initPachClient: span start\"}\n{\"severity\":\"debug\",\"time\":\"2024-04-25T17:24:58.01800542Z\",\"caller\":\"proc/proc.go:203\",\"message\":\"meter: system_cpu_time_seconds\",\"type\":\"float\",\"value\":6490248.76,\"meter\":\"system_cpu_time_seconds\"}\n","event":{"namespace":"default","name":"pachd-7cbd956bd-nqqsj.17c995dccada320b","involvedObject":{"name":"Pod/pachd-7cbd956bd-nqqsj","fieldPath":"spec.containers{pachd}"},"reason":"Unhealthy","source.component":"kubelet","source.host":"pach-control-plane","firstTimestamp":1714065908,"lastTimestamp":1714065908,"count":1,"reportingController":"kubelet","reportingInstance":"pach-control-plane","type":"Warning"}}
{"level":"info","ts":1714068522.9045575,"logger":"event","caller":"kube-event-tail/main.go:98","msg":"Startup probe errored: rpc error: code = NotFound desc = failed to exec in container: failed to load task: no running task found: task cc233468ffdbd0a4cee4c1757038cef80cdac26f91fb3ad3695c050b2bb5fc62 not found: not found","event":{"namespace":"default","name":"pachd-7cbd956bd-nqqsj.17c995dd35804c21","involvedObject":{"name":"Pod/pachd-7cbd956bd-nqqsj","fieldPath":"spec.containers{pachd}"},"reason":"Unhealthy","source.component":"kubelet","source.host":"pach-control-plane","firstTimestamp":1714065910,"lastTimestamp":1714065910,"count":1,"reportingController":"kubelet","reportingInstance":"pach-control-plane","type":"Warning"}}
{"level":"info","ts":1714068522.9045634,"logger":"event","caller":"kube-event-tail/main.go:98","msg":"Container image \"localhost:5001/pachd:1bf46d7c60913e30814d1b58decdb3c63bef0f10b4177019cdb5cc872460f2f9\" already present on machine","event":{"namespace":"default","name":"pachd-7cbd956bd-nqqsj.17c995dd70295fdd","involvedObject":{"name":"Pod/pachd-7cbd956bd-nqqsj","fieldPath":"spec.containers{pachd}"},"reason":"Pulled","source.component":"kubelet","source.host":"pach-control-plane","firstTimestamp":1714065911,"lastTimestamp":1714065952,"ongoingDuration":41,"count":3,"reportingController":"kubelet","reportingInstance":"pach-control-plane"}}
{"level":"info","ts":1714068522.9045844,"logger":"event","caller":"kube-event-tail/main.go:98","msg":"Back-off restarting failed container pachd in pod pachd-7cbd956bd-nqqsj_default(e18b4ae5-8d48-4b22-b019-c03adcb56567)","event":{"namespace":"default","name":"pachd-7cbd956bd-nqqsj.17c995ddabf40d84","involvedObject":{"name":"Pod/pachd-7cbd956bd-nqqsj","fieldPath":"spec.containers{pachd}"},"reason":"BackOff","source.component":"kubelet","source.host":"pach-control-plane","firstTimestamp":1714065912,"lastTimestamp":1714066458,"ongoingDuration":546,"count":52,"reportingController":"kubelet","reportingInstance":"pach-control-plane","type":"Warning"}}
{"level":"info","ts":1714068522.9045944,"logger":"event","caller":"kube-event-tail/main.go:98","msg":"Created pod: pachd-7cbd956bd-nqqsj","event":{"namespace":"default","name":"pachd-7cbd956bd.17c995ce1922048f","involvedObject":{"name":"ReplicaSet/pachd-7cbd956bd"},"reason":"SuccessfulCreate","source.component":"replicaset-controller","firstTimestamp":1714065845,"lastTimestamp":1714065845,"count":1,"reportingController":"replicaset-controller"}}
{"level":"info","ts":1714068522.904599,"logger":"event","caller":"kube-event-tail/main.go:98","msg":"Deleted pod: pachd-7cbd956bd-nqqsj","event":{"namespace":"default","name":"pachd-7cbd956bd.17c99695878c83c3","involvedObject":{"name":"ReplicaSet/pachd-7cbd956bd"},"reason":"SuccessfulDelete","source.component":"replicaset-controller","firstTimestamp":1714066702,"lastTimestamp":1714066702,"count":1,"reportingController":"replicaset-controller"}}
{"level":"info","ts":1714068522.9046037,"logger":"event","caller":"kube-event-tail/main.go:98","msg":"Successfully assigned default/pachd-d868b489c-7s5xp to pach-control-plane","event":{"namespace":"default","name":"pachd-d868b489c-7s5xp.17c99693093a9c75","involvedObject":{"name":"Pod/pachd-d868b489c-7s5xp"},"reason":"Scheduled","source.component":"default-scheduler","firstTimestamp":1714066691,"lastTimestamp":1714066691,"count":1,"reportingController":"default-scheduler"}}
{"level":"info","ts":1714068522.9046078,"logger":"event","caller":"kube-event-tail/main.go:98","msg":"Pulling image \"localhost:5001/pachd:81d74ab385fe002f0ca96b9b75509cb8f0ba65cf73262f4d020ecd2fc736c917\"","event":{"namespace":"default","name":"pachd-d868b489c-7s5xp.17c9969321dd2b38","involvedObject":{"name":"Pod/pachd-d868b489c-7s5xp","fieldPath":"spec.containers{pachd}"},"reason":"Pulling","source.component":"kubelet","source.host":"pach-control-plane","firstTimestamp":1714066691,"lastTimestamp":1714066691,"count":1,"reportingController":"kubelet","reportingInstance":"pach-control-plane"}}
{"level":"info","ts":1714068522.9046128,"logger":"event","caller":"kube-event-tail/main.go:98","msg":"Successfully pulled image \"localhost:5001/pachd:81d74ab385fe002f0ca96b9b75509cb8f0ba65cf73262f4d020ecd2fc736c917\" in 758ms (758ms including waiting)","event":{"namespace":"default","name":"pachd-d868b489c-7s5xp.17c996934f0e007b","involvedObject":{"name":"Pod/pachd-d868b489c-7s5xp","fieldPath":"spec.containers{pachd}"},"reason":"Pulled","source.component":"kubelet","source.host":"pach-control-plane","firstTimestamp":1714066692,"lastTimestamp":1714066692,"count":1,"reportingController":"kubelet","reportingInstance":"pach-control-plane"}}
{"level":"info","ts":1714068522.904618,"logger":"event","caller":"kube-event-tail/main.go:98","msg":"Created container pachd","event":{"namespace":"default","name":"pachd-d868b489c-7s5xp.17c9969352568d8e","involvedObject":{"name":"Pod/pachd-d868b489c-7s5xp","fieldPath":"spec.containers{pachd}"},"reason":"Created","source.component":"kubelet","source.host":"pach-control-plane","firstTimestamp":1714066692,"lastTimestamp":1714066692,"count":1,"reportingController":"kubelet","reportingInstance":"pach-control-plane"}}
{"level":"info","ts":1714068522.9046252,"logger":"event","caller":"kube-event-tail/main.go:98","msg":"Started container pachd","event":{"namespace":"default","name":"pachd-d868b489c-7s5xp.17c9969359c9242a","involvedObject":{"name":"Pod/pachd-d868b489c-7s5xp","fieldPath":"spec.containers{pachd}"},"reason":"Started","source.component":"kubelet","source.host":"pach-control-plane","firstTimestamp":1714066692,"lastTimestamp":1714066692,"count":1,"reportingController":"kubelet","reportingInstance":"pach-control-plane"}}
{"level":"info","ts":1714068522.9046297,"logger":"event","caller":"kube-event-tail/main.go:98","msg":"Stopping container pachd","event":{"namespace":"default","name":"pachd-d868b489c-7s5xp.17c996dfe5c45e32","involvedObject":{"name":"Pod/pachd-d868b489c-7s5xp","fieldPath":"spec.containers{pachd}"},"reason":"Killing","source.component":"kubelet","source.host":"pach-control-plane","firstTimestamp":1714067021,"lastTimestamp":1714067021,"count":1,"reportingController":"kubelet","reportingInstance":"pach-control-plane"}}
{"level":"info","ts":1714068522.9046504,"logger":"event","caller":"kube-event-tail/main.go:98","msg":"Readiness probe failed: command \"/pachd --readiness\" timed out","event":{"namespace":"default","name":"pachd-d868b489c-7s5xp.17c996e030ac8d55","involvedObject":{"name":"Pod/pachd-d868b489c-7s5xp","fieldPath":"spec.containers{pachd}"},"reason":"Unhealthy","source.component":"kubelet","source.host":"pach-control-plane","firstTimestamp":1714067022,"lastTimestamp":1714067022,"count":1,"reportingController":"kubelet","reportingInstance":"pach-control-plane","type":"Warning"}}
{"level":"info","ts":1714068522.9046605,"logger":"event","caller":"kube-event-tail/main.go:98","msg":"Readiness probe errored: rpc error: code = NotFound desc = failed to exec in container: failed to load task: no running task found: task f5988f204e341450fd28e563c703c160d4c42e37fb190fb226c4d17190cebd9b not found: not found","event":{"namespace":"default","name":"pachd-d868b489c-7s5xp.17c996e25d55d387","involvedObject":{"name":"Pod/pachd-d868b489c-7s5xp","fieldPath":"spec.containers{pachd}"},"reason":"Unhealthy","source.component":"kubelet","source.host":"pach-control-plane","firstTimestamp":1714067032,"lastTimestamp":1714067032,"count":1,"reportingController":"kubelet","reportingInstance":"pach-control-plane","type":"Warning"}}
{"level":"info","ts":1714068522.9046662,"logger":"event","caller":"kube-event-tail/main.go:98","msg":"Created pod: pachd-d868b489c-7s5xp","event":{"namespace":"default","name":"pachd-d868b489c.17c996930899a275","involvedObject":{"name":"ReplicaSet/pachd-d868b489c"},"reason":"SuccessfulCreate","source.component":"replicaset-controller","firstTimestamp":1714066691,"lastTimestamp":1714066691,"count":1,"reportingController":"replicaset-controller"}}
{"level":"info","ts":1714068522.9046707,"logger":"event","caller":"kube-event-tail/main.go:98","msg":"Deleted pod: pachd-d868b489c-7s5xp","event":{"namespace":"default","name":"pachd-d868b489c.17c996dfe5a80c68","involvedObject":{"name":"ReplicaSet/pachd-d868b489c"},"reason":"SuccessfulDelete","source.component":"replicaset-controller","firstTimestamp":1714067021,"lastTimestamp":1714067021,"count":1,"reportingController":"replicaset-controller"}}
{"level":"info","ts":1714068522.9046822,"logger":"event","caller":"kube-event-tail/main.go:98","msg":"Scaled up replica set pachd-7cbd956bd to 1","event":{"namespace":"default","name":"pachd.17c995ce18283be3","involvedObject":{"name":"Deployment/pachd"},"reason":"ScalingReplicaSet","source.component":"deployment-controller","firstTimestamp":1714065845,"lastTimestamp":1714065845,"count":1,"reportingController":"deployment-controller"}}
{"level":"info","ts":1714068522.9046867,"logger":"event","caller":"kube-event-tail/main.go:98","msg":"Scaled up replica set pachd-d868b489c to 1","event":{"namespace":"default","name":"pachd.17c9969307d3d0fa","involvedObject":{"name":"Deployment/pachd"},"reason":"ScalingReplicaSet","source.component":"deployment-controller","firstTimestamp":1714066691,"lastTimestamp":1714066691,"count":1,"reportingController":"deployment-controller"}}
{"level":"info","ts":1714068522.9046912,"logger":"event","caller":"kube-event-tail/main.go:98","msg":"Scaled down replica set pachd-7cbd956bd to 0 from 1","event":{"namespace":"default","name":"pachd.17c9969586b758e4","involvedObject":{"name":"Deployment/pachd"},"reason":"ScalingReplicaSet","source.component":"deployment-controller","firstTimestamp":1714066702,"lastTimestamp":1714066702,"count":1,"reportingController":"deployment-controller"}}
{"level":"info","ts":1714068522.9046955,"logger":"event","caller":"kube-event-tail/main.go:98","msg":"Scaled up replica set pachd-5bdcfbd65b to 1","event":{"namespace":"default","name":"pachd.17c996dd50848b0c","involvedObject":{"name":"Deployment/pachd"},"reason":"ScalingReplicaSet","source.component":"deployment-controller","firstTimestamp":1714067010,"lastTimestamp":1714067010,"count":1,"reportingController":"deployment-controller"}}
{"level":"info","ts":1714068522.9047008,"logger":"event","caller":"kube-event-tail/main.go:98","msg":"Scaled down replica set pachd-d868b489c to 0 from 1","event":{"namespace":"default","name":"pachd.17c996dfe5266367","involvedObject":{"name":"Deployment/pachd"},"reason":"ScalingReplicaSet","source.component":"deployment-controller","firstTimestamp":1714067021,"lastTimestamp":1714067021,"count":1,"reportingController":"deployment-controller"}}
{"level":"info","ts":1714068522.904705,"logger":"event","caller":"kube-event-tail/main.go:98","msg":"Successfully assigned default/pachw-6f8fb9fd9c-gg69j to pach-control-plane","event":{"namespace":"default","name":"pachw-6f8fb9fd9c-gg69j.17c996e8a1455632","involvedObject":{"name":"Pod/pachw-6f8fb9fd9c-gg69j"},"reason":"Scheduled","source.component":"default-scheduler","firstTimestamp":1714067059,"lastTimestamp":1714067059,"count":1,"reportingController":"default-scheduler"}}
{"level":"info","ts":1714068522.9047098,"logger":"event","caller":"kube-event-tail/main.go:98","msg":"Container image \"localhost:5001/pachd:22f229cb51e294acfd461f8b751e2937cfc2054a080f5a6a5a74f4028c495dec\" already present on machine","event":{"namespace":"default","name":"pachw-6f8fb9fd9c-gg69j.17c996e8bc2a08fd","involvedObject":{"name":"Pod/pachw-6f8fb9fd9c-gg69j","fieldPath":"spec.containers{pachw}"},"reason":"Pulled","source.component":"kubelet","source.host":"pach-control-plane","firstTimestamp":1714067059,"lastTimestamp":1714067059,"count":1,"reportingController":"kubelet","reportingInstance":"pach-control-plane"}}
{"level":"info","ts":1714068522.904715,"logger":"event","caller":"kube-event-tail/main.go:98","msg":"Created container pachw","event":{"namespace":"default","name":"pachw-6f8fb9fd9c-gg69j.17c996e8bf49edfe","involvedObject":{"name":"Pod/pachw-6f8fb9fd9c-gg69j","fieldPath":"spec.containers{pachw}"},"reason":"Created","source.component":"kubelet","source.host":"pach-control-plane","firstTimestamp":1714067059,"lastTimestamp":1714067059,"count":1,"reportingController":"kubelet","reportingInstance":"pach-control-plane"}}
{"level":"info","ts":1714068522.9047198,"logger":"event","caller":"kube-event-tail/main.go:98","msg":"Started container pachw","event":{"namespace":"default","name":"pachw-6f8fb9fd9c-gg69j.17c996e8c6847dac","involvedObject":{"name":"Pod/pachw-6f8fb9fd9c-gg69j","fieldPath":"spec.containers{pachw}"},"reason":"Started","source.component":"kubelet","source.host":"pach-control-plane","firstTimestamp":1714067059,"lastTimestamp":1714067059,"count":1,"reportingController":"kubelet","reportingInstance":"pach-control-plane"}}
{"level":"info","ts":1714068522.9047413,"logger":"event","caller":"kube-event-tail/main.go:98","msg":"Stopping container pachw","event":{"namespace":"default","name":"pachw-6f8fb9fd9c-gg69j.17c996f697af952d","involvedObject":{"name":"Pod/pachw-6f8fb9fd9c-gg69j","fieldPath":"spec.containers{pachw}"},"reason":"Killing","source.component":"kubelet","source.host":"pach-control-plane","firstTimestamp":1714067119,"lastTimestamp":1714067119,"count":1,"reportingController":"kubelet","reportingInstance":"pach-control-plane"}}
{"level":"info","ts":1714068522.9047582,"logger":"event","caller":"kube-event-tail/main.go:98","msg":"Created pod: pachw-6f8fb9fd9c-gg69j","event":{"namespace":"default","name":"pachw-6f8fb9fd9c.17c996e8a05e8b7e","involvedObject":{"name":"ReplicaSet/pachw-6f8fb9fd9c"},"reason":"SuccessfulCreate","source.component":"replicaset-controller","firstTimestamp":1714067059,"lastTimestamp":1714067059,"count":1,"reportingController":"replicaset-controller"}}
{"level":"info","ts":1714068522.9047625,"logger":"event","caller":"kube-event-tail/main.go:98","msg":"Deleted pod: pachw-6f8fb9fd9c-gg69j","event":{"namespace":"default","name":"pachw-6f8fb9fd9c.17c996f697ac7e24","involvedObject":{"name":"ReplicaSet/pachw-6f8fb9fd9c"},"reason":"SuccessfulDelete","source.component":"replicaset-controller","firstTimestamp":1714067119,"lastTimestamp":1714067119,"count":1,"reportingController":"replicaset-controller"}}
{"level":"info","ts":1714068522.904767,"logger":"event","caller":"kube-event-tail/main.go:98","msg":"Scaled up replica set pachw-6f8fb9fd9c to 1 from 0","event":{"namespace":"default","name":"pachw.17c996e89f19d0ef","involvedObject":{"name":"Deployment/pachw"},"reason":"ScalingReplicaSet","source.component":"deployment-controller","firstTimestamp":1714067059,"lastTimestamp":1714067059,"count":1,"reportingController":"deployment-controller"}}
{"level":"info","ts":1714068522.904771,"logger":"event","caller":"kube-event-tail/main.go:98","msg":"Scaled down replica set pachw-6f8fb9fd9c to 0 from 1","event":{"namespace":"default","name":"pachw.17c996f696d371e2","involvedObject":{"name":"Deployment/pachw"},"reason":"ScalingReplicaSet","source.component":"deployment-controller","firstTimestamp":1714067119,"lastTimestamp":1714067119,"count":1,"reportingController":"deployment-controller"}}
{"level":"info","ts":1714068522.9047754,"logger":"event","caller":"kube-event-tail/main.go:98","msg":"0/1 nodes are available: 1 node(s) had untolerated taint {node.kubernetes.io/not-ready: }. preemption: 0/1 nodes are available: 1 Preemption is not helpful for scheduling.","event":{"namespace":"default","name":"pachyderm-kube-event-tail-7d7764b7c6-dlqgb.17c995ce18240fe3","involvedObject":{"name":"Pod/pachyderm-kube-event-tail-7d7764b7c6-dlqgb"},"reason":"FailedScheduling","source.component":"default-scheduler","firstTimestamp":1714065845,"lastTimestamp":1714065845,"count":1,"reportingController":"default-scheduler","type":"Warning"}}
{"level":"info","ts":1714068522.9047828,"logger":"event","caller":"kube-event-tail/main.go:98","msg":"Successfully assigned default/pachyderm-kube-event-tail-7d7764b7c6-dlqgb to pach-control-plane","event":{"namespace":"default","name":"pachyderm-kube-event-tail-7d7764b7c6-dlqgb.17c995ce891b9bb6","involvedObject":{"name":"Pod/pachyderm-kube-event-tail-7d7764b7c6-dlqgb"},"reason":"Scheduled","source.component":"default-scheduler","firstTimestamp":1714065847,"lastTimestamp":1714065847,"count":1,"reportingController":"default-scheduler"}}
{"level":"info","ts":1714068522.9047878,"logger":"event","caller":"kube-event-tail/main.go:98","msg":"Pulling image \"pachyderm/kube-event-tail:v0.0.7\"","event":{"namespace":"default","name":"pachyderm-kube-event-tail-7d7764b7c6-dlqgb.17c995ceb673275b","involvedObject":{"name":"Pod/pachyderm-kube-event-tail-7d7764b7c6-dlqgb","fieldPath":"spec.containers{kube-event-tail}"},"reason":"Pulling","source.component":"kubelet","source.host":"pach-control-plane","firstTimestamp":1714065848,"lastTimestamp":1714065848,"count":1,"reportingController":"kubelet","reportingInstance":"pach-control-plane"}}
{"level":"info","ts":1714068522.9047925,"logger":"event","caller":"kube-event-tail/main.go:98","msg":"Successfully pulled image \"pachyderm/kube-event-tail:v0.0.7\" in 1.378s (14s including waiting)","event":{"namespace":"default","name":"pachyderm-kube-event-tail-7d7764b7c6-dlqgb.17c995d1f8f8cb12","involvedObject":{"name":"Pod/pachyderm-kube-event-tail-7d7764b7c6-dlqgb","fieldPath":"spec.containers{kube-event-tail}"},"reason":"Pulled","source.component":"kubelet","source.host":"pach-control-plane","firstTimestamp":1714065862,"lastTimestamp":1714065862,"count":1,"reportingController":"kubelet","reportingInstance":"pach-control-plane"}}
{"level":"info","ts":1714068522.9047976,"logger":"event","caller":"kube-event-tail/main.go:98","msg":"Created container kube-event-tail","event":{"namespace":"default","name":"pachyderm-kube-event-tail-7d7764b7c6-dlqgb.17c995d1fb4c443f","involvedObject":{"name":"Pod/pachyderm-kube-event-tail-7d7764b7c6-dlqgb","fieldPath":"spec.containers{kube-event-tail}"},"reason":"Created","source.component":"kubelet","source.host":"pach-control-plane","firstTimestamp":1714065862,"lastTimestamp":1714065862,"count":1,"reportingController":"kubelet","reportingInstance":"pach-control-plane"}}
{"level":"info","ts":1714068522.9048023,"logger":"event","caller":"kube-event-tail/main.go:98","msg":"Started container kube-event-tail","event":{"namespace":"default","name":"pachyderm-kube-event-tail-7d7764b7c6-dlqgb.17c995d201a459a4","involvedObject":{"name":"Pod/pachyderm-kube-event-tail-7d7764b7c6-dlqgb","fieldPath":"spec.containers{kube-event-tail}"},"reason":"Started","source.component":"kubelet","source.host":"pach-control-plane","firstTimestamp":1714065862,"lastTimestamp":1714065862,"count":1,"reportingController":"kubelet","reportingInstance":"pach-control-plane"}}
{"level":"info","ts":1714068522.904807,"logger":"event","caller":"kube-event-tail/main.go:98","msg":"Created pod: pachyderm-kube-event-tail-7d7764b7c6-dlqgb","event":{"namespace":"default","name":"pachyderm-kube-event-tail-7d7764b7c6.17c995ce16b0c616","involvedObject":{"name":"ReplicaSet/pachyderm-kube-event-tail-7d7764b7c6"},"reason":"SuccessfulCreate","source.component":"replicaset-controller","firstTimestamp":1714065845,"lastTimestamp":1714065845,"count":1,"reportingController":"replicaset-controller"}}
{"level":"info","ts":1714068522.9048135,"logger":"event","caller":"kube-event-tail/main.go:98","msg":"Scaled up replica set pachyderm-kube-event-tail-7d7764b7c6 to 1","event":{"namespace":"default","name":"pachyderm-kube-event-tail.17c995ce15bf174b","involvedObject":{"name":"Deployment/pachyderm-kube-event-tail"},"reason":"ScalingReplicaSet","source.component":"deployment-controller","firstTimestamp":1714065845,"lastTimestamp":1714065845,"count":1,"reportingController":"deployment-controller"}}
{"level":"info","ts":1714068522.904818,"logger":"event","caller":"kube-event-tail/main.go:98","msg":"0/1 nodes are available: 1 node(s) had untolerated taint {node.kubernetes.io/not-ready: }. preemption: 0/1 nodes are available: 1 Preemption is not helpful for scheduling.","event":{"namespace":"default","name":"pachyderm-loki-0.17c995ce19a12d62","involvedObject":{"name":"Pod/pachyderm-loki-0"},"reason":"FailedScheduling","source.component":"default-scheduler","firstTimestamp":1714065845,"lastTimestamp":1714065845,"count":1,"reportingController":"default-scheduler","type":"Warning"}}
{"level":"info","ts":1714068522.9048398,"logger":"event","caller":"kube-event-tail/main.go:98","msg":"Successfully assigned default/pachyderm-loki-0 to pach-control-plane","event":{"namespace":"default","name":"pachyderm-loki-0.17c995cfb45bff4f","involvedObject":{"name":"Pod/pachyderm-loki-0"},"reason":"Scheduled","source.component":"default-scheduler","firstTimestamp":1714065852,"lastTimestamp":1714065852,"count":1,"reportingController":"default-scheduler"}}
{"level":"info","ts":1714068522.9048483,"logger":"event","caller":"kube-event-tail/main.go:98","msg":"Pulling image \"grafana/loki:2.6.1\"","event":{"namespace":"default","name":"pachyderm-loki-0.17c995cfd1459bfc","involvedObject":{"name":"Pod/pachyderm-loki-0","fieldPath":"spec.containers{loki}"},"reason":"Pulling","source.component":"kubelet","source.host":"pach-control-plane","firstTimestamp":1714065852,"lastTimestamp":1714065852,"count":1,"reportingController":"kubelet","reportingInstance":"pach-control-plane"}}
{"level":"info","ts":1714068522.9048536,"logger":"event","caller":"kube-event-tail/main.go:98","msg":"Successfully pulled image \"grafana/loki:2.6.1\" in 1.867s (31.754s including waiting)","event":{"namespace":"default","name":"pachyderm-loki-0.17c995d735fda647","involvedObject":{"name":"Pod/pachyderm-loki-0","fieldPath":"spec.containers{loki}"},"reason":"Pulled","source.component":"kubelet","source.host":"pach-control-plane","firstTimestamp":1714065884,"lastTimestamp":1714065884,"count":1,"reportingController":"kubelet","reportingInstance":"pach-control-plane"}}
{"level":"info","ts":1714068522.9048588,"logger":"event","caller":"kube-event-tail/main.go:98","msg":"Created container loki","event":{"namespace":"default","name":"pachyderm-loki-0.17c995d73a800a92","involvedObject":{"name":"Pod/pachyderm-loki-0","fieldPath":"spec.containers{loki}"},"reason":"Created","source.component":"kubelet","source.host":"pach-control-plane","firstTimestamp":1714065884,"lastTimestamp":1714065884,"count":1,"reportingController":"kubelet","reportingInstance":"pach-control-plane"}}
{"level":"info","ts":1714068522.904865,"logger":"event","caller":"kube-event-tail/main.go:98","msg":"Started container loki","event":{"namespace":"default","name":"pachyderm-loki-0.17c995d74098c4c8","involvedObject":{"name":"Pod/pachyderm-loki-0","fieldPath":"spec.containers{loki}"},"reason":"Started","source.component":"kubelet","source.host":"pach-control-plane","firstTimestamp":1714065884,"lastTimestamp":1714065884,"count":1,"reportingController":"kubelet","reportingInstance":"pach-control-plane"}}
{"level":"info","ts":1714068522.9048903,"logger":"event","caller":"kube-event-tail/main.go:98","msg":"Readiness probe failed: HTTP probe failed with statuscode: 503","event":{"namespace":"default","name":"pachyderm-loki-0.17c995e26754aa51","involvedObject":{"name":"Pod/pachyderm-loki-0","fieldPath":"spec.containers{loki}"},"reason":"Unhealthy","source.component":"kubelet","source.host":"pach-control-plane","firstTimestamp":1714065932,"lastTimestamp":1714065942,"ongoingDuration":10,"count":2,"reportingController":"kubelet","reportingInstance":"pach-control-plane","type":"Warning"}}
{"level":"info","ts":1714068522.9048998,"logger":"event","caller":"kube-event-tail/main.go:98","msg":"Liveness probe failed: HTTP probe failed with statuscode: 503","event":{"namespace":"default","name":"pachyderm-loki-0.17c995e26755c9d3","involvedObject":{"name":"Pod/pachyderm-loki-0","fieldPath":"spec.containers{loki}"},"reason":"Unhealthy","source.component":"kubelet","source.host":"pach-control-plane","firstTimestamp":1714065932,"lastTimestamp":1714065942,"ongoingDuration":10,"count":2,"reportingController":"kubelet","reportingInstance":"pach-control-plane","type":"Warning"}}
{"level":"info","ts":1714068522.9049053,"logger":"event","caller":"kube-event-tail/main.go:98","msg":"create Claim storage-pachyderm-loki-0 Pod pachyderm-loki-0 in StatefulSet pachyderm-loki success","event":{"namespace":"default","name":"pachyderm-loki.17c995ce175235c0","involvedObject":{"name":"StatefulSet/pachyderm-loki"},"reason":"SuccessfulCreate","source.component":"statefulset-controller","firstTimestamp":1714065845,"lastTimestamp":1714065845,"count":1,"reportingController":"statefulset-controller"}}
{"level":"info","ts":1714068522.9049103,"logger":"event","caller":"kube-event-tail/main.go:98","msg":"create Pod pachyderm-loki-0 in StatefulSet pachyderm-loki successful","event":{"namespace":"default","name":"pachyderm-loki.17c995ce17cdf905","involvedObject":{"name":"StatefulSet/pachyderm-loki"},"reason":"SuccessfulCreate","source.component":"statefulset-controller","firstTimestamp":1714065845,"lastTimestamp":1714065845,"count":1,"reportingController":"statefulset-controller"}}
{"level":"info","ts":1714068522.9049146,"logger":"event","caller":"kube-event-tail/main.go:98","msg":"Successfully assigned default/pachyderm-promtail-27cx4 to pach-control-plane","event":{"namespace":"default","name":"pachyderm-promtail-27cx4.17c995ce2646943c","involvedObject":{"name":"Pod/pachyderm-promtail-27cx4"},"reason":"Scheduled","source.component":"default-scheduler","firstTimestamp":1714065845,"lastTimestamp":1714065845,"count":1,"reportingController":"default-scheduler"}}
{"level":"info","ts":1714068522.9049194,"logger":"event","caller":"kube-event-tail/main.go:98","msg":"Pulling image \"docker.io/grafana/promtail:2.6.1\"","event":{"namespace":"default","name":"pachyderm-promtail-27cx4.17c995ce4971b596","involvedObject":{"name":"Pod/pachyderm-promtail-27cx4","fieldPath":"spec.containers{promtail}"},"reason":"Pulling","source.component":"kubelet","source.host":"pach-control-plane","firstTimestamp":1714065846,"lastTimestamp":1714065846,"count":1,"reportingController":"kubelet","reportingInstance":"pach-control-plane"}}
{"level":"info","ts":1714068522.9049242,"logger":"event","caller":"kube-event-tail/main.go:98","msg":"Successfully pulled image \"docker.io/grafana/promtail:2.6.1\" in 4.104s (5.944s including waiting)","event":{"namespace":"default","name":"pachyderm-promtail-27cx4.17c995cfabc42693","involvedObject":{"name":"Pod/pachyderm-promtail-27cx4","fieldPath":"spec.containers{promtail}"},"reason":"Pulled","source.component":"kubelet","source.host":"pach-control-plane","firstTimestamp":1714065852,"lastTimestamp":1714065852,"count":1,"reportingController":"kubelet","reportingInstance":"pach-control-plane"}}
{"level":"info","ts":1714068522.9049292,"logger":"event","caller":"kube-event-tail/main.go:98","msg":"Created container promtail","event":{"namespace":"default","name":"pachyderm-promtail-27cx4.17c995cfb0ef1f19","involvedObject":{"name":"Pod/pachyderm-promtail-27cx4","fieldPath":"spec.containers{promtail}"},"reason":"Created","source.component":"kubelet","source.host":"pach-control-plane","firstTimestamp":1714065852,"lastTimestamp":1714065852,"count":1,"reportingController":"kubelet","reportingInstance":"pach-control-plane"}}
{"level":"info","ts":1714068522.9049537,"logger":"event","caller":"kube-event-tail/main.go:98","msg":"Started container promtail","event":{"namespace":"default","name":"pachyderm-promtail-27cx4.17c995cfb76719f1","involvedObject":{"name":"Pod/pachyderm-promtail-27cx4","fieldPath":"spec.containers{promtail}"},"reason":"Started","source.component":"kubelet","source.host":"pach-control-plane","firstTimestamp":1714065852,"lastTimestamp":1714065852,"count":1,"reportingController":"kubelet","reportingInstance":"pach-control-plane"}}
{"level":"info","ts":1714068522.9049625,"logger":"event","caller":"kube-event-tail/main.go:98","msg":"Readiness probe failed: Get \"http://10.244.0.6:3101/ready\": context deadline exceeded (Client.Timeout exceeded while awaiting headers)","event":{"namespace":"default","name":"pachyderm-promtail-27cx4.17c995e36b119c6e","involvedObject":{"name":"Pod/pachyderm-promtail-27cx4","fieldPath":"spec.containers{promtail}"},"reason":"Unhealthy","source.component":"kubelet","source.host":"pach-control-plane","firstTimestamp":1714065937,"lastTimestamp":1714066027,"ongoingDuration":90,"count":11,"reportingController":"kubelet","reportingInstance":"pach-control-plane","type":"Warning"}}
{"level":"info","ts":1714068522.9049685,"logger":"event","caller":"kube-event-tail/main.go:98","msg":"Created pod: pachyderm-promtail-27cx4","event":{"namespace":"default","name":"pachyderm-promtail.17c995ce2571a694","involvedObject":{"name":"DaemonSet/pachyderm-promtail"},"reason":"SuccessfulCreate","source.component":"daemonset-controller","firstTimestamp":1714065845,"lastTimestamp":1714065845,"count":1,"reportingController":"daemonset-controller"}}
{"level":"info","ts":1714068522.9049728,"logger":"event","caller":"kube-event-tail/main.go:98","msg":"0/1 nodes are available: 1 node(s) had untolerated taint {node.kubernetes.io/not-ready: }. preemption: 0/1 nodes are available: 1 Preemption is not helpful for scheduling.","event":{"namespace":"default","name":"pachyderm-proxy-5585cd764c-64hgc.17c995ce16472afd","involvedObject":{"name":"Pod/pachyderm-proxy-5585cd764c-64hgc"},"reason":"FailedScheduling","source.component":"default-scheduler","firstTimestamp":1714065845,"lastTimestamp":1714065845,"count":1,"reportingController":"default-scheduler","type":"Warning"}}
{"level":"info","ts":1714068522.904978,"logger":"event","caller":"kube-event-tail/main.go:98","msg":"Successfully assigned default/pachyderm-proxy-5585cd764c-64hgc to pach-control-plane","event":{"namespace":"default","name":"pachyderm-proxy-5585cd764c-64hgc.17c995ce891b44fe","involvedObject":{"name":"Pod/pachyderm-proxy-5585cd764c-64hgc"},"reason":"Scheduled","source.component":"default-scheduler","firstTimestamp":1714065847,"lastTimestamp":1714065847,"count":1,"reportingController":"default-scheduler"}}
{"level":"info","ts":1714068522.9049823,"logger":"event","caller":"kube-event-tail/main.go:98","msg":"Pulling image \"envoyproxy/envoy-distroless:v1.29.3\"","event":{"namespace":"default","name":"pachyderm-proxy-5585cd764c-64hgc.17c995ceb69929b2","involvedObject":{"name":"Pod/pachyderm-proxy-5585cd764c-64hgc","fieldPath":"spec.containers{envoy}"},"reason":"Pulling","source.component":"kubelet","source.host":"pach-control-plane","firstTimestamp":1714065848,"lastTimestamp":1714065848,"count":1,"reportingController":"kubelet","reportingInstance":"pach-control-plane"}}
{"level":"info","ts":1714068522.904987,"logger":"event","caller":"kube-event-tail/main.go:98","msg":"Successfully pulled image \"envoyproxy/envoy-distroless:v1.29.3\" in 2.583s (16.581s including waiting)","event":{"namespace":"default","name":"pachyderm-proxy-5585cd764c-64hgc.17c995d292f3eaf0","involvedObject":{"name":"Pod/pachyderm-proxy-5585cd764c-64hgc","fieldPath":"spec.containers{envoy}"},"reason":"Pulled","source.component":"kubelet","source.host":"pach-control-plane","firstTimestamp":1714065864,"lastTimestamp":1714065864,"count":1,"reportingController":"kubelet","reportingInstance":"pach-control-plane"}}
{"level":"info","ts":1714068522.904992,"logger":"event","caller":"kube-event-tail/main.go:98","msg":"Created container envoy","event":{"namespace":"default","name":"pachyderm-proxy-5585cd764c-64hgc.17c995d295307ab9","involvedObject":{"name":"Pod/pachyderm-proxy-5585cd764c-64hgc","fieldPath":"spec.containers{envoy}"},"reason":"Created","source.component":"kubelet","source.host":"pach-control-plane","firstTimestamp":1714065864,"lastTimestamp":1714065864,"count":1,"reportingController":"kubelet","reportingInstance":"pach-control-plane"}}
{"level":"info","ts":1714068522.904999,"logger":"event","caller":"kube-event-tail/main.go:98","msg":"Started container envoy","event":{"namespace":"default","name":"pachyderm-proxy-5585cd764c-64hgc.17c995d29c018add","involvedObject":{"name":"Pod/pachyderm-proxy-5585cd764c-64hgc","fieldPath":"spec.containers{envoy}"},"reason":"Started","source.component":"kubelet","source.host":"pach-control-plane","firstTimestamp":1714065864,"lastTimestamp":1714065864,"count":1,"reportingController":"kubelet","reportingInstance":"pach-control-plane"}}
{"level":"info","ts":1714068522.9050033,"logger":"event","caller":"kube-event-tail/main.go:98","msg":"Created pod: pachyderm-proxy-5585cd764c-64hgc","event":{"namespace":"default","name":"pachyderm-proxy-5585cd764c.17c995ce16453e02","involvedObject":{"name":"ReplicaSet/pachyderm-proxy-5585cd764c"},"reason":"SuccessfulCreate","source.component":"replicaset-controller","firstTimestamp":1714065845,"lastTimestamp":1714065845,"count":1,"reportingController":"replicaset-controller"}}
{"level":"info","ts":1714068522.9050078,"logger":"event","caller":"kube-event-tail/main.go:98","msg":"Scaled up replica set pachyderm-proxy-5585cd764c to 1","event":{"namespace":"default","name":"pachyderm-proxy.17c995ce15c52fe2","involvedObject":{"name":"Deployment/pachyderm-proxy"},"reason":"ScalingReplicaSet","source.component":"deployment-controller","firstTimestamp":1714065845,"lastTimestamp":1714065845,"count":1,"reportingController":"deployment-controller"}}
{"level":"info","ts":1714068522.9050121,"logger":"event","caller":"kube-event-tail/main.go:98","msg":"0/1 nodes are available: 1 node(s) had untolerated taint {node.kubernetes.io/not-ready: }. preemption: 0/1 nodes are available: 1 Preemption is not helpful for scheduling.","event":{"namespace":"default","name":"pg-bouncer-7f45dc7865-cmrt7.17c995ce16f357f2","involvedObject":{"name":"Pod/pg-bouncer-7f45dc7865-cmrt7"},"reason":"FailedScheduling","source.component":"default-scheduler","firstTimestamp":1714065845,"lastTimestamp":1714065845,"count":1,"reportingController":"default-scheduler","type":"Warning"}}
{"level":"info","ts":1714068522.9050171,"logger":"event","caller":"kube-event-tail/main.go:98","msg":"Successfully assigned default/pg-bouncer-7f45dc7865-cmrt7 to pach-control-plane","event":{"namespace":"default","name":"pg-bouncer-7f45dc7865-cmrt7.17c995ce891b42a6","involvedObject":{"name":"Pod/pg-bouncer-7f45dc7865-cmrt7"},"reason":"Scheduled","source.component":"default-scheduler","firstTimestamp":1714065847,"lastTimestamp":1714065847,"count":1,"reportingController":"default-scheduler"}}
{"level":"info","ts":1714068522.9050236,"logger":"event","caller":"kube-event-tail/main.go:98","msg":"Pulling image \"pachyderm/pgbouncer:1.16.2\"","event":{"namespace":"default","name":"pg-bouncer-7f45dc7865-cmrt7.17c995ceb5a52e9b","involvedObject":{"name":"Pod/pg-bouncer-7f45dc7865-cmrt7","fieldPath":"spec.containers{pg-bouncer}"},"reason":"Pulling","source.component":"kubelet","source.host":"pach-control-plane","firstTimestamp":1714065848,"lastTimestamp":1714065848,"count":1,"reportingController":"kubelet","reportingInstance":"pach-control-plane"}}
{"level":"info","ts":1714068522.9050283,"logger":"event","caller":"kube-event-tail/main.go:98","msg":"Successfully pulled image \"pachyderm/pgbouncer:1.16.2\" in 6.15s (12.636s including waiting)","event":{"namespace":"default","name":"pg-bouncer-7f45dc7865-cmrt7.17c995d1a6d25c21","involvedObject":{"name":"Pod/pg-bouncer-7f45dc7865-cmrt7","fieldPath":"spec.containers{pg-bouncer}"},"reason":"Pulled","source.component":"kubelet","source.host":"pach-control-plane","firstTimestamp":1714065860,"lastTimestamp":1714065860,"count":1,"reportingController":"kubelet","reportingInstance":"pach-control-plane"}}
{"level":"info","ts":1714068522.905033,"logger":"event","caller":"kube-event-tail/main.go:98","msg":"Created container pg-bouncer","event":{"namespace":"default","name":"pg-bouncer-7f45dc7865-cmrt7.17c995d1a94dcf2c","involvedObject":{"name":"Pod/pg-bouncer-7f45dc7865-cmrt7","fieldPath":"spec.containers{pg-bouncer}"},"reason":"Created","source.component":"kubelet","source.host":"pach-control-plane","firstTimestamp":1714065860,"lastTimestamp":1714065860,"count":1,"reportingController":"kubelet","reportingInstance":"pach-control-plane"}}
{"level":"info","ts":1714068522.9050379,"logger":"event","caller":"kube-event-tail/main.go:98","msg":"Started container pg-bouncer","event":{"namespace":"default","name":"pg-bouncer-7f45dc7865-cmrt7.17c995d1b0519d1d","involvedObject":{"name":"Pod/pg-bouncer-7f45dc7865-cmrt7","fieldPath":"spec.containers{pg-bouncer}"},"reason":"Started","source.component":"kubelet","source.host":"pach-control-plane","firstTimestamp":1714065861,"lastTimestamp":1714065861,"count":1,"reportingController":"kubelet","reportingInstance":"pach-control-plane"}}
{"level":"info","ts":1714068522.9050424,"logger":"event","caller":"kube-event-tail/main.go:98","msg":"Created pod: pg-bouncer-7f45dc7865-cmrt7","event":{"namespace":"default","name":"pg-bouncer-7f45dc7865.17c995ce16c45860","involvedObject":{"name":"ReplicaSet/pg-bouncer-7f45dc7865"},"reason":"SuccessfulCreate","source.component":"replicaset-controller","firstTimestamp":1714065845,"lastTimestamp":1714065845,"count":1,"reportingController":"replicaset-controller"}}
{"level":"info","ts":1714068522.9050498,"logger":"event","caller":"kube-event-tail/main.go:98","msg":"Scaled up replica set pg-bouncer-7f45dc7865 to 1","event":{"namespace":"default","name":"pg-bouncer.17c995ce15c29f9d","involvedObject":{"name":"Deployment/pg-bouncer"},"reason":"ScalingReplicaSet","source.component":"deployment-controller","firstTimestamp":1714065845,"lastTimestamp":1714065845,"count":1,"reportingController":"deployment-controller"}}
{"level":"info","ts":1714068522.9050546,"logger":"event","caller":"kube-event-tail/main.go:98","msg":"0/1 nodes are available: 1 node(s) had untolerated taint {node.kubernetes.io/not-ready: }. preemption: 0/1 nodes are available: 1 Preemption is not helpful for scheduling.","event":{"namespace":"default","name":"postgres-0.17c995ce1a33333d","involvedObject":{"name":"Pod/postgres-0"},"reason":"FailedScheduling","source.component":"default-scheduler","firstTimestamp":1714065845,"lastTimestamp":1714065845,"count":1,"reportingController":"default-scheduler","type":"Warning"}}
{"level":"info","ts":1714068522.9050753,"logger":"event","caller":"kube-event-tail/main.go:98","msg":"Successfully assigned default/postgres-0 to pach-control-plane","event":{"namespace":"default","name":"postgres-0.17c995cfb3cd809a","involvedObject":{"name":"Pod/postgres-0"},"reason":"Scheduled","source.component":"default-scheduler","firstTimestamp":1714065852,"lastTimestamp":1714065852,"count":1,"reportingController":"default-scheduler"}}
{"level":"info","ts":1714068522.905084,"logger":"event","caller":"kube-event-tail/main.go:98","msg":"Pulling image \"docker.io/pachyderm/postgresql:13.3.0\"","event":{"namespace":"default","name":"postgres-0.17c995cfd0f35550","involvedObject":{"name":"Pod/postgres-0","fieldPath":"spec.containers{postgres}"},"reason":"Pulling","source.component":"kubelet","source.host":"pach-control-plane","firstTimestamp":1714065852,"lastTimestamp":1714065852,"count":1,"reportingController":"kubelet","reportingInstance":"pach-control-plane"}}
{"level":"info","ts":1714068522.9050908,"logger":"event","caller":"kube-event-tail/main.go:98","msg":"Successfully pulled image \"docker.io/pachyderm/postgresql:13.3.0\" in 4.572s (29.892s including waiting)","event":{"namespace":"default","name":"postgres-0.17c995d6c6b5083e","involvedObject":{"name":"Pod/postgres-0","fieldPath":"spec.containers{postgres}"},"reason":"Pulled","source.component":"kubelet","source.host":"pach-control-plane","firstTimestamp":1714065882,"lastTimestamp":1714065882,"count":1,"reportingController":"kubelet","reportingInstance":"pach-control-plane"}}
{"level":"info","ts":1714068522.9051266,"logger":"event","caller":"kube-event-tail/main.go:98","msg":"Created container postgres","event":{"namespace":"default","name":"postgres-0.17c995d6c95a34d2","involvedObject":{"name":"Pod/postgres-0","fieldPath":"spec.containers{postgres}"},"reason":"Created","source.component":"kubelet","source.host":"pach-control-plane","firstTimestamp":1714065882,"lastTimestamp":1714065882,"count":1,"reportingController":"kubelet","reportingInstance":"pach-control-plane"}}
{"level":"info","ts":1714068522.9051359,"logger":"event","caller":"kube-event-tail/main.go:98","msg":"Started container postgres","event":{"namespace":"default","name":"postgres-0.17c995d6cf4d4a72","involvedObject":{"name":"Pod/postgres-0","fieldPath":"spec.containers{postgres}"},"reason":"Started","source.component":"kubelet","source.host":"pach-control-plane","firstTimestamp":1714065883,"lastTimestamp":1714065883,"count":1,"reportingController":"kubelet","reportingInstance":"pach-control-plane"}}
{"level":"info","ts":1714068522.9051404,"logger":"event","caller":"kube-event-tail/main.go:98","msg":"create Claim data-postgres-0 Pod postgres-0 in StatefulSet postgres success","event":{"namespace":"default","name":"postgres.17c995ce17879e62","involvedObject":{"name":"StatefulSet/postgres"},"reason":"SuccessfulCreate","source.component":"statefulset-controller","firstTimestamp":1714065845,"lastTimestamp":1714065845,"count":1,"reportingController":"statefulset-controller"}}
{"level":"info","ts":1714068522.9051452,"logger":"event","caller":"kube-event-tail/main.go:98","msg":"create Pod postgres-0 in StatefulSet postgres successful","event":{"namespace":"default","name":"postgres.17c995ce18264c8f","involvedObject":{"name":"StatefulSet/postgres"},"reason":"SuccessfulCreate","source.component":"statefulset-controller","firstTimestamp":1714065845,"lastTimestamp":1714065845,"count":1,"reportingController":"statefulset-controller"}}
{"level":"info","ts":1714068522.9051495,"logger":"event","caller":"kube-event-tail/main.go:98","msg":"waiting for first consumer to be created before binding","event":{"namespace":"default","name":"storage-pachyderm-loki-0.17c995ce17473739","involvedObject":{"name":"PersistentVolumeClaim/storage-pachyderm-loki-0"},"reason":"WaitForFirstConsumer","source.component":"persistentvolume-controller","firstTimestamp":1714065845,"lastTimestamp":1714065845,"count":1,"reportingController":"persistentvolume-controller"}}
{"level":"info","ts":1714068522.905154,"logger":"event","caller":"kube-event-tail/main.go:98","msg":"Waiting for a volume to be created either by the external provisioner 'rancher.io/local-path' or manually by the system administrator. If volume creation is delayed, please verify that the provisioner is running and correctly registered.","event":{"namespace":"default","name":"storage-pachyderm-loki-0.17c995ce89bae111","involvedObject":{"name":"PersistentVolumeClaim/storage-pachyderm-loki-0"},"reason":"ExternalProvisioning","source.component":"persistentvolume-controller","firstTimestamp":1714065847,"lastTimestamp":1714065847,"count":1,"reportingController":"persistentvolume-controller"}}
{"level":"info","ts":1714068522.9051595,"logger":"event","caller":"kube-event-tail/main.go:98","msg":"External provisioner is provisioning volume for claim \"default/storage-pachyderm-loki-0\"","event":{"namespace":"default","name":"storage-pachyderm-loki-0.17c995ceb052e174","involvedObject":{"name":"PersistentVolumeClaim/storage-pachyderm-loki-0"},"reason":"Provisioning","source.component":"rancher.io/local-path_local-path-provisioner-7577fdbbfb-ldff9_07bdbd19-02b2-4c93-a877-75c260fa3e3f","firstTimestamp":1714065848,"lastTimestamp":1714065848,"count":1}}
{"level":"info","ts":1714068522.9051666,"logger":"event","caller":"kube-event-tail/main.go:98","msg":"Successfully provisioned volume pvc-9f17eee5-f857-47b7-963e-a092453c63b9","event":{"namespace":"default","name":"storage-pachyderm-loki-0.17c995cfaff7d649","involvedObject":{"name":"PersistentVolumeClaim/storage-pachyderm-loki-0"},"reason":"ProvisioningSucceeded","source.component":"rancher.io/local-path_local-path-provisioner-7577fdbbfb-ldff9_07bdbd19-02b2-4c93-a877-75c260fa3e3f","firstTimestamp":1714065852,"lastTimestamp":1714065852,"count":1}}
{"level":"info","ts":1714068977.9339397,"logger":"event","caller":"kube-event-tail/main.go:98","msg":"Successfully assigned default/console-75589574fd-bbf9t to pach-control-plane","event":{"namespace":"default","name":"console-75589574fd-bbf9t.17c996dd4dee45c5","involvedObject":{"name":"Pod/console-75589574fd-bbf9t"},"reason":"Scheduled","source.component":"default-scheduler","firstTimestamp":1714067010,"lastTimestamp":1714067010,"count":1,"reportingController":"default-scheduler"}}
{"level":"info","ts":1714068977.934003,"logger":"event","caller":"kube-event-tail/main.go:98","msg":"Container image \"pachyderm/haberdashery:2.8.0-alpha.5\" already present on machine","event":{"namespace":"default","name":"console-75589574fd-bbf9t.17c996dd6b26b757","involvedObject":{"name":"Pod/console-75589574fd-bbf9t","fieldPath":"spec.containers{console}"},"reason":"Pulled","source.component":"kubelet","source.host":"pach-control-plane","firstTimestamp":1714067010,"lastTimestamp":1714067010,"count":1,"reportingController":"kubelet","reportingInstance":"pach-control-plane"}}
{"level":"info","ts":1714068977.9340146,"logger":"event","caller":"kube-event-tail/main.go:98","msg":"Created container console","event":{"namespace":"default","name":"console-75589574fd-bbf9t.17c996dd6df0e72e","involvedObject":{"name":"Pod/console-75589574fd-bbf9t","fieldPath":"spec.containers{console}"},"reason":"Created","source.component":"kubelet","source.host":"pach-control-plane","firstTimestamp":1714067010,"lastTimestamp":1714067010,"count":1,"reportingController":"kubelet","reportingInstance":"pach-control-plane"}}
{"level":"info","ts":1714068977.9340203,"logger":"event","caller":"kube-event-tail/main.go:98","msg":"Started container console","event":{"namespace":"default","name":"console-75589574fd-bbf9t.17c996dd7503e35d","involvedObject":{"name":"Pod/console-75589574fd-bbf9t","fieldPath":"spec.containers{console}"},"reason":"Started","source.component":"kubelet","source.host":"pach-control-plane","firstTimestamp":1714067011,"lastTimestamp":1714067011,"count":1,"reportingController":"kubelet","reportingInstance":"pach-control-plane"}}
{"level":"info","ts":1714068977.934026,"logger":"event","caller":"kube-event-tail/main.go:98","msg":"Readiness probe failed: Get \"http://10.244.0.23:4000/health\": dial tcp 10.244.0.23:4000: connect: connection refused","event":{"namespace":"default","name":"console-75589574fd-bbf9t.17c996dd854bab61","involvedObject":{"name":"Pod/console-75589574fd-bbf9t","fieldPath":"spec.containers{console}"},"reason":"Unhealthy","source.component":"kubelet","source.host":"pach-control-plane","firstTimestamp":1714067011,"lastTimestamp":1714067011,"count":1,"reportingController":"kubelet","reportingInstance":"pach-control-plane","type":"Warning"}}
{"level":"info","ts":1714068977.934032,"logger":"event","caller":"kube-event-tail/main.go:98","msg":"Created pod: console-75589574fd-bbf9t","event":{"namespace":"default","name":"console-75589574fd.17c996dd4d7d949f","involvedObject":{"name":"ReplicaSet/console-75589574fd"},"reason":"SuccessfulCreate","source.component":"replicaset-controller","firstTimestamp":1714067010,"lastTimestamp":1714067010,"count":1,"reportingController":"replicaset-controller"}}
{"level":"info","ts":1714068977.9340382,"logger":"event","caller":"kube-event-tail/main.go:98","msg":"0/1 nodes are available: 1 node(s) had untolerated taint {node.kubernetes.io/not-ready: }. preemption: 0/1 nodes are available: 1 Preemption is not helpful for scheduling.","event":{"namespace":"default","name":"console-75f9f5b8d8-qvkwn.17c995ce1786fb19","involvedObject":{"name":"Pod/console-75f9f5b8d8-qvkwn"},"reason":"FailedScheduling","source.component":"default-scheduler","firstTimestamp":1714065845,"lastTimestamp":1714065845,"count":1,"reportingController":"default-scheduler","type":"Warning"}}
{"level":"info","ts":1714068977.9340441,"logger":"event","caller":"kube-event-tail/main.go:98","msg":"Successfully assigned default/console-75f9f5b8d8-qvkwn to pach-control-plane","event":{"namespace":"default","name":"console-75f9f5b8d8-qvkwn.17c995ce891cdec4","involvedObject":{"name":"Pod/console-75f9f5b8d8-qvkwn"},"reason":"Scheduled","source.component":"default-scheduler","firstTimestamp":1714065847,"lastTimestamp":1714065847,"count":1,"reportingController":"default-scheduler"}}
{"level":"info","ts":1714068977.9340491,"logger":"event","caller":"kube-event-tail/main.go:98","msg":"Pulling image \"pachyderm/haberdashery:2.8.0-alpha.5\"","event":{"namespace":"default","name":"console-75f9f5b8d8-qvkwn.17c995ceb6ca8b70","involvedObject":{"name":"Pod/console-75f9f5b8d8-qvkwn","fieldPath":"spec.containers{console}"},"reason":"Pulling","source.component":"kubelet","source.host":"pach-control-plane","firstTimestamp":1714065848,"lastTimestamp":1714065848,"count":1,"reportingController":"kubelet","reportingInstance":"pach-control-plane"}}
{"level":"info","ts":1714068977.9340549,"logger":"event","caller":"kube-event-tail/main.go:98","msg":"Successfully pulled image \"pachyderm/haberdashery:2.8.0-alpha.5\" in 13.475s (30.054s including waiting)","event":{"namespace":"default","name":"console-75f9f5b8d8-qvkwn.17c995d5b62ef554","involvedObject":{"name":"Pod/console-75f9f5b8d8-qvkwn","fieldPath":"spec.containers{console}"},"reason":"Pulled","source.component":"kubelet","source.host":"pach-control-plane","firstTimestamp":1714065878,"lastTimestamp":1714065878,"count":1,"reportingController":"kubelet","reportingInstance":"pach-control-plane"}}
{"level":"info","ts":1714068977.934061,"logger":"event","caller":"kube-event-tail/main.go:98","msg":"Created container console","event":{"namespace":"default","name":"console-75f9f5b8d8-qvkwn.17c995d5b8de059e","involvedObject":{"name":"Pod/console-75f9f5b8d8-qvkwn","fieldPath":"spec.containers{console}"},"reason":"Created","source.component":"kubelet","source.host":"pach-control-plane","firstTimestamp":1714065878,"lastTimestamp":1714065878,"count":1,"reportingController":"kubelet","reportingInstance":"pach-control-plane"}}
